Workbook
Name CMNOTES: #REF!
Name GLNo: '[1]GL#'!$A$2:$A$1329
Name RESULTS: #REF!
Name Status: #REF!

Sheet NEW OSAR
B1: CREFC Investor Reporting Package
C2: MULTIFAMILY OPERATING STATEMENT ANALYSIS REPORT (includes Mobile Home Parks, Single Family Rentals, and Co-ops)
C3: as of 03/31/2026
C4: PROPERTY OVERVIEW | H4: Allocated Loan Amount/Percentage
C5: Property ID | E5: 1001-001 | F5: Paid Thru Date | G5: Debt Outside Trust (1) | H5: $ | I5: %
C6: Note A-Scheduled Loan Balance | E6: 92071459 | G6: 0 | H6: 0 | I6: 0
C7: Note B-Scheduled Loan Balance | E7: 0 | G7: 0 | H7: 0 | I7: 0
C8: Note C-Scheduled Loan Balance | E8: 0 | G8: 0 | H8: 0 | I8: 0
C9: Property Name | E9: Strada
C10: Property Type | E10: MF
C11: Property Address, City, State | E11: 701 W Grove Pkwy, Tempe, AZ 85283
C12: Current Net Rentable SF/Units/Beds/Rooms | E12: 495 | G12: Use second box to specify sqft.,units…
C13: Year Built/Year Renovated | E13: 1995 | F13: 2020
C14: Cap Ex Reserve (annually)/per Unit.etc. (2) | E14: 250 | F14: 0 | G14: specify annual/per unit…
C15: Statement Ending Date | E15: Underwriting | F15: 45930 | G15: 46022 | H15: 46112 | I15: =H15 -> 46112
C16: Occupancy Rate (physical) | E16: =1-5.9% -> 0.941 | F16: 0.93333333 | G16: 0.91717172 | H16: 0.91919192 | I16: ='Rent Roll'!L543 -> 0.9195171 | M16: =I16-H16 -> 0.00032518342
C17: Occupancy Date | F17: 45930 | G17: 46022 | H17: 46112 | I17: =I15 -> 46112
E18: (1) "X" if debt is outside of the trust, otherwise leave blank
E19: (2) Total $ amount of Capital Reserves required annually by loan documents
C20: INCOME:
C21: Number of Mos. Covered | F21: 12 | G21: 12 | H21: 12 | I21: 12 | J21: (prcdng yr to base) | K21: (prcdng yr to 2nd prcdng)
C22: Period Ended | E22: At Contribution | F22: DY TEST | G22: DY TEST | H22: TTM | I22: DY TEST | J22: YYYY-U/W | K22: YYYY-YYYY
C23: Statement Ending Date | E23: Information | F23: as of 09/30/2025 | G23: as of 12/31/2025 | H23: =I23 -> as of 03/31/2026 | I23: ="as of "&TEXT(I15,"MM/DD/YYYY") -> as of 03/31/2026 | J23: Variance | K23: Variance | L23: Notes
C24: Gross Potential Rent (3) | E24: 8474519 | F24: 7840380 | G24: 7679808 | H24: =INDEX('Operating Statement'!W:W,MATCH('NEW OSAR'!$C24,'Operating Statement'!V:V,0)) -> 7969528.7 | I24: =('Rent Roll'!M542*12)+'Operating Statement'!R54 -> 7693836 | J24: =IF(E24=0, " ",(H24-E24)/E24) -> -0.05958926 | K24: =IF(G24=0, " ",(H24-G24)/G24) -> 0.037724987 | L24: Annualized Rent Roll as of 3/31/2026 less delinquent rents 60+ days | N24: =I24-G24 -> 14028 | O24: =(I24-G24)/G24 -> 0.0018266082
C25: Less: Vacancy Loss | E25: -499996.62 | F25: 0 | G25: 0 | H25: =INDEX('Operating Statement'!W:W,MATCH('NEW OSAR'!$C25,'Operating Statement'!V:V,0)) -> -576358.57 | I25: =IF(I16>0.95,(I24/I16)*M25,0) -> 0 | J25: =IF(E25=0, " ",(H25-E25)/E25) -> 0.15272493 | K25: =IF(G25=0, " ",(H25-G25)/G25) | L25: ="Greater of actual vacancy ("&TEXT(1-I16,"0.00%")&") and 5.00%" -> Greater of actual vacancy (8.05%) and 5.00% | M25: =5%-(1-I16) -> -0.030482897
C26: OR
C27: Base Rent (3) | H27: =INDEX('Operating Statement'!W:W,MATCH('NEW OSAR'!$C27,'Operating Statement'!V:V,0)) -> 0 | I27: =SUMIF('Operating Statement'!A:A,'NEW OSAR'!$C27,'Operating Statement'!S:S) -> 0 | J27: =IF(E27=0, " ",(H27-E27)/E27) | K27: =IF(G27=0, " ",(H27-G27)/G27) | L27: =IF(G27=0, " ",(J27-G27)/G27)
C28: Laundry/Vending Income | E28: 0 | F28: 0 | G28: 0 | H28: =INDEX('Operating Statement'!W:W,MATCH('NEW OSAR'!$C28,'Operating Statement'!V:V,0)) -> 0 | I28: =SUMIF('Operating Statement'!A:A,'NEW OSAR'!$C28,'Operating Statement'!S:S) -> 0 | J28: =IF(E28=0, " ",(H28-E28)/E28) | K28: =IF(G28=0, " ",(H28-G28)/G28) | L28: =IF(G28=0, " ",(J28-G28)/G28)
C29: Parking Income | E29: 0 | F29: 45753.12 | G29: 43723.24 | H29: =INDEX('Operating Statement'!W:W,MATCH('NEW OSAR'!$C29,'Operating Statement'!V:V,0)) -> 44205.67 | I29: =SUMIF('Operating Statement'!A:A,'NEW OSAR'!$C29,'Operating Statement'!S:S) -> 43379.96 | J29: =IF(E29=0, " ",(H29-E29)/E29) | K29: =IF(G29=0, " ",(H29-G29)/G29) -> 0.01103372 | L29: T3A | N29: =I29-G29 -> -343.28 | O29: =(I29-G29)/G29 -> -0.0078512022
C30: Other Income | E30: =1242919.25-117056-10606-114839.31 -> 1000417.9 | F30: 793695.26 | G30: 812340.8 | H30: =INDEX('Operating Statement'!W:W,MATCH('NEW OSAR'!$C30,'Operating Statement'!V:V,0)) -> 1009345 | I30: ='Operating Statement'!R55 -> 820163.88 | J30: =IF(E30=0, " ",(H30-E30)/E30) -> 0.0089233406 | K30: =IF(G30=0, " ",(H30-G30)/G30) -> 0.24251424 | L30: T3A total less T6A concessions + T6 special allowance | N30: =I30-G30 -> 7823.08 | O30: =(I30-G30)/G30 -> 0.0096302931
C32: *Effective Gross Income | E32: =SUM(E24:E30) -> 8974940.3 | F32: 8679828.4 | G32: 8535872 | H32: =INDEX('Operating Statement'!W:W,MATCH('NEW OSAR'!$C32,'Operating Statement'!V:V,0)) -> 8446720.8 | I32: =SUM(I24:I30) -> 8557379.8 | J32: =IF(E32=0, " ",(H32-E32)/E32) -> -0.058854935 | K32: =IF(G32=0, " ",(H32-G32)/G32) -> -0.010444307 | L32: =IF(G32=0, " ",(I32-G32)/G32) -> 0.0025196957 | N32: =I32-G32 -> 21507.8 | O32: =(I32-G32)/G32 -> 0.0025196957
E33: (3) Use either Gross Potential (with Vacancy Loss) or Base Rents; use negative $amt for Vacancy Loss
C35: OPERATING EXPENSES: | J35: =IF(E35=0, " ",(H35-E35)/E35) | L35: =IF(G35=0, " ",(J35-G35)/G35)
C36: Real Estate Taxes | E36: 387583 | F36: 384021.67 | G36: 385107.81 | H36: =INDEX('Operating Statement'!W:W,MATCH('NEW OSAR'!$C36,'Operating Statement'!V:V,0)) -> 389066.52 | I36: =MAX(H36,Tax!B3) -> 389066.52 | J36: =IF(E36=0, " ",(H36-E36)/E36) -> 0.0038276189 | K36: =IF(G36=0, " ",(H36-G36)/G36) -> 0.010279485 | L36: Greater of actual 2025 tax bill dated 5/18/2026 ($382.2K) and T12 ending 3/31/2026 | N36: =I36-G36 -> 3958.71 | O36: =(I36-G36)/G36 -> 0.010279485
C37: Property Insurance | E37: 139580.38 | F37: 130448.95 | G37: 131369.85 | H37: =INDEX('Operating Statement'!W:W,MATCH('NEW OSAR'!$C37,'Operating Statement'!V:V,0)) -> 130999.1 | I37: =INDEX('Operating Statement'!W:W,MATCH('NEW OSAR'!$C37,'Operating Statement'!V:V,0)) -> 130999.1 | J37: =IF(E37=0, " ",(H37-E37)/E37) -> -0.061479104 | K37: =IF(G37=0, " ",(H37-G37)/G37) -> -0.0028221848 | L37: Greater of actual insurance premium from 6/28/2025-6/28/2026 ($130.4K) | N37: =I37-G37 -> -370.75 | O37: =(I37-G37)/G37 -> -0.0028221848
C38: Utilities | E38: =287016.97+42872 -> 329888.97 | F38: 368598.31 | G38: 374867.92 | H38: =INDEX('Operating Statement'!W:W,MATCH('NEW OSAR'!$C38,'Operating Statement'!V:V,0)) -> 411158.29 | I38: =H38 -> 411158.29 | J38: =IF(E38=0, " ",(H38-E38)/E38) -> 0.24635355 | K38: =IF(G38=0, " ",(H38-G38)/G38) -> 0.096808417 | L38: T12 ended 3/31/2026 | N38: =I38-G38 -> 36290.37 | O38: =(I38-G38)/G38 -> 0.096808417
C39: Repairs and Maintenance | E39: 232268.57 | F39: 381931.97 | G39: 367637.38 | H39: =INDEX('Operating Statement'!W:W,MATCH('NEW OSAR'!$C39,'Operating Statement'!V:V,0)) -> 354217.02 | I39: =H39 -> 354217.02 | J39: =IF(E39=0, " ",(H39-E39)/E39) -> 0.52503208 | K39: =IF(G39=0, " ",(H39-G39)/G39) -> -0.03650434 | L39: T12 ended 3/31/2026 | N39: =I39-G39 -> -13420.36 | O39: =(I39-G39)/G39 -> -0.03650434
C40: Management Fees | E40: 314494.13 | F40: 260394.85 | G40: 256076.16 | H40: =INDEX('Operating Statement'!W:W,MATCH('NEW OSAR'!$C40,'Operating Statement'!V:V,0)) -> 210758.11 | I40: =MAX(H40,(I32*M40)) -> 256721.4 | J40: =IF(E40=0, " ",(H40-E40)/E40) -> -0.32985042 | K40: =IF(G40=0, " ",(H40-G40)/G40) -> -0.17697099 | L40: Greater of actual fees and 3% of EGI | M40: 0.03 | N40: =I40-G40 -> 645.234 | O40: =(I40-G40)/G40 -> 0.0025196957
C41: Payroll & Benefits | E41: 574480.84 | F41: 571910.18 | G41: 583888.92 | H41: =INDEX('Operating Statement'!W:W,MATCH('NEW OSAR'!$C41,'Operating Statement'!V:V,0)) -> 589879.68 | I41: =H41 -> 589879.68 | J41: =IF(E41=0, " ",(H41-E41)/E41) -> 0.026804793 | K41: =IF(G41=0, " ",(H41-G41)/G41) -> 0.010260102 | L41: T12 ended 3/31/2026 | N41: =I41-G41 -> 5990.76 | O41: =(I41-G41)/G41 -> 0.010260102
C42: Advertising & Marketing | E42: 91494.43 | F42: 123097.15 | G42: 129586.72 | H42: =INDEX('Operating Statement'!W:W,MATCH('NEW OSAR'!$C42,'Operating Statement'!V:V,0)) -> 107708.43 | I42: =H42 -> 107708.43 | J42: =IF(E42=0, " ",(H42-E42)/E42) -> 0.17721297 | K42: =IF(G42=0, " ",(H42-G42)/G42) -> -0.16883127 | L42: T12 ended 3/31/2026 | N42: =I42-G42 -> -21878.29 | O42: =(I42-G42)/G42 -> -0.16883127
...

Sheet Paydown Scenario
B2: DY
B3: Target DY | D3: 0.0625
B5: Current Principal | D5: =#REF! -> #REF!
B6: Paydown | D6: =+IF(D9/D5<D3,D5-(D9/D3),0) -> #REF!
B7: Total Principal | D7: =+D5-D6 -> #REF!
B9: Current Net Cash Flow | D9: =#REF! -> #REF!
B11: Needed Net Cash Flow | D11: =+D5*D3 -> #REF!
B12: DY | D12: =D11/D5 -> #REF!
B13: NCF Change | D13: =D11-D9 -> #REF!

Sheet Comm OSAR
C1: CREFC Investor Reporting Package
C2: COMMERCIAL OPERATING STATEMENT ANALYSIS REPORT (includes Retail/Office/Industrial/Mixed Use/Self Storage)
C3: as of MM/DD/YY
C4: PROPERTY OVERVIEW | H4: Allocated Loan Amount/Percentage
C5: Property ID | E5: 1001-001 | F5: Paid Thru Date | G5: Debt Outside Trust (1) | H5: $ | I5: %
C6: Note A-Scheduled Loan Balance | E6: 0 | F6: MM/DD/YY | G6: X or Blank | H6: 0 | I6: 0
C7: Note B-Scheduled Loan Balance | E7: 0 | F7: MM/DD/YY | G7: X or Blank | H7: 0 | I7: 0
C8: Note C-Scheduled Loan Balance | E8: 0 | F8: MM/DD/YY | G8: X or Blank | H8: 0 | I8: 0
C9: Property Name
C10: Property Type
C11: Property Address, City, State
C12: Current Net Rentable SF/Units/Beds/Rooms | G12: Use second box to specify sqft.,units…
C13: Year Built/Year Renovated | E13: YYYY | F13: YYYY
C14: Cap Ex Reserve (annually)/per Unit.etc. (2) | E14: 0 | F14: 0 | G14: specify annual/per unit…
C15: Statement Ending Date | E15: Underwriting | F15: MM/DD/YY | G15: MM/DD/YY | H15: MM/DD/YY | I15: MM/DD/YY
C16: Occupancy Rate (physical) | E16: 0 | F16: 0 | G16: 0 | H16: 0 | I16: 0
C17: Occupancy Date | E17: MM/DD/YY | F17: MM/DD/YY | G17: MM/DD/YY | H17: MM/DD/YY | I17: MM/DD/YY
E18: (1) "X" if debt is outside of the trust, otherwise leave blank
E19: (2) Total $ amount of Capital Reserves required annually by loan documents
C21: INCOME:
C22: Number of Mos. Covered
C23: Period Ended | E23: At Contribution | F23: 3rd Preceding | G23: 2nd Preceding | H23: Preceding Yr. | I23: TTM/YTD | J23: DY Test | K23: Notes
C24: Statement Ending Date | E24: Information | H24: (fm NOI Adj Sheet) | I24: as of / / | J24: as of / /
C25: Gross Potential Rent (3)
C26: Less: Vacancy Loss
C27: OR
C28: Base Rent (3)
C29: Expense Reimbursement
C30: Percentage Rent
C31: Parking Income
C32: Other Income
C34: *Effective Gross Income
E35: (3) Use either Gross Potential (with Vacancy Loss) or Base Rents; use negative $amt for Vacancy Loss
C37: OPERATING EXPENSES:
C38: Real Estate Taxes
C39: Property Insurance
C40: Utilities
C41: Repairs and Maintenance
C42: Janitorial
C43: Management Fees
...

Sheet Operating Statement
B3: Location: Strada
B4: Strada
AC5: MULTIFAMILY CASH FLOW
B6: Knightvest Management LLC | AC6: Strada
B7: 12 Month Income Statement | AC7: Investment Year | AD7: IRE In-Place NOI Definition | AE7: 1 | AF7: 2 | AG7: 3 | AH7: 4 | AI7: 5 | AJ7: 6 | AK7: 7 | AL7: 8 | AM7: 9 | AN7: 10
B8: Reporting Book: | C8: ACCRUAL | AC8: Year Ending | AE8: 46173 | AF8: 46538 | AG8: 46904 | AH8: 47269 | AI8: 47634 | AJ8: 47999 | AK8: 48365 | AL8: 48730 | AM8: 49095 | AN8: 49460
B9: As of Date: | C9: 03/31/2026
AC10: INCOME | AD10: $ Gross
C11: Month Ending | D11: Month Ending | E11: Month Ending | F11: Month Ending | G11: Month Ending | H11: Month Ending | I11: Month Ending | J11: Month Ending | K11: Month Ending | L11: Month Ending | M11: Month Ending | N11: Month Ending | O11: Total | AC11: Potential Rental Revenue | AD11: 8474519 | AE11: 8357667.1 | AF11: 8579313.5 | AG11: 8960894.7 | AH11: 9318313.2 | AI11: 9674923.9 | AJ11: 9995970.5 | AK11: 10295850 | AL11: 10604725 | AM11: 10922867 | AN11: 11250553
C12: 04/30/2025 | D12: 05/31/2025 | E12: 06/30/2025 | F12: 07/31/2025 | G12: 08/31/2025 | H12: 09/30/2025 | I12: 10/31/2025 | J12: 11/30/2025 | K12: 12/31/2025 | L12: 01/31/2026 | M12: 02/28/2026 | N12: 03/31/2026 | O12: 03/31/2026 | AC12: Loss To Lease | AD12: 0 | AE12: 33125.696 | AF12: -103648.36 | AG12: -153090.98 | AH12: -156337.08 | AI12: -147550.63 | AJ12: -121551.92 | AK12: -111673.93 | AL12: -110350.84 | AM12: -108988.06 | AN12: -107584.39
C13: Actual | D13: Actual | E13: Actual | F13: Actual | G13: Actual | H13: Actual | I13: Actual | J13: Actual | K13: Actual | L13: Actual | M13: Actual | N13: Actual | O13: Actual | AC13: Scheduled Base Rental Revenue | AD13: 8474519 | AE13: 8390792.8 | AF13: 8475665.2 | AG13: 8807803.7 | AH13: 9161976.1 | AI13: 9527373.3 | AJ13: 9874418.6 | AK13: 10184176 | AL13: 10494374 | AM13: 10813879 | AN13: 11142968
B14: INCOME | AC14: Other Income | AD14: 1242919.2 | AE14: 1220508 | AF14: 1503810.3 | AG14: 1640643.9 | AH14: 1679333.5 | AI14: 1718943.7 | AJ14: 1759496.8 | AK14: 1801015.2 | AL14: 1843522.3 | AM14: 1887041.6 | AN14: 1931597.6
AC15: Potential Gross Income | AD15: 9717438.2 | AE15: 9611300.8 | AF15: 9979475.5 | AG15: 10448448 | AH15: 10841310 | AI15: 11246317 | AJ15: 11633915 | AK15: 11985191 | AL15: 12337897 | AM15: 12700920 | AN15: 13074566
B16: RENTAL REVENUE | Q16: Annualized T12 | R16: Annualized T6 | S16: Annualized T3 | V16: 46022 | W16: T12 ROLLUP | X16: Lender Calc | AC16: Minus: Vacancy | AD16: -499996.62 | AE16: -461493.6 | AF16: -466161.58 | AG16: -484429.2 | AH16: -503908.69 | AI16: -524005.53 | AJ16: -543093.02 | AK16: -560129.66 | AL16: -577190.58 | AM16: -594763.33 | AN16: -612863.26
A17: Gross Potential Rent (3) | B17: 4001.000 - Gross Potential Rent | C17: 710972.5 | D17: 709919.04 | E17: 709165.83 | F17: 707103.39 | G17: 706700.48 | H17: 706373.63 | I17: 707219.04 | J17: 658440 | K17: 657027.42 | L17: 677622.1 | M17: 692639.3 | N17: 692640 | O17: 8335822.7 | Q17: =IF(SUM(C17:N17)=0,0,SUM(C17:N17)) -> 8335822.7 | R17: =IF(Q17=0,0,SUM(I17:N17)*2) -> 8171175.7 | S17: =IF(Q17=0,0,SUM(L17:N17)*4) -> 8251605.6 | V17: Gross Potential Rent (3) | W17: =SUMIF(A:A,$V17,O:O) -> 7969528.7 | AC17: Minus: Credit Loss | AD17: -114839.31 | AE17: -125861.89 | AF17: -105945.81 | AG17: -88078.037 | AH17: -91619.761 | AI17: -95273.733 | AJ17: -98744.186 | AK17: -101841.76 | AL17: -104943.74 | AM17: -108138.79 | AN17: -111429.68
A18: Less: Vacancy Loss | B18: 4002.000 - Loss/Gain to Lease | C18: -2799.58 | D18: -2650.15 | E18: -2687.68 | F18: -4409.17 | G18: -3076.69 | H18: -5544.37 | I18: -5613.39 | J18: 37972.64 | K18: 37968.9 | L18: 18710.7 | M18: 3754.9 | N18: 3279.74 | O18: 74905.85 | Q18: =IF(SUM(C18:N18)=0,0,SUM(C18:N18)) -> 74905.85 | R18: =IF(Q18=0,0,SUM(I18:N18)*2) -> 192146.98 | S18: =IF(Q18=0,0,SUM(L18:N18)*4) -> 102981.36 | V18: Less: Vacancy Loss | W18: =SUMIF(A:A,$V18,O:O) -> -576358.57 | AC18: Minus: Model Unit | AD18: 0 | AE18: 0 | AF18: 0 | AG18: 0 | AH18: 0 | AI18: 0 | AJ18: 0 | AK18: 0 | AL18: 0 | AM18: 0 | AN18: 0
A19: Less: Vacancy Loss | B19: 4011.000 - Vacancy Loss | C19: -43114.26 | D19: -53948.19 | E19: -57543.33 | F19: -56344.1 | G19: -51258.7 | H19: -47472.31 | I19: -52857.62 | J19: -67000.77 | K19: -61906.17 | L19: -51872.73 | M19: -54647.44 | N19: -53298.8 | O19: -651264.42 | Q19: =IF(SUM(C19:N19)=0,0,SUM(C19:N19)) -> -651264.42 | R19: =IF(Q19=0,0,SUM(I19:N19)*2) -> -683167.06 | S19: =IF(Q19=0,0,SUM(L19:N19)*4) -> -639275.88 | AC19: Minus: Concessions Initial Lease Up | AD19: -117055.64 | AE19: -47462.588 | AF19: -36695.348 | AG19: -2996.4319 | AH19: 0 | AI19: 0 | AJ19: 0 | AK19: 0 | AL19: 0 | AM19: 0 | AN19: 0
A20: Gross Potential Rent (3) | B20: 4011.100 - Month to Month Rent | C20: 1867.85 | D20: 2266.4 | E20: 2106.89 | F20: 2499.91 | G20: 3028.37 | H20: 2796.34 | I20: 3222.05 | J20: 2775.95 | K20: 2887.84 | L20: 2276.35 | M20: 3193.24 | N20: 1918.15 | O20: 30839.34 | Q20: =IF(SUM(C20:N20)=0,0,SUM(C20:N20)) -> 30839.34 | R20: =IF(Q20=0,0,SUM(I20:N20)*2) -> 32547.16 | S20: =IF(Q20=0,0,SUM(L20:N20)*4) -> 29550.96 | V20: Base Rent (3) | W20: =SUMIF(A:A,$V20,O:O) -> 0 | AC20: Minus: Concessions Ongoing | AE20: -349333.62 | AF20: -177978.04 | AG20: -94639.172 | AH20: 0 | AI20: 0 | AJ20: 0 | AK20: 0 | AL20: 0 | AM20: 0 | AN20: 0
A21: Gross Potential Rent (3) | B21: 4012.000 - Discounts/Concessions | C21: 0 | D21: 0 | E21: 0 | F21: -200.52 | G21: -1554 | H21: -1554 | I21: -1554 | J21: -1554 | K21: -1554 | L21: -1604.13 | M21: -1665 | N21: -1554 | O21: -12793.65 | Q21: =IF(SUM(C21:N21)=0,0,SUM(C21:N21)) -> -12793.65 | R21: =IF(Q21=0,0,SUM(I21:N21)*2) -> -18970.26 | S21: =IF(Q21=0,0,SUM(L21:N21)*4) -> -19292.52 | V21: Laundry/Vending Income | W21: =SUMIF(A:A,$V21,O:O) -> 0 | AC21: Effective Gross Income | AD21: 8985546.7 | AE21: 8627149.1 | AF21: 9192694.7 | AG21: 9778304.8 | AH21: 10245781 | AI21: 10627038 | AJ21: 10992078 | AK21: 11323219 | AL21: 11655762 | AM21: 11998018 | AN21: 12350273
A22: Gross Potential Rent (3) | B22: 4014.000 - Bad Debt | C22: -8091.09 | D22: -2715.94 | E22: -27759.2 | F22: -3529.88 | G22: -3581.47 | H22: -12831.95 | I22: -18168.46 | J22: -12021.55 | K22: -12156.51 | L22: -35285.15 | M22: -248.68 | N22: -22978.88 | O22: -159368.76 | Q22: =IF(SUM(C22:N22)=0,0,SUM(C22:N22)) -> -159368.76 | R22: =IF(Q22=0,0,SUM(I22:N22)*2) -> -201718.46 | S22: =IF(Q22=0,0,SUM(L22:N22)*4) -> -234050.84 | V22: Parking Income | W22: =SUMIF(A:A,$V22,O:O) -> 44205.67
A23: Gross Potential Rent (3) | B23: 4040.000 - One-Time Special or Allowance | C23: -14875 | D23: -5032.26 | E23: 451 | F23: -8422.98 | G23: -34920.51 | H23: -47726.38 | I23: -22988.63 | J23: -9278.94 | K23: -1774.92 | L23: -30293.36 | M23: -35474.34 | N23: -14634.68 | O23: -224971 | Q23: =IF(SUM(C23:N23)=0,0,SUM(C23:N23)) -> -224971 | R23: =IF(Q23=0,0,SUM(I23:N23)*2) -> -228889.74 | S23: =IF(Q23=0,0,SUM(L23:N23)*4) -> -321609.52 | V23: Other Income | W23: =SUMIF(A:A,$V23,O:O) -> 1009345 | AC23: OPERATING EXPENSES | AD23: $ Gross
B24: NET RENTAL REVENUE | C24: 643960.42 | D24: 647838.9 | E24: 623733.51 | F24: 636696.65 | G24: 615337.48 | H24: 594040.96 | I24: 609258.99 | J24: 609333.33 | K24: 620492.56 | L24: 579553.78 | M24: 607551.98 | N24: 605371.53 | O24: 7393170.1 | Q24: =SUM(Q17:Q23) -> 7393170.1 | R24: =SUM(R17:R23) -> 7263124.3 | S24: =SUM(S17:S23) -> 7169909.2 | AC24: Payroll | AD24: 574480.84 | AE24: 569345.6 | AF24: 586425.97 | AG24: 604018.75 | AH24: 622139.31 | AI24: 640803.49 | AJ24: 660027.59 | AK24: 679828.42 | AL24: 700223.27 | AM24: 721229.97 | AN24: 742866.87
U25: =IF(W25=O49,"YES","NO") -> YES | V25: *Effective Gross Income | W25: =SUM(W17:W23) -> 8446720.8 | AC25: Employee Units | AD25: 10605.92 | AE25: 10924.098 | AF25: 11251.821 | AG25: 11589.375 | AH25: 11937.056 | AI25: 12295.168 | AJ25: 12664.023 | AK25: 13043.944 | AL25: 13435.262 | AM25: 13838.32 | AN25: 14253.47
B26: OTHER TENANT INCOME | AC26: Marketing | AD26: 91494.43 | AE26: 91575 | AF26: 94322.25 | AG26: 97151.917 | AH26: 100066.48 | AI26: 103068.47 | AJ26: 106160.52 | AK26: 109345.34 | AL26: 112625.7 | AM26: 116004.47 | AN26: 119484.6
A27: Other Income | B27: 4100.000 - Late Charges | C27: 5493 | D27: 9660 | E27: 2484.37 | F27: 7065 | G27: 8715 | H27: 9660 | I27: 5790 | J27: 10425 | K27: 12561.6 | L27: 2808 | M27: 9660 | N27: 3780.23 | O27: 88102.2 | Q27: =IF(SUM(C27:N27)=0,0,SUM(C27:N27)) -> 88102.2 | R27: =IF(Q27=0,0,SUM(I27:N27)*2) -> 90049.66 | S27: =IF(Q27=0,0,SUM(L27:N27)*4) -> 64992.92 | V27: OPERATING EXPENSES: | W27: =SUMIF(A:A,$V27,O:O) -> 0 | AC27: General & Admin. | AD27: 207771.55 | AE27: 210375 | AF27: 216686.25 | AG27: 223186.84 | AH27: 229882.44 | AI27: 236778.92 | AJ27: 243882.28 | AK27: 251198.75 | AL27: 258734.71 | AM27: 266496.76 | AN27: 274491.66
A28: Other Income | B28: 4120.000 - Application Fee Income | C28: 1500 | D28: 800 | E28: 1800 | F28: 2300 | G28: 2295.58 | H28: 1050 | I28: 200 | J28: 600 | K28: -50 | L28: 0 | M28: 0 | N28: 0 | O28: 10495.58 | Q28: =IF(SUM(C28:N28)=0,0,SUM(C28:N28)) -> 10495.58 | R28: =IF(Q28=0,0,SUM(I28:N28)*2) -> 1500 | S28: =IF(Q28=0,0,SUM(L28:N28)*4) -> 0 | V28: Real Estate Taxes | W28: =SUMIF(A:A,$V28,O:O) -> 389066.52 | AC28: Managed WiFi | AD28: 0 | AE28: 44550 | AF28: 183546 | AG28: 189052.38 | AH28: 194723.95 | AI28: 200565.67 | AJ28: 206582.64 | AK28: 212780.12 | AL28: 219163.52 | AM28: 225738.43 | AN28: 232510.58
A29: Other Income | B29: 4120.100 - Pet Fees | C29: 3801 | D29: 2872.34 | E29: 2839.68 | F29: 2641.94 | G29: 2611.45 | H29: 2473.33 | I29: 3661.46 | J29: 2903.5 | K29: 2888.07 | L29: 3905.02 | M29: 2993.75 | N29: 3424.35 | O29: 37015.89 | Q29: =IF(SUM(C29:N29)=0,0,SUM(C29:N29)) -> 37015.89 | R29: =IF(Q29=0,0,SUM(I29:N29)*2) -> 39552.3 | S29: =IF(Q29=0,0,SUM(L29:N29)*4) -> 41292.48 | V29: Property Insurance | W29: =SUMIF(A:A,$V29,O:O) -> 130999.1 | AC29: Landscaping/Grounds | AD29: 113265.91 | AE29: 111375 | AF29: 114716.25 | AG29: 118157.74 | AH29: 121702.47 | AI29: 125353.54 | AJ29: 129114.15 | AK29: 132987.57 | AL29: 136977.2 | AM29: 141086.52 | AN29: 145319.11
A30: Other Income | B30: 4120.200 - Administrative Fees | C30: 5400 | D30: 3100.69 | E30: 6875 | F30: 10179.03 | G30: 11150 | H30: 5450 | I30: 1683.07 | J30: 1850 | K30: 7800 | L30: 10000 | M30: 6000 | N30: 7750 | O30: 77237.79 | Q30: =IF(SUM(C30:N30)=0,0,SUM(C30:N30)) -> 77237.79 | R30: =IF(Q30=0,0,SUM(I30:N30)*2) -> 70166.14 | S30: =IF(Q30=0,0,SUM(L30:N30)*4) -> 95000 | V30: Utilities | W30: =SUMIF(A:A,$V30,O:O) -> 411158.29 | AC30: Make-ready | AD30: 0 | AE30: 0 | AF30: 0 | AG30: 0 | AH30: 0 | AI30: 0 | AJ30: 0 | AK30: 0 | AL30: 0 | AM30: 0 | AN30: 0
A31: Other Income | B31: 4124.000 - Lease Termination Fees | C31: 3915.58 | D31: 7301.51 | E31: 6030.86 | F31: 4375.64 | G31: 3907.48 | H31: 3745.08 | I31: 3513.02 | J31: 2993.54 | K31: 2924.22 | L31: 10335.01 | M31: 6742.67 | N31: 2852.95 | O31: 58637.56 | Q31: =IF(SUM(C31:N31)=0,0,SUM(C31:N31)) -> 58637.56 | R31: =IF(Q31=0,0,SUM(I31:N31)*2) -> 58722.82 | S31: =IF(Q31=0,0,SUM(L31:N31)*4) -> 79722.52 | V31: Repairs and Maintenance | W31: =SUMIF(A:A,$V31,O:O) -> 354217.02 | AC31: Repairs & Maint. | AD31: 232268.57 | AE31: 232268.57 | AF31: 239236.63 | AG31: 246413.73 | AH31: 253806.14 | AI31: 261420.32 | AJ31: 269262.93 | AK31: 277340.82 | AL31: 285661.04 | AM31: 294230.88 | AN31: 303057.8
A32: Parking Income | B32: 4140.000 - Reserved/ Covered Parking Fees | C32: 3611 | D32: 3717.59 | E32: 3663 | F32: 3819.67 | G32: 3861.26 | H32: 3757.35 | I32: 3692.92 | J32: 3651 | K32: 3586.89 | L32: 3644.49 | M32: 3561.79 | N32: 3638.71 | O32: 44205.67 | Q32: =IF(SUM(C32:N32)=0,0,SUM(C32:N32)) -> 44205.67 | R32: =IF(Q32=0,0,SUM(I32:N32)*2) -> 43551.6 | S32: =IF(Q32=0,0,SUM(L32:N32)*4) -> 43379.96 | V32: Management Fees | W32: =SUMIF(A:A,$V32,O:O) -> 210758.11 | AC32: Trash Expense | AD32: 42871.94 | AE32: 45045 | AF32: 46396.35 | AG32: 47788.24 | AH32: 49221.888 | AI32: 50698.544 | AJ32: 52219.501 | AK32: 53786.086 | AL32: 55399.668 | AM32: 57061.658 | AN32: 58773.508
A33: Other Income | B33: 4150.000 - Miscellaneous Income | C33: -826.67 | D33: 4721.78 | E33: 3229.02 | F33: 1661.33 | G33: 1759.53 | H33: 3333.07 | I33: 546.03 | J33: 5269.3 | K33: 2390.74 | L33: 5622.64 | M33: 1658.02 | N33: 1033.83 | O33: 30398.62 | Q33: =IF(SUM(C33:N33)=0,0,SUM(C33:N33)) -> 30398.62 | R33: =IF(Q33=0,0,SUM(I33:N33)*2) -> 33041.12 | S33: =IF(Q33=0,0,SUM(L33:N33)*4) -> 33257.96 | V33: Payroll & Benefits | W33: =SUMIF(A:A,$V33,O:O) -> 589879.68 | AC33: Security/Life Safety | AD33: 20740.1 | AE33: 25245 | AF33: 26002.35 | AG33: 26782.42 | AH33: 27585.893 | AI33: 28413.47 | AJ33: 29265.874 | AK33: 30143.85 | AL33: 31048.166 | AM33: 31979.611 | AN33: 32938.999
A34: Other Income | B34: 4150.100 - Cable/Internet Charges | C34: 7 | D34: 151.3 | E34: 619.68 | F34: 1494.84 | G34: 3201.9 | H34: 4362.44 | I34: 4644.46 | J34: 6360.67 | K34: 7056.44 | L34: 8744.64 | M34: 10446.94 | N34: 11940.66 | O34: 59030.97 | Q34: =IF(SUM(C34:N34)=0,0,SUM(C34:N34)) -> 59030.97 | R34: =IF(Q34=0,0,SUM(I34:N34)*2) -> 98387.62 | S34: =IF(Q34=0,0,SUM(L34:N34)*4) -> 124528.96 | V34: Advertising & Marketing | W34: =SUMIF(A:A,$V34,O:O) -> 107708.43 | AC34: Utilities | AD34: 287016.97 | AE34: 294525 | AF34: 303360.75 | AG34: 312461.57 | AH34: 321835.42 | AI34: 331490.48 | AJ34: 341435.2 | AK34: 351678.25 | AL34: 362228.6 | AM34: 373095.46 | AN34: 384288.32
A35: Other Income | B35: 4150.200 - Renters Insurance Charges | C35: 7283.15 | D35: 7288.32 | E35: 6946.32 | F35: 6895.83 | G35: 7339.34 | H35: 7252.47 | I35: 7072.01 | J35: 7007.73 | K35: 7064.69 | L35: 7094.77 | M35: 7248.44 | N35: 7140.91 | O35: 85633.98 | Q35: =IF(SUM(C35:N35)=0,0,SUM(C35:N35)) -> 85633.98 | R35: =IF(Q35=0,0,SUM(I35:N35)*2) -> 85257.1 | S35: =IF(Q35=0,0,SUM(L35:N35)*4) -> 85936.48 | V35: Professional Fees | W35: =SUMIF(A:A,$V35,O:O) -> 2732 | AC35: Insurance | AD35: 139580.38 | AE35: 139580.38 | AF35: 132601.36 | AG35: 135253.38 | AH35: 139310.99 | AI35: 143490.32 | AJ35: 147795.03 | AK35: 152228.88 | AL35: 156795.74 | AM35: 161499.61 | AN35: 166344.6
A36: Other Income | B36: 4150.300 - Transfer Fee | C36: 350 | D36: 0 | E36: 0 | F36: 0 | G36: 0 | H36: 750 | I36: 200 | J36: 1250 | K36: 0 | L36: 2450 | M36: -750 | N36: 1750 | O36: 6000 | Q36: =IF(SUM(C36:N36)=0,0,SUM(C36:N36)) -> 6000 | R36: =IF(Q36=0,0,SUM(I36:N36)*2) -> 9800 | S36: =IF(Q36=0,0,SUM(L36:N36)*4) -> 13800 | V36: General and Administrative | W36: =SUMIF(A:A,$V36,O:O) -> 238036.4 | AC36: Replacement Reserves | AD36: 123750 | AE36: 123750 | AF36: 123750 | AG36: 123750 | AH36: 123750 | AI36: 123750 | AJ36: 123750 | AK36: 123750 | AL36: 123750 | AM36: 123750 | AN36: 123750
A37: Other Income | B37: 4150.400 - Keys, Cards and Remotes | C37: 0 | D37: 0 | E37: 0 | F37: 0 | G37: 0 | H37: 0 | I37: 0 | J37: 5 | K37: 0 | L37: 0 | M37: 0 | N37: 0 | O37: 5 | Q37: =IF(SUM(C37:N37)=0,0,SUM(C37:N37)) -> 5 | R37: =IF(Q37=0,0,SUM(I37:N37)*2) -> 10 | S37: =IF(Q37=0,0,SUM(L37:N37)*4) -> 0 | V37: Other Expenses | W37: =SUMIF(A:A,$V37,O:O) -> 0 | AC37: Misc #2 | AD37: 0 | AE37: 0 | AF37: 0 | AG37: 0 | AH37: 0 | AI37: 0 | AJ37: 0 | AK37: 0 | AL37: 0 | AM37: 0 | AN37: 0
A38: Other Income | B38: 4150.600 - Technology Fee | C38: 13725 | D38: 13639.08 | E38: 13073.14 | F38: 13542.56 | G38: 13643.96 | H38: 13598.29 | I38: 13289.51 | J38: 13015.55 | K38: 13147.75 | L38: 13022.73 | M38: 13594.01 | N38: 13314.53 | O38: 160606.11 | Q38: =IF(SUM(C38:N38)=0,0,SUM(C38:N38)) -> 160606.11 | R38: =IF(Q38=0,0,SUM(I38:N38)*2) -> 158768.16 | S38: =IF(Q38=0,0,SUM(L38:N38)*4) -> 159725.08 | V38: Ground Rent | W38: =SUMIF(A:A,$V38,O:O) -> 0 | AC38: RE Taxes | AD38: 387583 | AE38: 387583 | AF38: 406962.15 | AG38: 427310.26 | AH38: 448675.77 | AI38: 471109.56 | AJ38: 494665.04 | AK38: 519398.29 | AL38: 545368.2 | AM38: 572636.61 | AN38: 601268.44
A39: Other Income | B39: 4160.000 - Utility Reimb/Water | C39: 19604.18 | D39: 19942.16 | E39: 20778.64 | F39: 21955.42 | G39: 21638.14 | H39: 21098.62 | I39: 28712.46 | J39: 28448.09 | K39: 24277.72 | L39: 18897.34 | M39: 19324.65 | N39: 20444.21 | O39: 265121.63 | Q39: =IF(SUM(C39:N39)=0,0,SUM(C39:N39)) -> 265121.63 | R39: =IF(Q39=0,0,SUM(I39:N39)*2) -> 280208.94 | S39: =IF(Q39=0,0,SUM(L39:N39)*4) -> 234664.8 | U39: =IF(W39=O138,"YES","NO") -> YES | V39: *Total Operating Expenses | W39: =SUM(W27:W38) -> 2434555.6 | AC39: Management Fee | AD39: 314494.13 | AE39: 301950.22 | AF39: 321744.31 | AG39: 342240.67 | AH39: 358602.34 | AI39: 371946.32 | AJ39: 384722.73 | AK39: 396312.68 | AL39: 407951.68 | AM39: 419930.64 | AN39: 432259.56
A40: Other Income | B40: 4161.000 - Utility Reimb/Electric | C40: 1727.91 | D40: 1599.61 | E40: 2261.64 | F40: 1607.7 | G40: 1578.72 | H40: 2256.44 | I40: 2475.36 | J40: 3856.12 | K40: 3533.05 | L40: 2044.64 | M40: 2000.75 | N40: 2241.36 | O40: 27183.3 | Q40: =IF(SUM(C40:N40)=0,0,SUM(C40:N40)) -> 27183.3 | R40: =IF(Q40=0,0,SUM(I40:N40)*2) -> 32302.56 | S40: =IF(Q40=0,0,SUM(L40:N40)*4) -> 25147 | AC40: Total Operating Expenses | AD40: 2545923.7 | AE40: 2588091.9 | AF40: 2807002.4 | AG40: 2905157.3 | AH40: 3003240.1 | AI40: 3101184.3 | AJ40: 3201547.5 | AK40: 3303823 | AL40: 3409362.8 | AM40: 3518578.9 | AN40: 3631607.5
A41: Other Income | B41: 4162.000 - Utility Reimb/Trash | C41: 4598.67 | D41: 4570.12 | E41: 4375.31 | F41: 4520.93 | G41: 4560.31 | H41: 4536.34 | I41: 4438.32 | J41: 4357.33 | K41: 4392.61 | L41: 4340.92 | M41: 4558.41 | N41: 4440.98 | O41: 53690.25 | Q41: =IF(SUM(C41:N41)=0,0,SUM(C41:N41)) -> 53690.25 | R41: =IF(Q41=0,0,SUM(I41:N41)*2) -> 53057.14 | S41: =IF(Q41=0,0,SUM(L41:N41)*4) -> 53361.24 | V41: Operating Expense Ratio | W41: =W39/W25 -> 0.28822494 | AC41: Operating Expenses % EGR | AE41: 0.29999387 | AF41: 0.30535143 | AG41: 0.29710234 | AH41: 0.29311969 | AI41: 0.2918202 | AJ41: 0.29125953 | AK41: 0.29177417 | AL41: 0.29250449 | AM41: 0.29326334 | AN41: 0.29405079
A42: Other Income | B42: 4163.000 - Utility Reimb/Pest Control | C42: 2300.66 | D42: 2283.74 | E42: 2187.69 | F42: 2260.5 | G42: 2280.17 | H42: 2268.14 | I42: 2219.13 | J42: 2178.67 | K42: 2196.29 | L42: 2175.47 | M42: 2279.28 | N42: 2220.49 | O42: 26850.23 | Q42: =IF(SUM(C42:N42)=0,0,SUM(C42:N42)) -> 26850.23 | R42: =IF(Q42=0,0,SUM(I42:N42)*2) -> 26538.66 | S42: =IF(Q42=0,0,SUM(L42:N42)*4) -> 26700.96 | AC42: Real Estate Taxes %/EGR | AE42: 0.044925965 | AF42: 0.044270169 | AG42: 0.04369983 | AH42: 0.04379127 | AI42: 0.044331221 | AJ42: 0.045001958 | AK42: 0.045870195 | AL42: 0.046789579 | AM42: 0.0477276 | AN42: 0.048684627
...

Sheet Rent Roll
A1: Knightvest Management LLC - Strada
A2: RENT ROLL DETAIL
A3: 05/15/2026 03:30 PM
A4: As of Date: 03/31/2026
A5: Parameters: Properties: - all subproperties-; Show All Unit Designations or Filter by: ALL; Subjournals: ALL; Sort by: Unit; Report Type: Details + Summary; Exclude Formers?: Yes; Show Unit Rent as: Market Rent; Hide all PII Data?: No
A6: Resh ID | B6: Lease ID | C6: Unit | D6: Floorplan | F6: Unit Designation | G6: SQFT | H6: Unit/Lease Status | I6: Name | J6: Move-In | K6: Move-Out | L6: Lease Start | M6: Lease End | N6: Market Rent | O6: Sub Journal | P6: Required Deposit | Q6: Dep On Hand | R6: Balance | S6: Lease Rent | T6: RENT | U6: SMARTHOME | V6: TRASHREIMB | W6: UTILITY | X6: PESTREIMNB | Y6: RENTERSINS | Z6: CARPORT | AA6: Internet | AB6: PETRENT | AC6: SHRTTERM | AD6: MTOM | AE6: CONC/SPECL | AF6: EMPLCRED | AG6: CARES | AH6: Total Billing
A7: 32095 | B7: 43131 | C7: 1-101 | D7: B2Q | E7: =RIGHT(D7,1) -> Q | F7: N/A | G7: 1076 | H7: Occupied | I7: Jou-Zanfack, Carine | J7: 01/14/2026 | L7: 01/14/2026 | M7: 01/13/2027 | N7: 1659 | O7: RESIDENT | P7: 0 | Q7: 0 | R7: 0 | S7: 1589 | T7: 1589 | U7: 30 | V7: 10 | W7: 5.5 | X7: 5 | Y7: 18 | Z7: 0 | AA7: 0 | AB7: 0 | AC7: 0 | AD7: 0 | AE7: 0 | AF7: 0 | AG7: 0 | AH7: 1657.5 | AJ7: Investment Year | AK7: 0 | AL7: 1 | AO7: MULTIFAMILY CASH FLOW
A8: 31530 | B8: 42707 | C8: 1-102 | D8: B2Q | E8: =RIGHT(D8,1) -> Q | F8: N/A | G8: 1076 | H8: Occupied | I8: Arellano, samantha | J8: 06/13/2025 | L8: 06/13/2025 | M8: 06/11/2026 | N8: 1659 | O8: RESIDENT | P8: 0 | Q8: 0 | R8: 62.69 | S8: 1689 | T8: 1689 | U8: 30 | V8: 10 | W8: 5.5 | X8: 5 | Y8: 18 | Z8: 0 | AA8: 0 | AB8: 0 | AC8: 0 | AD8: 0 | AE8: 0 | AF8: 0 | AG8: 0 | AH8: 1757.5 | AJ8: Year Ending | AK8: In Place | AL8: 46172 | AO8: Strada
A9: 31601 | B9: 42858 | C9: 1-103 | D9: B2G | E9: =RIGHT(D9,1) -> G | F9: N/A | G9: 1076 | H9: Occupied | I9: Walker, Darion | J9: 08/01/2025 | L9: 08/01/2025 | M9: 08/03/2026 | N9: 1609 | O9: RESIDENT | P9: 0 | Q9: 0 | R9: 0 | S9: 1639 | T9: 1639 | U9: 30 | V9: 10 | W9: 5.5 | X9: 5 | Y9: 18 | Z9: 30 | AA9: 0 | AB9: 0 | AC9: 0 | AD9: 0 | AE9: 0 | AF9: 0 | AG9: 0 | AH9: 1737.5 | AJ9: Annual Base Rent | AK9: =+AP15 -> 8474519 | AL9: =+AQ15 -> 8390792.8 | AO9: Investment Year | AP9: IRE In-Place NOI Definition | AQ9: 1 | AR9: 2 | AS9: 3 | AT9: 4 | AU9: 5 | AV9: 6 | AW9: 7 | AX9: 8 | AY9: 9 | AZ9: 10
A10: 768 | B10: 42766 | C10: 1-104 | D10: B2G | E10: =RIGHT(D10,1) -> G | F10: N/A | G10: 1076 | H10: Occupied | I10: Cesar, Maria | J10: 06/01/2022 | L10: 07/29/2025 | M10: 07/27/2026 | N10: 1609 | O10: RESIDENT | P10: 0 | Q10: 0 | R10: 0 | S10: 1730 | T10: 1730 | U10: 30 | V10: 10 | W10: 5.5 | X10: 5 | Y10: 18 | Z10: 15 | AA10: 0 | AB10: 0 | AC10: 0 | AD10: 0 | AE10: 0 | AF10: 0 | AG10: 0 | AH10: 1813.5 | AJ10: Monthly Base Rent | AK10: =AK9/12 -> 706209.91 | AL10: =AL9/12 -> 699232.73 | AO10: Year Ending | AQ10: 46173 | AR10: 46538 | AS10: 46904 | AT10: 47269 | AU10: 47634 | AV10: 47999 | AW10: 48365 | AX10: 48730 | AY10: 49095 | AZ10: 49460
A11: 31930 | B11: 42826 | C11: 1-105 | D11: B2G | E11: =RIGHT(D11,1) -> G | F11: N/A | G11: 1076 | H11: Occupied | I11: Wendy, FNU | J11: 07/11/2025 | L11: 07/11/2025 | M11: 07/10/2026 | N11: 1609 | O11: RESIDENT | P11: 0 | Q11: 0 | R11: -46.69 | S11: 1589 | T11: 1589 | U11: 30 | V11: 10 | W11: 5.5 | X11: 5 | Y11: 18 | Z11: 30 | AA11: 0 | AB11: 0 | AC11: 0 | AD11: 0 | AE11: 0 | AF11: 0 | AG11: 0 | AH11: 1687.5 | AJ11: % Occ. | AK11: 1 | AL11: 1
A12: 31990 | B12: 42926 | C12: 1-106 | D12: B2Q | E12: =RIGHT(D12,1) -> Q | F12: N/A | G12: 1076 | H12: Occupied | I12: Belyeu, Akelya | J12: 09/18/2025 | L12: 09/18/2025 | M12: 09/17/2026 | N12: 1659 | O12: RESIDENT | P12: 0 | Q12: 0 | R12: 0 | S12: 1689 | T12: 1689 | U12: 30 | V12: 10 | W12: 5.5 | X12: 5 | Y12: 0 | Z12: 30 | AA12: 0 | AB12: 0 | AC12: 0 | AD12: 0 | AE12: 0 | AF12: 0 | AG12: 0 | AH12: 1769.5 | AJ12: Rent/Occ Unit | AK12: =+AK10/(495*AK11) -> 1426.6867 | AL12: =+AL10/(495*AL11) -> 1412.5914 | AO12: INCOME | AP12: $ Gross
A13: 31995 | B13: 42933 | C13: 1-107 | D13: B2Q | E13: =RIGHT(D13,1) -> Q | F13: N/A | G13: 1076 | H13: Occupied | I13: Rodriguez, David | J13: 09/19/2025 | L13: 09/19/2025 | M13: 09/18/2026 | N13: 1659 | O13: RESIDENT | P13: 0 | Q13: 0 | R13: 0 | S13: 1689 | T13: 1689 | U13: 30 | V13: 10 | W13: 5.5 | X13: 5 | Y13: 18 | Z13: 0 | AA13: 0 | AB13: 0 | AC13: 0 | AD13: 0 | AE13: 0 | AF13: 0 | AG13: 0 | AH13: 1757.5 | AJ13: Multiplier | AK13: 0.41666667 | AL13: =1-AK13 -> 0.58333333 | AO13: Potential Rental Revenue | AP13: 8474519 | AQ13: 8357667.1 | AR13: 8579313.5 | AS13: 8960894.7 | AT13: 9318313.2 | AU13: 9674923.9 | AV13: 9995970.5 | AW13: 10295850 | AX13: 10604725 | AY13: 10922867 | AZ13: 11250553
A14: 31552 | B14: 42815 | C14: 1-108 | D14: B2Q | E14: =RIGHT(D14,1) -> Q | F14: N/A | G14: 1076 | H14: Occupied | I14: Snider, Lillian | J14: 08/24/2024 | L14: 08/23/2025 | M14: 08/24/2026 | N14: 1629 | O14: RESIDENT | P14: 0 | Q14: 0 | R14: 0 | S14: 1764 | T14: 1764 | U14: 30 | V14: 10 | W14: 5.5 | X14: 5 | Y14: 18 | Z14: 15 | AA14: 0 | AB14: 0 | AC14: 0 | AD14: 0 | AE14: 0 | AF14: 0 | AG14: 0 | AH14: 1847.5 | AJ14: Average UW Rent | AL14: =SUMPRODUCT(AK13:AL13,AK12:AL12) -> 1418.4644 | AO14: Loss To Lease | AP14: 0 | AQ14: 33125.696 | AR14: -103648.36 | AS14: -153090.98 | AT14: -156337.08 | AU14: -147550.63 | AV14: -121551.92 | AW14: -111673.93 | AX14: -110350.84 | AY14: -108988.06 | AZ14: -107584.39
A15: 31948 | B15: 42909 | C15: 1-109 | D15: A3Q | E15: =RIGHT(D15,1) -> Q | F15: N/A | G15: 825 | H15: Occupied | I15: Contreras, Brooklynn | J15: 08/14/2025 | L15: 08/14/2025 | M15: 08/13/2026 | N15: 1419 | O15: RESIDENT | P15: 0 | Q15: 0 | R15: 0 | S15: 1369 | T15: 1369 | U15: 30 | V15: 10 | W15: 5.5 | X15: 5 | Y15: 18 | Z15: 15 | AA15: 0 | AB15: 0 | AC15: 0 | AD15: 0 | AE15: 0 | AF15: 0 | AG15: 0 | AH15: 1452.5 | AJ15: In-Place Rent | AL15: =AVERAGEIFS(T7:T501,T7:T501,">0") -> 1403.4336 | AO15: Scheduled Base Rental Revenue | AP15: 8474519 | AQ15: 8390792.8 | AR15: 8475665.2 | AS15: 8807803.7 | AT15: 9161976.1 | AU15: 9527373.3 | AV15: 9874418.6 | AW15: 10184176 | AX15: 10494374 | AY15: 10813879 | AZ15: 11142968
A16: 11048 | B16: 42717 | C16: 1-110 | D16: A3G | E16: =RIGHT(D16,1) -> G | F16: N/A | G16: 825 | H16: Occupied | I16: Tapia, Angela | J16: 04/12/2023 | L16: 05/13/2025 | M16: 05/12/2026 | N16: 1379 | O16: RESIDENT | P16: 0 | Q16: 0 | R16: -551.92 | S16: 1430 | T16: 1430 | U16: 30 | V16: 10 | W16: 5.5 | X16: 5 | Y16: 18 | Z16: 0 | AA16: 0 | AB16: 0 | AC16: 0 | AD16: 0 | AE16: 0 | AF16: 0 | AG16: 0 | AH16: 1498.5 | AJ16: Market Rent | AL16: =+AVERAGE(N7:N501) -> 1358.6343 | AO16: Other Income | AP16: 1242919.2 | AQ16: 1220508 | AR16: 1503810.3 | AS16: 1640643.9 | AT16: 1679333.5 | AU16: 1718943.7 | AV16: 1759496.8 | AW16: 1801015.2 | AX16: 1843522.3 | AY16: 1887041.6 | AZ16: 1931597.6
A17: 32066 | B17: 43094 | C17: 1-111 | D17: A3G | E17: =RIGHT(D17,1) -> G | F17: N/A | G17: 825 | H17: Occupied | I17: Preis, Taryn | J17: 12/10/2025 | L17: 12/10/2025 | M17: 03/09/2027 | N17: 1379 | O17: RESIDENT | P17: 0 | Q17: 0 | R17: 0 | S17: 1309 | T17: 1309 | U17: 30 | V17: 10 | W17: 5 | X17: 5 | Y17: 0 | Z17: 15 | AA17: 0 | AB17: 35 | AC17: 0 | AD17: 0 | AE17: 0 | AF17: 0 | AG17: 0 | AH17: 1409 | AL17: =(AL15/AL14)-1 -> -0.010596585 | AO17: Potential Gross Income | AP17: 9717438.2 | AQ17: 9611300.8 | AR17: 9979475.5 | AS17: 10448448 | AT17: 10841310 | AU17: 11246317 | AV17: 11633915 | AW17: 11985191 | AX17: 12337897 | AY17: 12700920 | AZ17: 13074566
A18: 31607 | B18: 42856 | C18: 1-112 | D18: A3Q | E18: =RIGHT(D18,1) -> Q | F18: N/A | G18: 825 | H18: Occupied | I18: Davis, Bailey | J18: 08/09/2024 | L18: 08/09/2025 | M18: 08/10/2026 | N18: 1419 | O18: RESIDENT | P18: 0 | Q18: 0 | R18: 0 | S18: 1479 | T18: 1479 | U18: 30 | V18: 10 | W18: 5.5 | X18: 5 | Y18: 18 | Z18: 0 | AA18: 0 | AB18: 0 | AC18: 0 | AD18: 0 | AE18: 0 | AF18: 0 | AG18: 0 | AH18: 1547.5 | AL18: =(AL15/AL16)-1 -> 0.032973705 | AO18: Minus: Vacancy | AP18: -499996.62 | AQ18: -461493.6 | AR18: -466161.58 | AS18: -484429.2 | AT18: -503908.69 | AU18: -524005.53 | AV18: -543093.02 | AW18: -560129.66 | AX18: -577190.58 | AY18: -594763.33 | AZ18: -612863.26
A19: 11370 | B19: 43152 | C19: 1-113 | D19: A3Q | E19: =RIGHT(D19,1) -> Q | F19: N/A | G19: 825 | H19: Occupied | I19: Rossell, Shanna | J19: 01/26/2024 | L19: 01/24/2026 | M19: 01/25/2027 | N19: 1419 | O19: RESIDENT | P19: 0 | Q19: 0 | R19: 0 | S19: 1379 | T19: 1379 | U19: 30 | V19: 10 | W19: 5.5 | X19: 5 | Y19: 0 | Z19: 15 | AA19: 0 | AB19: 0 | AC19: 0 | AD19: 0 | AE19: 0 | AF19: 0 | AG19: 0 | AH19: 1444.5 | AO19: Minus: Credit Loss | AP19: -114839.31 | AQ19: -125861.89 | AR19: -105945.81 | AS19: -88078.037 | AT19: -91619.761 | AU19: -95273.733 | AV19: -98744.186 | AW19: -101841.76 | AX19: -104943.74 | AY19: -108138.79 | AZ19: -111429.68
A20: 32055 | B20: 43069 | C20: 1-114 | D20: A3F | E20: =RIGHT(D20,1) -> F | F20: N/A | G20: 825 | H20: Occupied | I20: Engelman, Jessica | J20: 12/02/2025 | L20: 12/02/2025 | M20: 12/01/2026 | N20: 1309 | O20: RESIDENT | P20: 0 | Q20: 0 | R20: 0 | S20: 1089 | T20: 1089 | U20: 30 | V20: 10 | W20: 5.5 | X20: 5 | Y20: 18 | Z20: 0 | AA20: 0 | AB20: 0 | AC20: 0 | AD20: 0 | AE20: 0 | AF20: 0 | AG20: 0 | AH20: 1157.5 | AO20: Minus: Model Unit | AP20: 0 | AQ20: 0 | AR20: 0 | AS20: 0 | AT20: 0 | AU20: 0 | AV20: 0 | AW20: 0 | AX20: 0 | AY20: 0 | AZ20: 0
A21: 58 | B21: 42648 | C21: 1-115 | D21: A3F | E21: =RIGHT(D21,1) -> F | F21: N/A | G21: 825 | H21: Occupied-NTV | I21: Kupka, William | J21: 09/18/2015 | K21: 04/27/2026 | L21: 03/18/2025 | M21: 03/17/2026 | N21: 1309 | O21: RESIDENT | P21: 0 | Q21: 250 | R21: -391 | S21: 1379 | T21: 1379 | U21: 30 | V21: 10 | W21: 5.5 | X21: 5 | Y21: 18 | Z21: 0 | AA21: 0 | AB21: 70 | AC21: 0 | AD21: 0 | AE21: 0 | AF21: 0 | AG21: 0 | AH21: 1517.5 | AO21: Minus: Concessions Initial Lease Up | AP21: -117055.64 | AQ21: -47462.588 | AR21: -36695.348 | AS21: -2996.4319 | AT21: 0 | AU21: 0 | AV21: 0 | AW21: 0 | AX21: 0 | AY21: 0 | AZ21: 0
A22: 31967 | B22: 42895 | C22: 1-116 | D22: A3Q | E22: =RIGHT(D22,1) -> Q | F22: N/A | G22: 825 | H22: Occupied | I22: Ramirez, Guillermo | J22: 08/28/2025 | L22: 08/28/2025 | M22: 08/27/2026 | N22: 1419 | O22: RESIDENT | P22: 0 | Q22: 0 | R22: 0 | S22: 1319 | T22: 1319 | U22: 30 | V22: 10 | W22: 5.5 | X22: 5 | Y22: 18 | Z22: 0 | AA22: 0 | AB22: 0 | AC22: 0 | AD22: 0 | AE22: 0 | AF22: 0 | AG22: 0 | AH22: 1387.5 | AJ22: 3Q 2025 Concessions | AO22: Minus: Concessions Ongoing | AQ22: -349333.62 | AR22: -177978.04 | AS22: -94639.172 | AT22: 0 | AU22: 0 | AV22: 0 | AW22: 0 | AX22: 0 | AY22: 0 | AZ22: 0
A23: 31935 | B23: 42834 | C23: 1-117 | D23: A1G | E23: =RIGHT(D23,1) -> G | F23: N/A | G23: 600 | H23: Occupied | I23: Tuttle, Gianah | J23: 07/14/2025 | L23: 07/14/2025 | M23: 07/13/2026 | N23: 1269 | O23: RESIDENT | P23: 0 | Q23: 0 | R23: 0 | S23: 1219 | T23: 1219 | U23: 30 | V23: 10 | W23: 5.5 | X23: 5 | Y23: 18 | Z23: 15 | AA23: 0 | AB23: 0 | AC23: 0 | AD23: 0 | AE23: 0 | AF23: 0 | AG23: 0 | AH23: 1302.5 | AJ23: Oct | AK23: 0 | AO23: Effective Gross Income | AP23: 8985546.7 | AQ23: 8627149.1 | AR23: 9192694.7 | AS23: 9778304.8 | AT23: 10245781 | AU23: 10627038 | AV23: 10992078 | AW23: 11323219 | AX23: 11655762 | AY23: 11998018 | AZ23: 12350273
A24: 31749 | B24: 43029 | C24: 1-118 | D24: A1F | E24: =RIGHT(D24,1) -> F | F24: N/A | G24: 600 | H24: Occupied | I24: Igwee, Lydia | J24: 12/28/2024 | L24: 12/27/2025 | M24: 12/28/2026 | N24: 1199 | O24: RESIDENT | P24: 0 | Q24: 0 | R24: -1448.59 | S24: 1228 | T24: 1228 | U24: 30 | V24: 10 | W24: 5.5 | X24: 5 | Y24: 18 | Z24: 15 | AA24: 0 | AB24: 0 | AC24: 0 | AD24: 0 | AE24: 0 | AF24: 0 | AG24: 0 | AH24: 1311.5 | AJ24: Nov | AK24: 0
A25: 31896 | B25: 42749 | C25: 1-119 | D25: A1F | E25: =RIGHT(D25,1) -> F | F25: N/A | G25: 600 | H25: Occupied | I25: Cochran, Matthew | J25: 07/01/2025 | L25: 07/01/2025 | M25: 07/01/2026 | N25: 1169 | O25: RESIDENT | P25: 0 | Q25: 0 | R25: 0 | S25: 1229 | T25: 1229 | U25: 30 | V25: 10 | W25: 5.5 | X25: 5 | Y25: 18 | Z25: 0 | AA25: 0 | AB25: 0 | AC25: 0 | AD25: 0 | AE25: 0 | AF25: 0 | AG25: 0 | AH25: 1297.5 | AJ25: Dec | AK25: 0 | AO25: OPERATING EXPENSES | AP25: $ Gross
A26: 31834 | B26: 43211 | C26: 1-120 | D26: A1Q | E26: =RIGHT(D26,1) -> Q | F26: N/A | G26: 600 | H26: Occupied | I26: Biggers, Jessica | J26: 02/21/2025 | L26: 02/21/2026 | M26: 03/01/2027 | N26: 1309 | O26: RESIDENT | P26: 0 | Q26: 0 | R26: 0 | S26: 1299 | T26: 1299 | U26: 30 | V26: 10 | W26: 5.5 | X26: 5 | Y26: 18 | Z26: 0 | AA26: 0 | AB26: 35 | AC26: 0 | AD26: 0 | AE26: 0 | AF26: 0 | AG26: 0 | AH26: 1402.5 | AJ26: Quarterly | AK26: =+SUM(AK23:AK25) -> 0 | AO26: Payroll | AP26: 574480.84 | AQ26: 569345.6 | AR26: 586425.97 | AS26: 604018.75 | AT26: 622139.31 | AU26: 640803.49 | AV26: 660027.59 | AW26: 679828.42 | AX26: 700223.27 | AY26: 721229.97 | AZ26: 742866.87
A27: 83 | B27: 42828 | C27: 1-121 | D27: A1 | E27: =RIGHT(D27,1) -> 1 | F27: N/A | G27: 600 | H27: Occupied | I27: Kane, Alan | J27: 07/06/2017 | L27: 09/03/2025 | M27: 09/02/2026 | N27: 1299 | O27: RESIDENT | P27: 0 | Q27: 0 | R27: -1431.44 | S27: 1326 | T27: 1326 | U27: 30 | V27: 10 | W27: 5.5 | X27: 5 | Y27: 18 | Z27: 0 | AA27: 0 | AB27: 0 | AC27: 0 | AD27: 0 | AE27: 0 | AF27: 0 | AG27: 0 | AH27: 1394.5 | AJ27: Yearly | AK27: =+AK26*4 -> 0 | AO27: Employee Units | AP27: 10605.92 | AQ27: 10924.098 | AR27: 11251.821 | AS27: 11589.375 | AT27: 11937.056 | AU27: 12295.168 | AV27: 12664.023 | AW27: 13043.944 | AX27: 13435.262 | AY27: 13838.32 | AZ27: 14253.47
A28: 31660 | B28: 42989 | C28: 1-122 | D28: A1F | E28: =RIGHT(D28,1) -> F | F28: N/A | G28: 600 | H28: Occupied | I28: Dossani, Omer | J28: 10/04/2024 | L28: 10/04/2025 | M28: 10/05/2026 | N28: 1169 | O28: RESIDENT | P28: 0 | Q28: 0 | R28: 0 | S28: 1199 | T28: 1199 | U28: 30 | V28: 10 | W28: 5.5 | X28: 5 | Y28: 18 | Z28: 0 | AA28: 0 | AB28: 0 | AC28: 0 | AD28: 0 | AE28: 0 | AF28: 0 | AG28: 0 | AH28: 1267.5 | AO28: Marketing | AP28: 91494.43 | AQ28: 91575 | AR28: 94322.25 | AS28: 97151.917 | AT28: 100066.48 | AU28: 103068.47 | AV28: 106160.52 | AW28: 109345.34 | AX28: 112625.7 | AY28: 116004.47 | AZ28: 119484.6
A29: 0 | B29: 0 | C29: 1-123 | D29: A1Q | E29: =RIGHT(D29,1) -> Q | F29: N/A | G29: 600 | H29: Vacant | I29: VACANT | N29: 1309 | P29: 0 | Q29: 0 | R29: 0 | S29: 0 | T29: 0 | U29: 0 | V29: 0 | W29: 0 | X29: 0 | Y29: 0 | Z29: 0 | AA29: 0 | AB29: 0 | AC29: 0 | AD29: 0 | AE29: 0 | AF29: 0 | AG29: 0 | AH29: 0 | AJ29: 3Q 2025 Concessions | AO29: General & Admin. | AP29: 207771.55 | AQ29: 210375 | AR29: 216686.25 | AS29: 223186.84 | AT29: 229882.44 | AU29: 236778.92 | AV29: 243882.28 | AW29: 251198.75 | AX29: 258734.71 | AY29: 266496.76 | AZ29: 274491.66
A30: 0 | B30: 0 | C30: 1-124 | D30: A1G | E30: =RIGHT(D30,1) -> G | F30: N/A | G30: 600 | H30: Vacant-Leased | I30: VACANT | N30: 1099 | P30: 0 | Q30: 0 | R30: 0 | S30: 0 | T30: 0 | U30: 0 | V30: 0 | W30: 0 | X30: 0 | Y30: 0 | Z30: 0 | AA30: 0 | AB30: 0 | AC30: 0 | AD30: 0 | AE30: 0 | AF30: 0 | AG30: 0 | AH30: 0 | AJ30: July | AK30: 0 | AO30: Managed WiFi | AP30: 0 | AQ30: 44550 | AR30: 183546 | AS30: 189052.38 | AT30: 194723.95 | AU30: 200565.67 | AV30: 206582.64 | AW30: 212780.12 | AX30: 219163.52 | AY30: 225738.43 | AZ30: 232510.58
A31: 32161 | B31: 43264 | C31: 1-124 | D31: A1G | E31: =RIGHT(D31,1) -> G | F31: N/A | G31: 600 | H31: Applicant | I31: Gargiulo, Timothy | J31: 04/02/2026 | L31: 04/02/2026 | M31: 04/01/2027 | N31: 0 | O31: RESIDENT | P31: 0 | Q31: 0 | R31: 250 | S31: 1099 | T31: 1099 | U31: 30 | V31: 10 | W31: 5.5 | X31: 5 | Y31: 18 | Z31: 15 | AA31: 70 | AB31: 0 | AC31: 0 | AD31: 0 | AE31: 0 | AF31: 0 | AG31: 0 | AH31: 1252.5 | AJ31: August | AK31: 0 | AO31: Landscaping/Grounds | AP31: 113265.91 | AQ31: 111375 | AR31: 114716.25 | AS31: 118157.74 | AT31: 121702.47 | AU31: 125353.54 | AV31: 129114.15 | AW31: 132987.57 | AX31: 136977.2 | AY31: 141086.52 | AZ31: 145319.11
A32: 761 | B32: 42750 | C32: 1-125 | D32: B2G | E32: =RIGHT(D32,1) -> G | F32: N/A | G32: 1076 | H32: Occupied | I32: Moran, Keegan | J32: 05/27/2022 | L32: 07/08/2025 | M32: 07/06/2026 | N32: 1609 | O32: RESIDENT | P32: 0 | Q32: 0 | R32: 0 | S32: 1730 | T32: 1730 | U32: 30 | V32: 10 | W32: 5.5 | X32: 5 | Y32: 18 | Z32: 0 | AA32: 0 | AB32: 35 | AC32: 0 | AD32: 0 | AE32: 0 | AF32: 0 | AG32: 0 | AH32: 1833.5 | AJ32: September | AK32: 0 | AO32: Make-ready | AP32: 0 | AQ32: 0 | AR32: 0 | AS32: 0 | AT32: 0 | AU32: 0 | AV32: 0 | AW32: 0 | AX32: 0 | AY32: 0 | AZ32: 0
A33: 31927 | B33: 42817 | C33: 1-126 | D33: B2F | E33: =RIGHT(D33,1) -> F | F33: N/A | G33: 1076 | H33: Occupied | I33: Javier, Ejay | J33: 07/07/2025 | L33: 07/07/2025 | M33: 07/06/2026 | N33: 1539 | O33: RESIDENT | P33: 0 | Q33: 0 | R33: -863 | S33: 1569 | T33: 1569 | U33: 30 | V33: 10 | W33: 5.5 | X33: 5 | Y33: 18 | Z33: 30 | AA33: 0 | AB33: 0 | AC33: 0 | AD33: 0 | AE33: 0 | AF33: 0 | AG33: 0 | AH33: 1667.5 | AJ33: Quarterly | AK33: =+SUM(AK30:AK32) -> 0 | AO33: Repairs & Maint. | AP33: 232268.57 | AQ33: 232268.57 | AR33: 239236.63 | AS33: 246413.73 | AT33: 253806.14 | AU33: 261420.32 | AV33: 269262.93 | AW33: 277340.82 | AX33: 285661.04 | AY33: 294230.88 | AZ33: 303057.8
A34: 31892 | B34: 42741 | C34: 1-127 | D34: B2F | E34: =RIGHT(D34,1) -> F | F34: N/A | G34: 1076 | H34: Occupied-NTV | I34: Ramirez, Alejandra | J34: 05/12/2025 | K34: 05/11/2026 | L34: 05/12/2025 | M34: 05/11/2026 | N34: 1539 | O34: RESIDENT | P34: 0 | Q34: 0 | R34: 0 | S34: 1569 | T34: 1569 | U34: 30 | V34: 10 | W34: 5.5 | X34: 5 | Y34: 18 | Z34: 30 | AA34: 0 | AB34: 0 | AC34: 0 | AD34: 0 | AE34: 0 | AF34: 0 | AG34: 0 | AH34: 1667.5 | AJ34: Yearly | AK34: =+AK33*4 -> 0 | AO34: Trash Expense | AP34: 42871.94 | AQ34: 45045 | AR34: 46396.35 | AS34: 47788.24 | AT34: 49221.888 | AU34: 50698.544 | AV34: 52219.501 | AW34: 53786.086 | AX34: 55399.668 | AY34: 57061.658 | AZ34: 58773.508
A35: 154 | B35: 42869 | C35: 1-128 | D35: B2 | E35: =RIGHT(D35,1) -> 2 | F35: N/A | G35: 1076 | H35: Occupied | I35: Coleman, Quinsey | J35: 08/06/2019 | L35: 10/02/2025 | M35: 10/05/2026 | N35: 1609 | O35: RESIDENT | P35: 0 | Q35: 0 | R35: 25 | S35: 1744 | T35: 1744 | U35: 30 | V35: 10 | W35: 5.5 | X35: 5 | Y35: 18 | Z35: 45 | AA35: 0 | AB35: 0 | AC35: 0 | AD35: 0 | AE35: 0 | AF35: 0 | AG35: 0 | AH35: 1857.5 | AO35: Security/Life Safety | AP35: 20740.1 | AQ35: 25245 | AR35: 26002.35 | AS35: 26782.42 | AT35: 27585.893 | AU35: 28413.47 | AV35: 29265.874 | AW35: 30143.85 | AX35: 31048.166 | AY35: 31979.611 | AZ35: 32938.999
A36: 10977 | B36: 42680 | C36: 1-129 | D36: B2G | E36: =RIGHT(D36,1) -> G | F36: N/A | G36: 1076 | H36: Occupied | I36: Harrell Jr, Calvin | J36: 02/21/2023 | L36: 04/03/2025 | M36: 04/02/2026 | N36: 1579 | O36: RESIDENT | P36: 0 | Q36: 0 | R36: 25 | S36: 1652 | T36: 1652 | U36: 30 | V36: 10 | W36: 5.5 | X36: 5 | Y36: 18 | Z36: 30 | AA36: 0 | AB36: 0 | AC36: 0 | AD36: 0 | AE36: 0 | AF36: 0 | AG36: 0 | AH36: 1750.5 | AO36: Utilities | AP36: 287016.97 | AQ36: 294525 | AR36: 303360.75 | AS36: 312461.57 | AT36: 321835.42 | AU36: 331490.48 | AV36: 341435.2 | AW36: 351678.25 | AX36: 362228.6 | AY36: 373095.46 | AZ36: 384288.32
A37: 0 | B37: 0 | C37: 1-130 | D37: B2Q | E37: =RIGHT(D37,1) -> Q | F37: N/A | G37: 1076 | H37: Vacant | I37: VACANT | N37: 1659 | P37: 0 | Q37: 0 | R37: 0 | S37: 0 | T37: 0 | U37: 0 | V37: 0 | W37: 0 | X37: 0 | Y37: 0 | Z37: 0 | AA37: 0 | AB37: 0 | AC37: 0 | AD37: 0 | AE37: 0 | AF37: 0 | AG37: 0 | AH37: 0 | AO37: Insurance | AP37: 139580.38 | AQ37: 139580.38 | AR37: 132601.36 | AS37: 135253.38 | AT37: 139310.99 | AU37: 143490.32 | AV37: 147795.03 | AW37: 152228.88 | AX37: 156795.74 | AY37: 161499.61 | AZ37: 166344.6
A38: 31973 | B38: 42904 | C38: 1-131 | D38: B2F | E38: =RIGHT(D38,1) -> F | F38: N/A | G38: 1076 | H38: Occupied | I38: Chavez Mora, Jeremy | J38: 09/06/2025 | L38: 09/06/2025 | M38: 09/04/2026 | N38: 1539 | O38: RESIDENT | P38: 0 | Q38: 0 | R38: 0 | S38: 1569 | T38: 1569 | U38: 30 | V38: 10 | W38: 5.5 | X38: 5 | Y38: 18 | Z38: 0 | AA38: 0 | AB38: 0 | AC38: 0 | AD38: 0 | AE38: 0 | AF38: 0 | AG38: 0 | AH38: 1637.5 | AO38: Replacement Reserves | AP38: 123750 | AQ38: 123750 | AR38: 123750 | AS38: 123750 | AT38: 123750 | AU38: 123750 | AV38: 123750 | AW38: 123750 | AX38: 123750 | AY38: 123750 | AZ38: 123750
A39: 0 | B39: 0 | C39: 1-132 | D39: B2G | E39: =RIGHT(D39,1) -> G | F39: N/A | G39: 1076 | H39: Vacant | I39: VACANT | N39: 1609 | P39: 0 | Q39: 0 | R39: 0 | S39: 0 | T39: 0 | U39: 0 | V39: 0 | W39: 0 | X39: 0 | Y39: 0 | Z39: 0 | AA39: 0 | AB39: 0 | AC39: 0 | AD39: 0 | AE39: 0 | AF39: 0 | AG39: 0 | AH39: 0 | AO39: Misc #2 | AP39: 0 | AQ39: 0 | AR39: 0 | AS39: 0 | AT39: 0 | AU39: 0 | AV39: 0 | AW39: 0 | AX39: 0 | AY39: 0 | AZ39: 0
A40: 11324 | B40: 43016 | C40: 1-133 | D40: A2Q | E40: =RIGHT(D40,1) -> Q | F40: N/A | G40: 700 | H40: Occupied | I40: Teller, Damian | J40: 12/26/2023 | L40: 12/27/2025 | M40: 12/28/2026 | N40: 1359 | O40: RESIDENT | P40: 0 | Q40: 0 | R40: 0 | S40: 1439 | T40: 1439 | U40: 30 | V40: 10 | W40: 5.5 | X40: 5 | Y40: 18 | Z40: 15 | AA40: 0 | AB40: 0 | AC40: 0 | AD40: 0 | AE40: 0 | AF40: 0 | AG40: 0 | AH40: 1522.5 | AO40: RE Taxes | AP40: 387583 | AQ40: 387583 | AR40: 406962.15 | AS40: 427310.26 | AT40: 448675.77 | AU40: 471109.56 | AV40: 494665.04 | AW40: 519398.29 | AX40: 545368.2 | AY40: 572636.61 | AZ40: 601268.44
...

Sheet AR
A1: Knightvest Management LLC - Strada DELINQUENT AND PREPAID FISCAL PERIOD 032026 AS OF 05/15/2026 05/15/2026 03:33 PM Parameters: Report Type: Details Subproperties: - all subproperties- Subjournals: ALL Statuses to include: Current resident; Include delinquencies that equal NTV Credit? Yes; Exclude transactions payable in arrears: No; Delinquency range 0 through 99999999; Aging Columns: Fiscal; Filter type: ALL; Show Prepaid As Allocated: Yes; Include outstanding deposits: No; Hide all PII data: No; Delinquent Comments: Current only | AB1: =+SUM($AB$3:$AB$10) -> 0
A2: Resh ID | B2: Lease ID | C2: Bldg/Unit | D2: Name | E2: Phone Number | F2: Email | G2: Status | H2: Move-In/Out | I2: Code Description | J2: Total Prepaid | K2: Total Delinquent | L2: D | M2: O | N2: Net Balance | O2: Current | P2: 30 Days | Q2: 60 Days | R2: 90+ Days | S2: Prorate Credit | T2: Deposits Held | U2: Outstanding Deposit | V2: #Late | W2: #NSF | X2: Comment Date | Y2: Leasing Agent | AA2: RENT
A3: 31939 | B3: 42841 | C3: 1-158 | D3: Stevenson, DeAvion Alicia | E3: (602)456-9286 | F3: deavionstvn98@gmail.com | G3: Current resident | H3: 07/15/2025 | I3: RENT | J3: 0 | K3: 1328.37 | L3: † | N3: 1328.37 | O3: 0 | P3: 1328.37 | Q3: 0 | R3: 0 | S3: 0 | T3: 0 | U3: 0 | V3: 8 | W3: 2 | X3: 03/23/2026 | AA3: =+_xlfn.XLOOKUP(C3,'Rent Roll'!$C$7:$C$501,'Rent Roll'!$T$7:$T$501) -> 1329 | AB3: =+IF(SUM(Q3:R3)>AA3,AA3,0) -> 0
A4: 31939 | B4: 42841 | C4: 1-158 | D4: Stevenson, DeAvion Alicia | E4: (602)456-9286 | F4: deavionstvn98@gmail.com | G4: Current resident | H4: 07/15/2025 | I4: RENT | J4: 0 | K4: 1329 | N4: 1329 | O4: 1329 | P4: 0 | Q4: 0 | R4: 0 | S4: 0 | T4: 0 | U4: 0 | V4: 8 | W4: 2 | X4: 03/23/2026 | AA4: =+_xlfn.XLOOKUP(C4,'Rent Roll'!$C$7:$C$501,'Rent Roll'!$T$7:$T$501) -> 1329 | AB4: =+IF(SUM(Q4:R4)>AA4,AA4,0) -> 0
A5: 31964 | B5: 42889 | C5: 1-160 | D5: Catherine Wicks | E5: (480)772-9296 | F5: catherinem.wicks@gmail.com | G5: Current resident | H5: 09/19/2025 | I5: RENT | J5: 0 | K5: 1369 | N5: 1369 | O5: 1369 | P5: 0 | Q5: 0 | R5: 0 | S5: 0 | T5: 0 | U5: 0 | V5: 7 | W5: 1 | X5: 03/23/2026 | AA5: =+_xlfn.XLOOKUP(C5,'Rent Roll'!$C$7:$C$501,'Rent Roll'!$T$7:$T$501) -> 1369 | AB5: =+IF(SUM(Q5:R5)>AA5,AA5,0) -> 0
A6: 31926 | B6: 42816 | C6: 1-263 | D6: Pinder, John Timothy | E6: (602)247-0742 | F6: john.t.pinder@outlook.com | G6: Current resident | H6: 06/28/2025 | I6: RENT | J6: 0 | K6: 1324 | N6: 1324 | O6: 1324 | P6: 0 | Q6: 0 | R6: 0 | S6: 0 | T6: 0 | U6: 0 | V6: 6 | W6: 0 | X6: 03/23/2026 | AA6: =+_xlfn.XLOOKUP(C6,'Rent Roll'!$C$7:$C$501,'Rent Roll'!$T$7:$T$501) -> 1324 | AB6: =+IF(SUM(Q6:R6)>AA6,AA6,0) -> 0
A7: 31893 | B7: 42745 | C7: 1-374 | D7: Uribe, Bryan Alejandro | E7: N/A | F7: bryan.2911@hotmail.com | G7: Current resident | H7: 05/31/2025 | I7: RENT | J7: 0 | K7: 1579 | N7: 1579 | O7: 1579 | P7: 0 | Q7: 0 | R7: 0 | S7: 0 | T7: 0 | U7: 0 | V7: 5 | W7: 1 | X7: 03/23/2026 | AA7: =+_xlfn.XLOOKUP(C7,'Rent Roll'!$C$7:$C$501,'Rent Roll'!$T$7:$T$501) -> 1579 | AB7: =+IF(SUM(Q7:R7)>AA7,AA7,0) -> 0
A8: 32132 | B8: 43199 | C8: 2-163 | D8: Spade, Eric | E8: (606) 401-8122 | F8: eespade2@gmail.com | G8: Current resident | H8: 03/30/2026 | I8: RENT | J8: 0 | K8: 101.87 | N8: 101.87 | O8: 101.87 | P8: 0 | Q8: 0 | R8: 0 | S8: 0 | T8: 0 | U8: 0 | V8: 1 | W8: 0 | AA8: =+_xlfn.XLOOKUP(C8,'Rent Roll'!$C$7:$C$501,'Rent Roll'!$T$7:$T$501) -> 1579 | AB8: =+IF(SUM(Q8:R8)>AA8,AA8,0) -> 0
A9: 32086 | B9: 43118 | C9: 2-180 | D9: Dawson, Dion | E9: (480) 720-1590 | F9: dion.dawson16@gmail.com | G9: Current resident | H9: 12/26/2025 | I9: RENT | J9: 0 | K9: 2358 | N9: 2358 | O9: 1179 | P9: 1179 | Q9: 0 | R9: 0 | S9: 0 | T9: 0 | U9: 0 | V9: 2 | W9: 0 | X9: 03/23/2026 | AA9: =+_xlfn.XLOOKUP(C9,'Rent Roll'!$C$7:$C$501,'Rent Roll'!$T$7:$T$501) -> 1179 | AB9: =+IF(SUM(Q9:R9)>AA9,AA9,0) -> 0
A10: 31695 | B10: 43053 | C10: 2-241 | D10: Traill, Cameron Rosser | E10: (209) 596-1519 | F10: ctraill74@gmail.com | G10: Current resident | H10: 11/16/2024 | I10: RENT | J10: 0 | K10: 1249 | N10: 1249 | O10: 1249 | P10: 0 | Q10: 0 | R10: 0 | S10: 0 | T10: 0 | U10: 0 | V10: 5 | W10: 0 | X10: 03/23/2026 | AA10: =+_xlfn.XLOOKUP(C10,'Rent Roll'!$C$7:$C$501,'Rent Roll'!$T$7:$T$501) -> 1249 | AB10: =+IF(SUM(Q10:R10)>AA10,AA10,0) -> 0
I12: TOTALS | J12: 0 | K12: 10638.24 | N12: 10638.24 | O12: 8130.87 | P12: 2507.37 | Q12: 0 | R12: 0 | S12: 0 | T12: 0
A13: * -- Resident is under eviction † -- Balance due includes NSF transaction(s). Please refer to the appropriate ledger for more information ‡ -- Includes amounts that are 120+ days past due § -- Cash basis charge codes: Income account will match the AR account

Sheet Tax
F1: Address | G1: Parcel # | H1: Tax | I1: Updated
B2: Tax Details | E2: Parcel 1 | F2: 701 W Grove Pkwy Tempe, AZ 85283 | G2: 301-90-007A | H2: 196372.3 | I2: 46160
B3: =+SUM(H2:H3) -> 384207.82 | E3: Parcel 2 | F3: 7250 S Kyrene Rd Tempe, AZ 85283 | G3: 301-90-007B | H3: 187835.52 | I3: 46160

Sheet Debt Service
B2: Interest Rate Cap | C2: 0.045 | D2: =IF(C2=C3,"At-the-Money",IF(C2<C3,"In-the-Money",IF(C2>C3,"Out-of-the-Money"))) -> Out-of-the-Money
B3: SOFR | C3: 0.0368 | D3: 46022
B4: Spread | C4: 0.0235
B5: Effective Interest Rate | C5: =SUM(MIN(C3,C2),C4) -> 0.0603
B7: Current Principal Balance | C7: ='NEW OSAR'!E6 -> 92071459
B9: NOI | C9: ='NEW OSAR'!I57 -> 5953111
B10: Debt Service (w/o Cap) | C10: =C7*(C3+C4)*(365/360) -> 5629018.8
B11: Debt Service (w/Cap) | C11: =C7*C5*(365/360) -> 5629018.8
B13: DSCR (w/o Cap) | C13: =C9/C10 -> 1.0575753
B14: DSCR (w/Cap) | C14: =C9/C11 -> 1.0575753

Sheet Variance Analysis
A1: 1
C2: 3Q 2025 | G2: 4Q 2025 | K2: QoQ ∆ | O2: Cash Management
B3: Property | C3: Occupancy | D3: NOI | E3: DY | F3: DSCR | G3: Occupancy | H3: NOI | I3: DY | J3: DSCR | K3: Occupancy | L3: NOI | M3: DY | N3: DSCR | O3: In CM? | P3: Threshold
B4: Strada Apartments | C4: 0.93333333 | D4: 6115743.6 | E4: 0.066692951 | F4: 0.98803841 | G4: =#REF! -> #REF! | H4: =+#REF! -> #REF! | I4: =#REF! -> #REF! | J4: =#REF! -> #REF! | K4: =IF(G4="","-",G4-C4) -> #REF! | L4: =IF(H4="","-",H4-D4) -> #REF! | M4: =IF(I4="","-",I4-E4) -> #REF! | N4: =IF(J4="","-",J4-F4) -> #REF! | O4: No | P4: 0.07
B6: Notes:
B7: NOI adjusted per the loan agreement.
B8: DSCR inclusive of benefit from in-the-money rate cap.

Sheet Insurance
A1: 130448.95

Sheet Renovation Schedule
B2: At Close Renovations | C2: 431
B3: 06/30 Renovations | C3: 436
B4: IRE Assumed Renovations | C4: 64
B5: Total Renovations | C5: =+C4+C2 -> 495
B6: Total Units | C6: =+#REF! -> #REF! | D6: =+C6/C5 -> #REF!
B7: Renovation Start | C7: 45809
B9: Renovation Schedule | D9: =+C7+365 -> 46174 | E9: =+D9+365 -> 46539 | F9: =+E9+365 -> 46904 | G9: =+F9+365 -> 47269 | H9: =+G9+365 -> 47634 | I9: =+H9+365 -> 47999 | J9: =+I9+365 -> 48364 | K9: =+J9+365 -> 48729 | L9: =+K9+365 -> 49094 | ... O9: =+N9+365 -> 50189
D10: 1 | E10: =+D10+1 -> 2 | F10: =+E10+1 -> 3 | G10: =+F10+1 -> 4 | H10: =+G10+1 -> 5 | I10: =+H10+1 -> 6 | J10: =+I10+1 -> 7 | K10: =+J10+1 -> 8 | L10: =+K10+1 -> 9 | ... O10: =+N10+1 -> 12
B11: Non-Renovated Units
B12: Units Renovated | D12: 12 | E12: 12 | F12: 0 | G12: 0 | H12: 0 | I12: 0 | J12: 0 | K12: 0 | L12: 0 | M12: 0 | N12: 0 | O12: 0
B13: Non-Renovated Units Remaining | C13: 64 | D13: =+C13-D12 -> 52 | E13: =+D13-E12 -> 40 | F13: =+E13-F12 -> 40 | G13: =+F13-G12 -> 40 | H13: =+G13-H12 -> 40 | I13: =+H13-I12 -> 40 | J13: =+I13-J12 -> 40 | K13: =+J13-K12 -> 40 | ... O13: =+N13-O12 -> 40
B14: Completed per month | D14: =+D12/12 -> 1 | E14: =+E12/12 -> 1 | F14: =+F12/12 -> 0 | G14: =+G12/12 -> 0 | H14: =+H12/12 -> 0 | I14: =+I12/12 -> 0 | J14: =+J12/12 -> 0 | K14: =+K12/12 -> 0 | ... O14: =+O12/12 -> 0
B16: Mid-Renovated Units
B17: Units Renovated | D17: 24 | E17: 12 | F17: 0 | G17: 0 | H17: 0 | I17: 0 | J17: 0 | K17: 0 | L17: 0 | M17: 0 | N17: 0 | O17: 0
B18: Non-Renovated Units Remaining | C18: 95 | D18: =+C18-D17 -> 71 | E18: =+D18-E17 -> 59 | F18: =+E18-F17 -> 59 | G18: =+F18-G17 -> 59 | H18: =+G18-H17 -> 59 | I18: =+H18-I17 -> 59 | J18: =+I18-J17 -> 59 | K18: =+J18-K17 -> 59 | ... O18: =+N18-O17 -> 59
B19: Completed per month | D19: =+D17/12 -> 2 | E19: =+E17/12 -> 1 | F19: =+F17/12 -> 0 | G19: =+G17/12 -> 0 | H19: =+H17/12 -> 0 | I19: =+I17/12 -> 0 | J19: =+J17/12 -> 0 | K19: =+K17/12 -> 0 | ... O19: =+O17/12 -> 0

Sheet Unit Mix
A2: Knightvest Management LLC - Solano at Chapel Hill
A3: RENT ROLL DETAIL
A4: 07/26/2022 09:07 AM
A5: As of Date: 06/30/2022
A6: Parameters: Properties: - all subproperties-; Show All Unit Designations or Filter by: ALL; Subjournals: ALL; Sort by: Unit; Report Type: Details + Summary; Exclude Formers?: Yes; Show Unit Rent as: Market Rent
A7: Amt / SQFT: Market = 266,365 SQFT; Leased = 235,641 SQFT;
A8: Floorplan | B8: # Units | C8: Average SQFT | D8: Average Market Rent | E8: Market Rent Amt/SQFT | F8: Average Leased | G8: Leased Amt/SQFT | H8: Units Occupied | I8: Occupancy % | J8: Units Available
A9: A1 | B9: 9 | C9: 713 | D9: 1,300.00 | E9: 1.82 | F9: 1,296.33 | G9: 1.82 | H9: 9 | I9: 100.00 | J9: 0
A10: A1F | B10: 9 | C10: 713 | D10: 1,300.00 | E10: 1.82 | F10: 1,263.71 | G10: 1.77 | H10: 7 | I10: 77.78 | J10: 1
A11: A1Q | B11: 6 | C11: 713 | D11: 1,425.00 | E11: 2.00 | F11: 1,334.50 | G11: 1.87 | H11: 2 | I11: 33.33 | J11: 1
