Workbook
Name \0: #REF!
Name \A: #REF!
Name \A: #REF!
Name \B: #REF!
Name \B: #REF!
Name \C: #REF!
Name \D: #REF!
Name \E: #REF!
Name \g: '[1]Mixed Use'!#REF!
Name \g: '[1]Mixed Use'!#REF!
Name \H: #REF!
Name \H: #REF!
Name \I: #REF!
Name \j: #REF!
Name \L: #REF!
Name \N: #REF!
Name \o: '[1]Mixed Use'!#REF!
Name \p: #N/A
Name \s: '[1]Mixed Use'!#REF!
Name \t: #REF!
Name \x: '[1]Mixed Use'!#REF!
Name \Y: #REF!
Name \z: '[1]Mixed Use'!#REF!
Name ____________________cap104: #REF!
Name ___________________cap104: #REF!
Name ___________________LSC1: 1439078
Name ___________________LSC2: 611287
Name ___________________LSC3: 302107
Name ___________________LSE1: 201298
Name ___________________LSE2: 24644
Name ___________________LSE3: 399493
Name ___________________LSE4: 802332
Name ___________________LSE9: 604106
Name ___________________LSF1: 255134
Name ___________________LSF2: 90236
Name ___________________LSG1: 15916
Name ___________________LSK1: 10216765
Name ___________________LSK2: 97598247
Name ___________________LSK4: -75746217
Name ___________________LSM1: -289783200
Name ___________________LSM2: -23132787
Name ___________________LSP1: -426407
Name ___________________LSP2: -619666
Name ___________________LSP3: -115995
Name ___________________LSP4: -513016
Name ___________________LST1: 277494370
Name ___________________MAC2: #REF!
Name ___________________MAC3: #REF!
Name ___________________MAC4: #REF!
Name __________________cap104: #REF!
Name __________________LSC1: 1439078
Name __________________LSC2: 611287
Name __________________LSC3: 302107
Name __________________LSE1: 201298
Name __________________LSE2: 24644
Name __________________LSE3: 399493
Name __________________LSE4: 802332
Name __________________LSE9: 604106
Name __________________LSF1: 255134
Name __________________LSF2: 90236

Sheet Comm OSAR
C1: CREFC Investor Reporting Package
C2: COMMERCIAL OPERATING STATEMENT ANALYSIS REPORT (includes Retail/Office/Industrial/Mixed Use/Self Storage)
C3: ="as of " &TEXT(F6," mm/dd/yyyy") -> as of 03/31/2026
C4: PROPERTY OVERVIEW | H4: Allocated Loan Amount/Percentage
C5: Property ID | E5: 1001-001 | F5: Paid Thru Date | G5: Debt Outside Trust (1) | H5: $ | I5: %
C6: Note A-Scheduled Loan Balance | E6: 63000000 | F6: 46112 | H6: 0 | I6: 1
C7: Note B-Scheduled Loan Balance | E7: 0 | H7: 0 | I7: 0
C8: Note C-Scheduled Loan Balance | E8: 0 | H8: 0 | I8: 0
C9: Property Name | E9: The Campus at Villa La Jolla
C10: Property Type | E10: Medical Office
C11: Property Address, City, State | E11: 8950 Villa La Jolla Dr, La Jolla, CA 92037
C12: Current Net Rentable SF/Units/Beds/Rooms | E12: 191454 | F12: SF | G12: Use second box to specify sqft.,units…
C13: Year Built/Year Renovated | E13: 2018 | F13: 2025
C14: Cap Ex Reserve (annually)/per Unit.etc. (2) | E14: 0.25 | F14: PSF | G14: specify annual/per unit…
C15: Statement Ending Date | E15: Underwriting | G15: 46022 | H15: =+F6 -> 46112 | I15: =+F6 -> 46112
C16: Occupancy Rate (physical) | E16: 0.714 | G16: 0.67098943 | H16: ='Rent Roll'!B95 -> 0.68435973 | I16: =+H16 -> 0.68435973
C17: Occupancy Date | E17: 46265 | G17: 46022 | H17: =+H15 -> 46112 | I17: =+I15 -> 46112
E18: (1) "X" if debt is outside of the trust, otherwise leave blank
E19: (2) Total $ amount of Capital Reserves required annually by loan documents | N19: Vacancy factor | O19: 0.05
N20: Actual | O20: =1-I16 -> 0.31564027
C21: INCOME:
C22: Number of Mos. Covered | J22: (prcdng yr to base) | K22: (prcdng yr to 2nd prcdng)
C23: Period Ended | E23: At Contribution | F23: 3rd Preceding | G23: DY Test | H23: TTM | I23: DY Test | J23: =TEXT(H15," mm/dd/yyyy")& "-U/W" -> 03/31/2026-U/W | K23: =TEXT(G15," mm/dd/yyyy -") & TEXT(H15,"mm/dd/yyyy") -> 12/31/2025 -03/31/2026
C24: Statement Ending Date | E24: Information | G24: as of 12/31/2025 | H24: =+H17 -> 46112 | I24: ="as of" &TEXT(I15," mm/dd/yyyy") -> as of 03/31/2026 | J24: Variance | K24: Variance | L24: Notes | M24: Var $ | N24: Var %
C25: Gross Potential Rent (3) | E25: 9567046 | G25: 6673141.8 | H25: =_xlfn.XLOOKUP($C25,TTM!$T:$T,TTM!$U:$U,0) -> 0 | I25: =+'Rent Roll'!$Y$87 -> 6695002.4 | J25: =IFERROR(IF(E25=0, " ",(H25-E25)/E25),"") -> -1 | K25: =IF(G25=0, " ",(H25-G25)/G25) -> -1 | L25: ="Annualized RR as of" & TEXT($I$15," mm/dd/yyyy") & ", adjusted for free rent and KVs" -> Annualized RR as of 03/31/2026, adjusted for free rent and KVs | M25: =+IFERROR(I25-G25,"N/A") -> 21860.58 | N25: =+IFERROR(M25/G25,"N/A") -> 0.0032759052
C26: Less: Vacancy Loss | E26: -2897565 | H26: =_xlfn.XLOOKUP($C26,TTM!$T:$T,TTM!$U:$U,0) -> 0 | I26: =+IF(O20>O19,"",(O19-O20)*-I25) | J26: =IFERROR(IF(E26=0, " ",(H26-E26)/E26),"") -> -1 | K26: =IF(G26=0, " ",(H26-G26)/G26) -> #VALUE! | L26: ="Greater of Actual "&TEXT(1-I16,"(0.00%)")&" or 5.00% of GPR" -> Greater of Actual (31.56%) or 5.00% of GPR | M26: =+IFERROR(I26-G26,"N/A") -> N/A | N26: =+IFERROR(M26/G26,"N/A") -> N/A
C27: OR | H27: =_xlfn.XLOOKUP($C27,TTM!$T:$T,TTM!$U:$U,0) -> 0 | J27: =IFERROR(IF(E27=0, " ",(H27-E27)/E27),"") | K27: =IF(G27=0, " ",(H27-G27)/G27) | M27: =+IFERROR(I27-G27,"N/A") -> 0 | N27: =+IFERROR(M27/G27,"N/A") -> N/A
C28: Base Rent (3) | H28: =_xlfn.XLOOKUP($C28,TTM!$T:$T,TTM!$U:$U,0) -> 5796406.8 | J28: =IFERROR(IF(E28=0, " ",(H28-E28)/E28),"") | K28: =IF(G28=0, " ",(H28-G28)/G28) | M28: =+IFERROR(I28-G28,"N/A") -> 0 | N28: =+IFERROR(M28/G28,"N/A") -> N/A
C29: Expense Reimbursement | E29: 700149 | G29: 381795.51 | H29: =_xlfn.XLOOKUP($C29,TTM!$T:$T,TTM!$U:$U,0) -> 504137.47 | I29: ='Rent Roll'!$Z$87 -> 435812.98 | J29: =IFERROR(IF(E29=0, " ",(H29-E29)/E29),"") -> -0.27995688 | K29: =IF(G29=0, " ",(H29-G29)/G29) -> 0.32043845 | L29: ="Annualized RR as of" & TEXT($I$15," mm/dd/yyyy") -> Annualized RR as of 03/31/2026 | M29: =+IFERROR(I29-G29,"N/A") -> 54017.47 | N29: =+IFERROR(M29/G29,"N/A") -> 0.14148273
C30: Percentage Rent | G30: 0 | H30: =_xlfn.XLOOKUP($C30,TTM!$T:$T,TTM!$U:$U,0) -> 0 | I30: =_xlfn.XLOOKUP($C30,TTM!$T:$T,TTM!$U:$U,0) -> 0 | J30: =IFERROR(IF(E30=0, " ",(H30-E30)/E30),"") | K30: =IF(G30=0, " ",(H30-G30)/G30) | L30: ="TTM ended" &TEXT($I$15, " mm/dd/yyyy") -> TTM ended 03/31/2026 | M30: =+IFERROR(I30-G30,"N/A") -> 0 | N30: =+IFERROR(M30/G30,"N/A") -> N/A
C31: Parking Income | E31: 333230 | G31: 414384.19 | H31: =_xlfn.XLOOKUP($C31,TTM!$T:$T,TTM!$U:$U,0) -> 448011.03 | I31: =_xlfn.XLOOKUP($C31,TTM!$T:$T,TTM!$U:$U,0) -> 448011.03 | J31: =IFERROR(IF(E31=0, " ",(H31-E31)/E31),"") -> 0.34444987 | K31: =IF(G31=0, " ",(H31-G31)/G31) -> 0.081148945 | L31: ="TTM ended" &TEXT($I$15, " mm/dd/yyyy") -> TTM ended 03/31/2026 | M31: =+IFERROR(I31-G31,"N/A") -> 33626.84 | N31: =+IFERROR(M31/G31,"N/A") -> 0.081148945
C32: Other Income | E32: -48753 | G32: 44055.18 | H32: =_xlfn.XLOOKUP($C32,TTM!$T:$T,TTM!$U:$U,0) -> 58413.56 | I32: =_xlfn.XLOOKUP($C32,TTM!$T:$T,TTM!$U:$U,0) -> 58413.56 | J32: =IFERROR(IF(E32=0, " ",(H32-E32)/E32),"") -> -2.1981531 | K32: =IF(G32=0, " ",(H32-G32)/G32) -> 0.32591809 | L32: ="TTM ended" &TEXT($I$15, " mm/dd/yyyy") -> TTM ended 03/31/2026 | M32: =+IFERROR(I32-G32,"N/A") -> 14358.38 | N32: =+IFERROR(M32/G32,"N/A") -> 0.32591809
L33: =IF(G33=0, " ",(J33-G33)/G33)
C34: *Effective Gross Income | E34: =+SUM(E25:E32) -> 7654107 | G34: 7513376.7 | H34: =+SUM(H25:H32) -> 6806968.9 | I34: =+SUM(I25:I32) -> 7637240 | J34: =IFERROR(IF(E34=0, " ",(H34-E34)/E34),"") -> -0.11067759 | K34: =IF(G34=0, " ",(H34-G34)/G34) -> -0.094020015 | M34: =+IFERROR(I34-G34,"N/A") -> 123863.27 | N34: =+IFERROR(M34/G34,"N/A") -> 0.016485699
E35: (3) Use either Gross Potential (with Vacancy Loss) or Base Rents; use negative $amt for Vacancy Loss
L36: =IF(G36=0, " ",(J36-G36)/G36)
C37: OPERATING EXPENSES: | L37: =IF(G37=0, " ",(J37-G37)/G37)
C38: Real Estate Taxes | E38: 915368 | G38: 1038275.6 | H38: =_xlfn.XLOOKUP($C38,TTM!$T:$T,TTM!$U:$U,0) -> 1032690.2 | I38: =+MAX(H38,Tax!$D$6) -> 1038275.6 | J38: =IFERROR(IF(E38=0, " ",(H38-E38)/E38),"") -> 0.12816946 | K38: =IF(G38=0, " ",(H38-G38)/G38) -> -0.0053795156 | L38: ="Greater of actual tax bill from " & TEXT(Tax!$B$8,"mm/d/yyyy") & "-" & TEXT(Tax!$B$9,"mm/d/yyyy") & " (" & TEXT(Tax!$D$6/1000000,"$0.0""MM""") & ") and TTM ended " & TEXT($I$15,"mm/d/yyyy") -> Greater of actual tax bill from 07/1/2025-06/30/2026 ($1.0MM) and TTM ended 03/31/2026 | M38: =+IFERROR(I38-G38,"N/A") -> 0 | N38: =+IFERROR(M38/G38,"N/A") -> 0
C39: Property Insurance | E39: 185337 | G39: 189226.62 | H39: =_xlfn.XLOOKUP($C39,TTM!$T:$T,TTM!$U:$U,0) -> 191090.61 | I39: =+MAX(H39,Insurance!R9) -> 191090.61 | J39: =IFERROR(IF(E39=0, " ",(H39-E39)/E39),"") -> 0.031044044 | K39: =IF(G39=0, " ",(H39-G39)/G39) -> 0.0098505697 | L39: ="Greater of Actual insurance premium from 5/17/2025 - 5/17/2026 "&TEXT(Insurance!R9/1000,"($0.0K)")&" and TTM ended "&TEXT($I$15,"mm/dd/yyyy") -> Greater of Actual insurance premium from 5/17/2025 - 5/17/2026 ($187.0K) and TTM ended 03/31/2026 | M39: =+IFERROR(I39-G39,"N/A") -> 1863.99 | N39: =+IFERROR(M39/G39,"N/A") -> 0.0098505697
C40: Utilities | E40: 529032 | G40: 616358.64 | H40: =_xlfn.XLOOKUP($C40,TTM!$T:$T,TTM!$U:$U,0) -> 663763.62 | I40: =+H40 -> 663763.62 | J40: =IFERROR(IF(E40=0, " ",(H40-E40)/E40),"") -> 0.25467575 | K40: =IF(G40=0, " ",(H40-G40)/G40) -> 0.076911358 | L40: ="TTM ended" &TEXT($I$15, " mm/dd/yyyy") -> TTM ended 03/31/2026 | M40: =+IFERROR(I40-G40,"N/A") -> 47404.98 | N40: =+IFERROR(M40/G40,"N/A") -> 0.076911358
...

Sheet DS
L1: Previous | M1: Current
L2: 46022 | M2: =+'Comm OSAR'!I15 -> 46112
C3: UPB | L3: 63000000 | M3: =+'Comm OSAR'!E6 -> 63000000
C4: Occupancy | L4: 0.67098943 | M4: =+'Comm OSAR'!I16 -> 0.68435973
C6: Rate Cap | L6: 0.05 | M6: 0.05
C7: SOFR | L7: 0.0378659 | M7: 0.0368
C8: Spread | L8: 0.0298 | M8: 0.0298
C10: Effective Interest Rate | L10: 0.0676659 | M10: =+SUM(M7:M8) -> 0.0666
C11: Effective Capped Interest Rate | L11: 0.0676659 | M11: =+MIN(M6,M7)+M8 -> 0.0666
C13: Net Cash Flow | L13: 3734510.6 | M13: =+'Comm OSAR'!I62 -> 3824433.6
C15: Debt Service (Excluding Rate Cap) | L15: 4322159.4 | M15: =+M10*$M$3*(365/360) -> 4254075
C16: Debt Service (Including Rate Cap) | L16: 4322159.4 | M16: =+M11*$M$3*(365/360) -> 4254075
C18: DSCR (Excluding Rate Cap) | L18: 0.86403816 | M18: =+$M$13/M15 -> 0.89900475
C19: DSCR (Including Rate Cap) | L19: 0.86403816 | M19: =+$M$13/M16 -> 0.89900475
C21: DY | L21: 0.059277947 | M21: =M13/M3 -> 0.060705296

Sheet OSAR
A1: 1
B2: CREFC Investor Reporting Package
B3: COMMERCIAL OPERATING STATEMENT ANALYSIS REPORT
B4: 46022
B5: PROPERTY OVERVIEW | F5: Allocated Loan Amount/Percentage
B6: THE RESERVE | D6: Paid Thru Date | E6: Debt Outside Trust (1) | F6: $ | G6: %
B7: Note A-Scheduled Loan Balance | C7: 63000000 | D7: =+B4 -> 46022 | G7: 1
B8: Property Name | C8: The Campus at Villa La Jolla
B9: Property Type | C9: Medical Office
B10: Property Address, City, State
B11: Current Net Rentable SF/Units/Beds/Rooms | C11: 191454
B12: Year Built/Year Renovated | C12: 2018/2018
B13: CapEx Reserve (annually)/per Unit.etc. | C13: 0.25
B14: Statement Ending Date | C14: Underwriting | G14: =B4 -> 46022 | H14: =G14 -> 46022
B15: Occupancy Rate (physical) | C15: =1-0.286 -> 0.714 | G15: ='Rent Roll'!B95 -> 0.68435973 | H15: =G15 -> 0.68435973
B16: Occupancy Date | C16: 46265 | G16: =G14 -> 46022 | H16: =G16 -> 46022
K18: Vacancy Factor | L18: 0.05
G20: T12 | H20: DY Test | K20: DY Test | L20: DY Test
B21: INCOME | C21: At Contribution | G21: =$G$14 -> 46022 | H21: =$G$14 -> 46022 | I21: Notes | K21: QoQ | L21: QoQ (%)
B22: Gross Potential Rent | C22: 9567046 | G22: =+TTM!U10 -> 5796406.8 | H22: ='Rent Roll'!Y87 -> 6695002.4 | I22: ="Annualized RR as of" & TEXT($D$7," mm/dd/yyyy") & ", adjusted for free rent and KVs" -> Annualized RR as of 12/31/2025, adjusted for free rent and KVs
B23: Less: Vacancy Loss | C23: -2897565 | H23: =IF(H15<(1-L18),0,-(H15-(1-L18))*H22) -> 0 | I23: ="Greater of Actual "&TEXT(1-$H$15,"(0.00%)")&" or 5.00% of GPR" -> Greater of Actual (31.56%) or 5.00% of GPR
B24: OR
B25: Base Rent | K25: =H25-F25 -> 0 | L25: =+IFERROR(K25/F25," - ") -> -
B26: Expense Reimbursement | C26: 700149 | G26: =_xlfn.XLOOKUP($B26,TTM!$T:$T,TTM!$U:$U,0) -> 0 | H26: ='Rent Roll'!Z87 -> 435812.98 | I26: ="Annualized RR as of" & TEXT($D$7," mm/dd/yyyy") -> Annualized RR as of 12/31/2025 | K26: =H26-F26 -> 435812.98 | L26: =+IFERROR(K26/F26," - ") -> -
B27: Percentage Rent | G27: =_xlfn.XLOOKUP($B27,TTM!$T:$T,TTM!$U:$U,0) -> 0 | H27: 0 | I27: ="T12 ended" &TEXT($D$7, " mm/dd/yyyy") -> T12 ended 12/31/2025 | K27: =H27-F27 -> 0 | L27: =+IFERROR(K27/F27," - ") -> -
B28: Parking Income | C28: 333230 | G28: =_xlfn.XLOOKUP($B28,TTM!$T:$T,TTM!$U:$U,0) -> 0 | H28: =G28 -> 0 | I28: ="T12 ended" &TEXT($D$7, " mm/dd/yyyy") -> T12 ended 12/31/2025 | K28: =H28-F28 -> 0 | L28: =+IFERROR(K28/F28," - ") -> -
B29: Other Income | C29: -48753 | G29: =_xlfn.XLOOKUP($B29,TTM!$T:$T,TTM!$U:$U,0) -> 0 | H29: =+G29 -> 0 | I29: ="T12 ended" &TEXT($D$7, " mm/dd/yyyy") -> T12 ended 12/31/2025 | K29: =H29-F29 -> 0 | L29: =+IFERROR(K29/F29," - ") -> -
B31: Effective Gross Income | C31: 7654107 | G31: =SUM(G22:G30) -> 5796406.8 | H31: =SUM(H22:H29) -> 7130815.4 | K31: =H31-F31 -> 7130815.4 | L31: =+IFERROR(K31/F31," - ") -> -
B33: OPERATING EXPENSES
B34: Real Estate Taxes | C34: 915368 | G34: =_xlfn.XLOOKUP($B34,TTM!$T:$T,TTM!$U:$U,0) -> 0 | H34: =+MAX(G34,Tax!$D$6) -> 1038275.6 | I34: ="Greater of Actual "&TEXT(Tax!$D$6/1000,"($0.0K)")&" T12 ended "&TEXT($D$7,"mm/dd/yyyy") -> Greater of Actual ($1038.3K) T12 ended 12/31/2025 | K34: =H34-F34 -> 1038275.6 | L34: =+IFERROR(K34/F34," - ") -> -
B35: Property Insurance | C35: 185337 | G35: =_xlfn.XLOOKUP($B35,TTM!$T:$T,TTM!$U:$U,0) -> 0 | H35: =MAX(G35,Insurance!R9) -> 186983.74 | I35: ="Greater of Actual "&TEXT(Insurance!R9/1000,"($0.0K)")&" T12 ended "&TEXT($D$7,"mm/dd/yyyy") -> Greater of Actual ($187.0K) T12 ended 12/31/2025 | K35: =H35-F35 -> 186983.74 | L35: =+IFERROR(K35/F35," - ") -> -
B36: Utilities | C36: 529032 | G36: =_xlfn.XLOOKUP($B36,TTM!$T:$T,TTM!$U:$U,0) -> 0 | H36: =G36 -> 0 | I36: ="T12 ended" &TEXT($D$7, " mm/dd/yyyy") -> T12 ended 12/31/2025 | K36: =H36-F36 -> 0 | L36: =+IFERROR(K36/F36," - ") -> -
B37: Repairs & Maintenance | C37: 366300 | G37: =_xlfn.XLOOKUP($B37,TTM!$T:$T,TTM!$U:$U,0) -> 0 | H37: =G37 -> 0 | I37: ="T12 ended" &TEXT($D$7, " mm/dd/yyyy") -> T12 ended 12/31/2025 | K37: =H37-F37 -> 0 | L37: =+IFERROR(K37/F37," - ") -> -
B38: Janitorial | C38: 305250 | G38: =_xlfn.XLOOKUP($B38,TTM!$T:$T,TTM!$U:$U,0) -> 0 | H38: =G38 -> 0 | I38: ="T12 ended" &TEXT($D$7, " mm/dd/yyyy") -> T12 ended 12/31/2025 | K38: =H38-F38 -> 0 | L38: =+IFERROR(K38/F38," - ") -> -
B39: Management Fees | C39: 229623 | G39: =_xlfn.XLOOKUP($B39,TTM!$T:$T,TTM!$U:$U,0) -> 0 | H39: =MAX(G39,H31*0.03) -> 213924.46 | I39: ="Greater of Actual "&TEXT(G39/1000,"($###.#K)")&" or 3.00% of EGI" -> Greater of Actual ($.K) or 3.00% of EGI | K39: =H39-F39 -> 213924.46 | L39: =+IFERROR(K39/F39," - ") -> -
B40: Payroll & Benefits | C40: 358499 | G40: =_xlfn.XLOOKUP($B40,TTM!$T:$T,TTM!$U:$U,0) -> 0 | H40: =G40 -> 0 | I40: ="T12 ended" &TEXT($D$7, " mm/dd/yyyy") -> T12 ended 12/31/2025 | K40: =H40-F40 -> 0 | L40: =+IFERROR(K40/F40," - ") -> -
B41: Advertising & Marketing | C41: 0 | G41: =_xlfn.XLOOKUP($B41,TTM!$T:$T,TTM!$U:$U,0) -> 0 | H41: =G41 -> 0 | I41: ="T12 ended" &TEXT($D$7, " mm/dd/yyyy") -> T12 ended 12/31/2025 | K41: =H41-F41 -> 0 | L41: =+IFERROR(K41/F41," - ") -> -
B42: Professional Fees | C42: 235046 | G42: =_xlfn.XLOOKUP($B42,TTM!$T:$T,TTM!$U:$U,0) -> 0 | H42: =G42 -> 0 | I42: ="T12 ended" &TEXT($D$7, " mm/dd/yyyy") -> T12 ended 12/31/2025 | K42: =H42-F42 -> 0 | L42: =+IFERROR(K42/F42," - ") -> -
B43: General and Administrative | C43: 61820 | G43: =_xlfn.XLOOKUP($B43,TTM!$T:$T,TTM!$U:$U,0) -> 0 | H43: =G43 -> 0 | I43: ="T12 ended" &TEXT($D$7, " mm/dd/yyyy") -> T12 ended 12/31/2025 | K43: =H43-F43 -> 0 | L43: =+IFERROR(K43/F43," - ") -> -
B44: Other Expenses | C44: 186206 | G44: =_xlfn.XLOOKUP($B44,TTM!$T:$T,TTM!$U:$U,0) -> 0 | H44: =G44 -> 0 | I44: ="T12 ended" &TEXT($D$7, " mm/dd/yyyy") -> T12 ended 12/31/2025 | K44: =H44-F44 -> 0 | L44: =+IFERROR(K44/F44," - ") -> -
...

Sheet QoQ
A1: 1
D2: 4Q 2025 | H2: 1Q 2026 | L2: QoQ ∆ | P2: Cash Management
C3: Property | D3: Occupancy | E3: NOI | F3: DY | G3: DSCR | H3: Occupancy | I3: NOI | J3: DY | K3: DSCR | L3: Occupancy | M3: NOI | N3: DY | O3: DSCR | P3: In CM? | Q3: Threshold
C4: The Campus on Villa La Jolla | D4: 0.67098943 | E4: 3734510.6 | F4: 0.059277947 | G4: 0.86403816 | H4: ='Comm OSAR'!I16 -> 0.68435973 | I4: =+'Comm OSAR'!I62 -> 3824433.6 | J4: =+DS!M21 -> 0.060705296 | K4: =+DS!M19 -> 0.89900475 | L4: =IF(H4="","-",H4-D4) -> 0.013370296 | M4: =IF(I4="","-",I4-E4) -> 89923.002 | N4: =IF(J4="","-",J4-F4) -> 0.0014273492 | O4: =IF(K4="","-",K4-G4) -> 0.034966588 | P4: No | Q4: 0.055
C6: Notes:
C7: NOI adjusted per the Loan Agreement.
C8: DSCR includes the benefit of the rate cap.
C9: Performance remained flat QoQ.

Sheet TTM
A1: Ocotillo SD VillaLaJolla, LLC (a01030)
A2: Statement (12 months)
A3: Period = Apr 2025-Mar 2026
A4: Book = Accrual
C5: Apr 2025 | D5: May 2025 | E5: Jun 2025 | F5: Jul 2025 | G5: Aug 2025 | H5: Sep 2025 | I5: Oct 2025 | J5: Nov 2025 | K5: Dec 2025 | L5: Jan 2026 | M5: Feb 2026 | N5: Mar 2026 | O5: Total | Q5: Expense Category
A6: 4000-0000 | B6: INCOME | U6: =+'Comm OSAR'!F6 -> 46112 | V6: 46022
A7: 4002-0000 | B7: OPERATING REVENUE | U7: Current | V7: Prior
A8: 4003-0000 | B8: TENANT RENTS & SERVICES | T8: Line Item | U8: T12 Total | V8: T12 Total
A9: 4100-0000 | B9: OFFICE
A10: 4110-0000 | B10: Rent-Office | C10: 521739.2 | D10: 529051.3 | E10: 531023.73 | F10: 526271.3 | G10: 530117.07 | H10: 526728.34 | I10: 534666.46 | J10: 539426.81 | K10: 552216.53 | L10: 569474.28 | M10: 578337.56 | N10: 581867.15 | O10: 6520919.7 | Q10: =_xlfn.XLOOKUP($B10,coding!$A:$A,coding!$C:$C,"") -> Base Rent (3) | T10: Base Rent (3) | U10: =SUMIF($Q:$Q,T10,$O:$O) -> 5796406.8 | V10: 5799465
A11: 4125-0000 | B11: Rent-Office Parking | C11: 21375.47 | D11: 23025.31 | E11: 27995.14 | F11: 28798.34 | G11: 27361.77 | H11: 21583.11 | I11: 19678.4 | J11: 143443.58 | K11: 31252.83 | L11: 32028.81 | M11: 24555.74 | N11: 46912.53 | O11: 448011.03 | Q11: =_xlfn.XLOOKUP($B11,coding!$A:$A,coding!$C:$C,"") -> Parking Income | T11: Expense Reimbursement | U11: =SUMIF($Q:$Q,T11,$O:$O) -> 504137.47 | V11: 569922.03
A12: 4130-0000 | B12: Rent Abatement-Office | C12: -21738.04 | D12: -21910.6 | E12: -28167.4 | F12: -36532.48 | G12: -51621.2 | H12: -20268.7 | I12: -95323.43 | J12: -91901.35 | K12: -88203.85 | L12: -104449.45 | M12: -115819.95 | N12: -48576.45 | O12: -724512.9 | Q12: =_xlfn.XLOOKUP($B12,coding!$A:$A,coding!$C:$C,"") -> Base Rent (3) | T12: Percentage Rent | U12: =SUMIF($Q:$Q,T12,$O:$O) -> 0 | V12: 0
A13: 4190-0000 | B13: TOTAL OFFICE | C13: 521376.63 | D13: 530166.01 | E13: 530851.47 | F13: 518537.16 | G13: 505857.64 | H13: 528042.75 | I13: 459021.43 | J13: 590969.04 | K13: 495265.51 | L13: 497053.64 | M13: 487073.35 | N13: 580203.23 | O13: 6244417.9 | Q13: =_xlfn.XLOOKUP($B13,coding!$A:$A,coding!$C:$C,"") -> 0 | T13: Parking Income | U13: =SUMIF($Q:$Q,T13,$O:$O) -> 448011.03 | V13: 414384.19
A14: 4400-0000 | B14: RESIDENTIAL | Q14: =_xlfn.XLOOKUP($B14,coding!$A:$A,coding!$C:$C,"") -> 0 | T14: Other Income | U14: =SUMIF($Q:$Q,T14,$O:$O) -> 58413.56 | V14: 44055.18
A15: 4700-0000 | B15: REIMBURSABLE EXPENSES | Q15: =_xlfn.XLOOKUP($B15,coding!$A:$A,coding!$C:$C,"") -> 0
A16: 4705-0000 | B16: CAM Recovery-Estimate | C16: 51383.77 | D16: 52748.84 | E16: 52748.84 | F16: 51402.76 | G16: 51254.99 | H16: 32311.27 | I16: 32311.27 | J16: 32311.27 | K16: 32311.27 | L16: 37866.81 | M16: 37568.54 | N16: 37568.54 | O16: 501788.17 | Q16: =_xlfn.XLOOKUP($B16,coding!$A:$A,coding!$C:$C,"") -> Expense Reimbursement | T16: Effective Gross Income | U16: =SUM(U10:U15) -> 6806968.9 | V16: 6827826.4
A17: 4710-0000 | B17: CAM Recovery-Y/End | C17: 0 | D17: 0 | E17: -181768.85 | F17: 118289.6 | G17: 0 | H17: 0 | I17: -10567.33 | J17: 0 | K17: 0 | L17: 0 | M17: 0 | N17: 0 | O17: -74046.58 | Q17: =_xlfn.XLOOKUP($B17,coding!$A:$A,coding!$C:$C,"") -> Expense Reimbursement
A18: 4745-0000 | B18: Utilities Recovery-Estimate | C18: 4381.83 | D18: 4033.14 | E18: 4601.54 | F18: 3209.21 | G18: 5661.65 | H18: 3344.98 | I18: 4811.78 | J18: 5982.63 | K18: 183.88 | L18: -671.13 | M18: 507.63 | N18: 340 | O18: 36387.14 | Q18: =_xlfn.XLOOKUP($B18,coding!$A:$A,coding!$C:$C,"") -> Expense Reimbursement | T18: OPERATING EXPENSES
A19: 4760-0000 | B19: Misc Income | C19: 18642.49 | D19: 2347.59 | E19: 0 | F19: 0 | G19: 5276.43 | H19: 38742.41 | I19: 349.75 | J19: 5724.29 | K19: -37747.5 | L19: 318.97 | M19: 3774.54 | N19: 2579.77 | O19: 40008.74 | Q19: =_xlfn.XLOOKUP($B19,coding!$A:$A,coding!$C:$C,"") -> Expense Reimbursement | T19: Real Estate Taxes | U19: =SUMIF($Q:$Q,T19,$O:$O) -> 1032690.2 | V19: 997085.11
A20: 4799-0000 | B20: TOTAL REIMBURSABLE EXPENSES | C20: 74408.09 | D20: 59129.57 | E20: -124418.47 | F20: 172901.57 | G20: 62193.07 | H20: 74398.66 | I20: 26905.47 | J20: 44018.19 | K20: -5252.35 | L20: 37514.65 | M20: 41850.71 | N20: 40488.31 | O20: 504137.47 | Q20: =_xlfn.XLOOKUP($B20,coding!$A:$A,coding!$C:$C,"") -> 0 | T20: Property Insurance | U20: =SUMIF($Q:$Q,T20,$O:$O) -> 191090.61 | V20: 189226.62
A21: 4800-0000 | B21: OTHER OPERATING INCOME | Q21: =_xlfn.XLOOKUP($B21,coding!$A:$A,coding!$C:$C,"") -> 0 | T21: Utilities | U21: =SUMIF($Q:$Q,T21,$O:$O) -> 663763.62 | V21: 616358.64
A22: 4851-0000 | B22: Tenant Service Revenue | C22: 0 | D22: 8262.24 | E22: 8674.83 | F22: 8382.44 | G22: 1034.26 | H22: 8644.64 | I22: 2319.13 | J22: 6737.64 | K22: 0 | L22: 7769.71 | M22: 1526.84 | N22: 6619.82 | O22: 59971.55 | Q22: =_xlfn.XLOOKUP($B22,coding!$A:$A,coding!$C:$C,"") -> Other Income | T22: Repairs and Maintenance | U22: =SUMIF($Q:$Q,T22,$O:$O) -> 477146.7 | V22: 507856.18
A23: 4852-0000 | B23: Cost of Tenant Services | C23: 0 | D23: 0 | E23: 0 | F23: -111.64 | G23: 111.64 | H23: 0 | I23: 0 | J23: 0 | K23: 0 | L23: 0 | M23: 0 | N23: 0 | O23: 0 | Q23: =_xlfn.XLOOKUP($B23,coding!$A:$A,coding!$C:$C,"") -> Other Income | T23: Janitorial | U23: =SUMIF($Q:$Q,T23,$O:$O) -> 275362.38 | V23: 275372.32
A24: 4855-0000 | B24: Late Fees | C24: 0 | D24: 0 | E24: 0 | F24: 0 | G24: 0 | H24: 0 | I24: 0 | J24: 0 | K24: 0 | L24: -5 | M24: 0 | N24: 5 | O24: 0 | Q24: =_xlfn.XLOOKUP($B24,coding!$A:$A,coding!$C:$C,"") -> Other Income | T24: Management Fees | U24: =SUMIF($Q:$Q,T24,$O:$O) -> 111110.94 | V24: 97431.15
A25: 4865-0000 | B25: Miscellaneous | C25: 409.05 | D25: 422.95 | E25: 344.32 | F25: 359.68 | G25: -3093.99 | H25: 0 | I25: 0 | J25: 0 | K25: 0 | L25: 0 | M25: 0 | N25: 0 | O25: -1557.99 | Q25: =_xlfn.XLOOKUP($B25,coding!$A:$A,coding!$C:$C,"") -> Other Income | T25: Payroll & Benefits | U25: =SUMIF($Q:$Q,T25,$O:$O) -> 434643.21 | V25: 416599.89
A26: 4890-0000 | B26: TOTAL OTHER OPERATING INCOME | C26: 409.05 | D26: 8685.19 | E26: 9019.15 | F26: 8630.48 | G26: -1948.09 | H26: 8644.64 | I26: 2319.13 | J26: 6737.64 | K26: 0 | L26: 7764.71 | M26: 1526.84 | N26: 6624.82 | O26: 58413.56 | Q26: =_xlfn.XLOOKUP($B26,coding!$A:$A,coding!$C:$C,"") -> 0 | T26: Advertising & Marketing | U26: =SUMIF($Q:$Q,T26,$O:$O) -> 7395.28 | V26: 6290.29
A27: 4999-0000 | B27: TOTAL OPERATING REVENUE | C27: 596193.77 | D27: 597980.77 | E27: 415452.15 | F27: 700069.21 | G27: 566102.62 | H27: 611086.05 | I27: 488246.03 | J27: 641724.87 | K27: 490013.16 | L27: 542333 | M27: 530450.9 | N27: 627316.36 | O27: 6806968.9 | Q27: =_xlfn.XLOOKUP($B27,coding!$A:$A,coding!$C:$C,"") -> 0 | T27: Professional Fees | U27: =SUMIF($Q:$Q,T27,$O:$O) -> 201585.86 | V27: 215728.76
A28: 5001-0000 | B28: OPERATING EXPENSES | Q28: =_xlfn.XLOOKUP($B28,coding!$A:$A,coding!$C:$C,"") -> 0 | T28: General and Administrative | U28: =SUMIF($Q:$Q,T28,$O:$O) -> 59576.01 | V28: 57292.11
A29: 5002-0000 | B29: OPERATING EXPENSES - RECOVERABLE | Q29: =_xlfn.XLOOKUP($B29,coding!$A:$A,coding!$C:$C,"") -> 0 | T29: Other Expenses | U29: =SUMIF($Q:$Q,T29,$O:$O) -> 186986.3 | V29: 182600.79
A30: 5100-0000 | B30: CLEANING - RECOVERABLE | Q30: =_xlfn.XLOOKUP($B30,coding!$A:$A,coding!$C:$C,"") -> 0 | T30: Ground Rent | U30: =SUMIF($Q:$Q,T30,$O:$O) -> 0 | V30: 0
A31: 5110-0000 | B31: Cleaning-Day Porter | C31: 5147 | D31: 5147 | E31: 5147 | F31: 5147 | G31: 5147 | H31: 5147 | I31: 5147 | J31: 5147 | K31: 5147 | L31: 5472.95 | M31: 5266 | N31: 5266 | O31: 62327.95 | Q31: =_xlfn.XLOOKUP($B31,coding!$A:$A,coding!$C:$C,"") -> Janitorial | T31: Total Operating Expenses | U31: =SUM(U19:U30) -> 3641351.1 | V31: 3561841.9
A32: 5112-0000 | B32: Cleaning-Contract Srvcs | C32: 13924.79 | D32: 13815.52 | E32: 15471.04 | F32: 14112 | G32: 14209.23 | H32: 14892.55 | I32: 14221.5 | J32: 14221.5 | K32: 14221.5 | L32: 14549.3 | M32: 14221.5 | N32: 14133.24 | O32: 171993.67 | Q32: =_xlfn.XLOOKUP($B32,coding!$A:$A,coding!$C:$C,"") -> Janitorial
A33: 5116-0000 | B33: Cleaning-Window Cleaning | C33: 0 | D33: 0 | E33: 204 | F33: 0 | G33: 0 | H33: 0 | I33: 0 | J33: 0 | K33: 0 | L33: 0 | M33: 0 | N33: 0 | O33: 204 | Q33: =_xlfn.XLOOKUP($B33,coding!$A:$A,coding!$C:$C,"") -> Janitorial | T33: NOI | U33: =U16-U31 -> 3165617.8 | V33: 3265984.5
A34: 5118-0000 | B34: Cleaning-Supplies | C34: 3899.07 | D34: 4996.7 | E34: 1864.33 | F34: 3948.68 | G34: 2774.57 | H34: 2897.06 | I34: 7185.92 | J34: 4289.41 | K34: 1036.34 | L34: 3360.15 | M34: 2012.53 | N34: 2300 | O34: 40564.76 | Q34: =_xlfn.XLOOKUP($B34,coding!$A:$A,coding!$C:$C,"") -> Janitorial
A35: 5199-0000 | B35: TOTAL CLEANING - RECOVERABLE | C35: 22970.86 | D35: 23959.22 | E35: 22686.37 | F35: 23207.68 | G35: 22130.8 | H35: 22936.61 | I35: 26554.42 | J35: 23657.91 | K35: 20404.84 | L35: 23382.4 | M35: 21500.03 | N35: 21699.24 | O35: 275090.38 | Q35: =_xlfn.XLOOKUP($B35,coding!$A:$A,coding!$C:$C,"") -> 0 | T35: Non-Operating Expenses | U35: =SUMIF($Q:$Q,T35,$O:$O) -> 0 | V35: 0
A36: 5200-0000 | B36: REPAIR & MAINTENANCE - RECOVERABLE | Q36: =_xlfn.XLOOKUP($B36,coding!$A:$A,coding!$C:$C,"") -> 0 | T36: Interest Expense | U36: =SUMIF($Q:$Q,T36,$O:$O) -> 1583007.7 | V36: 1576987.6
A37: 5201-0000 | B37: RM-Pay/Wages | C37: 19739.02 | D37: 18501.38 | E37: 18681.6 | F37: 19108.17 | G37: 20901.38 | H37: 26205.96 | I37: 7992.68 | J37: 20020.52 | K37: 14507.23 | L37: 19773.14 | M37: 27863.56 | N37: 18672.24 | O37: 231966.88 | Q37: =_xlfn.XLOOKUP($B37,coding!$A:$A,coding!$C:$C,"") -> Repairs and Maintenance | T37: Debt Service | U37: =SUMIF($Q:$Q,T37,$O:$O) -> 4904625.8 | V37: 5207007.6
A38: 5207-0000 | B38: RM-Supplies | C38: 46.77 | D38: 0 | E38: 0 | F38: 1455.2 | G38: 154.7 | H38: 2185.23 | I38: 387.89 | J38: 26.92 | K38: 102.78 | L38: 0 | M38: 0 | N38: 496.19 | O38: 4855.68 | Q38: =_xlfn.XLOOKUP($B38,coding!$A:$A,coding!$C:$C,"") -> Repairs and Maintenance
A39: 5208-0000 | B39: RM-Uniforms | C39: 131 | D39: 131 | E39: 131 | F39: 416.58 | G39: 131 | H39: 131 | I39: 131 | J39: 65.5 | K39: 1260.03 | L39: -800.82 | M39: 131.4 | N39: 131.2 | O39: 1989.89 | Q39: =_xlfn.XLOOKUP($B39,coding!$A:$A,coding!$C:$C,"") -> Repairs and Maintenance | T39: Non-Recurring Expenses
A40: 5209-0000 | B40: RM-Equipment | C40: 87.79 | D40: 0 | E40: 0 | F40: 37.02 | G40: 0 | H40: 0 | I40: 0 | J40: 0 | K40: 0 | L40: 0 | M40: 0 | N40: 290.85 | O40: 415.66 | Q40: =_xlfn.XLOOKUP($B40,coding!$A:$A,coding!$C:$C,"") -> Repairs and Maintenance | T40: HVAC R&M
...

Sheet Rent Roll
A1: Tenancy Schedule I
A2: All Selected Properties As of Date: 03/31/2026 By Property Notes : 1. * Future Active lease / Future Active Amendment 2. ** Pending Amendments 3. *** Past / Superseded Amendments
A3: Property | B3: Unit(s) | C3: Lease | D3: Lease Type | E3: Area | F3: Lease From | G3: Lease To | H3: Term | I3: Tenancy | J3: Monthly | K3: Monthly | L3: Annual | M3: Annual | N3: Annual | O3: Annual | P3: Security | Q3: LOC Amount/ | T3: Include in DY Test? | U3: Term (YR) | V3: Free Rent Period | W3: Month Excluded | X3: Months Included | Y3: Adj Annnal Rent | Z3: Adj. Annual Recoveries | AA3: Adjusted Occupied SF | AC3: Last Update
I4: Years | J4: Rent | K4: Rent/Area | L4: Rent | M4: Rent/Area | N4: Rec./Area | O4: Misc/Area | P4: Deposit | Q4: Bank Guarantee | T4: 46112 | AC4: 46112
A5: x | B5: x | C5: x | D5: x | E5: x | F5: x | G5: x | H5: x | I5: x | J5: x | K5: x | L5: x | M5: x | N5: x | O5: x | P5: Received | Q5: x | S5: Notes | AC5: Credit Rating Rating above (BBB-) ?
A6: Campus at LaJolla (a0103013) | B6: 8910 | C6: The Regents of the University of California (8910) (t0000137) | D6: Office Net | E6: 14750 | F6: 42594 | G6: 49887 | H6: 240 | I6: 9.67 | J6: 73012.5 | K6: 4.95 | L6: 876150 | M6: 59.4 | N6: 6.07 | O6: 0 | P6: 0 | Q6: 0 | T6: =+IF(OR(C6="Vacant",G6=""),FALSE,IF($AC6="Yes",F6<=($T$4+180),F6<=($T$4+90))) -> TRUE | U6: =+IF(G6="",0,DATEDIF(F6,G6,"M")/12) -> 19.916667 | W6: =+MAX(V6-U6,0) -> 0 | X6: =12-W6 -> 12 | Y6: =+(J6*X6+E6*O6)*T6 -> 876150 | Z6: =(X6*N6*E6/12)*T6 -> 89532.5 | AA6: =+T6*E6 -> 14750 | AC6: Yes
A7: Campus at LaJolla (a0103013) | B7: A105 | C7: Coleman Meadows DDS, Inc. (A105) (t0000071) | D7: Office Net | E7: 2548 | F7: 43678 | G7: 47330 | H7: 120 | I7: 6.67 | J7: 11873.68 | K7: 4.66 | L7: 142484.16 | M7: 55.92 | N7: 6.65 | O7: 0 | P7: 9200 | Q7: 0 | T7: =+IF(OR(C7="Vacant",G7=""),FALSE,IF($AC7="Yes",F7<=($T$4+180),F7<=($T$4+90))) -> TRUE | U7: =+IF(G7="",0,DATEDIF(F7,G7,"M")/12) -> 9.9166667 | W7: =+MAX(V7-U7,0) -> 0 | X7: =12-W7 -> 12 | Y7: =+(J7*X7+E7*O7)*T7 -> 142484.16 | Z7: =(X7*N7*E7/12)*T7 -> 16944.2 | AA7: =+T7*E7 -> 2548
A8: Campus at LaJolla (a0103013) | B8: A107 | C8: Bronner Handwerger (A107) (t0000072) | D8: Office Net | E8: 1438 | F8: 45170 | G8: 47118 | H8: 64 | I8: 2.58 | J8: 6859.26 | K8: 4.77 | L8: 82311.12 | M8: 57.24 | N8: 2.47 | O8: 0 | P8: 4807.33 | Q8: 0 | T8: =+IF(OR(C8="Vacant",G8=""),FALSE,IF($AC8="Yes",F8<=($T$4+180),F8<=($T$4+90))) -> TRUE | U8: =+IF(G8="",0,DATEDIF(F8,G8,"M")/12) -> 5.25 | W8: =+MAX(V8-U8,0) -> 0 | X8: =12-W8 -> 12 | Y8: =+(J8*X8+E8*O8)*T8 -> 82311.12 | Z8: =(X8*N8*E8/12)*T8 -> 3551.86 | AA8: =+T8*E8 -> 1438
A9: Campus at LaJolla (a0103013) | B9: A108 | C9: Nancy Markel (A108) (t0000073) | D9: Office Net | E9: 620 | F9: 44896 | G9: 46174 | I9: 3.33 | J9: 2728 | K9: 4.4 | L9: 32736 | M9: 52.8 | N9: 8.34 | O9: 0 | P9: 1652.52 | Q9: 0 | T9: =+IF(OR(C9="Vacant",G9=""),FALSE,IF($AC9="Yes",F9<=($T$4+180),F9<=($T$4+90))) -> TRUE | U9: =+IF(G9="",0,DATEDIF(F9,G9,"M")/12) -> 3.5 | W9: =+MAX(V9-U9,0) -> 0 | X9: =12-W9 -> 12 | Y9: =+(J9*X9+E9*O9)*T9 -> 32736 | Z9: =(X9*N9*E9/12)*T9 -> 5170.8 | AA9: =+T9*E9 -> 620
A10: Campus at LaJolla (a0103013) | B10: A109 | C10: Advantech GS Enterprises, Inc. (B208) (t0000074) | D10: Office Net | E10: 1284 | F10: 44350 | G10: 48060 | H10: 122 | I10: 4.83 | J10: 5970.6 | K10: 4.65 | L10: 71647.2 | M10: 55.8 | N10: 6.34 | O10: 0 | P10: 14381.5 | Q10: 0 | T10: =+IF(OR(C10="Vacant",G10=""),FALSE,IF($AC10="Yes",F10<=($T$4+180),F10<=($T$4+90))) -> TRUE | U10: =+IF(G10="",0,DATEDIF(F10,G10,"M")/12) -> 10.083333 | W10: =+MAX(V10-U10,0) -> 0 | X10: =12-W10 -> 12 | Y10: =+(J10*X10+E10*O10)*T10 -> 71647.2 | Z10: =(X10*N10*E10/12)*T10 -> 8140.56 | AA10: =+T10*E10 -> 1284
A11: Campus at LaJolla (a0103013) | B11: A110 | C11: Maria Hiraldo (A110) (t0000075) | D11: Office Net | E11: 326 | F11: 44044 | G11: 47695 | H11: 120 | I11: 5.67 | J11: 1483.3 | K11: 4.55 | L11: 17799.6 | M11: 54.6 | N11: 6.33 | O11: 0 | P11: 1499.6 | Q11: 0 | T11: =+IF(OR(C11="Vacant",G11=""),FALSE,IF($AC11="Yes",F11<=($T$4+180),F11<=($T$4+90))) -> TRUE | U11: =+IF(G11="",0,DATEDIF(F11,G11,"M")/12) -> 9.9166667 | W11: =+MAX(V11-U11,0) -> 0 | X11: =12-W11 -> 12 | Y11: =+(J11*X11+E11*O11)*T11 -> 17799.6 | Z11: =(X11*N11*E11/12)*T11 -> 2063.58 | AA11: =+T11*E11 -> 326
A12: Campus at LaJolla (a0103013) | B12: A118 | C12: SureFire CPR (A118) (t0000149) | D12: Office Net | E12: 309 | F12: 45498 | G12: 46599 | H12: 37 | I12: 1.75 | J12: 1384.32 | K12: 4.48 | L12: 16611.84 | M12: 53.76 | N12: 2.05 | O12: 0 | P12: 2848.98 | Q12: 0 | T12: =+IF(OR(C12="Vacant",G12=""),FALSE,IF($AC12="Yes",F12<=($T$4+180),F12<=($T$4+90))) -> TRUE | U12: =+IF(G12="",0,DATEDIF(F12,G12,"M")/12) -> 3 | W12: =+MAX(V12-U12,0) -> 0 | X12: =12-W12 -> 12 | Y12: =+(J12*X12+E12*O12)*T12 -> 16611.84 | Z12: =(X12*N12*E12/12)*T12 -> 633.45 | AA12: =+T12*E12 -> 309
A13: Campus at LaJolla (a0103013) | B13: A125 | C13: La Jolla Sol Ventures, Inc. (A125) (t0000076) | D13: Office Net | E13: 1846 | F13: 44986 | G13: 46904 | H13: 63 | I13: 3.08 | J13: 9008.48 | K13: 4.88 | L13: 108101.76 | M13: 58.56 | N13: 2.32 | O13: 0 | P13: 4190.45 | Q13: 0 | T13: =+IF(OR(C13="Vacant",G13=""),FALSE,IF($AC13="Yes",F13<=($T$4+180),F13<=($T$4+90))) -> TRUE | U13: =+IF(G13="",0,DATEDIF(F13,G13,"M")/12) -> 5.1666667 | W13: =+MAX(V13-U13,0) -> 0 | X13: =12-W13 -> 12 | Y13: =+(J13*X13+E13*O13)*T13 -> 108101.76 | Z13: =(X13*N13*E13/12)*T13 -> 4282.72 | AA13: =+T13*E13 -> 1846
A14: Campus at LaJolla (a0103013) | B14: A127 | C14: Chemometec, Inc. (A127) (t0000077) | D14: Office Net | E14: 1469 | F14: 44562 | G14: 46507 | H14: 64 | I14: 4.25 | J14: 6654.57 | K14: 4.53 | L14: 79854.84 | M14: 54.36 | N14: 3.25 | O14: 0 | P14: 0 | Q14: 0 | T14: =+IF(OR(C14="Vacant",G14=""),FALSE,IF($AC14="Yes",F14<=($T$4+180),F14<=($T$4+90))) -> TRUE | U14: =+IF(G14="",0,DATEDIF(F14,G14,"M")/12) -> 5.25 | W14: =+MAX(V14-U14,0) -> 0 | X14: =12-W14 -> 12 | Y14: =+(J14*X14+E14*O14)*T14 -> 79854.84 | Z14: =(X14*N14*E14/12)*T14 -> 4774.25 | AA14: =+T14*E14 -> 1469
A15: Campus at LaJolla (a0103013) | B15: A128 | C15: J Zeidan, DMD, Inc. (A128) (t0000078) | D15: Office Net | E15: 2354 | F15: 44953 | G15: 46934 | H15: 66 | I15: 3.25 | J15: 11534.6 | K15: 4.9 | L15: 138415.2 | M15: 58.8 | N15: 2.81 | O15: 0 | P15: 12553 | Q15: 0 | T15: =+IF(OR(C15="Vacant",G15=""),FALSE,IF($AC15="Yes",F15<=($T$4+180),F15<=($T$4+90))) -> TRUE | U15: =+IF(G15="",0,DATEDIF(F15,G15,"M")/12) -> 5.4166667 | W15: =+MAX(V15-U15,0) -> 0 | X15: =12-W15 -> 12 | Y15: =+(J15*X15+E15*O15)*T15 -> 138415.2 | Z15: =(X15*N15*E15/12)*T15 -> 6614.74 | AA15: =+T15*E15 -> 2354
A16: Campus at LaJolla (a0103013) | B16: A207 | C16: Katherine A. Thomson, DDS, MS Inc. (A207) (t0000066) | D16: Office Net | E16: 1665 | F16: 43770 | G16: 47542 | H16: 124 | I16: 6.42 | J16: 7958.7 | K16: 4.78 | L16: 95504.4 | M16: 57.36 | N16: 4.23 | O16: 0 | P16: 6000 | Q16: 0 | T16: =+IF(OR(C16="Vacant",G16=""),FALSE,IF($AC16="Yes",F16<=($T$4+180),F16<=($T$4+90))) -> TRUE | U16: =+IF(G16="",0,DATEDIF(F16,G16,"M")/12) -> 10.25 | W16: =+MAX(V16-U16,0) -> 0 | X16: =12-W16 -> 12 | Y16: =+(J16*X16+E16*O16)*T16 -> 95504.4 | Z16: =(X16*N16*E16/12)*T16 -> 7042.95 | AA16: =+T16*E16 -> 1665
A17: Campus at LaJolla (a0103013) | B17: A215 | C17: Arash Khatami (A215) (t0000079) | D17: Office Net | E17: 907 | F17: 44531 | G17: 46478 | H17: 64 | I17: 4.33 | J17: 4181.27 | K17: 4.61 | L17: 50175.24 | M17: 55.32 | N17: 3.21 | O17: 0 | P17: 3700 | Q17: 0 | T17: =+IF(OR(C17="Vacant",G17=""),FALSE,IF($AC17="Yes",F17<=($T$4+180),F17<=($T$4+90))) -> TRUE | U17: =+IF(G17="",0,DATEDIF(F17,G17,"M")/12) -> 5.3333333 | W17: =+MAX(V17-U17,0) -> 0 | X17: =12-W17 -> 12 | Y17: =+(J17*X17+E17*O17)*T17 -> 50175.24 | Z17: =(X17*N17*E17/12)*T17 -> 2911.47 | AA17: =+T17*E17 -> 907
A18: Campus at LaJolla (a0103013) | B18: A218 | C18: Marin Wellness Pharmacy LLC (A218) (t0000606) | D18: Office Net | E18: 1422 | F18: 45778 | G18: 46904 | H18: 37 | I18: 0.92 | J18: 6256.8 | K18: 4.4 | L18: 75081.6 | M18: 52.8 | N18: 1.91 | O18: 0 | P18: 6839.82 | Q18: 0 | T18: =+IF(OR(C18="Vacant",G18=""),FALSE,IF($AC18="Yes",F18<=($T$4+180),F18<=($T$4+90))) -> TRUE | U18: =+IF(G18="",0,DATEDIF(F18,G18,"M")/12) -> 3 | W18: =+MAX(V18-U18,0) -> 0 | X18: =12-W18 -> 12 | Y18: =+(J18*X18+E18*O18)*T18 -> 75081.6 | Z18: =(X18*N18*E18/12)*T18 -> 2716.02 | AA18: =+T18*E18 -> 1422
A19: Campus at LaJolla (a0103013) | B19: A219 | C19: Rui Liu (A219) (t0000080) | D19: Office Net | E19: 905 | F19: 44501 | G19: 46387 | H19: 62 | I19: 4.42 | J19: 4126.8 | K19: 4.56 | L19: 49521.6 | M19: 54.72 | N19: 6.34 | O19: 0 | P19: 4253.5 | Q19: 0 | T19: =+IF(OR(C19="Vacant",G19=""),FALSE,IF($AC19="Yes",F19<=($T$4+180),F19<=($T$4+90))) -> TRUE | U19: =+IF(G19="",0,DATEDIF(F19,G19,"M")/12) -> 5.0833333 | W19: =+MAX(V19-U19,0) -> 0 | X19: =12-W19 -> 12 | Y19: =+(J19*X19+E19*O19)*T19 -> 49521.6 | Z19: =(X19*N19*E19/12)*T19 -> 5737.7 | AA19: =+T19*E19 -> 905
A20: Campus at LaJolla (a0103013) | B20: A220 | C20: Practical Recovery Psychology Group, Inc. & Mario Salguero Inc. (A220) (t0000081) | D20: Office Net | E20: 1386 | F20: 43558 | G20: 47573 | H20: 132 | I20: 7 | J20: 6278.58 | K20: 4.53 | L20: 75342.96 | M20: 54.36 | N20: 4.42 | O20: 0 | P20: 6347.88 | Q20: 0 | T20: =+IF(OR(C20="Vacant",G20=""),FALSE,IF($AC20="Yes",F20<=($T$4+180),F20<=($T$4+90))) -> TRUE | U20: =+IF(G20="",0,DATEDIF(F20,G20,"M")/12) -> 10.916667 | W20: =+MAX(V20-U20,0) -> 0 | X20: =12-W20 -> 12 | Y20: =+(J20*X20+E20*O20)*T20 -> 75342.96 | Z20: =(X20*N20*E20/12)*T20 -> 6126.12 | AA20: =+T20*E20 -> 1386
A21: Campus at LaJolla (a0103013) | B21: B101 | C21: Farnaz Farid, D.M.D., Inc. (B101) (t0000068) | D21: Office Net | E21: 1325 | F21: 43678 | G21: 47330 | H21: 120 | I21: 6.67 | J21: 6015.5 | K21: 4.54 | L21: 72186 | M21: 54.48 | N21: 6.23 | O21: 0 | P21: 6572 | Q21: 0 | T21: =+IF(OR(C21="Vacant",G21=""),FALSE,IF($AC21="Yes",F21<=($T$4+180),F21<=($T$4+90))) -> TRUE | U21: =+IF(G21="",0,DATEDIF(F21,G21,"M")/12) -> 9.9166667 | W21: =+MAX(V21-U21,0) -> 0 | X21: =12-W21 -> 12 | Y21: =+(J21*X21+E21*O21)*T21 -> 72186 | Z21: =(X21*N21*E21/12)*T21 -> 8254.75 | AA21: =+T21*E21 -> 1325
A22: Campus at LaJolla (a0103013) | B22: B107 | C22: Conference Room (B107) (t0000162) | D22: Office Net | E22: 1434 | F22: 44515 | I22: 4.42 | J22: 0 | K22: 0 | L22: 0 | M22: 0 | N22: 0 | O22: 0 | P22: 0 | Q22: 0 | T22: =+IF(OR(C22="Vacant",G22=""),FALSE,IF($AC22="Yes",F22<=($T$4+180),F22<=($T$4+90))) -> FALSE | U22: =+IF(G22="",0,DATEDIF(F22,G22,"M")/12) -> 0 | W22: =+MAX(V22-U22,0) -> 0 | X22: =12-W22 -> 12 | Y22: =+(J22*X22+E22*O22)*T22 -> 0 | Z22: =(X22*N22*E22/12)*T22 -> 0 | AA22: =+T22*E22 -> 0
A23: Campus at LaJolla (a0103013) | B23: B108 | C23: Jesse Sanchez (t0000601) | D23: Office Net | E23: 870 | F23: 45784 | G23: 49552 | H23: 124 | I23: 0.92 | J23: 3697.5 | K23: 4.25 | L23: 44370 | M23: 51 | N23: 0 | O23: 0 | P23: 10440 | Q23: 0 | T23: =+IF(OR(C23="Vacant",G23=""),FALSE,IF($AC23="Yes",F23<=($T$4+180),F23<=($T$4+90))) -> TRUE | U23: =+IF(G23="",0,DATEDIF(F23,G23,"M")/12) -> 10.25 | W23: =+MAX(V23-U23,0) -> 0 | X23: =12-W23 -> 12 | Y23: =+(J23*X23+E23*O23)*T23 -> 44370 | Z23: =(X23*N23*E23/12)*T23 -> 0 | AA23: =+T23*E23 -> 870
A24: Campus at LaJolla (a0103013) | B24: B109 | C24: Ayman Naser DDS, Inc (B109) (t0000604) | D24: Office Net | E24: 2271 | F24: 45924 | G24: 51409 | H24: 181 | I24: 0.58 | J24: 9651.75 | K24: 4.25 | L24: 115821 | M24: 51 | N24: 2.13 | O24: 0 | P24: 14602.53 | Q24: 0 | T24: =+IF(OR(C24="Vacant",G24=""),FALSE,IF($AC24="Yes",F24<=($T$4+180),F24<=($T$4+90))) -> TRUE | U24: =+IF(G24="",0,DATEDIF(F24,G24,"M")/12) -> 15 | V24: 6 | W24: =+MAX(V24-U24,0) -> 0 | X24: =12-W24 -> 12 | Y24: =+(J24*X24+E24*O24)*T24 -> 115821 | Z24: =(X24*N24*E24/12)*T24 -> 4837.23 | AA24: =+T24*E24 -> 2271
A25: Campus at LaJolla (a0103013) | B25: B112 | C25: Skin & Vein Center West, P.C. (B112) (t0000082) | D25: Office Net | E25: 1271 | F25: 44958 | G25: 47238 | H25: 75 | I25: 3.17 | J25: 6011.83 | K25: 4.73 | L25: 72141.96 | M25: 56.76 | N25: 6.24 | O25: 0 | P25: 6609.2 | Q25: 0 | T25: =+IF(OR(C25="Vacant",G25=""),FALSE,IF($AC25="Yes",F25<=($T$4+180),F25<=($T$4+90))) -> TRUE | U25: =+IF(G25="",0,DATEDIF(F25,G25,"M")/12) -> 6.1666667 | W25: =+MAX(V25-U25,0) -> 0 | X25: =12-W25 -> 12 | Y25: =+(J25*X25+E25*O25)*T25 -> 72141.96 | Z25: =(X25*N25*E25/12)*T25 -> 7931.04 | AA25: =+T25*E25 -> 1271
A26: Campus at LaJolla (a0103013) | B26: B114 | C26: Chris Proud (B114) (t0000034) | D26: Office Net | E26: 1027 | F26: 43617 | G26: 47330 | H26: 122 | I26: 6.83 | J26: 4765.28 | K26: 4.64 | L26: 57183.36 | M26: 55.68 | N26: 2.07 | O26: 0 | P26: 3385 | Q26: 0 | T26: =+IF(OR(C26="Vacant",G26=""),FALSE,IF($AC26="Yes",F26<=($T$4+180),F26<=($T$4+90))) -> TRUE | U26: =+IF(G26="",0,DATEDIF(F26,G26,"M")/12) -> 10.083333 | W26: =+MAX(V26-U26,0) -> 0 | X26: =12-W26 -> 12 | Y26: =+(J26*X26+E26*O26)*T26 -> 57183.36 | Z26: =(X26*N26*E26/12)*T26 -> 2125.89 | AA26: =+T26*E26 -> 1027
A27: Campus at LaJolla (a0103013) | B27: B115 | C27: Silva Laine, LLC (B115) (t0000874) | D27: Office Net | E27: 1282 | F27: 46054 | G27: 47968 | H27: 63 | I27: 0.17 | J27: =K27*E27 -> 5769 | K27: 4.5 | L27: =+J27*12 -> 69228 | M27: =+K27*12 -> 54 | N27: 0 | O27: 0 | P27: 0 | Q27: 0 | T27: =+IF(OR(C27="Vacant",G27=""),FALSE,IF($AC27="Yes",F27<=($T$4+180),F27<=($T$4+90))) -> TRUE | U27: =+IF(G27="",0,DATEDIF(F27,G27,"M")/12) -> 5.1666667 | V27: 11 | W27: =+MAX(V27-U27,0) -> 5.8333333 | X27: =12-W27 -> 6.1666667 | Y27: =+(J27*X27+E27*O27)*T27 -> 35575.5 | Z27: =(X27*N27*E27/12)*T27 -> 0 | AA27: =+T27*E27 -> 1282
A28: Campus at LaJolla (a0103013) | B28: B120 | C28: Mehrack Kajian-Faraji (B120) (t0000083) | D28: Office Net | E28: 2530 | F28: 43739 | G28: 48273 | H28: 149 | I28: 6.5 | J28: 11207.9 | K28: 4.43 | L28: 134494.8 | M28: 53.16 | N28: 0.78 | O28: 0 | P28: 14081.28 | Q28: 0 | T28: =+IF(OR(C28="Vacant",G28=""),FALSE,IF($AC28="Yes",F28<=($T$4+180),F28<=($T$4+90))) -> TRUE | U28: =+IF(G28="",0,DATEDIF(F28,G28,"M")/12) -> 12.333333 | W28: =+MAX(V28-U28,0) -> 0 | X28: =12-W28 -> 12 | Y28: =+(J28*X28+E28*O28)*T28 -> 134494.8 | Z28: =(X28*N28*E28/12)*T28 -> 1973.4 | AA28: =+T28*E28 -> 2530
A29: Campus at LaJolla (a0103013) | B29: B123 | C29: Shelley Cassar (B123) (t0000160) | D29: Retail Gross | E29: 1320 | F29: 44545 | G29: 46356 | H29: 60 | I29: 4.33 | J29: 0 | K29: 0 | L29: 0 | M29: 0 | N29: 0 | O29: 3.09 | P29: 1000 | Q29: 0 | T29: =+IF(OR(C29="Vacant",G29=""),FALSE,IF($AC29="Yes",F29<=($T$4+180),F29<=($T$4+90))) -> TRUE | U29: =+IF(G29="",0,DATEDIF(F29,G29,"M")/12) -> 4.9166667 | W29: =+MAX(V29-U29,0) -> 0 | X29: =12-W29 -> 12 | Y29: =+(J29*X29+E29*O29)*T29 -> 4078.8 | Z29: =(X29*N29*E29/12)*T29 -> 0 | AA29: =+T29*E29 -> 1320
A30: Campus at LaJolla (a0103013) | B30: B124 | C30: Robert C. Kim (B124) (t0000085) | D30: Office Net | E30: 2234 | F30: 43252 | G30: 46904 | H30: 120 | I30: 7.83 | J30: 10432.78 | K30: 4.67 | L30: 125193.36 | M30: 56.04 | N30: 6.09 | O30: 0 | P30: 11080.64 | Q30: 0 | T30: =+IF(OR(C30="Vacant",G30=""),FALSE,IF($AC30="Yes",F30<=($T$4+180),F30<=($T$4+90))) -> TRUE | U30: =+IF(G30="",0,DATEDIF(F30,G30,"M")/12) -> 9.9166667 | W30: =+MAX(V30-U30,0) -> 0 | X30: =12-W30 -> 12 | Y30: =+(J30*X30+E30*O30)*T30 -> 125193.36 | Z30: =(X30*N30*E30/12)*T30 -> 13605.06 | AA30: =+T30*E30 -> 2234
A31: Campus at LaJolla (a0103013) | B31: B128 | C31: Claude A. Valenti (B128) (t0000086) | D31: Office Net | E31: 3691 | F31: 44197 | G31: 46203 | H31: 66 | I31: 5.25 | J31: 16055.85 | K31: 4.35 | L31: 192670.2 | M31: 52.2 | N31: 5.58 | O31: 0 | P31: 10807.72 | Q31: 0 | T31: =+IF(OR(C31="Vacant",G31=""),FALSE,IF($AC31="Yes",F31<=($T$4+180),F31<=($T$4+90))) -> TRUE | U31: =+IF(G31="",0,DATEDIF(F31,G31,"M")/12) -> 5.4166667 | W31: =+MAX(V31-U31,0) -> 0 | X31: =12-W31 -> 12 | Y31: =+(J31*X31+E31*O31)*T31 -> 192670.2 | Z31: =(X31*N31*E31/12)*T31 -> 20595.78 | AA31: =+T31*E31 -> 3691
A32: Campus at LaJolla (a0103013) | B32: B129 | C32: Julia Simonton (B129) (t0000087) | D32: Office Net | E32: 1281 | F32: 44896 | G32: 46843 | H32: 64 | I32: 3.33 | J32: 4355.4 | K32: 3.4 | L32: 52264.8 | M32: 40.8 | N32: 0 | O32: 0 | P32: 5879.79 | Q32: 0 | T32: =+IF(OR(C32="Vacant",G32=""),FALSE,IF($AC32="Yes",F32<=($T$4+180),F32<=($T$4+90))) -> TRUE | U32: =+IF(G32="",0,DATEDIF(F32,G32,"M")/12) -> 5.25 | W32: =+MAX(V32-U32,0) -> 0 | X32: =12-W32 -> 12 | Y32: =+(J32*X32+E32*O32)*T32 -> 52264.8 | Z32: =(X32*N32*E32/12)*T32 -> 0 | AA32: =+T32*E32 -> 1281
A33: Campus at LaJolla (a0103013) | B33: B203 | C33: Randolph Foote Alexander and Andrew Alexander (B203) (t0000088) | D33: Office Net | E33: 1292 | F33: 44348 | G33: 47452 | H33: 102 | I33: 4.83 | J33: 5852.76 | K33: 4.53 | L33: 70233.12 | M33: 54.36 | N33: 0.97 | O33: 0 | P33: 4588.33 | Q33: 0 | T33: =+IF(OR(C33="Vacant",G33=""),FALSE,IF($AC33="Yes",F33<=($T$4+180),F33<=($T$4+90))) -> TRUE | U33: =+IF(G33="",0,DATEDIF(F33,G33,"M")/12) -> 8.4166667 | W33: =+MAX(V33-U33,0) -> 0 | X33: =12-W33 -> 12 | Y33: =+(J33*X33+E33*O33)*T33 -> 70233.12 | Z33: =(X33*N33*E33/12)*T33 -> 1253.24 | AA33: =+T33*E33 -> 1292
A34: Campus at LaJolla (a0103013) | B34: B204 | C34: HPA Support Services, LLC (B204) (t0000089) | D34: Office Net | E34: 1310 | F34: 44788 | G34: 46752 | H34: 65 | I34: 3.67 | J34: 5868.8 | K34: 4.48 | L34: 70425.6 | M34: 53.76 | N34: 3.24 | O34: 0 | P34: 6576.2 | Q34: 0 | T34: =+IF(OR(C34="Vacant",G34=""),FALSE,IF($AC34="Yes",F34<=($T$4+180),F34<=($T$4+90))) -> TRUE | U34: =+IF(G34="",0,DATEDIF(F34,G34,"M")/12) -> 5.3333333 | W34: =+MAX(V34-U34,0) -> 0 | X34: =12-W34 -> 12 | Y34: =+(J34*X34+E34*O34)*T34 -> 70425.6 | Z34: =(X34*N34*E34/12)*T34 -> 4244.4 | AA34: =+T34*E34 -> 1310
A35: Campus at LaJolla (a0103013) | B35: B206 | C35: Srinivas Iyengar (B206) (t0000090) | D35: Office Net | E35: 770 | F35: 43892 | G35: 48029 | H35: 136 | I35: 6.08 | J35: 3526.6 | K35: 4.58 | L35: 42319.2 | M35: 54.96 | N35: 5.97 | O35: 0 | P35: 3642.1 | Q35: 0 | T35: =+IF(OR(C35="Vacant",G35=""),FALSE,IF($AC35="Yes",F35<=($T$4+180),F35<=($T$4+90))) -> TRUE | U35: =+IF(G35="",0,DATEDIF(F35,G35,"M")/12) -> 11.25 | W35: =+MAX(V35-U35,0) -> 0 | X35: =12-W35 -> 12 | Y35: =+(J35*X35+E35*O35)*T35 -> 42319.2 | Z35: =(X35*N35*E35/12)*T35 -> 4596.9 | AA35: =+T35*E35 -> 770
A36: Campus at LaJolla (a0103013) | B36: B207 | C36: Fereshteh Maghsoudy, D.M.D., Inc. (B207) (t0000091) | D36: Office Net | E36: 690 | F36: 45017 | G36: 47999 | H36: 98 | I36: 3 | J36: 3513.1 | K36: 5.09 | L36: 42157.2 | M36: 61.1 | N36: 2.29 | O36: 0 | P36: 2507.81 | Q36: 0 | T36: =+IF(OR(C36="Vacant",G36=""),FALSE,IF($AC36="Yes",F36<=($T$4+180),F36<=($T$4+90))) -> TRUE | U36: =+IF(G36="",0,DATEDIF(F36,G36,"M")/12) -> 8.0833333 | W36: =+MAX(V36-U36,0) -> 0 | X36: =12-W36 -> 12 | Y36: =+(J36*X36+E36*O36)*T36 -> 42157.2 | Z36: =(X36*N36*E36/12)*T36 -> 1580.1 | AA36: =+T36*E36 -> 690
A37: Campus at LaJolla (a0103013) | B37: B212 | C37: Brandon W. Goldstein (B212) (t0000070) | D37: Office Net | E37: 1797 | F37: 43191 | G37: 46112 | H37: 96 | I37: 8 | J37: 8398.31 | K37: 4.67 | L37: 100779.72 | M37: 56.08 | N37: 5.78 | O37: 0 | P37: 0 | Q37: 0 | T37: FALSE | U37: =+IF(G37="",0,DATEDIF(F37,G37,"M")/12) -> 7.9166667 | W37: =+MAX(V37-U37,0) -> 0 | X37: =12-W37 -> 12 | Y37: =+(J37*X37+E37*O37)*T37 -> 0 | Z37: =(X37*N37*E37/12)*T37 -> 0 | AA37: =+T37*E37 -> 0
A38: Campus at LaJolla (a0103013) | B38: B214 | C38: Seattle Sperm Bank, LLC. (B214) (t0000093) | D38: Office Net | E38: 2553 | F38: 43619 | G38: 47269 | H38: 120 | I38: 6.83 | J38: 12075.69 | K38: 4.73 | L38: 144908.28 | M38: 56.76 | N38: 6.33 | O38: 0 | P38: 12075.69 | Q38: 0 | T38: =+IF(OR(C38="Vacant",G38=""),FALSE,IF($AC38="Yes",F38<=($T$4+180),F38<=($T$4+90))) -> TRUE | U38: =+IF(G38="",0,DATEDIF(F38,G38,"M")/12) -> 9.9166667 | W38: =+MAX(V38-U38,0) -> 0 | X38: =12-W38 -> 12 | Y38: =+(J38*X38+E38*O38)*T38 -> 144908.28 | Z38: =(X38*N38*E38/12)*T38 -> 16160.49 | AA38: =+T38*E38 -> 2553
A39: Campus at LaJolla (a0103013) | B39: B216 | C39: NKMD MGMT, LLC (B216) (t0000094) | D39: Office Net | E39: 2058 | F39: 45170 | G39: 47149 | H39: 65 | I39: 2.58 | J39: 9816.66 | K39: 4.77 | L39: 117799.92 | M39: 57.24 | N39: 2.79 | O39: 0 | P39: 20826.96 | Q39: 0 | T39: =+IF(OR(C39="Vacant",G39=""),FALSE,IF($AC39="Yes",F39<=($T$4+180),F39<=($T$4+90))) -> TRUE | U39: =+IF(G39="",0,DATEDIF(F39,G39,"M")/12) -> 5.3333333 | W39: =+MAX(V39-U39,0) -> 0 | X39: =12-W39 -> 12 | Y39: =+(J39*X39+E39*O39)*T39 -> 117799.92 | Z39: =(X39*N39*E39/12)*T39 -> 5741.82 | AA39: =+T39*E39 -> 2058
A40: Campus at LaJolla (a0103013) | B40: B223 | C40: Jessica Sperber (Individual) and Clinical and Consulting Psychology Group, LLC (B223) (t0000095) | D40: Office Net | E40: 1397 | F40: 43358 | G40: 47026 | H40: 121 | I40: 7.58 | J40: 6817.36 | K40: 4.88 | L40: 81808.32 | M40: 58.56 | N40: 8.19 | O40: 0 | P40: 7264.4 | Q40: 0 | T40: =+IF(OR(C40="Vacant",G40=""),FALSE,IF($AC40="Yes",F40<=($T$4+180),F40<=($T$4+90))) -> TRUE | U40: =+IF(G40="",0,DATEDIF(F40,G40,"M")/12) -> 10 | W40: =+MAX(V40-U40,0) -> 0 | X40: =12-W40 -> 12 | Y40: =+(J40*X40+E40*O40)*T40 -> 81808.32 | Z40: =(X40*N40*E40/12)*T40 -> 11441.43 | AA40: =+T40*E40 -> 1397
...

Sheet WALT
A1: 1
C2: Tenant | D2: SF | E2: % of NRA | F2: LXD | G2: Exp. Year | H2: WALT | J2: Date
C3: The Regents of the University of California (8910) (t0000137) | D3: 14750 | E3: =$D3/$D$65 -> 0.077042005 | F3: 49887 | G3: =YEAR(F3) -> 2036 | H3: =(F3-$J$3)/365 -> 10.342466 | J3: 46112
C4: Coleman Meadows DDS, Inc. (A105) (t0000071) | D4: 2548 | E4: =$D4/$D$65 -> 0.01330868 | F4: 47330 | G4: =YEAR(F4) -> 2029 | H4: =(F4-$J$3)/365 -> 3.3369863
C5: Bronner Handwerger (A107) (t0000072) | D5: 1438 | E5: =$D5/$D$65 -> 0.0075109426 | F5: 47118 | G5: =YEAR(F5) -> 2028 | H5: =(F5-$J$3)/365 -> 2.7561644
C6: Nancy Markel (A108) (t0000073) | D6: 620 | E6: =$D6/$D$65 -> 0.0032383758 | F6: 46173 | G6: =YEAR(F6) -> 2026 | H6: =(F6-$J$3)/365 -> 0.16712329
C7: Advantech GS Enterprises, Inc. (B208) (t0000074) | D7: 1284 | E7: =$D7/$D$65 -> 0.0067065718 | F7: 48060 | G7: =YEAR(F7) -> 2031 | H7: =(F7-$J$3)/365 -> 5.3369863
C8: Maria Hiraldo (A110) (t0000075) | D8: 326 | E8: =$D8/$D$65 -> 0.0017027589 | F8: 47695 | G8: =YEAR(F8) -> 2030 | H8: =(F8-$J$3)/365 -> 4.3369863
C9: SureFire CPR (A118) (t0000149) | D9: 309 | E9: =$D9/$D$65 -> 0.0016139647 | F9: 46599 | G9: =YEAR(F9) -> 2027 | H9: =(F9-$J$3)/365 -> 1.3342466
C10: La Jolla Sol Ventures, Inc. (A125) (t0000076) | D10: 1846 | E10: =$D10/$D$65 -> 0.0096420028 | F10: 46904 | G10: =YEAR(F10) -> 2028 | H10: =(F10-$J$3)/365 -> 2.169863
C11: Chemometec, Inc. (A127) (t0000077) | D11: 1469 | E11: =$D11/$D$65 -> 0.0076728614 | F11: 46507 | G11: =YEAR(F11) -> 2027 | H11: =(F11-$J$3)/365 -> 1.0821918
C12: J Zeidan, DMD, Inc. (A128) (t0000078) | D12: 2354 | E12: =$D12/$D$65 -> 0.012295382 | F12: 46934 | G12: =YEAR(F12) -> 2028 | H12: =(F12-$J$3)/365 -> 2.2520548
C13: Katherine A. Thomson, DDS, MS Inc. (A207) (t0000066) | D13: 1665 | E13: =$D13/$D$65 -> 0.008696606 | F13: 47542 | G13: =YEAR(F13) -> 2030 | H13: =(F13-$J$3)/365 -> 3.9178082
C14: Arash Khatami (A215) (t0000079) | D14: 907 | E14: =$D14/$D$65 -> 0.0047374304 | F14: 46478 | G14: =YEAR(F14) -> 2027 | H14: =(F14-$J$3)/365 -> 1.0027397
C15: Marin Wellness Pharmacy LLC (A218) (t0000606) | D15: 1422 | E15: =$D15/$D$65 -> 0.0074273716 | F15: 46904 | G15: =YEAR(F15) -> 2028 | H15: =(F15-$J$3)/365 -> 2.169863
... C61: The Regents of the University of California (Node) (t0000135) | D61: 90 | E61: =$D61/$D$65 -> 0.00047008681 | F61: 46783 | G61: =YEAR(F61) -> 2028 | H61: =(F61-$J$3)/365 -> 1.8383562
H62: =SUMPRODUCT(H3:H61,D3:D61)/D63 -> 4.2523262
C63: Occupied SF | D63: =SUM(D3:D61)+I65 -> 131085 | E63: =D63/$D$65 -> 0.68468144
C64: Vacant SF | D64: =D65-D63 -> 60369 | E64: =D64/$D$65 -> 0.31531856
C65: Total SF | D65: =OSAR!C11 -> 191454 | E65: =D65/$D$65 -> 1 | H65: Unit Offset | I65: 2822
C67: *Excludes known vacates, MTM tenants, and amenity spaces.

Sheet Aging Report
A1: Aging Detail
A2: DB Caption: Live 09/11/2023 All Selected Properties Status: Current, Past, Future Age As Of: 03/31/2026 Post To: 03/2026
A3: Property | B3: Customer | C3: Lease | D3: Status | E3: Tran# | F3: Charge | G3: Date | H3: Month | I3: Current | J3: 0-30 | K3: 31-60 | L3: 61-90 | M3: Over | N3: Pre- | O3: Total
F4: Code | I4: Owed | J4: Owed | K4: Owed | L4: Owed | M4: 90 Owed | N4: payments | O4: Owed
A5: Campus at LaJolla (a0103013)
A6: Acacia Psychological Corporation (C121) (t0000101)
A7: a0103013 | C7: Acacia Psychological Corporation (C121) | D7: Current | E7: R-20487 | F7: Prepay | G7: 46112 | H7: 03/2026 | I7: 0 | J7: 0 | K7: 0 | L7: 0 | M7: 0 | N7: -18681 | O7: -18681
C8: Acacia Psychological Corporation (C121) | I8: 0 | J8: 0 | K8: 0 | L8: 0 | M8: 0 | N8: -18681 | O8: -18681
A10: Ayman Naser DDS, Inc (B109) (t0000604)
A11: a0103013 | C11: Ayman Naser DDS, Inc (B109) | D11: Current | E11: C-54392 | F11: cam | G11: 46082 | H11: 03/2026 | I11: 0.2 | J11: 0.2 | K11: 0 | L11: 0 | M11: 0 | N11: 0 | O11: 0.2
C12: Ayman Naser DDS, Inc (B109) | I12: 0.2 | J12: 0.2 | K12: 0 | L12: 0 | M12: 0 | N12: 0 | O12: 0.2
A14: Chemometec, Inc. (A127) (t0000077)
A15: a0103013 | C15: Chemometec, Inc. (A127) | D15: Current | E15: R-20025 | F15: Prepay | G15: 46106 | H15: 03/2026 | I15: 0 | J15: 0 | K15: 0 | L15: 0 | M15: 0 | N15: -7052.45 | O15: -7052.45
C16: Chemometec, Inc. (A127) | I16: 0 | J16: 0 | K16: 0 | L16: 0 | M16: 0 | N16: -7052.45 | O16: -7052.45
A18: Community Psychiatry Management, LLC (C217) (t0000106)
A19: a0103013 | C19: Community Psychiatry Management, LLC (C217) | D19: Current | E19: R-18215 | F19: Prepay | G19: 46052 | H19: 01/2026 | I19: 0 | J19: 0 | K19: 0 | L19: 0 | M19: 0 | N19: -956.68 | O19: -956.68
A20: a0103013 | C20: Community Psychiatry Management, LLC (C217) | D20: Current | E20: R-18215 | F20: Prepay | G20: 46052 | H20: 01/2026 | I20: 0 | J20: 0 | K20: 0 | L20: 0 | M20: 0 | N20: -118.53 | O20: -118.53
A21: a0103013 | C21: Community Psychiatry Management, LLC (C217) | D21: Current | E21: R-20486 | F21: Prepay | G21: 46112 | H21: 03/2026 | I21: 0 | J21: 0 | K21: 0 | L21: 0 | M21: 0 | N21: -18037.8 | O21: -18037.8
C22: Community Psychiatry Management, LLC (C217) | I22: 0 | J22: 0 | K22: 0 | L22: 0 | M22: 0 | N22: -19113.01 | O22: -19113.01
A24: Foyouzi Reproductive Genetics Medical Corporation (t0000151)
A25: a0103013 | C25: Foyouzi Reproductive Genetics Medical Corporation | D25: Current | E25: R-14093 | F25: Prepay | G25: 45938 | H25: 10/2025 | I25: 0 | J25: 0 | K25: 0 | L25: 0 | M25: 0 | N25: -767.06 | O25: -767.06
A26: a0103013 | C26: Foyouzi Reproductive Genetics Medical Corporation | D26: Current | E26: R-14093 | F26: Prepay | G26: 45938 | H26: 10/2025 | I26: 0 | J26: 0 | K26: 0 | L26: 0 | M26: 0 | N26: -437.38 | O26: -437.38
A27: a0103013 | C27: Foyouzi Reproductive Genetics Medical Corporation | D27: Current | E27: R-14093 | F27: Prepay | G27: 45938 | H27: 10/2025 | I27: 0 | J27: 0 | K27: 0 | L27: 0 | M27: 0 | N27: -7026.58 | O27: -7026.58
A28: a0103013 | C28: Foyouzi Reproductive Genetics Medical Corporation | D28: Current | E28: R-15619 | F28: Prepay | G28: 45978 | H28: 11/2025 | I28: 0 | J28: 0 | K28: 0 | L28: 0 | M28: 0 | N28: -11031.6 | O28: -11031.6
C29: Foyouzi Reproductive Genetics Medical Corporation | I29: 0 | J29: 0 | K29: 0 | L29: 0 | M29: 0 | N29: -19262.62 | O29: -19262.62
A31: Garrett M. Guess, DDS, Inc. (C113) (t0000168)
A32: a0103013 | C32: Garrett M. Guess, DDS, Inc. (C113) | D32: Current | E32: R-20294 | F32: Prepay | G32: 46111 | H32: 03/2026 | I32: 0 | J32: 0 | K32: 0 | L32: 0 | M32: 0 | N32: -5539.6 | O32: -5539.6
C33: Garrett M. Guess, DDS, Inc. (C113) | I33: 0 | J33: 0 | K33: 0 | L33: 0 | M33: 0 | N33: -5539.6 | O33: -5539.6
A35: Iman Shirali (C117) (t0000099)
A36: a0103013 | C36: Iman Shirali (C117) | D36: Past | E36: C-30782 | F36: cam | G36: 45870 | H36: 08/2025 | I36: 144.63 | J36: 0 | K36: 0 | L36: 0 | M36: 144.63 | N36: 0 | O36: 144.63
A37: a0103013 | C37: Iman Shirali (C117) | D37: Past | E37: C-30783 | F37: rnoff | G37: 45870 | H37: 08/2025 | I37: 6402.74 | J37: 0 | K37: 0 | L37: 0 | M37: 6402.74 | N37: 0 | O37: 6402.74
A38: a0103013 | C38: Iman Shirali (C117) | D38: Past | E38: C-33916 | F38: cam | G38: 45901 | H38: 09/2025 | I38: 276.78 | J38: 0 | K38: 0 | L38: 0 | M38: 276.78 | N38: 0 | O38: 276.78
A39: a0103013 | C39: Iman Shirali (C117) | D39: Past | E39: C-33917 | F39: rnoff | G39: 45901 | H39: 09/2025 | I39: 6402.74 | J39: 0 | K39: 0 | L39: 0 | M39: 6402.74 | N39: 0 | O39: 6402.74
A40: a0103013 | C40: Iman Shirali (C117) | D40: Past | E40: C-37018 | F40: cam | G40: 45931 | H40: 10/2025 | I40: 276.78 | J40: 0 | K40: 0 | L40: 0 | M40: 276.78 | N40: 0 | O40: 276.78
A41: a0103013 | C41: Iman Shirali (C117) | D41: Past | E41: C-37019 | F41: rnoff | G41: 45931 | H41: 10/2025 | I41: 3201.37 | J41: 0 | K41: 0 | L41: 0 | M41: 3201.37 | N41: 0 | O41: 3201.37
A42: a0103013 | C42: Iman Shirali (C117) | D42: Past | E42: C-40216 | F42: cam | G42: 45962 | H42: 11/2025 | I42: 276.78 | J42: 0 | K42: 0 | L42: 0 | M42: 276.78 | N42: 0 | O42: 276.78
A43: a0103013 | C43: Iman Shirali (C117) | D43: Past | E43: C-40217 | F43: rnoff | G43: 45962 | H43: 11/2025 | I43: 3201.37 | J43: 0 | K43: 0 | L43: 0 | M43: 3201.37 | N43: 0 | O43: 3201.37
A44: a0103013 | C44: Iman Shirali (C117) | D44: Past | E44: C-43547 | F44: cam | G44: 45992 | H44: 12/2025 | I44: 276.78 | J44: 0 | K44: 0 | L44: 0 | M44: 276.78 | N44: 0 | O44: 276.78
A45: a0103013 | C45: Iman Shirali (C117) | D45: Past | E45: C-43548 | F45: rnoff | G45: 45992 | H45: 12/2025 | I45: 3201.37 | J45: 0 | K45: 0 | L45: 0 | M45: 3201.37 | N45: 0 | O45: 3201.37
A46: a0103013 | C46: Iman Shirali (C117) | D46: Past | E46: C-50303 | F46: cam | G46: 46054 | H46: 02/2026 | I46: 383.32 | J46: 0 | K46: 383.32 | L46: 0 | M46: 0 | N46: 0 | O46: 383.32
...

Sheet coding
A1: Line Item | B1: Code | G1: Base Rent | I1: Gross Potential Rent (3)
A2: INCOME | G2: Expense Reimbursement | I2: Less: Vacancy Loss
A3: OPERATING REVENUE | G3: Percentage Rent | I3: OR
A4: TENANT RENTS & SERVICES | G4: Parking Income | I4: Base Rent (3)
A5: OFFICE | G5: Other Income | I5: Expense Reimbursement
A6: Rent-Office | B6: Base Rent | C6: Base Rent (3) | I6: Percentage Rent
A7: Rent-Office Parking | B7: Parking Income | C7: Parking Income | G7: Effective Gross Income | I7: Parking Income
A8: Rent Abatement-Office | B8: Base Rent | C8: Base Rent (3) | I8: Other Income
A9: TOTAL OFFICE | G9: OPERATING EXPENSES
A10: RESIDENTIAL | G10: Real Estate Taxes | I10: *Effective Gross Income
A11: REIMBURSABLE EXPENSES | G11: Property Insurance
A12: CAM Recovery-Estimate | B12: Expense Reimbursement | C12: Expense Reimbursement | G12: Utilities
A13: CAM Recovery-Y/End | B13: Expense Reimbursement | C13: Expense Reimbursement | G13: Repairs & Maintenance | I13: OPERATING EXPENSES:
A14: Utilities Recovery-Estimate | B14: Expense Reimbursement | C14: Expense Reimbursement | G14: Janitorial | I14: Real Estate Taxes
A15: Misc Income | B15: Expense Reimbursement | C15: Expense Reimbursement | G15: Management Fees | I15: Property Insurance
A16: TOTAL REIMBURSABLE EXPENSES | G16: Payroll & Benefits | I16: Utilities
A17: OTHER OPERATING INCOME | G17: Advertising & Marketing | I17: Repairs and Maintenance
A18: Tenant Service Revenue | B18: Other Income | C18: Other Income | G18: Professional Fees | I18: Janitorial
A19: Cost of Tenant Services | B19: Other Income | C19: Other Income | G19: General and Administrative | I19: Management Fees
A20: Miscellaneous | B20: Other Income | C20: Other Income | G20: Other Expenses | I20: Payroll & Benefits
A21: TOTAL OTHER OPERATING INCOME | G21: Ground Rent | I21: Advertising & Marketing
A22: TOTAL OPERATING REVENUE | G22: Total Operating Expenses | I22: Professional Fees
A23: OPERATING EXPENSES | G23: =TTM!T35 -> Non-Operating Expenses | I23: General and Administrative
A24: OPERATING EXPENSES - RECOVERABLE | G24: =TTM!T36 -> Interest Expense | I24: Other Expenses
A25: CLEANING - RECOVERABLE | G25: =TTM!T37 -> Debt Service | I25: Ground Rent
A26: Cleaning-Day Porter | B26: Janitorial | C26: Janitorial
A27: Cleaning-Contract Srvcs | B27: Janitorial | C27: Janitorial
A28: Cleaning-Window Cleaning | B28: Janitorial | C28: Janitorial
A29: Cleaning-Supplies | B29: Janitorial | C29: Janitorial
A30: TOTAL CLEANING - RECOVERABLE
A31: REPAIR & MAINTENANCE - RECOVERABLE
A32: RM-Pay/Wages | B32: Repairs & Maintenance | C32: Repairs and Maintenance
A33: RM-Supplies | B33: Repairs & Maintenance | C33: Repairs and Maintenance
A34: RM-Uniforms | B34: Repairs & Maintenance | C34: Repairs and Maintenance
A35: RM-Equipment | B35: Repairs & Maintenance | C35: Repairs and Maintenance
