Workbook
Name BiMonthly: #REF!
Name CMNOTES: #REF!
Name EffGrowth: #REF!
Name Expense_Growth: #REF!
Name Market: #REF!
Name MktGrowth: #REF!
Name N_Units: #REF!
Name OpexMonths: #REF!
Name Property_Name: #REF!
Name Quarterly_Growth: #REF!
Name Rent: #REF!
Name RESULTS: #REF!

Sheet (New) Comm OSAR
C1: CREFC Investor Reporting Package
C2: COMMERCIAL OPERATING STATEMENT ANALYSIS REPORT (includes Retail/Office/Industrial/Mixed Use/Self Storage)
C3: ="as of " &TEXT($I$15,"mm/dd/yyyy") -> as of 03/31/2026
C4: PROPERTY OVERVIEW | H4: Allocated Loan Amount/Percentage
C5: Property ID | E5: 1001-001 | F5: Paid Thru Date | G5: Debt Outside Trust (1) | H5: $ | I5: %
C6: Note A-Scheduled Loan Balance | E6: 42768425 | F6: 46112 | G6: X or Blank | I6: =IFERROR(E6/SUM($E$6:$E$8),0) -> 1
C7: Note B-Scheduled Loan Balance | F7: ='[1](Old) Comm OSAR'!G7 -> MM/DD/YY | G7: X or Blank | I7: =IFERROR(E7/SUM($E$6:$E$8),0) -> 0
C8: Note C-Scheduled Loan Balance | F8: ='[1](Old) Comm OSAR'!G8 -> MM/DD/YY | G8: X or Blank | I8: =IFERROR(E8/SUM($E$6:$E$8),0) -> 0
C9: Property Name | E9: Hialeah Infill Industrial Park
C10: Property Type | E10: Industrial
C11: Property Address, City, State | E11: 3455 NW 54th St & 5400 NW 32nd Ct & 5530 NW 32nd Ct Miami FL
C12: Current Net Rentable SF/Units/Beds/Rooms | E12: ='1Q26 RR'!F57 -> 298769 | F12: ='[1](Old) Comm OSAR'!G12 -> SF | G12: Use second box to specify sqft.,units…
C13: Year Built/Year Renovated | E13: 1959-1968 | F13: ='[1](Old) Comm OSAR'!G13 -> YYYY
C14: Cap Ex Reserve (annually)/per Unit.etc. (2) | E14: 0.25 | F14: ='[1](Old) Comm OSAR'!G14 -> (annual/per SF) | G14: specify annual/per unit…
C15: Statement Ending Date | E15: MM/DD/YY | F15: 45838 | G15: 45930 | H15: 46022 | I15: 46112
C16: Occupancy Rate (physical) | E16: 1 | F16: 0.53475853 | G16: 0.53475853 | H16: 0.5348 | I16: ='1Q26 RR'!F62 -> 0.44819576
C17: Occupancy Date | E17: =E15 -> MM/DD/YY | F17: 45838 | G17: 45930 | H17: 46022 | I17: 46112
E18: (1) "X" if debt is outside of the trust, otherwise leave blank
E19: (2) Total $ amount of Capital Reserves required annually by loan documents
C21: INCOME:
C22: Number of Mos. Covered | F22: DY Test | G22: DY Test | H22: T12 | I22: DY Test | J22: (prcdng yr to base) | K22: (prcdng yr to 2nd prcdng)
C23: Period Ended | E23: At Contribution | F23: 2nd Preceding | G23: Preceding | H23: Current | I23: Current | J23: YYYY-U/W | K23: =YEAR('[2](Old) Comm OSAR'!H24)&"-"&YEAR(F6) -> 2025-2026 | N23: QoQ Variance
C24: Statement Ending Date | E24: Information | F24: as of 9/30/25 | G24: as of 12/31/25 | H24: ="as of "&TEXT($F$6,"mm/dd/yy") -> as of 03/31/26 | I24: ="as of "&TEXT($F$6,"mm/dd/yy") -> as of 03/31/26 | J24: Variance | K24: Variance | L24: Notes | N24: Value | O24: %
C25: Gross Potential Rent (3) | E25: 2442036 | F25: 1605912.4 | G25: 1630918.4 | H25: ='1Q26 T12'!O13 -> 1604326.7 | I25: =SUM('1Q26 RR'!V:V) -> 1413927 | J25: =IF(E25=0," ",(I25-E25)/E25) -> -0.42100486 | K25: =IF(G25=0," ",(I25-G25)/G25) -> -0.13304862 | L25: Annualized in-place RR | N25: =IFERROR(I25-G25,0) -> -216991.45 | O25: =IFERROR(N25/G25,"") -> -0.13304862
C26: Less: Vacancy Loss | E26: 0 | F26: 0 | G26: 0 | H26: 0 | I26: =-IF(I16>0.95,(I16-0.95)*I25,0) -> 0 | J26: =IF(E26=0," ",(I26-E26)/E26) | K26: =IF(G26=0," ",(I26-G26)/G26) | L26: ="Greater of actual ("&TEXT(1-$I$16,"0%")&") or 5%" -> Greater of actual (55%) or 5% | N26: =IFERROR(I26-G26,0) -> 0 | O26: =IFERROR(N26/G26,"")
C27: OR | N27: =IFERROR(I27-G27,0) -> 0 | O27: =IFERROR(N27/G27,"")
C28: Base Rent (3) | N28: =IFERROR(I28-G28,0) -> 0 | O28: =IFERROR(N28/G28,"")
C29: Expense Reimbursement | E29: 949400 | F29: 466440 | G29: 466440 | H29: =SUM('1Q26 T12'!O14:O16) -> 298740 | I29: =SUM('1Q26 RR'!R:R)*12 -> 610140 | L29: Annualized in-place RR | N29: =IFERROR(I29-G29,0) -> 143700 | O29: =IFERROR(N29/G29,"") -> 0.30807821
C30: Percentage Rent | E30: 0 | F30: 0 | G30: 0 | H30: 0 | I30: 0 | J30: =IF(E30=0," ",(I30-E30)/E30) | K30: =IF(G30=0," ",(I30-G30)/G30) | N30: =IFERROR(I30-G30,0) -> 0 | O30: =IFERROR(N30/G30,"")
C31: Parking Income | E31: 0 | F31: 0 | G31: 0 | H31: 0 | I31: 0 | K31: =IF(G31=0," ",(I31-G31)/G31) | N31: =IFERROR(I31-G31,0) -> 0 | O31: =IFERROR(N31/G31,"")
C32: Other Income | E32: 0 | F32: 160.77 | G32: 60 | H32: ='1Q26 T12'!O21 -> 0 | I32: =H32 -> 0 | L32: ="T12 ended "&TEXT($I$15,"mm/dd/yyyy") -> T12 ended 03/31/2026 | N32: =IFERROR(I32-G32,0) -> -60 | O32: =IFERROR(N32/G32,"") -> -1
N33: =IFERROR(I33-G33,0) -> 0 | O33: =IFERROR(N33/G33,"")
C34: *Effective Gross Income | E34: 3391436 | F34: 2072513.1 | G34: 2097418.4 | H34: =SUM(H25:H32) -> 1903066.7 | I34: =SUM(I25:I32) -> 2024067 | N34: =IFERROR(I34-G34,0) -> -73351.446 | O34: =IFERROR(N34/G34,"") -> -0.034972252
E35: (3) Use either Gross Potential (with Vacancy Loss) or Base Rents; use negative $ amt for Vacancy Loss | N35: =IFERROR(I35-G35,0) -> 0 | O35: =IFERROR(N35/G35,"")
N36: =IFERROR(I36-G36,0) -> 0 | O36: =IFERROR(N36/G36,"")
C37: OPERATING EXPENSES: | N37: =IFERROR(I37-G37,0) -> 0 | O37: =IFERROR(N37/G37,"")
C38: Real Estate Taxes | E38: 561986 | F38: 494233.61 | G38: 474465 | H38: ='1Q26 T12'!O31 -> 383350.47 | I38: =MAX(H38,Tax!B7) -> 452696.25 | L38: ="Greater of actual tax bill from 01/01/2025-01/01/2026 ($"&TEXT(Tax!B7/1000,"0.0")&"K) and T12 ended "&TEXT('(New) Comm OSAR'!I15,"mm/dd/yyyy") -> Greater of actual tax bill from 01/01/2025-01/01/2026 ($452.7K) and T12 ended 03/31/2026 | N38: =IFERROR(I38-G38,0) -> -21768.75 | O38: =IFERROR(N38/G38,"") -> -0.045880623
C39: Property Insurance | E39: 344808 | F39: 171976.41 | G39: 210758 | H39: ='1Q26 T12'!O32 -> 194042.95 | I39: =MAX(H39,Insurance!O4) -> 194042.95 | L39: ="Greater of actual insurance bill from 05/31/2025-05/31/2026 ($"&TEXT(Insurance!O4/1000,"0.0")&"K) and T12 ended "&TEXT('(New) Comm OSAR'!I15,"mm/dd/yyyy") -> Greater of actual insurance bill from 05/31/2025-05/31/2026 ($112.8K) and T12 ended 03/31/2026 | N39: =IFERROR(I39-G39,0) -> -16715.05 | O39: =IFERROR(N39/G39,"") -> -0.079309208
C40: Utilities | E40: 0 | F40: 68375.81 | G40: 60040 | H40: ='1Q26 T12'!O59 -> 63835.99 | I40: =H40 -> 63835.99 | L40: ="T12 ended "&TEXT($I$15,"mm/dd/yyyy") -> T12 ended 03/31/2026 | N40: =IFERROR(I40-G40,0) -> 3795.99 | O40: =IFERROR(N40/G40,"") -> 0.06322435
C41: Repairs and Maintenance | E41: 71832 | F41: 66518.56 | G41: 52989 | H41: ='1Q26 T12'!O74 -> 67844.72 | I41: =H41 -> 67844.72 | L41: ="T12 ended "&TEXT($I$15,"mm/dd/yyyy") -> T12 ended 03/31/2026 | N41: =IFERROR(I41-G41,0) -> 14855.72 | O41: =IFERROR(N41/G41,"") -> 0.28035479
...

Sheet QoQ
C2: 4Q 2025 | G2: 1Q 2026 | K2: QoQ ∆ | O2: Cash Management
B3: Property | C3: Occupancy | D3: NOI | E3: DY | F3: DSCR | G3: Occupancy | H3: NOI | I3: DY | J3: DSCR | K3: Occupancy | L3: NOI | M3: DY | N3: DSCR | O3: In CM? | P3: Threshold/Cure
B4: =#REF! -> #REF! | C4: 0.5348 | D4: 1079121.6 | E4: 0.029349138 | F4: 0.41132581 | G4: ='(New) Comm OSAR'!I16 -> 0.44819576 | H4: ='(New) Comm OSAR'!I62 -> 919782.01 | I4: ='(New) Comm OSAR'!I78 -> 0.0215061 | J4: ='(New) Comm OSAR'!I74 -> 0.36519118 | K4: =IF(G4="","-",G4-C4) -> -0.086604237 | L4: =IF(H4="","-",H4-D4) -> -159339.6 | M4: =IF(I4="","-",I4-E4) -> -0.0078430386 | N4: =IF(J4="","-",J4-F4) -> -0.046134632 | O4: Yes | P4: 0.07
B6: Notes:
B7: NOI adjusted per the Loan Agreement.
B8: The Property remains in cash management as it failed to meet the DY cure of 7.00% for one quarter.
B9: DY decreased 73 bps QoQ due to both the UPB increasing from $36.8MM to $42.8MM QoQ and the tenant Beacon Sales Acquisition's lease ending inside the next 90 days. The decrease in In-Place Rents from Beacon vacating (-$650.3K) was only partially offset by the new lease with Zoox (+$450.5K).
B10: Occupancy increased 28% QoQ due to the new tenant Zoox leasing 143.5K SF and Beacon vacating only 55.4K SF.

Sheet Debt Service
B2: Interest Rate Cap | C2: 0.045 | D2: =IF(C2=C3,"At-the-Money",IF(C2<C3,"In-the-Money",IF(C2>C3,"Out-of-the-Money"))) -> Out-of-the-Money
B3: SOFR | C3: 0.0368 | D3: 46112
B4: Spread | C4: 0.026
B5: Effective Interest Rate | C5: =SUM(MIN(C3,C2),C4) -> 0.0628
B7: Current Principal Balance | C7: ='(New) Comm OSAR'!E6 -> 42768425
B9: NOI | C9: ='(New) Comm OSAR'!I54 -> 994474.26
B10: Debt Service (w/o Cap) | C10: =$C$7*($C$3+$C$4)*(365/360) -> 2723160.7
B11: Debt Service (w/Cap) | C11: =$C$7*$C$5*(365/360) -> 2723160.7
B13: DSCR (w/o Cap) | C13: =C9/C10 -> 0.36519118
B14: DSCR (w/Cap) | C14: =C9/C11 -> 0.36519118
B16: DY | C16: =C9/$C$7 -> 0.023252534

Sheet Tax
A1: Miami-Dade | B1: No 2026 Tax Data Available
B2: 2025
A3: 30-3116-016-0020 | B3: 84403.89
A4: 30-3116-016-0040 | B4: 161851.51
A5: 30-3116-016-0100 | B5: 206440.85
A7: Total | B7: =SUM(B3:B5) -> 452696.25

Sheet Insurance
O3: Total Insurance
O4: 112826.12

Sheet 1Q26 T12
A1: Database: | B1: MSDE_SE | C1: Rolling Twelve Month Income Statement | N1: Page: | O1: 1
A2: Report Id: | B2: LPC_R12MINCS | C2: Lincoln Property Company | N2: Date: | O2: 46162.707
C3: Seaboard 27279 | N3: Time: | O3: 46162.707
C4: Ending Period March 2026
A5: Accrual
C8: 04/25 | D8: 05/25 | E8: 06/25 | F8: 07/25 | G8: 08/25 | H8: 09/25 | I8: 10/25 | J8: 11/25 | K8: 12/25 | L8: 01/26 | M8: 02/26 | N8: 03/26 | O8: Total
A9: REVENUES
A11: RENTAL INCOME
A13: 4005-00 | B13: BASE/MINIMUM RENT | C13: 132240.35 | D13: 133826.03 | E13: 133826.03 | F13: 133826.03 | G13: 133826.03 | H13: 133826.03 | I13: 133826.03 | J13: 133826.03 | K13: 133826.03 | L13: 133826.03 | M13: 133826.03 | N13: 133826.03 | O13: 1604326.7
A14: 4105-02 | B14: INSURANCE REIMB | C14: 11494 | D14: -130205 | E14: 11494 | F14: 11494 | G14: 54224.58 | H14: 11494 | I14: 11494 | J14: 36494 | K14: 11494 | L14: 3414 | M14: 3414 | N14: 3414 | O14: 39719.58
A15: 4105-03 | B15: PROPERTY TAX REIMB | C15: 24390 | D15: 21093 | E15: 24390 | F15: 24390 | G15: 24390 | H15: 24390 | I15: 24390 | J15: 24390 | K15: 24390 | L15: 21006 | M15: 21006 | N15: 21006 | O15: 279231
A16: 4105-07 | B16: CAM REIMBURSEMENT | C16: 2986 | D16: -10326 | E16: -39744.58 | F16: 2986 | G16: 2986 | H16: 2986 | I16: 2986 | J16: 2986 | K16: 2986 | L16: 2986 | M16: 2986 | N16: 2986 | O16: -20210.58
A17: TOTAL RENTAL REVENUE | C17: 171110.35 | D17: 14388.03 | E17: 129965.45 | F17: 172696.03 | G17: 215426.61 | H17: 172696.03 | I17: 172696.03 | J17: 197696.03 | K17: 172696.03 | L17: 161232.03 | M17: 161232.03 | N17: 161232.03 | O17: 1903066.7
A19: OTHER INCOME
A21: TOTAL OTHER INCOME | C21: 0 | D21: 0 | E21: 0 | F21: 0 | G21: 0 | H21: 0 | I21: 0 | J21: 0 | K21: 0 | L21: 0 | M21: 0 | N21: 0 | O21: 0
A23: TOTAL INCOME | C23: 171110.35 | D23: 14388.03 | E23: 129965.45 | F23: 172696.03 | G23: 215426.61 | H23: 172696.03 | I23: 172696.03 | J23: 197696.03 | K23: 172696.03 | L23: 161232.03 | M23: 161232.03 | N23: 161232.03 | O23: 1903066.7
A25: EXPENSES
A27: OPERATING EXPENSES
A29: TAXES & INSURANCE
A31: 5005-01 | B31: REAL ESTATE TAXES | C31: 48858.75 | D31: 48858.75 | E31: 48858.75 | F31: 48858.75 | G31: 48858.75 | H31: 48858.75 | I31: 11578.75 | J31: 11578.75 | K31: 11578.75 | L31: 18487.24 | M31: 18487.24 | N31: 18487.24 | O31: 383350.47
A32: 5007-00 | B32: INSURANCE | C32: 751.41 | D32: 665.67 | E32: 9724.02 | F32: 19334.78 | G32: 19332.7 | H32: 9666.34 | I32: 85858.58 | J32: 9666.35 | K32: 9666.35 | L32: 9652.02 | M32: 9666.35 | N32: 10058.38 | O32: 194042.95
A33: TOTAL TAXES & INSURANCE | C33: 49610.16 | D33: 49524.42 | E33: 58582.77 | F33: 68193.53 | G33: 68191.45 | H33: 58525.09 | I33: 97437.33 | J33: 21245.1 | K33: 21245.1 | L33: 28139.26 | M33: 28153.59 | N33: 28545.62 | O33: 577393.42
A35: ADMINISTRATION
A37: 5010-04 | B37: BANK CHARGES | C37: 625 | D37: 625 | E37: 625 | F37: 625 | G37: 625 | H37: 625 | I37: 625 | J37: 625 | K37: 0 | L37: 0 | M37: 0 | N37: 0 | O37: 5000
A38: 5010-13 | B38: LICENSES & PERMITS | C38: 0 | D38: 0 | E38: 0 | F38: 0 | G38: 417.55 | H38: 0 | I38: 0 | J38: 0 | K38: 0 | L38: 0 | M38: 0 | N38: 0 | O38: 417.55
A39: 5010-15 | B39: OTHER ADMINISTRATIVE | C39: 440.65 | D39: 196.52 | E39: 0 | F39: 0 | G39: 786.1 | H39: 196.52 | I39: 3688.42 | J39: 196.53 | K39: 1494.5 | L39: 943.07 | M39: 0 | N39: 0 | O39: 7942.31
A40: 5010-16 | B40: POSTAGE & DELIVERY | C40: 0 | D40: 0 | E40: 0 | F40: 0 | G40: 45.68 | H40: 112.97 | I40: 0 | J40: 28.29 | K40: 0 | L40: 0 | M40: 0 | N40: 0 | O40: 186.94
A41: 5010-22 | B41: TRAVEL & TRANSPORTATION | C41: 0 | D41: 0 | E41: 0 | F41: 0 | G41: 0 | H41: 0 | I41: 0 | J41: 0 | K41: 1494.5 | L41: 0 | M41: 0 | N41: 0 | O41: 1494.5
A42: 5010-34 | B42: MILEAGE REIMBURSEMENT | C42: 0 | D42: 0 | E42: 9.73 | F42: 0 | G42: 2.88 | H42: 0 | I42: 0 | J42: 0 | K42: 0 | L42: 0 | M42: 0 | N42: 0 | O42: 12.61
A43: TOTAL ADMINISTRATION | C43: 1065.65 | D43: 821.52 | E43: 634.73 | F43: 625 | G43: 1877.21 | H43: 934.49 | I43: 4313.42 | J43: 849.82 | K43: 2989 | L43: 943.07 | M43: 0 | N43: 0 | O43: 15053.91
A45: PROFESSIONAL FEES
A47: 5015-00 | B47: PROFESSIONAL FEES | C47: 105 | D47: 0 | E47: 0 | F47: 0 | G47: 5500 | H47: 0 | I47: 0 | J47: 105 | K47: 1800 | L47: 3950 | M47: 5000 | N47: 0 | O47: 16460
A48: 5015-01 | B48: PROF FEES LEGAL | C48: 0 | D48: 0 | E48: 0 | F48: 0 | G48: 0 | H48: 2732.5 | I48: 0 | J48: 0 | K48: 174 | L48: 0 | M48: 0 | N48: 93420 | O48: 96326.5
A49: 5015-04 | B49: PROF FEES TAX APPEALS | C49: 0 | D49: 0 | E49: 7001.93 | F49: 0 | G49: 0 | H49: 0 | I49: 0 | J49: 0 | K49: 0 | L49: 0 | M49: 10384.54 | N49: 0 | O49: 17386.47
A50: TOTAL PROFESSIONAL FEES | C50: 105 | D50: 0 | E50: 7001.93 | F50: 0 | G50: 5500 | H50: 2732.5 | I50: 0 | J50: 105 | K50: 1974 | L50: 3950 | M50: 15384.54 | N50: 93420 | O50: 130172.97
A52: UTILITIES
A54: 5020-01 | B54: ELECTRICITY | C54: 0 | D54: 3053.81 | E54: 1589.06 | F54: 1492.63 | G54: 781.01 | H54: 604.7 | I54: 1392.11 | J54: 549.92 | K54: 1668.63 | L54: 1400 | M54: 1565.39 | N54: 1982.65 | O54: 16079.91
A55: 5020-05 | B55: WATER & SEWER | C55: 0 | D55: 8240.84 | E55: 0 | F55: -3268.32 | G55: 0 | H55: 8874.05 | I55: 0 | J55: 3486.56 | K55: 0 | L55: 0 | M55: 2599.38 | N55: -451.23 | O55: 19481.28
A56: 5020-09 | B56: ELECTRICITY VACANT | C56: 0 | D56: 0 | E56: 0 | F56: 0 | G56: 0 | H56: 0 | I56: 0 | J56: 0 | K56: 0 | L56: 0 | M56: 83 | N56: 0 | O56: 83
A57: 5020-13 | B57: WATER | C57: 0 | D57: 3459.36 | E57: 1729.68 | F57: 1729.68 | G57: 1729.68 | H57: 1729.68 | I57: 1729.68 | J57: 2162.11 | K57: 2162.11 | L57: 2599.38 | M57: 4324.22 | N57: 4324.22 | O57: 27679.8
...

Sheet 1Q RR
A2: Database: | B2: MSDE_SE | E2: Rent Roll | K2: Page: 1
A3: Bldg Status: | B3: Active only | E3: Seaboard Indust-3455 NW 54 St | K3: Date: 1/15/2025
E4: 45747 | K4: Time: 12/30/1899
A7: Bldg Id-Suit Id | F7: GLA | G7: Monthly | H7: Annual | I7: Monthly | J7: Expense | K7: Monthly ---------------- Future Rent Increases ----------------
A8: -Lease Id | B8: Occupant Name | D8: Lease Start | E8: Expiration | F8: Sqft | G8: Base Rent | H8: Rate PSF | I8: Cost Recovery | J8: Stop | K8: Other Income Cat Date Monthly Amount PSF
A10: Vacant Suites
A12: 2727901 | B12: -100 | C12: Vacant | F12: 101880
A14: 2727901 | B14: -100A | C14: Vacant | F14: 33201
A17: Totals: | B17: Occupied Sqft: | D17: 0 | E17: 0 Units | F17: 0 | G17: 0 | I17: 0 | K17: 0
B18: Leased/Unoccupied Sqft: | E18: 0 Units | F18: 0
B19: Vacant Sqft: | D19: 1 | E19: 2 Units | F19: 135,081
B20: Total Sqft: | E20: 2 Units | F20: 135,081
A23: Total Seaboard Indust-3455 NW 54 St:
B24: Occupied Sqft: | D24: 0 | E24: 0 Units | F24: 0 | G24: 0 | I24: 0 | K24: 0
B25: Leased/Unoccupied Sqft: | E25: 0 Units | F25: 0
B26: Vacant Sqft: | D26: 1 | E26: 2 Units | F26: 135,081
B27: Total Sqft: | E27: 2 Units | F27: 135,081
A57: Database: | B57: MSDE_SE | E57: Rent Roll | K57: Page: 2
A58: Bldg Status: | B58: Active only | E58: Seaboard Indust-5400 NW 32 Ct | K58: Date: 1/15/2025
E59: 45657 | K59: Time: 12/30/1899
A62: Bldg Id-Suit Id | F62: GLA | G62: Monthly | H62: Annual | I62: Monthly | J62: Expense | K62: Monthly ---------------- Future Rent Increases ----------------
A63: -Lease Id | B63: Occupant Name | D63: Lease Start | E63: Expiration | F63: Sqft | G63: Base Rent | H63: Rate PSF | I63: Cost Recovery | J63: Stop | K63: Other Income Cat Date Monthly Amount PSF
A65: Occupied Suites
A67: 2727902 | B67: -100 | C67: Sun Commodities Inc. | D67: 44805 | E67: 46721 | F67: 99907 | G67: 76699.73 | H67: 9.21 | I67: 23910 | K67: BRT 4/1/2025 79,384.22 9.53 | M67: Escalation within 90 Days | N67: Date | O67: DY Test Rent
B68: -6854 | K68: BRT 4/1/2026 82,162.67 9.87 | M68: 79384.22 | N68: 45748 | O68: =IF(N68-M71<1,M68,(ROUND((N68-M71)/30,0)/12)*G67+(((12-ROUND((N68-M71)/30,0))/12)*M68)) -> #REF!
K69: BRT 4/1/2027 85,038.36 10.21
M70: Forward start period
A71: Totals: | B71: Occupied Sqft: | D71: 1 | E71: 1 Units | F71: 99907 | G71: 76699.73 | I71: 23910 | K71: 0 | M71: =EOMONTH(#REF!,0)+1 -> #REF!
B72: Leased/Unoccupied Sqft: | E72: 0 Units | F72: 0
B73: Vacant Sqft: | E73: 0 Units | F73: 0
B74: Total Sqft: | E74: 1 Units | F74: 99,907 | G74: 76699.73
A77: Total Seaboard Indust-5400 NW 32 Ct:
B78: Occupied Sqft: | D78: 1 | E78: 1 Units | F78: 99907 | G78: 76699.73 | I78: 23910 | K78: 0
B79: Leased/Unoccupied Sqft: | E79: 0 Units | F79: 0
B80: Vacant Sqft: | E80: 0 Units | F80: 0
B81: Total Sqft: | E81: 1 Units | F81: 99,907 | G81: 76699.73
A112: Database: | B112: MSDE_SE | E112: Rent Roll | K112: Page: 3
A113: Bldg Status: | B113: Active only | E113: Seaboard Indust-5530 NW 32 Ct | K113: Date: 1/15/2025
E114: 45657 | K114: Time: 12/30/1899
A117: Bldg Id-Suit Id | F117: GLA | G117: Monthly | H117: Annual | I117: Monthly | J117: Expense | K117: Monthly ---------------- Future Rent Increases ----------------
...

Sheet 1Q26 RR
A1: Seaboard Indust-3455 NW 54 St (Building Id: 2727901)
J2: Bldg Status: Active only
A3: Rent Roll | J3: Report Date: 3/31/2026 | M3: 46112
A4: . | B4: . | C4: . | D4: . | E4: . | F4: GLA | G4: Monthly | H4: Annual | I4: Monthly Cost | J4: Expense | K4: Monthly | L4: ---------------- Future Rent Increases ---------------- | Q4: Excluding tenants with NTV inside 90 days
A5: Bldg Id | B5: Suite Id | C5: Occupant Name | D5: Rent Start | E5: Expiration | F5: Sqft | G5: Base Rent | H5: Rate PSF | I5: Recovery | J5: Stop | K5: Other Income | L5: Cat | M5: Date | N5: Monthly Amt | O5: PSF | Q5: DY Test Rent Monthly | R5: DY Cost Recovery | S5: WALT | T5: =SUMPRODUCT($T$7:$T$41,$S$7:$S$41)/SUM($T$7:$T$41) -> 4.098565 | V5: Annualized Amounts including step ups inside 90 days
A6: Occupied Suites
A7: 2727901 | B7: 100 | C7: Zoox, Inc | D7: 46082 | E7: 48791 | F7: 143504 | G7: 0 | I7: 30305 | L7: BRT | M7: 46235 | N7: 37541.66 | O7: 3.14 | Q7: =N7 -> 37541.66 | R7: =I15 -> 30305 | S7: =(E7-$M$3)/365 -> 7.339726 | T7: =F7 -> 143504 | V7: =(Q7*12)*0.95 -> 427974.92
L8: BRT | M8: 46419 | N8: 98270.83 | O8: 8.22
L9: BRT | M9: 46600 | N9: 158452.33 | O9: 13.25
L10: BRT | M10: 46966 | N10: 163998.17 | O10: 13.71
L11: BRT | M11: 47331 | N11: 169738.1 | O11: 14.19
L12: BRT | M12: 47696 | N12: 175678.93 | O12: 14.69
L13: BRT | M13: 48061 | N13: 181827.2 | O13: 15.2
L14: BRT | M14: 48427 | N14: 188191.67 | O14: 15.74
A15: Totals: | C15: Occupied Sqft: | D15: 1 | E15: 1 Units | F15: 143504 | G15: 0 | I15: 30305 | K15: 0
C16: Vacant Sqft: | E16: 0 Units | F16: 0
C17: Total Sqft: | E17: 1 Units | F17: 143504
C18: Total Sqft: | E18: 1 Units | F18: 143504
A20: Total Seaboard Owner-3455 NW 54 St:
C21: Occupied Sqft: | D21: 1 | E21: 1 Units | F21: 143504 | G21: 0 | I21: 30305 | K21: 0
C22: Vacant Sqft: | E22: 0 Units | F22: 0
C23: Total Sqft: | E23: 1 Units | F23: 143504
C24: Total Sqft: | E24: 1 Units | F24: 143504
A26: Occupied Suites
A27: 2727902 | B27: 100 | C27: Sun Commodities Inc. | D27: 44805 | E27: 46721 | F27: 99907 | G27: 79384.22 | H27: 9.53 | I27: 20540 | L27: BRT | M27: 46113 | N27: 82162.67 | O27: 9.87 | Q27: =N27 -> 82162.67 | R27: =I35 -> 20540 | S27: =(E27-$M$3)/365 -> 1.6684932 | T27: =F35 -> 99907 | V27: =Q27*12 -> 985952.04
L28: BRT | M28: 46478 | N28: 85038.36 | O28: 10.21
A29: Totals: | C29: Occupied Sqft: | D29: 1 | E29: 1 Units | F29: 99907 | G29: 79384.22 | I29: 20540 | K29: 0
C30: Vacant Sqft: | E30: 0 Units | F30: 0
C31: Total Sqft: | E31: 1 Units | F31: 99907 | G31: 79384.22
C32: Total Sqft: | E32: 1 Units | F32: 99907 | G32: 79384.22
A34: Total Seaboard Owner-5400 NW 32nd Ct:
C35: Occupied Sqft: | D35: 1 | E35: 1 Units | F35: 99907 | G35: 79384.22 | I35: 20540 | K35: 0
C36: Vacant Sqft: | E36: 0 Units | F36: 0
C37: Total Sqft: | E37: 1 Units | F37: 99907 | G37: 79384.22
C38: Total Sqft: | E38: 1 Units | F38: 99907 | G38: 79384.22
A40: Occupied Suites
A41: 2727903 | B41: 100 | C41: Beacon Sales Acquisition Inc | D41: 40585 | E41: 46142 | F41: 55358 | G41: 54441.81 | H41: 11.8 | I41: 6866 | S41: =(E41-$M$3)/365 -> 0.082191781 | T41: =F42 -> 55358
A42: Totals: | C42: Occupied Sqft: | D42: 1 | E42: 1 Units | F42: 55358 | G42: 54441.81 | I42: 6866 | K42: 0
C43: Vacant Sqft: | E43: 0 Units | F43: 0 | N43: =G41*12 -> 653301.72
C44: Total Sqft: | E44: 1 Units | F44: 55358 | G44: 54441.81
...

Sheet 3Q T12
A1: Database: MSDE_SE | H1: Forecast - Budget Report
A2: PROJ: 27279 | H2: Lincoln Property Company
H3: WSLP Seaboard Owner IX LP
A5: Accrual
H6: Actual amounts from 01/25 to 09/25, Budget amounts from 10/25 to 12/25
C9: 45566 | D9: 45597 | E9: 45627 | F9: 45688 | G9: 45716 | H9: 45747 | I9: 45777 | J9: 45808 | K9: 45838 | L9: 45869 | M9: 45900 | N9: 45930 | O9: Total
A10: REVENUES
A12: 4005-00 | B12: BASE/MINIMUM RENT | C12: =SUMIFS('2Q T12'!F:F,'2Q T12'!$A:$A,'3Q T12'!$B12) -> 129555.86 | D12: =SUMIFS('2Q T12'!G:G,'2Q T12'!$A:$A,'3Q T12'!$B12) -> 129555.86 | E12: =SUMIFS('2Q T12'!H:H,'2Q T12'!$A:$A,'3Q T12'!$B12) -> 129555.86 | F12: 129556 | G12: 129556 | H12: 129556 | I12: 132240 | J12: 133826 | K12: 133826 | L12: 133826 | M12: 133826 | N12: 133826 | O12: =SUM(C12:N12) -> 1578705.6
A13: 4007-00 | B13: RENT CONCESSIONS | C13: =SUMIFS('2Q T12'!F:F,'2Q T12'!$A:$A,'3Q T12'!$B13) -> 0 | D13: =SUMIFS('2Q T12'!G:G,'2Q T12'!$A:$A,'3Q T12'!$B13) -> 0 | E13: =SUMIFS('2Q T12'!H:H,'2Q T12'!$A:$A,'3Q T12'!$B13) -> 0 | F13: 0 | G13: 0 | H13: 0 | I13: 0 | J13: 0 | K13: 0 | L13: 0 | M13: 0 | N13: 0 | O13: =SUM(C13:N13) -> 0
A14: 4025-00 | B14: UTILITY INCOME | C14: =SUMIFS('2Q T12'!F:F,'2Q T12'!$A:$A,'3Q T12'!$B14) -> 0 | D14: =SUMIFS('2Q T12'!G:G,'2Q T12'!$A:$A,'3Q T12'!$B14) -> 0 | E14: =SUMIFS('2Q T12'!H:H,'2Q T12'!$A:$A,'3Q T12'!$B14) -> 0 | F14: 0 | G14: -325 | H14: 0 | I14: 0 | J14: 0 | K14: 0 | L14: 0 | M14: 0 | N14: 0 | O14: =SUM(C14:N14) -> -325
A15: 4025-53 | B15: UTILITY INCOME-ELECTRIC | C15: =SUMIFS('2Q T12'!F:F,'2Q T12'!$A:$A,'3Q T12'!$B15) -> 0 | D15: =SUMIFS('2Q T12'!G:G,'2Q T12'!$A:$A,'3Q T12'!$B15) -> 0 | E15: =SUMIFS('2Q T12'!H:H,'2Q T12'!$A:$A,'3Q T12'!$B15) -> 0 | F15: 26 | G15: 0 | H15: 0 | I15: 0 | J15: 0 | K15: 0 | L15: 0 | M15: 0 | N15: 0 | O15: =SUM(C15:N15) -> 26
A16: 4105-02 | B16: INSURANCE REIMB | C16: =SUMIFS('2Q T12'!F:F,'2Q T12'!$A:$A,'3Q T12'!$B16) -> 8569.83 | D16: =SUMIFS('2Q T12'!G:G,'2Q T12'!$A:$A,'3Q T12'!$B16) -> 8569.83 | E16: =SUMIFS('2Q T12'!H:H,'2Q T12'!$A:$A,'3Q T12'!$B16) -> 8569.83 | F16: 11494 | G16: 11494 | H16: 11494 | I16: 11494 | J16: -130205 | K16: 11494 | L16: 11494 | M16: 54225 | N16: 11494 | O16: =SUM(C16:N16) -> 30187.49
A17: 4105-03 | B17: PROPERTY TAX REIMB | C17: =SUMIFS('2Q T12'!F:F,'2Q T12'!$A:$A,'3Q T12'!$B17) -> 28825.92 | D17: =SUMIFS('2Q T12'!G:G,'2Q T12'!$A:$A,'3Q T12'!$B17) -> 28825.92 | E17: =SUMIFS('2Q T12'!H:H,'2Q T12'!$A:$A,'3Q T12'!$B17) -> 28825.92 | F17: 24390 | G17: 24390 | H17: 24390 | I17: 24390 | J17: 21093 | K17: 24390 | L17: 24390 | M17: 24390 | N17: 24390 | O17: =SUM(C17:N17) -> 302690.76
A18: 4105-07 | B18: CAM REIMBURSEMENT | C18: =SUMIFS('2Q T12'!F:F,'2Q T12'!$A:$A,'3Q T12'!$B18) -> 5119.75 | D18: =SUMIFS('2Q T12'!G:G,'2Q T12'!$A:$A,'3Q T12'!$B18) -> 5119.75 | E18: =SUMIFS('2Q T12'!H:H,'2Q T12'!$A:$A,'3Q T12'!$B18) -> 5119.75 | F18: 2986 | G18: 2986 | H18: 2986 | I18: 2986 | J18: -10326 | K18: -39745 | L18: 2986 | M18: 2986 | N18: 2986 | O18: =SUM(C18:N18) -> -13809.75
A19: 4105-10 | B19: RECOVERY YEAR END EST | C19: =SUMIFS('2Q T12'!F:F,'2Q T12'!$A:$A,'3Q T12'!$B19) -> 0 | D19: =SUMIFS('2Q T12'!G:G,'2Q T12'!$A:$A,'3Q T12'!$B19) -> 0 | E19: =SUMIFS('2Q T12'!H:H,'2Q T12'!$A:$A,'3Q T12'!$B19) -> 0 | F19: 0 | G19: 0 | H19: 0 | I19: 0 | J19: 0 | K19: 0 | L19: 0 | M19: 0 | N19: 0 | O19: =SUM(C19:N19) -> 0
A20: 4115-00 | B20: MISCELLANEOUS INCOME | C20: =SUMIFS('2Q T12'!F:F,'2Q T12'!$A:$A,'3Q T12'!$B20) -> 40.77 | D20: =SUMIFS('2Q T12'!G:G,'2Q T12'!$A:$A,'3Q T12'!$B20) -> 30 | E20: =SUMIFS('2Q T12'!H:H,'2Q T12'!$A:$A,'3Q T12'!$B20) -> 30 | F20: 30 | G20: 30 | H20: 0 | I20: 0 | J20: 0 | K20: 0 | L20: 0 | M20: 0 | N20: 0 | O20: =SUM(C20:N20) -> 160.77
A21: EFFECTIVE RENTAL REVENUE | C21: =SUM(C12:C20) -> 172112.13 | D21: =SUM(D12:D20) -> 172101.36 | E21: =SUM(E12:E20) -> 172101.36 | F21: 168481 | G21: 168131 | H21: 168426 | I21: 171110 | J21: 14388 | K21: 129965 | L21: 172696 | M21: 215427 | N21: 172696 | O21: =SUM(C21:N21) -> 1897634.9
O22: =SUM(C22:N22) -> 0
A23: EFFECTIVE GROSS REVENUE | C23: =SUMIFS('2Q T12'!F:F,'2Q T12'!$A:$A,'3Q T12'!$B23) -> 0 | D23: =SUMIFS('2Q T12'!G:G,'2Q T12'!$A:$A,'3Q T12'!$B23) -> 0 | E23: =SUMIFS('2Q T12'!H:H,'2Q T12'!$A:$A,'3Q T12'!$B23) -> 0 | F23: 0 | G23: 0 | H23: 0 | I23: 0 | J23: 0 | K23: 0 | L23: 0 | M23: 0 | N23: 0 | O23: =SUM(C23:N23) -> 0
O24: =SUM(C24:N24) -> 0
A25: EXPENSES | O25: =SUM(C25:N25) -> 0
O26: =SUM(C26:N26) -> 0
A27: OPERATING EXPENSES | O27: =SUM(C27:N27) -> 0
A28: 5005-01 | B28: REAL ESTATE TAXES | C28: =SUMIFS('2Q T12'!F:F,'2Q T12'!$A:$A,'3Q T12'!$B28) -> -109312.86 | D28: =SUMIFS('2Q T12'!G:G,'2Q T12'!$A:$A,'3Q T12'!$B28) -> 41186.13 | E28: =SUMIFS('2Q T12'!H:H,'2Q T12'!$A:$A,'3Q T12'!$B28) -> 57003.51 | F28: 48859 | G28: 48859 | H28: 48859 | I28: 48859 | J28: 48859 | K28: 48859 | L28: 48859 | M28: 48859 | N28: 48859 | O28: =SUM(C28:N28) -> 428607.78
A29: 5007-00 | B29: INSURANCE | C29: =SUMIFS('2Q T12'!F:F,'2Q T12'!$A:$A,'3Q T12'!$B29) -> 23757.58 | D29: =SUMIFS('2Q T12'!G:G,'2Q T12'!$A:$A,'3Q T12'!$B29) -> 23757.58 | E29: =SUMIFS('2Q T12'!H:H,'2Q T12'!$A:$A,'3Q T12'!$B29) -> 18894.25 | F29: 23046 | G29: 23046 | H29: 0 | I29: 751 | J29: 666 | K29: 9724 | L29: 19335 | M29: 19333 | N29: 9666 | O29: =SUM(C29:N29) -> 171976.41
A30: 5010-04 | B30: BANK CHARGES | C30: =SUMIFS('2Q T12'!F:F,'2Q T12'!$A:$A,'3Q T12'!$B30) -> 1525 | D30: =SUMIFS('2Q T12'!G:G,'2Q T12'!$A:$A,'3Q T12'!$B30) -> 1525 | E30: =SUMIFS('2Q T12'!H:H,'2Q T12'!$A:$A,'3Q T12'!$B30) -> 2025 | F30: 1535 | G30: 1535 | H30: 625 | I30: 625 | J30: 625 | K30: 625 | L30: 625 | M30: 625 | N30: 625 | O30: =SUM(C30:N30) -> 12520
A31: 5010-13 | B31: LICENSES & PERMITS | C31: =SUMIFS('2Q T12'!F:F,'2Q T12'!$A:$A,'3Q T12'!$B31) -> 0 | D31: =SUMIFS('2Q T12'!G:G,'2Q T12'!$A:$A,'3Q T12'!$B31) -> 0 | E31: =SUMIFS('2Q T12'!H:H,'2Q T12'!$A:$A,'3Q T12'!$B31) -> 0 | F31: 0 | G31: 0 | H31: 0 | I31: 0 | J31: 0 | K31: 0 | L31: 0 | M31: 418 | N31: 0 | O31: =SUM(C31:N31) -> 418
A32: 5010-15 | B32: OTHER ADMINISTRATIVE | C32: =SUMIFS('2Q T12'!F:F,'2Q T12'!$A:$A,'3Q T12'!$B32) -> 1054.84 | D32: =SUMIFS('2Q T12'!G:G,'2Q T12'!$A:$A,'3Q T12'!$B32) -> 0 | E32: =SUMIFS('2Q T12'!H:H,'2Q T12'!$A:$A,'3Q T12'!$B32) -> 32.08 | F32: 214 | G32: 0 | H32: 0 | I32: 441 | J32: 197 | K32: 0 | L32: 0 | M32: 786 | N32: 197 | O32: =SUM(C32:N32) -> 2921.92
A33: 5010-16 | B33: POSTAGE & DELIVERY | C33: =SUMIFS('2Q T12'!F:F,'2Q T12'!$A:$A,'3Q T12'!$B33) -> 0 | D33: =SUMIFS('2Q T12'!G:G,'2Q T12'!$A:$A,'3Q T12'!$B33) -> 0 | E33: =SUMIFS('2Q T12'!H:H,'2Q T12'!$A:$A,'3Q T12'!$B33) -> 0 | F33: 0 | G33: 0 | H33: 0 | I33: 0 | J33: 0 | K33: 0 | L33: 0 | M33: 46 | N33: 113 | O33: =SUM(C33:N33) -> 159
A34: 5010-22 | B34: TRAVEL & TRANSPORTATION | C34: =SUMIFS('2Q T12'!F:F,'2Q T12'!$A:$A,'3Q T12'!$B34) -> 0 | D34: =SUMIFS('2Q T12'!G:G,'2Q T12'!$A:$A,'3Q T12'!$B34) -> 0 | E34: =SUMIFS('2Q T12'!H:H,'2Q T12'!$A:$A,'3Q T12'!$B34) -> 0 | F34: 0 | G34: 0 | H34: 0 | I34: 0 | J34: 0 | K34: 0 | L34: 0 | M34: 0 | N34: 0 | O34: =SUM(C34:N34) -> 0
A35: 5010-34 | B35: MILEAGE REIMBURSEMENT | C35: =SUMIFS('2Q T12'!F:F,'2Q T12'!$A:$A,'3Q T12'!$B35) -> 0 | D35: =SUMIFS('2Q T12'!G:G,'2Q T12'!$A:$A,'3Q T12'!$B35) -> 0 | E35: =SUMIFS('2Q T12'!H:H,'2Q T12'!$A:$A,'3Q T12'!$B35) -> 0 | F35: 0 | G35: 0 | H35: 9 | I35: 0 | J35: 0 | K35: 10 | L35: 0 | M35: 3 | N35: 0 | O35: =SUM(C35:N35) -> 22
A36: 5015-00 | B36: PROFESSIONAL FEES | C36: =SUMIFS('2Q T12'!F:F,'2Q T12'!$A:$A,'3Q T12'!$B36) -> 0 | D36: =SUMIFS('2Q T12'!G:G,'2Q T12'!$A:$A,'3Q T12'!$B36) -> 0 | E36: =SUMIFS('2Q T12'!H:H,'2Q T12'!$A:$A,'3Q T12'!$B36) -> 0 | F36: 0 | G36: 0 | H36: 0 | I36: 105 | J36: 0 | K36: 0 | L36: 0 | M36: 5500 | N36: 0 | O36: =SUM(C36:N36) -> 5605
A37: 5015-01 | B37: PROF FEES LEGAL | C37: =SUMIFS('2Q T12'!F:F,'2Q T12'!$A:$A,'3Q T12'!$B37) -> -100 | D37: =SUMIFS('2Q T12'!G:G,'2Q T12'!$A:$A,'3Q T12'!$B37) -> 0 | E37: =SUMIFS('2Q T12'!H:H,'2Q T12'!$A:$A,'3Q T12'!$B37) -> 0 | F37: 0 | G37: 0 | H37: 1150 | I37: 0 | J37: 0 | K37: 0 | L37: 0 | M37: 0 | N37: 2733 | O37: =SUM(C37:N37) -> 3783
A38: 5015-04 | B38: PROF FEES TAX APPEALS | C38: =SUMIFS('2Q T12'!F:F,'2Q T12'!$A:$A,'3Q T12'!$B38) -> 0 | D38: =SUMIFS('2Q T12'!G:G,'2Q T12'!$A:$A,'3Q T12'!$B38) -> 0 | E38: =SUMIFS('2Q T12'!H:H,'2Q T12'!$A:$A,'3Q T12'!$B38) -> -3954.33 | F38: 0 | G38: 0 | H38: 0 | I38: 0 | J38: 0 | K38: 7002 | L38: 0 | M38: 0 | N38: 0 | O38: =SUM(C38:N38) -> 3047.67
A39: 5020-01 | B39: ELECTRICITY | C39: =SUMIFS('2Q T12'!F:F,'2Q T12'!$A:$A,'3Q T12'!$B39) -> 1527.52 | D39: =SUMIFS('2Q T12'!G:G,'2Q T12'!$A:$A,'3Q T12'!$B39) -> 1322.87 | E39: =SUMIFS('2Q T12'!H:H,'2Q T12'!$A:$A,'3Q T12'!$B39) -> 2572.5 | F39: 2275 | G39: 965 | H39: 4621 | I39: 0 | J39: 3054 | K39: 1589 | L39: 1493 | M39: 781 | N39: 605 | O39: =SUM(C39:N39) -> 20805.89
... A54: 5030-00 | B54: PROPERTY MANAGEMENT FEES | C54: =SUMIFS('2Q T12'!F:F,'2Q T12'!$A:$A,'3Q T12'!$B54) -> 8380.5 | D54: =SUMIFS('2Q T12'!G:G,'2Q T12'!$A:$A,'3Q T12'!$B54) -> 2000 | E54: =SUMIFS('2Q T12'!H:H,'2Q T12'!$A:$A,'3Q T12'!$B54) -> 5162.14 | F54: 5098 | G54: 5053 | H54: 5043 | I54: 5178 | J54: 2085 | K54: 3528 | L54: 8280 | M54: 3099 | N54: 5181 | O54: =SUM(C54:N54) -> 58087.64
A55: TOTAL OPERATING EXPENSES | C55: =SUM(C28:C54) -> -47307.01 | D55: =SUM(D28:D54) -> 75162.89 | E55: =SUM(E28:E54) -> 96183.91 | F55: 87688 | G55: 84465 | H55: 61003 | I55: 58737 | J55: 69859 | K55: 79803 | L55: 81476 | M55: 85104 | N55: 88504 | O55: =SUM(C55:N55) -> 820678.79
O56: =SUM(C56:N56) -> 0
A57: OPERATING EXPENSES - NON RECOVER | O57: =SUM(C57:N57) -> 0
A58: 6015-00 | B58: PROFESSIONAL FEES NON | C58: =SUMIFS('2Q T12'!F:F,'2Q T12'!$A:$A,'3Q T12'!$B58) -> 7406.07 | D58: =SUMIFS('2Q T12'!G:G,'2Q T12'!$A:$A,'3Q T12'!$B58) -> 0 | E58: =SUMIFS('2Q T12'!H:H,'2Q T12'!$A:$A,'3Q T12'!$B58) -> 0 | F58: 0 | G58: 0 | H58: 5775 | I58: 0 | J58: 20472 | K58: 16320 | L58: 1000 | M58: 0 | N58: 0 | O58: =SUM(C58:N58) -> 50973.07
...

Sheet 2Q T12
B1: Database: MSDE_SE | C1: Rolling Twelve Month Income Statement
B2: Report Id: MRI_R12MINCS | C2: Lincoln Property Company
B3: PROJ: 27279 | C3: WSLP Seaboard Owner IX LP
B4: SEABOARD
B6: Accrual | C6: Ending Period June 2025
A9: CODE for 3Q T12 | C9: 07/24 | D9: 08/24 | E9: 09/24 | F9: 10/24 | G9: 11/24 | H9: 12/24 | I9: 01/25 | J9: 02/25 | K9: 03/25 | L9: 04/25 | M9: 05/25 | N9: 06/25 | O9: Total
B10: REVENUES:
B12: RENTAL INCOME
A13: BASE/MINIMUM RENT | B13: BASE/MINIMUM RENT | C13: 129555.86 | D13: 129555.86 | E13: 129555.86 | F13: 129555.86 | G13: 129555.86 | H13: 129555.86 | I13: 129555.86 | J13: 129555.86 | K13: 129555.86 | L13: 132240.35 | M13: 133826.03 | N13: 133826.03 | O13: 1565895.1
A14: BASE/MINIMUM RENT | B14: HOLDOVER RENT | C14: 96708.93 | D14: 52952.55 | E14: 0 | F14: 0 | G14: 0 | H14: 0 | I14: 0 | J14: 0 | K14: 0 | L14: 0 | M14: 0 | N14: 0 | O14: 149661.48
B15: TOTAL RENTAL REVENUE | C15: 226264.79 | D15: 182508.41 | E15: 129555.86 | F15: 129555.86 | G15: 129555.86 | H15: 129555.86 | I15: 129555.86 | J15: 129555.86 | K15: 129555.86 | L15: 132240.35 | M15: 133826.03 | N15: 133826.03 | O15: 1715556.6
B17: OTHER INCOME
A18: UTILITY INCOME | B18: UTILITY INCOME | C18: 0 | D18: 0 | E18: 0 | F18: 0 | G18: 0 | H18: 0 | I18: 0 | J18: -325.25 | K18: 0 | L18: 0 | M18: 0 | N18: 0 | O18: -325.25
A19: UTILITY INCOME-ELECTRIC | B19: UTILITY INCOME-ELECTRIC | C19: 0 | D19: 0 | E19: 0 | F19: 0 | G19: 0 | H19: 0 | I19: 25.62 | J19: 0 | K19: 0 | L19: 0 | M19: 0 | N19: 0 | O19: 25.62
A20: INSURANCE REIMB | B20: INSURANCE REIMB | C20: 37986.67 | D20: 29330.68 | E20: 19972.39 | F20: 8569.83 | G20: 8569.83 | H20: 8569.83 | I20: 11494 | J20: 11494 | K20: 11494 | L20: 11494 | M20: -130205 | N20: 11494 | O20: 40264.23
A21: PROPERTY TAX REIMB | B21: PROPERTY TAX REIMB | C21: 36311.46 | D21: 27437.21 | E21: 17840.74 | F21: 28825.92 | G21: 28825.92 | H21: 28825.92 | I21: 24390 | J21: 24390 | K21: 24390 | L21: 24390 | M21: 21093 | N21: 24390 | O21: 311110.17
A22: CAM REIMBURSEMENT | B22: CAM REIMBURSEMENT | C22: 4992.7 | D22: 4992.7 | E22: 4992.7 | F22: 5119.75 | G22: 5119.75 | H22: 5119.75 | I22: 2986 | J22: 2986 | K22: 2986 | L22: 2986 | M22: -10326 | N22: -39744.58 | O22: -7789.23
A23: MISCELLANEOUS INCOME | B23: INTEREST ESCROW | C23: 6.49 | D23: 0 | E23: 0 | F23: 10.77 | G23: 0 | H23: 0 | I23: 0 | J23: 0 | K23: 0 | L23: 0 | M23: 0 | N23: 0 | O23: 17.26
A24: MISCELLANEOUS INCOME | B24: MISCELLANEOUS INCOME | C24: 30 | D24: 30 | E24: 30 | F24: 30 | G24: 30 | H24: 30 | I24: 30 | J24: 30 | K24: 0 | L24: 0 | M24: 0 | N24: 0 | O24: 240
A25: MISCELLANEOUS INCOME | B25: TENANT WORK ORDER REIMB | C25: 0 | D25: 7550 | E25: 0 | F25: 0 | G25: 0 | H25: 0 | I25: 0 | J25: 0 | K25: 0 | L25: 0 | M25: 0 | N25: 0 | O25: 7550
B26: TOTAL OTHER INCOME | C26: 79327.32 | D26: 69340.59 | E26: 42835.83 | F26: 42556.27 | G26: 42545.5 | H26: 42545.5 | I26: 38925.62 | J26: 38574.75 | K26: 38870 | L26: 38870 | M26: -119438 | N26: -3860.58 | O26: 351092.8
B28: TOTAL REVENUE | C28: 305592.11 | D28: 251849 | E28: 172391.69 | F28: 172112.13 | G28: 172101.36 | H28: 172101.36 | I28: 168481.48 | J28: 168130.61 | K28: 168425.86 | L28: 171110.35 | M28: 14388.03 | N28: 129965.45 | O28: 2066649.4
B30: EXPENSES:
B31: OPERATING EXPENSES
B33: TAXES & INSURANCE
A34: REAL ESTATE TAXES | B34: REAL ESTATE TAXES | C34: 57908.24 | D34: 57908.24 | E34: 57908.24 | F34: -109312.86 | G34: 41186.13 | H34: 41186.18 | I34: 48858.75 | J34: 48858.77 | K34: 48858.75 | L34: 48858.75 | M34: 48858.75 | N34: 48858.75 | O34: 439936.69
A35: REAL ESTATE TAXES | B35: RE TAXES - PRIOR YR | C35: 0 | D35: 0 | E35: 0 | F35: 0 | G35: 0 | H35: 15817.33 | I35: 0 | J35: 0 | K35: 0 | L35: 0 | M35: 0 | N35: 0 | O35: 15817.33
A36: INSURANCE | B36: INSURANCE | C36: 23157.56 | D36: 23757.58 | E36: 23757.58 | F36: 23757.58 | G36: 23757.58 | H36: 18894.25 | I36: 23045.86 | J36: 23045.86 | K36: 0 | L36: 751.41 | M36: 665.67 | N36: 9724.02 | O36: 194314.95
B37: TOTAL TAXES & INSURANCE | C37: 81065.8 | D37: 81665.82 | E37: 81665.82 | F37: -85555.28 | G37: 64943.71 | H37: 75897.76 | I37: 71904.61 | J37: 71904.63 | K37: 48858.75 | L37: 49610.16 | M37: 49524.42 | N37: 58582.77 | O37: 650068.97
B39: ADMINISTRATION
A40: BANK CHARGES | B40: BANK CHARGES | C40: 1518.2 | D40: 1523.08 | E40: 1525 | F40: 1525 | G40: 1525 | H40: 2025 | I40: 1534.68 | J40: 1534.68 | K40: 625 | L40: 625 | M40: 625 | N40: 625 | O40: 15210.64
A41: OTHER ADMINISTRATIVE | B41: OTHER ADMINISTRATIVE | C41: 0 | D41: 0 | E41: 0 | F41: 0 | G41: 0 | H41: 32.08 | I41: 214.39 | J41: 0 | K41: 0 | L41: 440.65 | M41: 196.52 | N41: 0 | O41: 883.64
A42: MILEAGE REIMBURSEMENT | B42: MILEAGE REIMBURSEMENT | C42: 0 | D42: 0 | E42: 0 | F42: 0 | G42: 0 | H42: 0 | I42: 0 | J42: 0 | K42: 9.1 | L42: 0 | M42: 0 | N42: 9.73 | O42: 18.83
B43: TOTAL ADMINISTRATION | C43: 1518.2 | D43: 1523.08 | E43: 1525 | F43: 1525 | G43: 1525 | H43: 2057.08 | I43: 1749.07 | J43: 1534.68 | K43: 634.1 | L43: 1065.65 | M43: 821.52 | N43: 634.73 | O43: 16113.11
B45: PROFESSIONAL FEES
A46: PROFESSIONAL FEES | B46: PROFESSIONAL FEES | C46: 0 | D46: 5500 | E46: 0 | F46: 0 | G46: 0 | H46: 0 | I46: 0 | J46: 0 | K46: 0 | L46: 105 | M46: 0 | N46: 0 | O46: 5605
A47: PROF FEES LEGAL | B47: PROF FEES LEGAL | C47: 3025 | D47: 6300 | E47: 0 | F47: -100 | G47: 0 | H47: 0 | I47: 0 | J47: 0 | K47: 1150 | L47: 0 | M47: 0 | N47: 0 | O47: 10375
A48: PROF FEES TAX APPEALS | B48: PROF FEES TAX APPEALS | C48: 0 | D48: 8018.51 | E48: 0 | F48: 0 | G48: 0 | H48: -3954.33 | I48: 0 | J48: 0 | K48: 0 | L48: 0 | M48: 0 | N48: 7001.93 | O48: 11066.11
B49: TOTAL PROFESSIONAL FEES | C49: 3025 | D49: 19818.51 | E49: 0 | F49: -100 | G49: 0 | H49: -3954.33 | I49: 0 | J49: 0 | K49: 1150 | L49: 105 | M49: 0 | N49: 7001.93 | O49: 27046.11
B51: UTILITIES
...

Sheet Definitions
