Workbook
Name and: #REF!
Name andd: #REF!
Name anddd: #REF!
Name andddd: #REF!
Name att: #REF!
Name Attribute: #REF!
Name Benchmark: #REF!
Name Body: #REF!
Name bug: #REF!
Name Capped: #REF!
Name CMNOTES: #REF!
Name date: #REF!
Name det: #REF!
Name Detail: #REF!
Name doo: #REF!
Name jeunee: #REF!
Name jnue: #REF!
Name JR_PAGE_ANCHOR_0_1: #REF!
Name juenn: #REF!
Name jul: #REF!
Name july614amt: #REF!
Name jun: #REF!
Name june: #REF!
Name june14amt: #REF!
Name june7380: #REF!
Name june7381: #REF!
Name june814amt: #REF!
Name june8810: #REF!
Name june8825: #REF!
Name june8826: #REF!
Name junee: #REF!
Name juneeee: #REF!
Name Level3IL: #REF!
Name my: #REF!
Name MyAttribute: #REF!
Name mybug: #REF!
Name MyDate: #REF!
Name MyQuarter: #REF!
Name MyRange: #REF!
Name MyRateIncrease: #REF!
Name myunit: #REF!
Name MyUnitTransferDecrease: #REF!
Name MyUnitTransIncrease: #REF!
Name nana: #REF!
Name nanana: #REF!
Name newsummary: #REF!
Name operations: #REF!
Name opie: #REF!
Name pre: #REF!
Name prep: #REF!
Name Prepaid3: #REF!
Name prepaid4: #REF!
Name quart: #REF!
Name range: #REF!
Name rate: #REF!
Name RESULTS: #REF!
Name Sample1: #REF!
Name savings: #REF!
Name sec: #REF!
Name Sec3TotalRes: #REF!

Sheet Comm OSAR
B1: CREFC Investor Reporting Package
B2: COMMERCIAL OPERATING STATEMENT ANALYSIS REPORT (includes Retail/Office/Industrial/Mixed Use/Self Storage)
B3: =H24 -> as of 03/31/2026
B4: PROPERTY OVERVIEW | G4: Allocated Loan Amount/Percentage
B5: Property ID | D5: 1001-001 | E5: Paid Thru Date | F5: Debt Outside Trust (1) | G5: $ | H5: %
B6: Note A-Scheduled Loan Balance | D6: ='Debt Service'!C4 -> 10409000 | E6: =H24 -> as of 03/31/2026 | F6: X or Blank | G6: 0 | H6: 0
B7: Note B-Scheduled Loan Balance | D7: 0 | E7: MM/DD/YY | F7: X or Blank | G7: 0 | H7: 0
B8: Note C-Scheduled Loan Balance | D8: 0 | E8: MM/DD/YY | F8: X or Blank | G8: 0 | H8: 0
B9: Property Name | D9: Ares Fund XI Industrial - 55th Ave
B10: Property Type | D10: Industrial
B11: Property Address, City, State | D11: 601 S 55th Ave | F11: Phoenix | H11: AZ
B12: Current Net Rentable SF/Units/Beds/Rooms | D12: 100000 | E12: RSF | F12: Use second box to specify sqft.,units…
B13: Year Built/Year Renovated | D13: 1986 | E13: N/A
B14: Cap Ex Reserve (annually)/per Unit.etc. (2) | D14: 0.09996 | E14: /SF/Yr | F14: specify annual/per unit…
B15: Statement Ending Date | D15: Underwriting | E15: =EOMONTH(F15,-3) -> 45838 | F15: =EOMONTH(G15,-3) -> 45930 | G15: =EOMONTH(H15,-3) -> 46022 | H15: 46112
B16: Occupancy Rate (physical) | D16: 0 | G16: 1 | H16: =SUM(RR!I:I)/'Comm OSAR'!$D$12 -> 1
B17: Occupancy Date | D17: MM/DD/YY | E17: =E15 -> 45838 | F17: =F15 -> 45930 | G17: =G15 -> 46022 | H17: =H15 -> 46112
D18: (1) "X" if debt is outside of the trust, otherwise leave blank
D19: (2) Total $ amount of Capital Reserves required annually by loan documents
B21: INCOME:
B22: Number of Mos. Covered | G22: 4 | H22: 7
B23: Period Ended | D23: At Contribution | E23: 3rd Preceding | F23: 2nd Preceding | G23: Preceding Yr. | H23: T7 | I23: Lender Calc | K23: Lender Calc Adjustments
B24: Statement Ending Date | D24: Information | E24: ="as of "&TEXT(E15,"MM/DD/YYYY") -> as of 06/30/2025 | F24: ="as of "&TEXT(F15,"MM/DD/YYYY") -> as of 09/30/2025 | G24: ="as of "&TEXT(G15,"MM/DD/YYYY") -> as of 12/31/2025 | H24: ="as of "&TEXT(H15,"MM/DD/YYYY") -> as of 03/31/2026 | I24: =H24 -> as of 03/31/2026
B25: Gross Potential Rent (3) | G25: 796403.76 | H25: ='Actuals (T12)'!E5 -> 771432.31 | I25: ='Lender Calc'!E5 -> 796403.76 | K25: Rent Roll less tenants 60+ days past due, MTM, BK, non-credit tenants "gone dark", credit tenants with < 2 years of remaining lease term that have "gone dark", known vacates. Include tenants taking occupancy within 90 day (180 days for BBB- or higher tenants), include rental value of free rent period of up to 1 month free per lease year,
B26: Less: Vacancy Loss | G26: -39820.188 | H26: ='Actuals (T12)'!E9 -> 0 | I26: ='Lender Calc'!E9 -> -39820.188 | K26: =1-H16 -> 0
B27: OR
B28: Base Rent (3) | G28: 0 | H28: 0 | I28: 0
B29: Expense Reimbursement | G29: 0 | H29: 0 | I29: 0
B30: Percentage Rent | G30: 0 | H30: 0 | I30: 0
B31: Parking Income | G31: 0 | H31: 0 | I31: 0
B32: Other Income | G32: 202044.12 | H32: ='Actuals (T12)'!E12 -> 187397.71 | I32: ='Lender Calc'!E12 -> 187397.71 | K32: =TEXT($H$23,)&TEXT(B32,) -> T7 Other Income
B34: *Effective Gross Income | G34: 958627.69 | H34: =SUM(H25:H32) -> 958830.02 | I34: =SUM(I25:I32) -> 943981.28
D35: (3) Use either Gross Potential (with Vacancy Loss) or Base Rents; use negative $amt for Vacancy Loss
B37: OPERATING EXPENSES:
B38: Real Estate Taxes | G38: 124384.24 | H38: ='Actuals (T12)'!E21 -> 100287.14 | I38: ='Lender Calc'!E18 -> 103093.34 | K38: ="Greater of actual tax bill from "&TEXT('RE Taxes'!$C$2,"MM/DD/YYYY")&"-"&TEXT('RE Taxes'!$D$2,"MM/DD/YYYY")&" ($"&TEXT('RE Taxes'!C3,"0.#")&"MM) and "&$H$23&" ended "&TEXT($H$15,"MM/DD/YYYY") -> Greater of actual tax bill from 03/01/2025-03/01/2026 ($0.1MM) and T7 ended 03/31/2026
B39: Property Insurance | G39: 14802.6 | H39: ='Actuals (T12)'!E23 -> 13287.446 | I39: ='Lender Calc'!E20 -> 13287.446 | K39: ="Greater of actual insurance premium from "&TEXT(Insurance!C2,"MM/DD/YYYY")&"-"&TEXT(Insurance!D2,"MM/DD/YYYY")&" ($"&TEXT(Insurance!C3,"0.##")&"MM) and origination" -> Greater of actual insurance premium from 04/01/2026-04/01/2027 ($0.01MM) and origination
B40: Utilities | G40: 1299.92 | H40: ='Actuals (T12)'!E25 -> 1713.2057 | I40: ='Lender Calc'!E22 -> 1713.2057 | K40: =TEXT($H$23,)&TEXT(B40,) -> T7 Utilities
B41: Repairs and Maintenance | G41: 21693.04 | H41: ='Actuals (T12)'!E28 -> 27018.823 | I41: ='Lender Calc'!E25 -> 27018.823 | K41: =TEXT($H$23,)&TEXT(B41,) -> T7 Repairs and Maintenance
B42: Janitorial | G42: 0 | H42: 0 | I42: 0 | K42: =TEXT($H$23,)&TEXT(B42,) -> T7 Janitorial
B43: Management Fees | G43: 38427 | H43: ='Actuals (T12)'!E31 -> 29701.594 | I43: ='Lender Calc'!E28 -> 29701.594 | K43: Greater of actual fees and 3.0% of EGI
...

Sheet Variance Analysis
B2: Period | C2: 46022 | D2: 46112 | F2: Variance | I2: =IF(MONTH('Comm OSAR'!G15)=12,"4Q",IF(MONTH('Comm OSAR'!G15)=9,"3Q",IF(MONTH('Comm OSAR'!G15)=6,"2Q","1Q")))&" "&YEAR('Comm OSAR'!G15) -> 4Q 2025 | M2: =IF(MONTH('Comm OSAR'!H15)=12,"4Q",IF(MONTH('Comm OSAR'!H15)=9,"3Q",IF(MONTH('Comm OSAR'!H15)=6,"2Q","1Q")))&" "&YEAR('Comm OSAR'!H15) -> 1Q 2026 | Q2: QoQ ∆
B4: INCOME: | I4: Occupancy | J4: NCF | K4: DY | L4: DSCR | M4: Occupancy | N4: NCF | O4: DY | P4: DSCR | Q4: Occupancy | R4: NCF | S4: DY | T4: DSCR
B5: Gross Potential Rent | C5: =INDEX('Lender Calc'!$D$5:$F$45,MATCH('Variance Analysis'!$B5,'Lender Calc'!$C$5:$C$45,0),MATCH('Variance Analysis'!$C$2,'Lender Calc'!$D$2:$F$2,0)) -> 796403.76 | D5: =INDEX('Lender Calc'!$E$5:$E$42,MATCH('Variance Analysis'!$B5,'Lender Calc'!$C$5:$C$42,0),MATCH('Variance Analysis'!$D$2,'Lender Calc'!$E$2:$E$2,0)) -> 796403.76 | F5: =IFERROR(D5-C5,0) -> 0 | G5: =IFERROR(F5/C5,0) -> 0 | I5: ='Comm OSAR'!G16 -> 1 | J5: ='Comm OSAR'!G62 -> 724494.97 | K5: ='Comm OSAR'!G78 -> 0.069602745 | L5: ='Comm OSAR'!G74 -> 1.1005879 | M5: ='Comm OSAR'!H16 -> 1 | N5: ='Comm OSAR'!I62 -> 737825.96 | O5: ='Lender Calc'!E42/'Comm OSAR'!D6 -> 0.071843785 | P5: ='Comm OSAR'!I74 -> 1.1221903 | Q5: =M5-I5 -> 0 | R5: =N5-J5 -> 13330.986 | S5: =(O5-K5)*10000 -> 22.4104 | T5: =P5-L5 -> 0.021602365
B6: Base Rent | C6: =INDEX('Lender Calc'!$E$5:$E$42,MATCH('Variance Analysis'!$B6,'Lender Calc'!$C$5:$C$42,0),MATCH('Variance Analysis'!$C$2,'Lender Calc'!$E$2:$E$2,0)) -> #N/A | D6: =INDEX('Lender Calc'!$E$5:$E$42,MATCH('Variance Analysis'!$B6,'Lender Calc'!$C$5:$C$42,0),MATCH('Variance Analysis'!$D$2,'Lender Calc'!$E$2:$E$2,0)) -> 0 | F6: =IFERROR(D6-C6,0) -> 0 | G6: =IFERROR(F6/C6,0) -> 0
B7: Straight-line Rent | C7: =INDEX('Lender Calc'!$E$5:$E$42,MATCH('Variance Analysis'!$B7,'Lender Calc'!$C$5:$C$42,0),MATCH('Variance Analysis'!$C$2,'Lender Calc'!$E$2:$E$2,0)) -> #N/A | D7: =INDEX('Lender Calc'!$E$5:$E$42,MATCH('Variance Analysis'!$B7,'Lender Calc'!$C$5:$C$42,0),MATCH('Variance Analysis'!$D$2,'Lender Calc'!$E$2:$E$2,0)) -> 0 | F7: =IFERROR(D7-C7,0) -> 0 | G7: =IFERROR(F7/C7,0) -> 0
B8: Other Rent | C8: =INDEX('Lender Calc'!$E$5:$E$42,MATCH('Variance Analysis'!$B8,'Lender Calc'!$C$5:$C$42,0),MATCH('Variance Analysis'!$C$2,'Lender Calc'!$E$2:$E$2,0)) -> #N/A | D8: =INDEX('Lender Calc'!$E$5:$E$42,MATCH('Variance Analysis'!$B8,'Lender Calc'!$C$5:$C$42,0),MATCH('Variance Analysis'!$D$2,'Lender Calc'!$E$2:$E$2,0)) -> 0 | F8: =IFERROR(D8-C8,0) -> 0 | G8: =IFERROR(F8/C8,0) -> 0
B9: Less: Vacancy Loss | C9: =INDEX('Lender Calc'!$D$5:$F$45,MATCH('Variance Analysis'!$B9,'Lender Calc'!$C$5:$C$45,0),MATCH('Variance Analysis'!$C$2,'Lender Calc'!$D$2:$F$2,0)) -> -39820.188 | D9: =INDEX('Lender Calc'!$E$5:$E$42,MATCH('Variance Analysis'!$B9,'Lender Calc'!$C$5:$C$42,0),MATCH('Variance Analysis'!$D$2,'Lender Calc'!$E$2:$E$2,0)) -> -39820.188 | F9: =IFERROR(D9-C9,0) -> 0 | G9: =IFERROR(F9/C9,0) -> 0
B10: Delinquent Rent | C10: =INDEX('Lender Calc'!$D$5:$F$45,MATCH('Variance Analysis'!$B10,'Lender Calc'!$C$5:$C$45,0),MATCH('Variance Analysis'!$C$2,'Lender Calc'!$D$2:$F$2,0)) -> 0 | D10: =INDEX('Lender Calc'!$E$5:$E$42,MATCH('Variance Analysis'!$B10,'Lender Calc'!$C$5:$C$42,0),MATCH('Variance Analysis'!$D$2,'Lender Calc'!$E$2:$E$2,0)) -> 0 | F10: =IFERROR(D10-C10,0) -> 0 | G10: =IFERROR(F10/C10,0) -> 0
B11: Concessions/Bad Debt | C11: =INDEX('Lender Calc'!$D$5:$F$45,MATCH('Variance Analysis'!$B11,'Lender Calc'!$C$5:$C$45,0),MATCH('Variance Analysis'!$C$2,'Lender Calc'!$D$2:$F$2,0)) -> 0 | D11: =INDEX('Lender Calc'!$E$5:$E$42,MATCH('Variance Analysis'!$B11,'Lender Calc'!$C$5:$C$42,0),MATCH('Variance Analysis'!$D$2,'Lender Calc'!$E$2:$E$2,0)) -> 0 | F11: =IFERROR(D11-C11,0) -> 0 | G11: =IFERROR(F11/C11,0) -> 0
B12: Other Income | C12: =INDEX('Lender Calc'!$D$5:$F$45,MATCH('Variance Analysis'!$B12,'Lender Calc'!$C$5:$C$45,0),MATCH('Variance Analysis'!$C$2,'Lender Calc'!$D$2:$F$2,0)) -> 202044.12 | D12: =INDEX('Lender Calc'!$E$5:$E$42,MATCH('Variance Analysis'!$B12,'Lender Calc'!$C$5:$C$42,0),MATCH('Variance Analysis'!$D$2,'Lender Calc'!$E$2:$E$2,0)) -> 187397.71 | F12: =IFERROR(D12-C12,0) -> -14646.411 | G12: =IFERROR(F12/C12,0) -> -0.072491154
B13: Total Recovery Rental Revenue | C13: =INDEX('Lender Calc'!$E$5:$E$42,MATCH('Variance Analysis'!$B13,'Lender Calc'!$C$5:$C$42,0),MATCH('Variance Analysis'!$C$2,'Lender Calc'!$E$2:$E$2,0)) -> #N/A | D13: =INDEX('Lender Calc'!$E$5:$E$42,MATCH('Variance Analysis'!$B13,'Lender Calc'!$C$5:$C$42,0),MATCH('Variance Analysis'!$D$2,'Lender Calc'!$E$2:$E$2,0)) -> 187397.71 | F13: =IFERROR(D13-C13,0) -> 0 | G13: =IFERROR(F13/C13,0) -> 0
B15: *Effective Gross Income | C15: =SUM(C12,C11,C10,C9,C5) -> 958627.69 | D15: =SUM(D12,D11,D10,D9,D5) -> 943981.28 | F15: =IFERROR(D15-C15,0) -> -14646.411 | G15: =IFERROR(F15/C15,0) -> -0.015278519
B17: OPERATING EXPENSES:
B18: Real Estate Taxes | C18: =INDEX('Lender Calc'!$D$5:$F$45,MATCH('Variance Analysis'!$B18,'Lender Calc'!$C$5:$C$45,0),MATCH('Variance Analysis'!$C$2,'Lender Calc'!$D$2:$F$2,0)) -> 124384.24 | D18: =INDEX('Lender Calc'!$E$5:$E$42,MATCH('Variance Analysis'!$B18,'Lender Calc'!$C$5:$C$42,0),MATCH('Variance Analysis'!$D$2,'Lender Calc'!$E$2:$E$2,0)) -> 103093.34 | F18: =IFERROR(D18-C18,0) -> -21290.9 | G18: =IFERROR(F18/C18,0) -> -0.1711704
B19: Total Real Estate Taxes | C19: =INDEX('Lender Calc'!$D$5:$F$45,MATCH('Variance Analysis'!$B19,'Lender Calc'!$C$5:$C$45,0),MATCH('Variance Analysis'!$C$2,'Lender Calc'!$D$2:$F$2,0)) -> 124384.24 | D19: =INDEX('Lender Calc'!$E$5:$E$42,MATCH('Variance Analysis'!$B19,'Lender Calc'!$C$5:$C$42,0),MATCH('Variance Analysis'!$D$2,'Lender Calc'!$E$2:$E$2,0)) -> 103093.34 | F19: =IFERROR(D19-C19,0) -> -21290.9 | G19: =IFERROR(F19/C19,0) -> -0.1711704
B20: Property Insurance | C20: =INDEX('Lender Calc'!$D$5:$F$45,MATCH('Variance Analysis'!$B20,'Lender Calc'!$C$5:$C$45,0),MATCH('Variance Analysis'!$C$2,'Lender Calc'!$D$2:$F$2,0)) -> 14802.6 | D20: =INDEX('Lender Calc'!$E$5:$E$42,MATCH('Variance Analysis'!$B20,'Lender Calc'!$C$5:$C$42,0),MATCH('Variance Analysis'!$D$2,'Lender Calc'!$E$2:$E$2,0)) -> 13287.446 | F20: =IFERROR(D20-C20,0) -> -1515.1543 | G20: =IFERROR(F20/C20,0) -> -0.10235731
B21: Total Property Insurance | C21: =INDEX('Lender Calc'!$D$5:$F$45,MATCH('Variance Analysis'!$B21,'Lender Calc'!$C$5:$C$45,0),MATCH('Variance Analysis'!$C$2,'Lender Calc'!$D$2:$F$2,0)) -> 14802.6 | D21: =INDEX('Lender Calc'!$E$5:$E$42,MATCH('Variance Analysis'!$B21,'Lender Calc'!$C$5:$C$42,0),MATCH('Variance Analysis'!$D$2,'Lender Calc'!$E$2:$E$2,0)) -> 13287.446 | F21: =IFERROR(D21-C21,0) -> -1515.1543 | G21: =IFERROR(F21/C21,0) -> -0.10235731
B22: Utilities | C22: =INDEX('Lender Calc'!$D$5:$F$45,MATCH('Variance Analysis'!$B22,'Lender Calc'!$C$5:$C$45,0),MATCH('Variance Analysis'!$C$2,'Lender Calc'!$D$2:$F$2,0)) -> 1299.92 | D22: =INDEX('Lender Calc'!$E$5:$E$42,MATCH('Variance Analysis'!$B22,'Lender Calc'!$C$5:$C$42,0),MATCH('Variance Analysis'!$D$2,'Lender Calc'!$E$2:$E$2,0)) -> 1713.2057 | F22: =IFERROR(D22-C22,0) -> 413.28571 | G22: =IFERROR(F22/C22,0) -> 0.31793165
B23: Total Utilities | C23: =INDEX('Lender Calc'!$D$5:$F$45,MATCH('Variance Analysis'!$B23,'Lender Calc'!$C$5:$C$45,0),MATCH('Variance Analysis'!$C$2,'Lender Calc'!$D$2:$F$2,0)) -> 1299.92 | D23: =INDEX('Lender Calc'!$E$5:$E$42,MATCH('Variance Analysis'!$B23,'Lender Calc'!$C$5:$C$42,0),MATCH('Variance Analysis'!$D$2,'Lender Calc'!$E$2:$E$2,0)) -> 1713.2057 | F23: =IFERROR(D23-C23,0) -> 413.28571 | G23: =IFERROR(F23/C23,0) -> 0.31793165
B24: NR - Utilities | C24: =INDEX('Lender Calc'!$D$5:$F$45,MATCH('Variance Analysis'!$B24,'Lender Calc'!$C$5:$C$45,0),MATCH('Variance Analysis'!$C$2,'Lender Calc'!$D$2:$F$2,0)) -> 0 | D24: =INDEX('Lender Calc'!$E$5:$E$42,MATCH('Variance Analysis'!$B24,'Lender Calc'!$C$5:$C$42,0),MATCH('Variance Analysis'!$D$2,'Lender Calc'!$E$2:$E$2,0)) -> 0 | F24: =IFERROR(D24-C24,0) -> 0 | G24: =IFERROR(F24/C24,0) -> 0
B25: Repairs and Maintenance | C25: =INDEX('Lender Calc'!$D$5:$F$45,MATCH('Variance Analysis'!$B25,'Lender Calc'!$C$5:$C$45,0),MATCH('Variance Analysis'!$C$2,'Lender Calc'!$D$2:$F$2,0)) -> 21693.04 | D25: =INDEX('Lender Calc'!$E$5:$E$42,MATCH('Variance Analysis'!$B25,'Lender Calc'!$C$5:$C$42,0),MATCH('Variance Analysis'!$D$2,'Lender Calc'!$E$2:$E$2,0)) -> 27018.823 | F25: =IFERROR(D25-C25,0) -> 5325.7829 | G25: =IFERROR(F25/C25,0) -> 0.24550652
B26: Total R&M | C26: =INDEX('Lender Calc'!$D$5:$F$45,MATCH('Variance Analysis'!$B26,'Lender Calc'!$C$5:$C$45,0),MATCH('Variance Analysis'!$C$2,'Lender Calc'!$D$2:$F$2,0)) -> 21693.04 | D26: =INDEX('Lender Calc'!$E$5:$E$42,MATCH('Variance Analysis'!$B26,'Lender Calc'!$C$5:$C$42,0),MATCH('Variance Analysis'!$D$2,'Lender Calc'!$E$2:$E$2,0)) -> 27018.823 | F26: =IFERROR(D26-C26,0) -> 5325.7829 | G26: =IFERROR(F26/C26,0) -> 0.24550652
B27: NR - Other Repairs | C27: =INDEX('Lender Calc'!$D$5:$F$45,MATCH('Variance Analysis'!$B27,'Lender Calc'!$C$5:$C$45,0),MATCH('Variance Analysis'!$C$2,'Lender Calc'!$D$2:$F$2,0)) -> 0 | D27: =INDEX('Lender Calc'!$E$5:$E$42,MATCH('Variance Analysis'!$B27,'Lender Calc'!$C$5:$C$42,0),MATCH('Variance Analysis'!$D$2,'Lender Calc'!$E$2:$E$2,0)) -> 0 | F27: =IFERROR(D27-C27,0) -> 0 | G27: =IFERROR(F27/C27,0) -> 0
B28: 0.03 | C28: =INDEX('Lender Calc'!$D$5:$F$45,MATCH('Variance Analysis'!$B28,'Lender Calc'!$C$5:$C$45,0),MATCH('Variance Analysis'!$C$2,'Lender Calc'!$D$2:$F$2,0)) -> 38427 | D28: =INDEX('Lender Calc'!$E$5:$E$42,MATCH('Variance Analysis'!$B28,'Lender Calc'!$C$5:$C$42,0),MATCH('Variance Analysis'!$D$2,'Lender Calc'!$E$2:$E$2,0)) -> 29701.594 | F28: =IFERROR(D28-C28,0) -> -8725.4057 | G28: =IFERROR(F28/C28,0) -> -0.22706445
B29: Payroll & Benefits | C29: =INDEX('Lender Calc'!$D$5:$F$45,MATCH('Variance Analysis'!$B29,'Lender Calc'!$C$5:$C$45,0),MATCH('Variance Analysis'!$C$2,'Lender Calc'!$D$2:$F$2,0)) -> 0 | D29: =INDEX('Lender Calc'!$E$5:$E$42,MATCH('Variance Analysis'!$B29,'Lender Calc'!$C$5:$C$42,0),MATCH('Variance Analysis'!$D$2,'Lender Calc'!$E$2:$E$2,0)) -> 0 | F29: =IFERROR(D29-C29,0) -> 0 | G29: =IFERROR(F29/C29,0) -> 0
B30: Advertising & Marketing | C30: =INDEX('Lender Calc'!$D$5:$F$45,MATCH('Variance Analysis'!$B30,'Lender Calc'!$C$5:$C$45,0),MATCH('Variance Analysis'!$C$2,'Lender Calc'!$D$2:$F$2,0)) -> 0 | D30: =INDEX('Lender Calc'!$E$5:$E$42,MATCH('Variance Analysis'!$B30,'Lender Calc'!$C$5:$C$42,0),MATCH('Variance Analysis'!$D$2,'Lender Calc'!$E$2:$E$2,0)) -> 0 | F30: =IFERROR(D30-C30,0) -> 0 | G30: =IFERROR(F30/C30,0) -> 0
B31: Professional Fees | C31: =INDEX('Lender Calc'!$D$5:$F$45,MATCH('Variance Analysis'!$B31,'Lender Calc'!$C$5:$C$45,0),MATCH('Variance Analysis'!$C$2,'Lender Calc'!$D$2:$F$2,0)) -> 0 | D31: =INDEX('Lender Calc'!$E$5:$E$42,MATCH('Variance Analysis'!$B31,'Lender Calc'!$C$5:$C$42,0),MATCH('Variance Analysis'!$D$2,'Lender Calc'!$E$2:$E$2,0)) -> 2192.2629 | F31: =IFERROR(D31-C31,0) -> 2192.2629 | G31: =IFERROR(F31/C31,0) -> 0
B32: NR - Consulting Services | C32: =INDEX('Lender Calc'!$D$5:$F$45,MATCH('Variance Analysis'!$B32,'Lender Calc'!$C$5:$C$45,0),MATCH('Variance Analysis'!$C$2,'Lender Calc'!$D$2:$F$2,0)) -> 0 | D32: =INDEX('Lender Calc'!$E$5:$E$42,MATCH('Variance Analysis'!$B32,'Lender Calc'!$C$5:$C$42,0),MATCH('Variance Analysis'!$D$2,'Lender Calc'!$E$2:$E$2,0)) -> 2192.2629 | F32: =IFERROR(D32-C32,0) -> 2192.2629 | G32: =IFERROR(F32/C32,0) -> 0
B33: General and Administrative | C33: =INDEX('Lender Calc'!$D$5:$F$45,MATCH('Variance Analysis'!$B33,'Lender Calc'!$C$5:$C$45,0),MATCH('Variance Analysis'!$C$2,'Lender Calc'!$D$2:$F$2,0)) -> 22092.6 | D33: =INDEX('Lender Calc'!$E$5:$E$42,MATCH('Variance Analysis'!$B33,'Lender Calc'!$C$5:$C$42,0),MATCH('Variance Analysis'!$D$2,'Lender Calc'!$E$2:$E$2,0)) -> 18579.326 | F33: =IFERROR(D33-C33,0) -> -3513.2743 | G33: =IFERROR(F33/C33,0) -> -0.15902494
B34: NR - Bank Fees | C34: =INDEX('Lender Calc'!$D$5:$F$45,MATCH('Variance Analysis'!$B34,'Lender Calc'!$C$5:$C$45,0),MATCH('Variance Analysis'!$C$2,'Lender Calc'!$D$2:$F$2,0)) -> 22092.6 | D34: =INDEX('Lender Calc'!$E$5:$E$42,MATCH('Variance Analysis'!$B34,'Lender Calc'!$C$5:$C$42,0),MATCH('Variance Analysis'!$D$2,'Lender Calc'!$E$2:$E$2,0)) -> 18579.326 | F34: =IFERROR(D34-C34,0) -> -3513.2743 | G34: =IFERROR(F34/C34,0) -> -0.15902494
B35: Other Expenses | C35: =INDEX('Lender Calc'!$D$5:$F$45,MATCH('Variance Analysis'!$B35,'Lender Calc'!$C$5:$C$45,0),MATCH('Variance Analysis'!$C$2,'Lender Calc'!$D$2:$F$2,0)) -> 1437.32 | D35: =INDEX('Lender Calc'!$E$5:$E$42,MATCH('Variance Analysis'!$B35,'Lender Calc'!$C$5:$C$42,0),MATCH('Variance Analysis'!$D$2,'Lender Calc'!$E$2:$E$2,0)) -> 573.32571 | F35: =IFERROR(D35-C35,0) -> -863.99429 | G35: =IFERROR(F35/C35,0) -> -0.60111477
B36: Total Other Recovery Expenses | C36: =INDEX('Lender Calc'!$E$5:$E$42,MATCH('Variance Analysis'!$B36,'Lender Calc'!$C$5:$C$42,0),MATCH('Variance Analysis'!$C$2,'Lender Calc'!$E$2:$E$2,0)) -> #N/A | D36: =INDEX('Lender Calc'!$E$5:$E$42,MATCH('Variance Analysis'!$B36,'Lender Calc'!$C$5:$C$42,0),MATCH('Variance Analysis'!$D$2,'Lender Calc'!$E$2:$E$2,0)) -> 573.32571 | F36: =IFERROR(D36-C36,0) -> 0 | G36: =IFERROR(F36/C36,0) -> 0
B38: *Total Operating Expenses | C38: =SUM(C18,C20,C22,C25,C28,C29,C30,C31,C33,C35) -> 224136.72 | D38: =SUM(D18,D20,D22,D25,D28,D29,D30,D31,D33,D35) -> 196159.32 | F38: =IFERROR(D38-C38,0) -> -27977.397 | G38: =IFERROR(F38/C38,0) -> -0.12482291
B40: Operating Expense Ratio | C40: =C38/C15 -> 0.23380998 | D40: =D38/D15 -> 0.20780001
B42: *Net Operating Income | C42: =C15-C38 -> 734490.97 | D42: =D15-D38 -> 747821.96 | F42: =IFERROR(D42-C42,0) -> 13330.986 | G42: =IFERROR(F42/C42,0) -> 0.018149965

Sheet Historicals>>>

Sheet Actuals (T12)
B2: CODE | C2: Period | D2: 46022 | E2: ='Comm OSAR'!H15 -> 46112
C4: INCOME:
C5: Gross Potential Rent | D5: 985934.36 | E5: =SUM(E6:E8) -> 771432.31
B6: Base Rent | C6: Base Rent | D6: 964533.32 | E6: =IFERROR(INDEX('T12'!$N:$N,MATCH('Actuals (T12)'!$B6,'T12'!$A:$A,0)),0) -> 754687.32
B7: Straight-line Rent | C7: Straight-line Rent | D7: 21401.04 | E7: =IFERROR(INDEX('T12'!$N:$N,MATCH('Actuals (T12)'!$B7,'T12'!$A:$A,0)),0) -> 16744.989
B8: Other Rent | C8: Other Rent | D8: 0 | E8: =IFERROR(INDEX('T12'!$N:$N,MATCH('Actuals (T12)'!$B8,'T12'!$A:$A,0)),0) -> 0
C9: Less: Vacancy Loss | D9: 0 | E9: =IFERROR(INDEX('T12'!$N:$N,MATCH('Actuals (T12)'!$B9,'T12'!$A:$A,0)),0) -> 0
C10: Delinquent Rent | D10: 0 | E10: =IFERROR(INDEX('T12'!$N:$N,MATCH('Actuals (T12)'!$B10,'T12'!$A:$A,0)),0) -> 0
C11: Concessions/Bad Debt | D11: 0 | E11: =IFERROR(INDEX('T12'!$O:$O,MATCH('Actuals (T12)'!$B11,'T12'!$A:$A,0)),0) -> 0
C12: Other Income | D12: 202044.12 | E12: =SUM(E13) -> 187397.71
B13: TOTAL RECOVERY RENTAL REV | C13: Total Recovery Rental Revenue | D13: 202044.12 | E13: =IFERROR(INDEX('T12'!$N:$N,MATCH('Actuals (T12)'!$B13,'T12'!$A:$A,0)),0) -> 187397.71
C15: *Effective Gross Income | D15: 1187978.5 | E15: =SUM(E5,E9,E10,E11,E12) -> 958830.02
C17: Check | D17: 0 | E17: =E15-E18 -> 0
B18: TOTAL REVENUE AND INCOME | D18: 1187978.5 | E18: =IFERROR(INDEX('T12'!$N:$N,MATCH('Actuals (T12)'!$B18,'T12'!$A:$A,0)),0) -> 958830.02
C20: OPERATING EXPENSES:
C21: Real Estate Taxes | D21: 124384.24 | E21: =SUM(E22) -> 100287.14
B22: TOTAL REAL ESTATE TAXES | C22: Total Real Estate Taxes | D22: 124384.24 | E22: =IFERROR(INDEX('T12'!$N:$N,MATCH('Actuals (T12)'!$B22,'T12'!$A:$A,0)),0) -> 100287.14
C23: Property Insurance | D23: 14802.6 | E23: =SUM(E24) -> 13287.446
B24: TOTAL PROPERTY INSURANCE | C24: Total Property Insurance | D24: 14802.6 | E24: =IFERROR(INDEX('T12'!$N:$N,MATCH('Actuals (T12)'!$B24,'T12'!$A:$A,0)),0) -> 13287.446
C25: Utilities | D25: 1299.92 | E25: =SUM(E26:E27) -> 1713.2057
B26: TOTAL UTILITIES | C26: Total Utilities | D26: 1299.92 | E26: =IFERROR(INDEX('T12'!$N:$N,MATCH('Actuals (T12)'!$B26,'T12'!$A:$A,0)),0) -> 1713.2057
B27: NR - Utilities | C27: NR - Utilities | D27: 0 | E27: =IFERROR(INDEX('T12'!$N:$N,MATCH('Actuals (T12)'!$B27,'T12'!$A:$A,0)),0) -> 0
C28: Repairs and Maintenance | D28: 21693.04 | E28: =SUM(E29:E30) -> 27018.823
B29: TOTAL REPAIR & MAINTENANC | C29: Total R&M | D29: 21693.04 | E29: =IFERROR(INDEX('T12'!$N:$N,MATCH('Actuals (T12)'!$B29,'T12'!$A:$A,0)),0) -> 27018.823
B30: NR - Other Repairs | C30: NR - Other Repairs | D30: 0 | E30: =IFERROR(INDEX('T12'!$N:$N,MATCH('Actuals (T12)'!$B30,'T12'!$A:$A,0)),0) -> 0
C31: 0.03 | D31: 38427 | E31: =SUM(E32) -> 29701.594
B32: TOTAL PROPERTY MANAGEMENT FEES | C32: Total Property Management Fees | D32: 38427 | E32: =IFERROR(INDEX('T12'!$N:$N,MATCH('Actuals (T12)'!$B32,'T12'!$A:$A,0)),0) -> 29701.594
C33: Payroll & Benefits | D33: 0 | E33: =IFERROR(INDEX('T12'!$N:$N,MATCH('Actuals (T12)'!$B33,'T12'!$A:$A,0)),0) -> 0
C34: Advertising & Marketing | D34: 0 | E34: =IFERROR(INDEX('T12'!$N:$N,MATCH('Actuals (T12)'!$B34,'T12'!$A:$A,0)),0) -> 0
C35: Professional Fees | D35: 0 | E35: =SUM(E36) -> 2192.2629
B36: NR - Consulting Services | C36: NR - Consulting Services | D36: 0 | E36: =IFERROR(INDEX('T12'!$N:$N,MATCH('Actuals (T12)'!$B36,'T12'!$A:$A,0)),0) -> 2192.2629
C37: General and Administrative | D37: 22092.6 | E37: =SUM(E38) -> 18579.326
B38: NR - Bank Fees | C38: NR - Bank Fees | D38: 22092.6 | E38: =IFERROR(INDEX('T12'!$N:$N,MATCH('Actuals (T12)'!$B38,'T12'!$A:$A,0)),0) -> 18579.326
C39: Other Expenses | D39: 1437.32 | E39: =SUM(E40) -> 573.32571
B40: TOTAL OTHER RECOV | C40: Total Other Recovery Expenses | D40: 1437.32 | E40: =IFERROR(INDEX('T12'!$N:$N,MATCH('Actuals (T12)'!$B40,'T12'!$A:$A,0)),0) -> 573.32571
C42: *Total Operating Expenses | D42: 224136.72 | E42: =SUM(E21,E23,E25,E28,E31,E33,E34,E35,E37,E39) -> 193353.12
C44: Check | D44: 0 | E44: =E42-SUM(E45:E46) -> 0
B45: TOTAL RECOVERABLE EXPENSES | D45: 202044.12 | E45: =IFERROR(INDEX('T12'!$N:$N,MATCH('Actuals (T12)'!$B45,'T12'!$A:$A,0)),0) -> 172581.53
B46: TOTAL NON-RECOVERABLE OPER EXP | D46: 22092.6 | E46: =IFERROR(INDEX('T12'!$N:$N,MATCH('Actuals (T12)'!$B46,'T12'!$A:$A,0)),0) -> 20771.589
C48: Operating Expense Ratio | D48: 0.18867069 | E48: =E42/E15 -> 0.20165526
...

Sheet Lender Calc
B2: CODE | C2: Period | D2: 46022 | E2: ='Comm OSAR'!H15 -> 46112
C4: INCOME:
C5: Gross Potential Rent | D5: 796403.76 | E5: =SUM(RR!J8) -> 796403.76
B6: Base Rent | C6: Base Rent | D6: 0 | E6: 0
B7: Straight-line Rent | C7: Straight-line Rent | D7: 0 | E7: 0
B8: Other Rent | C8: Other Rent | D8: 0 | E8: =IFERROR(INDEX('T12'!$N:$N,MATCH('Lender Calc'!$B8,'T12'!$A:$A,0)),0) -> 0
C9: Less: Vacancy Loss | D9: -39820.188 | E9: =IF('Comm OSAR'!H16<95%,'Actuals (T12)'!E9,-'Lender Calc'!E5*5%) -> -39820.188
C10: Delinquent Rent | D10: 0 | E10: =IFERROR(INDEX('T12'!$N:$N,MATCH('Lender Calc'!$B10,'T12'!$A:$A,0)),0) -> 0
C11: Concessions/Bad Debt | D11: 0 | E11: =IFERROR(INDEX('T12'!$O:$O,MATCH('Lender Calc'!$B11,'T12'!$A:$A,0)),0) -> 0
C12: Other Income | D12: 202044.12 | E12: =SUM(E13) -> 187397.71
B13: TOTAL RECOVERY RENTAL REV | C13: Total Recovery Rental Revenue | D13: 202044.12 | E13: =IFERROR(INDEX('T12'!$N:$N,MATCH('Lender Calc'!$B13,'T12'!$A:$A,0)),0) -> 187397.71
C15: *Effective Gross Income | D15: 958627.69 | E15: =SUM(E5,E9,E10,E11,E12) -> 943981.28
C17: OPERATING EXPENSES:
C18: Real Estate Taxes | D18: 124384.24 | E18: =SUM(E19) -> 103093.34
B19: TOTAL REAL ESTATE TAXES | C19: Total Real Estate Taxes | D19: 124384.24 | E19: =MAX('Actuals (T12)'!E22,'RE Taxes'!T5) -> 103093.34
C20: Property Insurance | D20: 14802.6 | E20: =SUM(E21) -> 13287.446
B21: TOTAL PROPERTY INSURANCE | C21: Total Property Insurance | D21: 14802.6 | E21: =MAX('Actuals (T12)'!E24,Insurance!C3/Insurance!C4) -> 13287.446
C22: Utilities | D22: 1299.92 | E22: =SUM(E23:E24) -> 1713.2057
B23: TOTAL UTILITIES | C23: Total Utilities | D23: 1299.92 | E23: =IFERROR(INDEX('T12'!$N:$N,MATCH('Lender Calc'!$B23,'T12'!$A:$A,0)),0) -> 1713.2057
B24: NR - Utilities | C24: NR - Utilities | D24: 0 | E24: =IFERROR(INDEX('T12'!$N:$N,MATCH('Lender Calc'!$B24,'T12'!$A:$A,0)),0) -> 0
C25: Repairs and Maintenance | D25: 21693.04 | E25: =SUM(E26:E27) -> 27018.823
B26: TOTAL REPAIR & MAINTENANC | C26: Total R&M | D26: 21693.04 | E26: =IFERROR(INDEX('T12'!$N:$N,MATCH('Lender Calc'!$B26,'T12'!$A:$A,0)),0) -> 27018.823
B27: NR - Other Repairs | C27: NR - Other Repairs | D27: 0 | E27: =IFERROR(INDEX('T12'!$N:$N,MATCH('Lender Calc'!$B27,'T12'!$A:$A,0)),0) -> 0
C28: 0.03 | D28: 38427 | E28: =MAX($C$28*E15,'Actuals (T12)'!E31) -> 29701.594
C29: Payroll & Benefits | D29: 0 | E29: =IFERROR(INDEX('T12'!$N:$N,MATCH('Lender Calc'!$B29,'T12'!$A:$A,0)),0) -> 0
C30: Advertising & Marketing | D30: 0 | E30: =IFERROR(INDEX('T12'!$N:$N,MATCH('Lender Calc'!$B30,'T12'!$A:$A,0)),0) -> 0
C31: Professional Fees | D31: 0 | E31: =SUM(E32) -> 2192.2629
B32: NR - Consulting Services | C32: NR - Consulting Services | D32: 0 | E32: =IFERROR(INDEX('T12'!$N:$N,MATCH('Lender Calc'!$B32,'T12'!$A:$A,0)),0) -> 2192.2629
C33: General and Administrative | D33: 22092.6 | E33: =SUM(E34) -> 18579.326
B34: NR - Bank Fees | C34: NR - Bank Fees | D34: 22092.6 | E34: =IFERROR(INDEX('T12'!$N:$N,MATCH('Lender Calc'!$B34,'T12'!$A:$A,0)),0) -> 18579.326
C35: Other Expenses | D35: 1437.32 | E35: =SUM(E36) -> 573.32571
B36: TOTAL OTHER RECOV | C36: Total Other Recovery Expenses | D36: 1437.32 | E36: =IFERROR(INDEX('T12'!$N:$N,MATCH('Lender Calc'!$B36,'T12'!$A:$A,0)),0) -> 573.32571
C38: *Total Operating Expenses | D38: 224136.72 | E38: =SUM(E18,E20,E22,E25,E28,E29,E30,E31,E33,E35) -> 196159.32
C40: Operating Expense Ratio | D40: 0.23380998 | E40: =E38/E15 -> 0.20780001
C42: *Net Operating Income | D42: 734490.97 | E42: =E15-E38 -> 747821.96

Sheet Support>>>

Sheet T12
A1: 601 S. 55th Avenue (v1103001)
A2: Statement (12 months)
A3: Period = Jan 2025-Dec 2025 | M3: Months Available | N3: ='Comm OSAR'!H22 -> 7
A4: Book = Accrual,Depreciation,Straight-Line Rent,Elimination ; Tree = ysi_is
B5: Apr 2025 | C5: May 2025 | D5: Jun 2025 | E5: Jul 2025 | F5: Aug 2025 | G5: Sep 2025 | H5: Oct 2025 | I5: Nov 2025 | J5: Dec 2025 | K5: Jan 2026 | L5: Feb 2026 | M5: Mar 2026 | N5: T12 | O5: T6 | P5: T3
A7: REVENUE & INCOME
A9: RENTAL REVENUE
A10: Base Rent | B10: 0 | C10: 0 | D10: 0 | E10: 0 | F10: 0 | G10: 42032.39 | H10: 66366.98 | I10: 66366.98 | J10: 66366.98 | K10: 66366.98 | L10: 66366.98 | M10: 66366.98 | N10: =IF(SUM(B10:M10)=0,"",SUM(B10:M10))/$N$3*12 -> 754687.32 | O10: =IF(N10="","",SUM(H10:M10)*2) -> 796403.76 | P10: =IF(O10="","",SUM(K10:M10)*4) -> 796403.76
A11: Straight-line Rent | B11: 0 | C11: 0 | D11: 0 | E11: 0 | F11: 0 | G11: 932.61 | H11: 1472.55 | I11: 1472.55 | J11: 1472.55 | K11: 1472.55 | L11: 1472.55 | M11: 1472.55 | N11: =IF(SUM(B11:M11)=0,"",SUM(B11:M11))/$N$3*12 -> 16744.989 | O11: =IF(N11="","",SUM(H11:M11)*2) -> 17670.6 | P11: =IF(O11="","",SUM(K11:M11)*4) -> 17670.6
A12: TOTAL RENTAL REVENUE | B12: 0 | C12: 0 | D12: 0 | E12: 0 | F12: 0 | G12: 42965 | H12: 67839.53 | I12: 67839.53 | J12: 67839.53 | K12: 67839.53 | L12: 67839.53 | M12: 67839.53 | N12: =IF(SUM(B12:M12)=0,"",SUM(B12:M12))/$N$3*12 -> 771432.31 | O12: =IF(N12="","",SUM(H12:M12)*2) -> 814074.36 | P12: =IF(O12="","",SUM(K12:M12)*4) -> 814074.36
N13: =IF(SUM(B13:M13)=0,"",SUM(B13:M13))/$N$3*12 -> #VALUE! | O13: =IF(N13="","",SUM(H13:M13)*2) -> #VALUE! | P13: =IF(O13="","",SUM(K13:M13)*4) -> #VALUE!
A14: RECOVERY RENTAL REVENUE | N14: =IF(SUM(B14:M14)=0,"",SUM(B14:M14))/$N$3*12 -> #VALUE! | O14: =IF(N14="","",SUM(H14:M14)*2) -> #VALUE! | P14: =IF(O14="","",SUM(K14:M14)*4) -> #VALUE!
N15: =IF(SUM(B15:M15)=0,"",SUM(B15:M15))/$N$3*12 -> #VALUE! | O15: =IF(N15="","",SUM(H15:M15)*2) -> #VALUE! | P15: =IF(O15="","",SUM(K15:M15)*4) -> #VALUE!
A16: ESTIMATED RECOV RENT REV | N16: =IF(SUM(B16:M16)=0,"",SUM(B16:M16))/$N$3*12 -> #VALUE! | O16: =IF(N16="","",SUM(H16:M16)*2) -> #VALUE! | P16: =IF(O16="","",SUM(K16:M16)*4) -> #VALUE!
A17: Recov Estimate - Oper Exp | B17: 0 | C17: 0 | D17: 0 | E17: 0 | F17: 0 | G17: 4820.96 | H17: 7612.04 | I17: 7612.04 | J17: 7612.04 | K17: 9191.9 | L17: 9191.9 | M17: 9191.9 | N17: =IF(SUM(B17:M17)=0,"",SUM(B17:M17))/$N$3*12 -> 94684.766 | O17: =IF(N17="","",SUM(H17:M17)*2) -> 100823.64 | P17: =IF(O17="","",SUM(K17:M17)*4) -> 110302.8
A18: Recov Estimate - RE Tax | B18: 0 | C18: 0 | D18: 0 | E18: 0 | F18: 0 | G18: 5687.68 | H18: 8980.54 | I18: 8980.54 | J18: 8980.54 | K18: 9155.75 | L18: 9155.75 | M18: 9155.75 | N18: =IF(SUM(B18:M18)=0,"",SUM(B18:M18))/$N$3*12 -> 103022.66 | O18: =IF(N18="","",SUM(H18:M18)*2) -> 108817.74 | P18: =IF(O18="","",SUM(K18:M18)*4) -> 109869
A19: Recov Estimate - Insuranc | B19: 0 | C19: 0 | D19: 0 | E19: 0 | F19: 0 | G19: 962.81 | H19: 1520.23 | I19: 1520.23 | J19: 1520.23 | K19: 1054.03 | L19: 1054.03 | M19: 1054.03 | N19: =IF(SUM(B19:M19)=0,"",SUM(B19:M19))/$N$3*12 -> 14889.583 | O19: =IF(N19="","",SUM(H19:M19)*2) -> 15445.56 | P19: =IF(O19="","",SUM(K19:M19)*4) -> 12648.36
A20: CAP Recov - Amortized | B20: 0 | C20: 0 | D20: 0 | E20: 0 | F20: 0 | G20: 2315.2 | H20: 3655.58 | I20: 3655.58 | J20: 3655.58 | K20: 0 | L20: 0 | M20: 0 | N20: =IF(SUM(B20:M20)=0,"",SUM(B20:M20))/$N$3*12 -> 22769.04 | O20: =IF(N20="","",SUM(H20:M20)*2) -> 21933.48 | P20: =IF(O20="","",SUM(K20:M20)*4) -> 0
A21: TOTAL EST. RECOV RENT REV | B21: 0 | C21: 0 | D21: 0 | E21: 0 | F21: 0 | G21: 13786.65 | H21: 21768.39 | I21: 21768.39 | J21: 21768.39 | K21: 19401.68 | L21: 19401.68 | M21: 19401.68 | N21: =IF(SUM(B21:M21)=0,"",SUM(B21:M21))/$N$3*12 -> 235366.05 | O21: =IF(N21="","",SUM(H21:M21)*2) -> 247020.42 | P21: =IF(O21="","",SUM(K21:M21)*4) -> 232820.16
N22: =IF(SUM(B22:M22)=0,"",SUM(B22:M22))/$N$3*12 -> #VALUE! | O22: =IF(N22="","",SUM(H22:M22)*2) -> #VALUE! | P22: =IF(O22="","",SUM(K22:M22)*4) -> #VALUE!
A23: RECONCIL RECOV RENT REV | N23: =IF(SUM(B23:M23)=0,"",SUM(B23:M23))/$N$3*12 -> #VALUE! | O23: =IF(N23="","",SUM(H23:M23)*2) -> #VALUE! | P23: =IF(O23="","",SUM(K23:M23)*4) -> #VALUE!
A24: CY Recon - Oper Exp | B24: 0 | C24: 0 | D24: 0 | E24: 0 | F24: 0 | G24: -4543 | H24: -7612.04 | I24: -5788.23 | J24: 6000.51 | K24: -4037.29 | L24: -6760.09 | M24: 1854.47 | N24: =IF(SUM(B24:M24)=0,"",SUM(B24:M24))/$N$3*12 -> -35804.006 | O24: =IF(N24="","",SUM(H24:M24)*2) -> -32685.34 | P24: =IF(O24="","",SUM(K24:M24)*4) -> -35771.64
A25: CY Recon - RE Tax | B25: 0 | C25: 0 | D25: 0 | E25: 0 | F25: 0 | G25: -364.93 | H25: -389.44 | I25: -389.43 | J25: -389.44 | K25: -20.82 | L25: -20.83 | M25: -20.83 | N25: =IF(SUM(B25:M25)=0,"",SUM(B25:M25))/$N$3*12 -> -2735.52 | O25: =IF(N25="","",SUM(H25:M25)*2) -> -2461.58 | P25: =IF(O25="","",SUM(K25:M25)*4) -> -249.92
A26: CY Recon - Insurance | B26: 0 | C26: 0 | D26: 0 | E26: 0 | F26: 0 | G26: -402.2 | H26: -1520.23 | I26: 269.69 | J26: -170.11 | K26: 296.09 | L26: 296.09 | M26: 296.09 | N26: =IF(SUM(B26:M26)=0,"",SUM(B26:M26))/$N$3*12 -> -1602.1371 | O26: =IF(N26="","",SUM(H26:M26)*2) -> -1064.76 | P26: =IF(O26="","",SUM(K26:M26)*4) -> 3553.08
A27: CY Recon - Amortized Capital | B27: 0 | C27: 0 | D27: 0 | E27: 0 | F27: 0 | G27: -2315.2 | H27: -3655.58 | I27: -3655.58 | J27: -3655.58 | K27: 0 | L27: 5810.92 | M27: 2905.46 | N27: =IF(SUM(B27:M27)=0,"",SUM(B27:M27))/$N$3*12 -> -7826.6743 | O27: =IF(N27="","",SUM(H27:M27)*2) -> -4500.72 | P27: =IF(O27="","",SUM(K27:M27)*4) -> 34865.52
A28: TOT CY RECON RECOV REV | B28: 0 | C28: 0 | D28: 0 | E28: 0 | F28: 0 | G28: -7625.33 | H28: -13177.29 | I28: -9563.55 | J28: 1785.38 | K28: -3762.02 | L28: -673.91 | M28: 5035.19 | N28: =IF(SUM(B28:M28)=0,"",SUM(B28:M28))/$N$3*12 -> -47968.337 | O28: =IF(N28="","",SUM(H28:M28)*2) -> -40712.4 | P28: =IF(O28="","",SUM(K28:M28)*4) -> 2397.04
A29: TOTAL RECOVERY RENTAL REV | B29: 0 | C29: 0 | D29: 0 | E29: 0 | F29: 0 | G29: 6161.32 | H29: 8591.1 | I29: 12204.84 | J29: 23553.77 | K29: 15639.66 | L29: 18727.77 | M29: 24436.87 | N29: =IF(SUM(B29:M29)=0,"",SUM(B29:M29))/$N$3*12 -> 187397.71 | O29: =IF(N29="","",SUM(H29:M29)*2) -> 206308.02 | P29: =IF(O29="","",SUM(K29:M29)*4) -> 235217.2
A30: TOTAL REVENUE AND INCOME | B30: 0 | C30: 0 | D30: 0 | E30: 0 | F30: 0 | G30: 49126.32 | H30: 76430.63 | I30: 80044.37 | J30: 91393.3 | K30: 83479.19 | L30: 86567.3 | M30: 92276.4 | N30: =IF(SUM(B30:M30)=0,"",SUM(B30:M30))/$N$3*12 -> 958830.02 | O30: =IF(N30="","",SUM(H30:M30)*2) -> 1020382.4 | P30: =IF(O30="","",SUM(K30:M30)*4) -> 1049291.6
N31: =IF(SUM(B31:M31)=0,"",SUM(B31:M31))/$N$3*12 -> #VALUE! | O31: =IF(N31="","",SUM(H31:M31)*2) -> #VALUE! | P31: =IF(O31="","",SUM(K31:M31)*4) -> #VALUE!
A32: RECOVERABLE EXPENSES | N32: =IF(SUM(B32:M32)=0,"",SUM(B32:M32))/$N$3*12 -> #VALUE! | O32: =IF(N32="","",SUM(H32:M32)*2) -> #VALUE! | P32: =IF(O32="","",SUM(K32:M32)*4) -> #VALUE!
N33: =IF(SUM(B33:M33)=0,"",SUM(B33:M33))/$N$3*12 -> #VALUE! | O33: =IF(N33="","",SUM(H33:M33)*2) -> #VALUE! | P33: =IF(O33="","",SUM(K33:M33)*4) -> #VALUE!
A34: REAL ESTATE TAXES | N34: =IF(SUM(B34:M34)=0,"",SUM(B34:M34))/$N$3*12 -> #VALUE! | O34: =IF(N34="","",SUM(H34:M34)*2) -> #VALUE! | P34: =IF(O34="","",SUM(K34:M34)*4) -> #VALUE!
A35: Property Taxes - Building | B35: 0 | C35: 0 | D35: 0 | E35: 0 | F35: 0 | G35: 5322.75 | H35: 8591.1 | I35: 8591.11 | J35: 8591.1 | K35: 9134.93 | L35: 9134.92 | M35: 9134.92 | N35: =IF(SUM(B35:M35)=0,"",SUM(B35:M35))/$N$3*12 -> 100287.14 | O35: =IF(N35="","",SUM(H35:M35)*2) -> 106356.16 | P35: =IF(O35="","",SUM(K35:M35)*4) -> 109619.08
A36: TOTAL REAL ESTATE TAXES | B36: 0 | C36: 0 | D36: 0 | E36: 0 | F36: 0 | G36: 5322.75 | H36: 8591.1 | I36: 8591.11 | J36: 8591.1 | K36: 9134.93 | L36: 9134.92 | M36: 9134.92 | N36: =IF(SUM(B36:M36)=0,"",SUM(B36:M36))/$N$3*12 -> 100287.14 | O36: =IF(N36="","",SUM(H36:M36)*2) -> 106356.16 | P36: =IF(O36="","",SUM(K36:M36)*4) -> 109619.08
N37: =IF(SUM(B37:M37)=0,"",SUM(B37:M37))/$N$3*12 -> #VALUE! | O37: =IF(N37="","",SUM(H37:M37)*2) -> #VALUE! | P37: =IF(O37="","",SUM(K37:M37)*4) -> #VALUE!
A38: PROPERTY INSURANCE | N38: =IF(SUM(B38:M38)=0,"",SUM(B38:M38))/$N$3*12 -> #VALUE! | O38: =IF(N38="","",SUM(H38:M38)*2) -> #VALUE! | P38: =IF(O38="","",SUM(K38:M38)*4) -> #VALUE!
A39: Building Insurance | B39: 0 | C39: 0 | D39: 0 | E39: 0 | F39: 0 | G39: 504.08 | H39: 0 | I39: 1609.52 | J39: 1225.8 | K39: 1225.8 | L39: 1225.8 | M39: 1225.8 | N39: =IF(SUM(B39:M39)=0,"",SUM(B39:M39))/$N$3*12 -> 12028.8 | O39: =IF(N39="","",SUM(H39:M39)*2) -> 13025.44 | P39: =IF(O39="","",SUM(K39:M39)*4) -> 14709.6
A40: Liability Insurance | B40: 0 | C40: 0 | D40: 0 | E40: 0 | F40: 0 | G40: 45.52 | H40: 0 | I40: 145.34 | J40: 100.14 | K40: 100.14 | L40: 100.14 | M40: 100.14 | N40: =IF(SUM(B40:M40)=0,"",SUM(B40:M40))/$N$3*12 -> 1013.8629 | O40: =IF(N40="","",SUM(H40:M40)*2) -> 1091.8 | P40: =IF(O40="","",SUM(K40:M40)*4) -> 1201.68
A41: Insurance - Other | B41: 0 | C41: 0 | D41: 0 | E41: 0 | F41: 0 | G41: 11.01 | H41: 0 | I41: 35.06 | J41: 24.18 | K41: 24.18 | L41: 24.18 | M41: 24.18 | N41: =IF(SUM(B41:M41)=0,"",SUM(B41:M41))/$N$3*12 -> 244.78286 | O41: =IF(N41="","",SUM(H41:M41)*2) -> 263.56 | P41: =IF(O41="","",SUM(K41:M41)*4) -> 290.16
A42: TOTAL PROPERTY INSURANCE | B42: 0 | C42: 0 | D42: 0 | E42: 0 | F42: 0 | G42: 560.61 | H42: 0 | I42: 1789.92 | J42: 1350.12 | K42: 1350.12 | L42: 1350.12 | M42: 1350.12 | N42: =IF(SUM(B42:M42)=0,"",SUM(B42:M42))/$N$3*12 -> 13287.446 | O42: =IF(N42="","",SUM(H42:M42)*2) -> 14380.8 | P42: =IF(O42="","",SUM(K42:M42)*4) -> 16201.44
...

Sheet RR
B1: As of 3/31/2026
B3: Property | C3: Unit(s) | D3: Lease | E3: Lease From | F3: Lease To | G3: Term | H3: Tenancy | I3: Lease Area | J3: Annual Rent | K3: Annual | L3: Lease Type | M3: LOC Amount/ | N3: Amendment | O3: Status | P3: From | Q3: To | R3: Move In | S3: Move Out | T3: Move Out | U3: Term | V3: Area | W3: Description | X3: Notes | Y3: Rent | Z3: Start Date | AA3: Unit | AB3: Area Label | AC3: Area | AD3: Rent Step | AE3: Monthly | AF3: Rent Step | AG3: Annual | AH3: Management | AI3: Annual Gross | AJ3: Next | AK3: Increase Type | AL3: Increase Value / Percent | AM3: Review Type | AN3: Market Rent | AO3: Who | AP3: Min Increase Type | AQ3: Min Increase Value | AR3: Max Increase Type | AS3: Max Increase Value
H4: Years | K4: Rent/Area | M4: Bank Guarantee | N4: Type | T4: Reason | Y4: Steps | AD4: Monthly | AE4: Rent/Area | AF4: Annual | AG4: Rent/Area | AH4: Fee | AI4: Amount | AJ4: Review Date
AD5: Amount | AE5: Amount | AF5: Amount | AG5: Amount
B8: 601 S. 55th Avenue (v1103001) | C8: 100 | D8: S&M Moving Systems West, Inc. (t0084001) | E8: 44545 | F8: 46568 | G8: 67 | H8: 4.08 | I8: 100000 | J8: 796403.76 | K8: 7.96 | L8: Industrial - Net | M8: 0 | N8: Original Lease | O8: Activated | P8: 44545 | Q8: 46568 | R8: 44545 | U8: 67 | V8: 100000 | W8: Original Lease | Y8: con | Z8: 44743 | AA8: 100 | AB8: Rentable Area | AC8: 100000 | AD8: 0 | AE8: 0 | AF8: 0 | AG8: 0 | AH8: 0 | AI8: 0 | AJ8: 1057624.4 | AK8: 10.57 | AL8: 44743 | AM8: Fixed Amount | AN8: 0 | AQ8: N/A
Y9: rnt | Z9: 45839 | AA9: 100 | AB9: Rentable Area | AC9: 100000 | AD9: 66366.98 | AE9: 0.664 | AF9: 796403.76 | AG9: 7.964 | AH9: 0 | AI9: 796403.76 | AL9: 45839 | AM9: Fixed Amount | AN9: 0 | AQ9: N/A
Y10: rnt | Z10: 46204 | AA10: 100 | AB10: Rentable Area | AC10: 100000 | AD10: 69021.66 | AE10: 0.69 | AF10: 828259.92 | AG10: 8.283 | AH10: 0 | AI10: 828259.92 | AL10: 46204 | AM10: Fixed Amount | AN10: 0 | AQ10: N/A

Sheet Debt Service
B2: Debt Service Calc
B4: UPB | C4: 10409000
B5: NCF | C5: ='Comm OSAR'!I62 -> 737825.96
B6: Whole Loan Spread | C6: 0.0255
B7: Rate Cap | C7: 0.05
B8: SOFR | C8: 0.0368
B9: Interest Rate | C9: =SUM(C6,MIN(C7,C8)) -> 0.0623
B11: Debt Service | C11: =((C6+C8)*C4*(365/360)) -> 657487.38
B12: Capped Debt Service | C12: =(C9)*C4*(365/360) -> 657487.38
B14: DY Event | C14: 0.065
B15: DSCR Event | C15: 1
B17: Capped DSCR | C17: =+C5/C12 -> 1.1221903
B18: DSCR w/o Rate Cap | C18: =+C5/C11 -> 1.1221903
B20: Rate Cap Renewal Calculation
B21: Current Capped DSCR | C21: =C17 -> 1.1221903
B22: Target Capped DSCR | C22: 1.05
B24: Rate Cap
B25: Spread | C25: =C6 -> 0.0255
B26: Effective Capped Interest Rate | C26: =SUM(C24:C25) -> 0.0255
B28: UPB
B29: Debt Service Capped | C29: =(C28*C26)*(365/360) -> 0
B30: Current Net Cash Flow
B32: Resulting Capped DSCR | C32: =C30/C29 -> #DIV/0!

Sheet RE Taxes
B2: Tax Bill From | C2: 45717 | D2: 46082
B3: Tax Amount | C3: =(T5)/C4 -> 0.10309334 | S3: Parcel ID: | T3: 104-20-022
B4: Factor | C4: 1000000 | S4: Link: | T4: https://www.mcassessor.maricopa.gov/
S5: Amt: | T5: =13748.26+89345.08 -> 103093.34

Sheet Insurance
B2: Insurance Policy From | C2: 46113 | D2: 46478
B3: Insurance Amount | C3: =Y41/C4 -> 0.00917582
B4: Factor | C4: 1000000
Y41: 9175.82
