Workbook
Name CMNOTES: #REF!
Name RESULTS: #REF!

Sheet NEW OSAR
B1: CREFC Investor Reporting Package
C2: MULTIFAMILY OPERATING STATEMENT ANALYSIS REPORT (includes Mobile Home Parks, Single Family Rentals, and Co-ops)
C3: as of 3/31/2026
C4: PROPERTY OVERVIEW | H4: Allocated Loan Amount/Percentage
C5: Property ID | E5: 1001-001 | F5: Paid Thru Date | G5: Debt Outside Trust (1) | H5: $ | I5: %
C6: Note A-Scheduled Loan Balance | E6: 52400000 | F6: MM/DD/YY | G6: X or Blank | H6: 0 | I6: 0 | L6: =E7/E12 -> 233971.29
C7: Note B-Scheduled Loan Balance | E7: =E6-3500000 -> 48900000 | F7: MM/DD/YY | G7: X or Blank | H7: 0 | I7: 0
C8: Note C-Scheduled Loan Balance | E8: 0 | F8: MM/DD/YY | G8: X or Blank | H8: 0 | I8: 0
C9: Property Name | E9: Lydian Apartments
C10: Property Type | E10: Multifamily
C11: Property Address, City, State
C12: Current Net Rentable SF/Units/Beds/Rooms | E12: 209 | G12: Use second box to specify sqft.,units…
C13: Year Built/Year Renovated | E13: YYYY | F13: YYYY
C14: Cap Ex Reserve (annually)/per Unit.etc. (2) | E14: 200 | F14: 0 | G14: specify annual/per unit…
C15: Statement Ending Date | E15: Underwriting | F15: 45930 | G15: 46022 | H15: 46112 | I15: =H15 -> 46112
C16: Occupancy Rate (physical) | E16: 0 | F16: 0.92344498 | G16: 0.9138756 | H16: 0.91866029 | I16: =RR!F262 -> 0.91866029 | M16: =I16-H16 -> 0
C17: Occupancy Date | E17: MM/DD/YY | F17: 45930 | G17: 46022 | H17: 46112 | I17: =I15 -> 46112
E18: (1) "X" if debt is outside of the trust, otherwise leave blank
E19: (2) Total $ amount of Capital Reserves required annually by loan documents
C20: INCOME:
C21: Number of Mos. Covered | F21: 12 | G21: 12 | H21: 12 | I21: 12 | J21: (prcdng yr to base) | K21: (prcdng yr to 2nd prcdng)
C22: Period Ended | E22: At Contribution | F22: DY TEST | G22: DY TEST | H22: TTM | I22: DY TEST | J22: YYYY-U/W | K22: YYYY-YYYY
C23: Statement Ending Date | E23: Information | F23: as of 09/30/2025 | G23: as of 12/31/2025 | H23: =I23 -> as of 03/31/2026 | I23: ="as of "&TEXT(I15,"MM/DD/YYYY") -> as of 03/31/2026 | J23: Variance | K23: Variance | L23: Notes
C24: Gross Potential Rent (3) | E24: 4156426 | F24: 4154232 | G24: 4135728 | H24: =INDEX('T12'!$W$13:$W$45,MATCH('NEW OSAR'!C24,'T12'!$V$13:$V$45,0)) -> 3975944.4 | I24: =RR!G259*12 -> 4653828 | J24: =IF(E24=0, " ",(H24-E24)/E24) -> -0.043422306 | K24: =IF(G24=0, " ",(H24-G24)/G24) -> -0.038634939 | L24: Rent Roll as of 3/31/2026 | N24: =I24-G24 -> 518100 | O24: =(I24-G24)/G24 -> 0.1252742
C25: Less: Vacancy Loss | E25: 346369 | F25: 0 | G25: 0 | H25: =INDEX('T12'!$W$13:$W$45,MATCH('NEW OSAR'!C25,'T12'!$V$13:$V$45,0)) -> 0 | I25: =IF(I16>0.95,I24*M25,0) -> 0 | J25: =IF(E25=0, " ",(H25-E25)/E25) -> -1 | K25: =IF(G25=0, " ",(H25-G25)/G25) | L25: ="Greater of actual vacancy ("&TEXT(1-I16,"0.00%")&") and 5.00%" -> Greater of actual vacancy (8.13%) and 5.00% | M25: =5%-(1-I16) -> -0.031339713
C26: OR
C27: Base Rent (3) | H27: =INDEX('T12'!$W$13:$W$45,MATCH('NEW OSAR'!C27,'T12'!$V$13:$V$45,0)) -> 0 | I27: =SUMIF('T12'!A:A,'NEW OSAR'!C27,'T12'!S:S) -> 0 | J27: =IF(E27=0, " ",(H27-E27)/E27) | K27: =IF(G27=0, " ",(H27-G27)/G27) | L27: =IF(G27=0, " ",(J27-G27)/G27)
C28: Laundry/Vending Income | E28: 0 | F28: 0 | H28: =INDEX('T12'!$W$13:$W$45,MATCH('NEW OSAR'!C28,'T12'!$V$13:$V$45,0)) -> 0 | I28: =SUMIF('T12'!A:A,'NEW OSAR'!C28,'T12'!S:S) -> 0 | J28: =IF(E28=0, " ",(H28-E28)/E28) | K28: =IF(G28=0, " ",(H28-G28)/G28) | L28: =IF(G28=0, " ",(J28-G28)/G28)
C29: Parking Income | E29: 0 | F29: 15470.72 | G29: 16313.92 | H29: =INDEX('T12'!$W$13:$W$45,MATCH('NEW OSAR'!C29,'T12'!$V$13:$V$45,0)) -> 19157.7 | I29: =SUMIF('T12'!A:A,'NEW OSAR'!C29,'T12'!S:S) -> 21098.36 | J29: =IF(E29=0, " ",(H29-E29)/E29) | K29: =IF(G29=0, " ",(H29-G29)/G29) -> 0.17431617 | L29: T3M Annualized | N29: =I29-G29 -> 4784.44 | O29: =(I29-G29)/G29 -> 0.29327347
C30: Other Income | E30: 335067 | F30: 323301.52 | G30: 359351.56 | H30: =INDEX('T12'!$W$13:$W$45,MATCH('NEW OSAR'!C30,'T12'!$V$13:$V$45,0)) -> 391050.98 | I30: ='T12'!R42 -> 388447.64 | J30: =IF(E30=0, " ",(H30-E30)/E30) -> 0.16708294 | K30: =IF(G30=0, " ",(H30-G30)/G30) -> 0.088212835 | L30: T3 other income less T3 concessions | N30: =I30-G30 -> 29096.08 | O30: =(I30-G30)/G30 -> 0.080968286
C32: *Effective Gross Income | E32: =SUM(E24:E30) -> 4837862 | F32: 4493004.2 | G32: 4511393.5 | H32: =INDEX('T12'!$W$13:$W$45,MATCH('NEW OSAR'!C32,'T12'!$V$13:$V$45,0)) -> 4386153.1 | I32: =SUM(I24:I30) -> 5063374 | J32: =IF(E32=0, " ",(H32-E32)/E32) -> -0.093369534 | K32: =IF(G32=0, " ",(H32-G32)/G32) -> -0.027760913 | L32: =IF(G32=0, " ",(I32-G32)/G32) -> 0.12235256 | N32: =I32-G32 -> 551980.52 | O32: =(I32-G32)/G32 -> 0.12235256
E33: (3) Use either Gross Potential (with Vacancy Loss) or Base Rents; use negative $amt for Vacancy Loss
C35: OPERATING EXPENSES: | J35: =IF(E35=0, " ",(H35-E35)/E35) | L35: =IF(G35=0, " ",(J35-G35)/G35)
C36: Real Estate Taxes | E36: 351064 | F36: 473998 | G36: 473998 | H36: =INDEX('T12'!$W$13:$W$45,MATCH('NEW OSAR'!C36,'T12'!$V$13:$V$45,0)) -> 516381.63 | I36: =MAX(H36,'Tax Statement'!Y34) -> 516381.63 | J36: =IF(E36=0, " ",(H36-E36)/E36) -> 0.47090454 | K36: =IF(G36=0, " ",(H36-G36)/G36) -> 0.089417318 | L36: Greater of actual tax bill from 3/1/2025-3/1/2026 ($474.0K) and T12 ended 3/31/2026 | N36: =I36-G36 -> 42383.63 | O36: =(I36-G36)/G36 -> 0.089417318
C37: Property Insurance | E37: 51224 | F37: 68100.36 | G37: 67955.4 | H37: =INDEX('T12'!$W$13:$W$45,MATCH('NEW OSAR'!C37,'T12'!$V$13:$V$45,0)) -> 67810.44 | I37: =MAX(H37,Insurance!P20) -> 67810.44 | J37: =IF(E37=0, " ",(H37-E37)/E37) -> 0.32380212 | K37: =IF(G37=0, " ",(H37-G37)/G37) -> -0.0021331638 | L37: Greater of actual insurance premium from 6/28/2025-6/28/2026 ($67.2K) and T12 ended 3/31/2026 | N37: =I37-G37 -> -144.96 | O37: =(I37-G37)/G37 -> -0.0021331638
C38: Utilities | E38: 208625 | F38: 219870.24 | G38: 222876.36 | H38: =INDEX('T12'!$W$13:$W$45,MATCH('NEW OSAR'!C38,'T12'!$V$13:$V$45,0)) -> 232766.67 | I38: =H38 -> 232766.67 | J38: =IF(E38=0, " ",(H38-E38)/E38) -> 0.11571801 | K38: =IF(G38=0, " ",(H38-G38)/G38) -> 0.04437577 | L38: T12 ended 3/31/2026 | N38: =I38-G38 -> 9890.31 | O38: =(I38-G38)/G38 -> 0.04437577
C39: Repairs and Maintenance | E39: 94050 | F39: 167454.19 | G39: 178154.19 | H39: =INDEX('T12'!$W$13:$W$45,MATCH('NEW OSAR'!C39,'T12'!$V$13:$V$45,0)) -> 161952.36 | I39: =H39 -> 161952.36 | J39: =IF(E39=0, " ",(H39-E39)/E39) -> 0.7219815 | K39: =IF(G39=0, " ",(H39-G39)/G39) -> -0.090942739 | L39: T12 ended 3/31/2026 | N39: =I39-G39 -> -16201.83 | O39: =(I39-G39)/G39 -> -0.090942739
C40: Management Fees | E40: 124354 | F40: 134790.13 | G40: 135341.8 | H40: =INDEX('T12'!$W$13:$W$45,MATCH('NEW OSAR'!C40,'T12'!$V$13:$V$45,0)) -> 132211.42 | I40: =MAX(H40,(I32*M40)) -> 151901.22 | J40: =IF(E40=0, " ",(H40-E40)/E40) -> 0.063185905 | K40: =IF(G40=0, " ",(H40-G40)/G40) -> -0.023129471 | L40: Greater of actual fees annualized and 3% of gross revenue | M40: 0.03 | N40: =I40-G40 -> 16559.416 | O40: =(I40-G40)/G40 -> 0.12235256
C41: Payroll & Benefits | E41: 447914 | F41: 335745.19 | G41: 344286.06 | H41: =INDEX('T12'!$W$13:$W$45,MATCH('NEW OSAR'!C41,'T12'!$V$13:$V$45,0)) -> 343527.32 | I41: =H41 -> 343527.32 | J41: =IF(E41=0, " ",(H41-E41)/E41) -> -0.23305072 | K41: =IF(G41=0, " ",(H41-G41)/G41) -> -0.0022038069 | L41: T12 ended 3/31/2026 | N41: =I41-G41 -> -758.74 | O41: =(I41-G41)/G41 -> -0.0022038069
C42: Advertising & Marketing | E42: 102380 | F42: 67982.66 | G42: 67039.78 | H42: =INDEX('T12'!$W$13:$W$45,MATCH('NEW OSAR'!C42,'T12'!$V$13:$V$45,0)) -> 72834.67 | I42: =H42 -> 72834.67 | J42: =IF(E42=0, " ",(H42-E42)/E42) -> -0.28858498 | K42: =IF(G42=0, " ",(H42-G42)/G42) -> 0.086439574 | L42: T12 ended 3/31/2026 | N42: =I42-G42 -> 5794.89 | O42: =(I42-G42)/G42 -> 0.086439574
...

Sheet T12
B1: Lydian Apartments
B2: 12 Month Income Statement
B3: Reporting Book: | C3: CASH
B4: As of Date: | C4: 03/31/2026
B5: Location: | C5: Lydian Apartments
C7: Month Ending | D7: Month Ending | E7: Month Ending | F7: Month Ending | G7: Month Ending | H7: Month Ending | I7: Month Ending | J7: Month Ending | K7: Month Ending | L7: Month Ending | M7: Month Ending | N7: Month Ending | O7: Total
C8: 04/30/2025 | D8: 05/31/2025 | E8: 06/30/2025 | F8: 07/31/2025 | G8: 08/31/2025 | H8: 09/30/2025 | I8: 10/31/2025 | J8: 11/30/2025 | K8: 12/31/2025 | L8: 01/31/2026 | M8: 02/28/2026 | N8: 03/31/2026 | O8: 03/31/2026
C9: Actual | D9: Actual | E9: Actual | F9: Actual | G9: Actual | H9: Actual | I9: Actual | J9: Actual | K9: Actual | L9: Actual | M9: Actual | N9: Actual | O9: Actual
B10: INCOME
B12: RENTAL REVENUE | Q12: Annualized T12 | R12: Annualized T6 | S12: Annualized T3 | V12: 46112
A13: Gross Potential Rent (3) | B13: 4010.000 - Rent | C13: 330533.89 | D13: 333988.81 | E13: 336658.47 | F13: 318379.58 | G13: 319407.19 | H13: 330944.81 | I13: 335956.73 | J13: 323336.98 | K13: 343700 | L13: 343279.25 | M13: 326666.73 | N13: 318552.66 | O13: 3961405.1 | Q13: =IF(SUM(C13:N13)=0,"",SUM(C13:N13)) -> 3961405.1 | R13: =IF(Q13=0,"",SUM(I13:N13)*2) -> 3982984.7 | S13: =IF(Q13=0,"",SUM(L13:N13)*4) -> 3953994.6 | V13: Gross Potential Rent (3) | W13: =SUMIF(A:A,$V13,O:O) -> 3975944.4
A14: Gross Potential Rent (3) | B14: 4011.100 - Month to Month Rent | C14: 1375 | D14: 1600.87 | E14: 1040.25 | F14: 1136.27 | G14: 588.71 | H14: 735.48 | I14: 1443.54 | J14: 1959.67 | K14: 1511.81 | L14: 1457.02 | M14: 865.83 | N14: 824.85 | O14: 14539.3 | Q14: =IF(SUM(C14:N14)=0,"",SUM(C14:N14)) -> 14539.3 | R14: =IF(Q14=0,"",SUM(I14:N14)*2) -> 16125.44 | S14: =IF(Q14=0,"",SUM(L14:N14)*4) -> 12590.8 | V14: Less: Vacancy Loss | W14: =SUMIF(A:A,$V14,O:O) -> 0
B15: NET RENTAL REVENUE | C15: 331908.89 | D15: 335589.68 | E15: 337698.72 | F15: 319515.85 | G15: 319995.9 | H15: 331680.29 | I15: 337400.27 | J15: 325296.65 | K15: 345211.81 | L15: 344736.27 | M15: 327532.56 | N15: 319377.51 | O15: 3975944.4 | Q15: =SUM(Q13:Q14) -> 3975944.4 | R15: =SUM(R13:R14) -> 3999110.1 | S15: =SUM(S13:S14) -> 3966585.4
V16: Base Rent (3) | W16: =SUMIF(A:A,$V16,O:O) -> 0
B17: OTHER TENANT INCOME | V17: Laundry/Vending Income | W17: =SUMIF(A:A,$V17,O:O) -> 0
A18: Other Income | B18: 4100.000 - Late Charges | C18: 1710 | D18: 2070 | E18: 2248 | F18: 2792 | G18: 2579.79 | H18: 4200 | I18: 4273 | J18: 2222 | K18: 3615 | L18: 3405 | M18: 2565 | N18: 2273.92 | O18: 33953.71 | Q18: =IF(SUM(C18:N18)=0,"",SUM(C18:N18)) -> 33953.71 | R18: =IF(Q18=0,"",SUM(I18:N18)*2) -> 36707.84 | S18: =IF(Q18=0,"",SUM(L18:N18)*4) -> 32975.68 | V18: Parking Income | W18: =SUMIF(A:A,$V18,O:O) -> 19157.7
A19: Other Income | B19: 4120.000 - Application Fee Income | C19: 1100 | D19: 1200 | E19: 700 | F19: 300 | G19: 800 | H19: 550 | I19: 200 | J19: 100 | K19: 150 | L19: 0 | M19: 0 | N19: 0 | O19: 5100 | Q19: =IF(SUM(C19:N19)=0,"",SUM(C19:N19)) -> 5100 | R19: =IF(Q19=0,"",SUM(I19:N19)*2) -> 900 | S19: =IF(Q19=0,"",SUM(L19:N19)*4) -> 0 | T19: Recurring | V19: Other Income | W19: =SUMIF(A:A,$V19,O:O) -> 391050.98
A20: Other Income | B20: 4120.100 - Pet Fees | C20: 1499.45 | D20: 660.48 | E20: 630 | F20: 700 | G20: 966.45 | H20: 649.83 | I20: 945 | J20: 1254.16 | K20: 595 | L20: 595 | M20: 667.5 | N20: 1253.71 | O20: 10416.58 | P20: 0 | Q20: =IF(SUM(C20:N20)=0,"",SUM(C20:N20)) -> 10416.58 | R20: =IF(Q20=0,"",SUM(I20:N20)*2) -> 10620.74 | S20: =IF(Q20=0,"",SUM(L20:N20)*4) -> 10064.84 | T20: Recurring
A21: Other Income | B21: 4120.200 - Administrative Fees | C21: 3450 | D21: 4300 | E21: 1900 | F21: 1300 | G21: 3105.75 | H21: 1250 | I21: 400 | J21: 450 | K21: 1000 | L21: 1000 | M21: 6750 | N21: 2000 | O21: 26905.75 | Q21: =IF(SUM(C21:N21)=0,"",SUM(C21:N21)) -> 26905.75 | R21: =IF(Q21=0,"",SUM(I21:N21)*2) -> 23200 | S21: =IF(Q21=0,"",SUM(L21:N21)*4) -> 39000 | T21: Recurring | V21: *Effective Gross Income | W21: =SUM(W13:W19) -> 4386153.1 | Y21: =IF(W21=O37,"YES","NO") -> YES
A22: Other Income | B22: 4124.000 - Lease Termination Fees | C22: 609.19 | D22: 3911.49 | E22: 784.96 | F22: 183.65 | G22: 207.48 | H22: 323.69 | I22: 7049.78 | J22: 1142.75 | K22: 3253.65 | L22: 399.87 | M22: 5438.6 | N22: 4029.2 | O22: 27334.31 | Q22: =IF(SUM(C22:N22)=0,"",SUM(C22:N22)) -> 27334.31 | R22: =IF(Q22=0,"",SUM(I22:N22)*2) -> 42627.7 | S22: =IF(Q22=0,"",SUM(L22:N22)*4) -> 39470.68 | T22: Recurring
A23: Parking Income | B23: 4140.000 - Reserved/ Covered Parking Fees | C23: 2463.74 | D23: -492.84 | E23: 3966.05 | F23: 1298.33 | G23: 1169.35 | H23: 1400 | I23: 1512.42 | J23: 1288.81 | K23: 1277.25 | L23: 1283.01 | M23: 1830.28 | N23: 2161.3 | O23: 19157.7 | Q23: =IF(SUM(C23:N23)=0,"",SUM(C23:N23)) -> 19157.7 | R23: =IF(Q23=0,"",SUM(I23:N23)*2) -> 18706.14 | S23: =IF(Q23=0,"",SUM(L23:N23)*4) -> 21098.36 | T23: Recurring | V23: OPERATING EXPENSES: | W23: =SUMIF(A:A,$V23,O:O) -> 0
A24: Other Income | B24: 4150.000 - Miscellaneous Income | C24: 11321.59 | D24: -7435.76 | E24: 9396.84 | F24: -9196.74 | G24: 1361.5 | H24: 1925.94 | I24: 1307.59 | J24: 1207.6 | K24: 2105.24 | L24: 1255.94 | M24: 1231.29 | N24: 1081.9 | O24: 15562.93 | Q24: =IF(SUM(C24:N24)=0,"",SUM(C24:N24)) -> 15562.93 | R24: =IF(Q24=0,"",SUM(I24:N24)*2) -> 16379.12 | S24: =IF(Q24=0,"",SUM(L24:N24)*4) -> 14276.52 | T24: Recurring | V24: Real Estate Taxes | W24: =SUMIF(A:A,$V24,O:O) -> 516381.63
A25: Other Income | B25: 4150.200 - Renters Insurance Charges | C25: 3013.13 | D25: 2921.4 | E25: 2942.95 | F25: 3058.62 | G25: 3089.03 | H25: 3048.11 | I25: 3202.55 | J25: 2725.55 | K25: 3174.4 | L25: 3073.48 | M25: 3043.72 | N25: 3039.82 | O25: 36332.76 | Q25: =IF(SUM(C25:N25)=0,"",SUM(C25:N25)) -> 36332.76 | R25: =IF(Q25=0,"",SUM(I25:N25)*2) -> 36519.04 | S25: =IF(Q25=0,"",SUM(L25:N25)*4) -> 36628.08 | T25: Recurring | V25: Property Insurance | W25: =SUMIF(A:A,$V25,O:O) -> 67810.44
A26: Other Income | B26: 4150.300 - Transfer Fee | C26: 0 | D26: 0 | E26: 0 | F26: 500 | G26: 0 | H26: 1500 | I26: -750 | J26: 0 | K26: 0 | L26: 250 | M26: 750 | N26: 250 | O26: 2500 | Q26: =IF(SUM(C26:N26)=0,"",SUM(C26:N26)) -> 2500 | R26: =IF(Q26=0,"",SUM(I26:N26)*2) -> 1000 | S26: =IF(Q26=0,"",SUM(L26:N26)*4) -> 5000 | T26: Recurring | V26: Utilities | W26: =SUMIF(A:A,$V26,O:O) -> 232766.67
A27: Other Income | B27: 4150.400 - Keys, Cards and Remotes | C27: 0 | D27: 125 | E27: 0 | F27: 0 | G27: 0 | H27: 0 | I27: 10 | J27: 150 | K27: 100 | L27: 0 | M27: 10 | N27: 0 | O27: 395 | Q27: =IF(SUM(C27:N27)=0,"",SUM(C27:N27)) -> 395 | R27: =IF(Q27=0,"",SUM(I27:N27)*2) -> 540 | S27: =IF(Q27=0,"",SUM(L27:N27)*4) -> 40 | T27: Recurring | V27: Repairs and Maintenance | W27: =SUMIF(A:A,$V27,O:O) -> 161952.36
A28: Other Income | B28: 4150.600 - Technology Fee | C28: 1299.36 | D28: 1591.25 | E28: 1979.16 | F28: 2265.31 | G28: 2555.65 | H28: 2628.34 | I28: 2591.13 | J28: 2601.4 | K28: 2615.35 | L28: 2696.75 | M28: 2814.94 | N28: 2821.22 | O28: 28459.86 | Q28: =IF(SUM(C28:N28)=0,"",SUM(C28:N28)) -> 28459.86 | R28: =IF(Q28=0,"",SUM(I28:N28)*2) -> 32281.58 | S28: =IF(Q28=0,"",SUM(L28:N28)*4) -> 33331.64 | T28: Recurring | V28: Management Fees | W28: =SUMIF(A:A,$V28,O:O) -> 132211.42
A29: Other Income | B29: 4160.000 - Utility Reimb/Water | C29: 4018.59 | D29: 4318.17 | E29: 3434.89 | F29: 3941.22 | G29: 3923.44 | H29: 4778.39 | I29: 4800 | J29: 5250.99 | K29: 5806.61 | L29: 6447.45 | M29: 6500.31 | N29: 5930.67 | O29: 59150.73 | Q29: =IF(SUM(C29:N29)=0,"",SUM(C29:N29)) -> 59150.73 | R29: =IF(Q29=0,"",SUM(I29:N29)*2) -> 69472.06 | S29: =IF(Q29=0,"",SUM(L29:N29)*4) -> 75513.72 | T29: Recurring | V29: Payroll & Benefits | W29: =SUMIF(A:A,$V29,O:O) -> 343527.32
A30: Other Income | B30: 4161.000 - Utility Reimb/Electric | C30: 3427.72 | D30: 3579.72 | E30: 3222.95 | F30: 3109.55 | G30: 3928 | H30: 4494.34 | I30: 4684.53 | J30: 5028.43 | K30: 5711.33 | L30: 5126.14 | M30: 5744.42 | N30: 5252.8 | O30: 53309.93 | Q30: =IF(SUM(C30:N30)=0,"",SUM(C30:N30)) -> 53309.93 | R30: =IF(Q30=0,"",SUM(I30:N30)*2) -> 63095.3 | S30: =IF(Q30=0,"",SUM(L30:N30)*4) -> 64493.44 | T30: Recurring | V30: Advertising & Marketing | W30: =SUMIF(A:A,$V30,O:O) -> 72834.67
A31: Other Income | B31: 4162.000 - Utility Reimb/Trash | C31: 1469.34 | D31: 1438.69 | E31: 1484.26 | F31: 1463.75 | G31: 1477.7 | H31: 1459.44 | I31: 1533.93 | J31: 1477.41 | K31: 1521.3 | L31: 1526.97 | M31: 1493.55 | N31: 1459.1 | O31: 17805.44 | Q31: =IF(SUM(C31:N31)=0,"",SUM(C31:N31)) -> 17805.44 | R31: =IF(Q31=0,"",SUM(I31:N31)*2) -> 18024.52 | S31: =IF(Q31=0,"",SUM(L31:N31)*4) -> 17918.48 | T31: Recurring | V31: Professional Fees | W31: =SUMIF(A:A,$V31,O:O) -> 0
A32: Other Income | B32: 4163.000 - Utility Reimb/Pest Control | C32: 552.4 | D32: 539.51 | E32: 556.6 | F32: 548.9 | G32: 554.13 | H32: 547.29 | I32: 575.24 | J32: 554.03 | K32: 570.5 | L32: 572.63 | M32: 560.06 | N32: 547.16 | O32: 6678.45 | Q32: =IF(SUM(C32:N32)=0,"",SUM(C32:N32)) -> 6678.45 | R32: =IF(Q32=0,"",SUM(I32:N32)*2) -> 6759.24 | S32: =IF(Q32=0,"",SUM(L32:N32)*4) -> 6719.4 | T32: Recurring | V32: General and Administrative | W32: =SUMIF(A:A,$V32,O:O) -> 136342.22
A33: Other Income | B33: 4164.000 - Utility/Gas | C33: 920.67 | D33: 899.19 | E33: 927.66 | F33: 909.85 | G33: 928.56 | H33: 912.14 | I33: 958.71 | J33: 923.38 | K33: 950.81 | L33: 954.37 | M33: 933.49 | N33: 911.93 | O33: 11130.76 | Q33: =IF(SUM(C33:N33)=0,"",SUM(C33:N33)) -> 11130.76 | R33: =IF(Q33=0,"",SUM(I33:N33)*2) -> 11265.38 | S33: =IF(Q33=0,"",SUM(L33:N33)*4) -> 11199.16 | T33: Recurring | V33: Other Expenses | W33: =SUMIF(A:A,$V33,O:O) -> 0
A34: Other Income | B34: 4165.000 - Valet Trash | C34: 4591.63 | D34: 4495.94 | E34: 4613.34 | F34: 4552.21 | G34: 4639.77 | H34: 4560.79 | I34: 4793.55 | J34: 4616.91 | K34: 4754.06 | L34: 4771.78 | M34: 4667.36 | N34: 4559.66 | O34: 55617 | Q34: =IF(SUM(C34:N34)=0,"",SUM(C34:N34)) -> 55617 | R34: =IF(Q34=0,"",SUM(I34:N34)*2) -> 56326.64 | S34: =IF(Q34=0,"",SUM(L34:N34)*4) -> 55995.2 | T34: Recurring | V34: Ground Rent | W34: =SUMIF(A:A,$V34,O:O) -> 0
A35: Other Income | B35: 4170.000 - Security Deposit Forfeiture | C35: 5.97 | D35: 0 | E35: 0.75 | F35: 0 | G35: 0 | H35: 491.05 | I35: -200 | J35: 0 | K35: 0 | L35: 0 | M35: 100 | N35: 0 | O35: 397.77 | Q35: =IF(SUM(C35:N35)=0,"",SUM(C35:N35)) -> 397.77 | R35: =IF(Q35=0,"",SUM(I35:N35)*2) -> -200 | S35: =IF(Q35=0,"",SUM(L35:N35)*4) -> 400 | T35: Recurring | V35: *Total Operating Expenses | W35: =SUM(W24:W34) -> 1663826.7 | Y35: =IF(W35=O121,"YES","NO") -> YES
B36: TOTAL OTHER TENANT INCOME | C36: 41452.78 | D36: 24122.24 | E36: 38788.41 | F36: 17726.65 | G36: 31286.6 | H36: 34719.35 | I36: 37887.43 | J36: 30993.42 | K36: 37200.5 | L36: 33358.39 | M36: 45100.52 | N36: 37572.39 | O36: 410208.68 | Q36: =SUM(Q18:Q35) -> 410208.68 | R36: =SUM(R18:R35) -> 444225.3 | S36: =SUM(S18:S35) -> 464125.2 | T36: Recurring
B37: TOTAL INCOME | C37: 373361.67 | D37: 359711.92 | E37: 376487.13 | F37: 337242.5 | G37: 351282.5 | H37: 366399.64 | I37: 375287.7 | J37: 356290.07 | K37: 382412.31 | L37: 378094.66 | M37: 372633.08 | N37: 356949.9 | O37: 4386153.1 | Q37: =Q36+Q15 -> 4386153.1 | R37: =R36+R15 -> 4443335.4 | S37: =S36+S15 -> 4430710.6 | V37: Operating Expense Ratio | W37: =W35/W21 -> 0.37933622
Q39: Other Income | R39: =S14+S36-S23 -> 455617.64 | V39: *Net Operating Income | W39: =W21-W35 -> 2722326.4 | Y39: =IF(W39=O123,"YES","NO") -> YES
B40: EXPENSES | Q40: Concessions | R40: =RR!AO11 -> -67170
Q41: AR | V41: Capital Expenditures | W41: =SUMIF(A:A,$V41,O:O) -> 0
B42: UTILITIES | Q42: Total | R42: =SUM(R39:R40) -> 388447.64 | V42: Extraordinary Capital Expenditures | W42: =SUMIF(A:A,$V42,O:O) -> 0
B43: 6010.000 - Utilities - Electric / Vacant | C43: 996.61 | D43: 613.95 | E43: 1396.69 | F43: 1451.57 | G43: 1423.5 | H43: 1670.22 | I43: 684.36 | J43: 1788.88 | K43: 1478.67 | L43: -471.26 | M43: 527.01 | N43: 1687.45 | O43: 13247.65 | V43: Total Capital Items | W43: =SUM(W41:W42) -> 0
...

Sheet RR
A1: Knightvest Management LLC - Lydian
A2: RENT ROLL DETAIL
A3: 03/31/2026 05:06 PM
A4: As of Date: 03/31/2026
A5: Parameters: Properties: - all subproperties-; Show All Unit Designations or Filter by: ALL; Subjournals: ALL; Sort by: Unit; Report Type: Details + Summary; Exclude Formers?: Yes; Show Unit Rent as: Market Rent; Hide all PII Data?: No
A6: Resh ID | B6: Lease ID | C6: Unit | D6: Floorplan | E6: Unit Designation | F6: SQFT | G6: Unit/Lease Status | H6: Name | I6: Move-In | J6: Move-Out | K6: Lease Start | L6: Lease End | M6: Market Rent | N6: Sub Journal | O6: Required Deposit | P6: Dep On Hand | Q6: Balance | R6: Lease Rent | S6: RENT | T6: VALETTRASH | U6: TRASHREIMB | V6: GASREIMB | W6: UTILITY | X6: PESTREIMNB | Y6: RENTERSINS | Z6: SMARTHOME | AA6: PARKING | AB6: PETRENT | AC6: SHRTTERM | AD6: EMPLCRED | AE6: CONC/SPECL | AF6: CARPORT | AG6: MTOM | AH6: GARAGE | AI6: CORPEMPLCRED | AJ6: Total Billing | AN6: Concessions | AS6: Investment Year | AT6: 3 | AU6: 4 | AW6: Investment Year | AX6: 3 | AY6: 4
A7: 40704 | B7: 41133 | C7: 1101 | D7: B1T | E7: N/A | F7: 1080 | G7: Occupied | H7: Gervais, Kenneth | I7: 10/28/2024 | K7: 10/28/2025 | L7: 10/27/2026 | M7: 1940 | N7: RESIDENT | O7: 0 | P7: 0 | Q7: 0 | R7: 2085 | S7: 2085 | T7: 25 | U7: 8 | V7: 5 | W7: 5 | X7: 3 | Y7: 18 | Z7: 25 | AA7: 0 | AB7: 0 | AC7: 0 | AD7: 0 | AE7: 0 | AF7: 0 | AG7: 0 | AH7: 0 | AI7: 0 | AJ7: 2174 | AN7: Jan | AO7: -1000 | AS7: Year Ending | AT7: 45747 | AU7: 46112 | AW7: Year Ending | AX7: 45747 | AY7: 46112 | BB7: 2 | BC7: 3 | BD7: 4 | BE7: 5 | BF7: 6 | BG7: 7 | BH7: 8 | BI7: 9 | BJ7: 10
A8: 40418 | B8: 41220 | C8: 1102 | D8: A2T | E8: N/A | F8: 690 | G8: Occupied | H8: Cornelius, Erica | I8: 03/28/2023 | K8: 03/25/2026 | L8: 03/24/2027 | M8: 1515 | N8: RESIDENT | O8: 0 | P8: 0 | Q8: -25 | R8: 1683 | S8: 1683 | T8: 25 | U8: 8 | V8: 5 | W8: 5 | X8: 3 | Y8: 18 | Z8: 25 | AA8: 0 | AB8: 0 | AC8: 0 | AD8: 0 | AE8: 0 | AF8: 0 | AG8: 0 | AH8: 0 | AI8: 0 | AJ8: 1772 | AN8: Feb | AO8: -5460 | AS8: Annual Base Rent | AT8: 5084648.4 | AU8: 5221028.7 | AW8: Annual OpEx | AX8: 1653335.1 | AY8: 1714345.3 | BB8: 45382 | BC8: 45747 | BD8: 46112 | BE8: 46477 | BF8: 46843 | BG8: 47208 | BH8: 47573 | BI8: 47938 | BJ8: 48304
A9: 40756 | B9: 41142 | C9: 1103 | D9: A2T | E9: N/A | F9: 690 | G9: Occupied | H9: Ortiz Alvarez, Fabian | I9: 11/30/2024 | K9: 11/29/2025 | L9: 05/28/2026 | M9: 1515 | N9: RESIDENT | O9: 0 | P9: 0 | Q9: 0 | R9: 1612 | S9: 1612 | T9: 25 | U9: 8 | V9: 5 | W9: 5 | X9: 3 | Y9: 18 | Z9: 0 | AA9: 0 | AB9: 0 | AC9: 75 | AD9: 0 | AE9: 0 | AF9: 0 | AG9: 0 | AH9: 0 | AI9: 0 | AJ9: 1751 | AN9: March | AO9: -10332.5 | AS9: Monthly Base Rent | AT9: =AT8/12 -> 423720.7 | AU9: =AU8/12 -> 435085.72 | AW9: Multiplier | AX9: =+AT12 -> 0.25 | AY9: =+AU12 -> 0.75
A10: 40857 | B10: 41030 | C10: 1104 | D10: A2T | E10: N/A | F10: 690 | G10: Occupied | H10: Ismond, Diane | I10: 06/10/2025 | K10: 06/10/2025 | L10: 09/09/2026 | M10: 1515 | N10: RESIDENT | O10: 0 | P10: 0 | Q10: -318.7 | R10: 1565 | S10: 1565 | T10: 25 | U10: 8 | V10: 5 | W10: 5 | X10: 3 | Y10: 18 | Z10: 25 | AA10: 0 | AB10: 0 | AC10: 0 | AD10: 0 | AE10: 0 | AF10: 0 | AG10: 0 | AH10: 0 | AI10: 0 | AJ10: 1654 | AN10: Quarterly | AO10: =SUM(AO7:AO9) -> -16792.5 | AS10: % Occ. | AT10: 1 | AU10: 1 | AW10: UW OpEx | AY10: =SUMPRODUCT(AX8:AY8,AX9:AY9) -> 1699092.7 | BA10: INCOME
A11: 40615 | B11: 40971 | C11: 1105 | D11: B1T | E11: N/A | F11: 1080 | G11: Occupied | H11: Harvey, Chauncey | I11: 04/11/2024 | K11: 05/10/2025 | L11: 05/08/2026 | M11: 1940 | N11: RESIDENT | O11: 0 | P11: 0 | Q11: -2305.39 | R11: 2100 | S11: 2100 | T11: 25 | U11: 8 | V11: 5 | W11: 5 | X11: 3 | Y11: 18 | Z11: 25 | AA11: 0 | AB11: 0 | AC11: 0 | AD11: 0 | AE11: 0 | AF11: 0 | AG11: 0 | AH11: 0 | AI11: 0 | AJ11: 2189 | AN11: Yearly | AO11: =+AO10*4 -> -67170 | AS11: Rent/Occ. Unit | AT11: =AT9/(209*AT10) -> 2027.3718 | AU11: =AU9/(209*AU10) -> 2081.7499 | AW11: Actual OpEx | AY11: =#REF! -> #REF! | BA11: Potential Rental Revenue | BB11: 5003799.2 | BC11: 5149491.3 | BD11: 5279975.4 | BE11: 5409303.2 | BF11: 5558631.9 | BG11: 5725390.8 | BH11: 5897152.5 | BI11: 6074067.1 | BJ11: 6256289.1
A12: 40525 | B12: 41101 | C12: 1106 | D12: A1T | E12: N/A | F12: 630 | G12: Occupied | H12: Anthony, Jacques | I12: 10/28/2023 | K12: 10/28/2025 | L12: 10/27/2026 | M12: 1485 | N12: RESIDENT | O12: 0 | P12: 0 | Q12: 0 | R12: 1650 | S12: 1650 | T12: 25 | U12: 8 | V12: 5 | W12: 5 | X12: 3 | Y12: 18 | Z12: 0 | AA12: 0 | AB12: 0 | AC12: 0 | AD12: 0 | AE12: 0 | AF12: 0 | AG12: 0 | AH12: 0 | AI12: 0 | AJ12: 1714 | AS12: Multiplier | AT12: 0.25 | AU12: 0.75 | AW12: Variance % | AY12: =(AY11/AY10)-1 -> #REF! | BA12: Loss To Lease | BB12: -89597.677 | BC12: -64842.873 | BD12: -58946.768 | BE12: -59824.745 | BF12: -71297.891 | BG12: -76873.487 | BH12: -79179.692 | BI12: -81555.082 | BJ12: -84001.735
A13: 0 | B13: 0 | C13: 1108 | D13: B1T | E13: N/A | F13: 1080 | G13: Vacant-Leased | H13: VACANT | M13: 1940 | O13: 0 | P13: 0 | Q13: 0 | R13: 0 | S13: 0 | T13: 0 | U13: 0 | V13: 0 | W13: 0 | X13: 0 | Y13: 0 | Z13: 0 | AA13: 0 | AB13: 0 | AC13: 0 | AD13: 0 | AE13: 0 | AF13: 0 | AG13: 0 | AH13: 0 | AI13: 0 | AJ13: 0 | AS13: Average UW Rent | AU13: =SUMPRODUCT(AT12:AU12,AT11:AU11) -> 2068.1553 | BA13: Scheduled Base Rental Revenue | BB13: 4914201.6 | BC13: 5084648.4 | BD13: 5221028.7 | BE13: 5349478.5 | BF13: 5487334 | BG13: 5648517.3 | BH13: 5817972.9 | BI13: 5992512 | BJ13: 6172287.4
A14: 40950 | B14: 41196 | C14: 1108 | D14: B1T | E14: N/A | F14: 1080 | G14: Applicant | H14: Gray, Reece | I14: 04/15/2026 | K14: 04/15/2026 | L14: 04/14/2027 | M14: 0 | N14: RESIDENT | O14: 0 | P14: 0 | Q14: 0 | R14: 1940 | S14: 1940 | T14: 25 | U14: 8 | V14: 5 | W14: 5 | X14: 3 | Y14: 18 | Z14: 25 | AA14: 0 | AB14: 0 | AC14: 0 | AD14: 0 | AE14: 0 | AF14: 0 | AG14: 0 | AH14: 0 | AI14: 0 | AJ14: 2029 | AS14: In-Place Rent | AU14: =AVERAGEIF(T7:T215,">0") -> 25 | AV14: =(AU14/AU13)-1 -> -0.98791193 | BA14: Other Income | BB14: 388846.63 | BC14: 400512.03 | BD14: 412527.39 | BE14: 424903.21 | BF14: 437650.31 | BG14: 450779.82 | BH14: 464303.21 | BI14: 478232.31 | BJ14: 492579.28
A15: 40607 | B15: 41057 | C15: 1109 | D15: A1T | E15: N/A | F15: 630 | G15: Occupied | H15: Whiteman, Elizabeth | I15: 03/08/2024 | K15: 05/16/2025 | L15: 05/22/2026 | M15: 1485 | N15: RESIDENT | O15: 0 | P15: 0 | Q15: -1785.76 | R15: 1625 | S15: 1625 | T15: 25 | U15: 8 | V15: 5 | W15: 5 | X15: 3 | Y15: 18 | Z15: 25 | AA15: 0 | AB15: 0 | AC15: 0 | AD15: 0 | AE15: 0 | AF15: 0 | AG15: 0 | AH15: 0 | AI15: 0 | AJ15: 1714 | AS15: Market Rent | AU15: =AVERAGEIF(P7:P215,">0") -> #DIV/0! | AV15: =(AU14/AU15)-1 -> #DIV/0! | BA15: Potential Gross Income | BB15: 5303048.2 | BC15: 5485160.5 | BD15: 5633556 | BE15: 5774381.7 | BF15: 5924984.3 | BG15: 6099297.1 | BH15: 6282276.1 | BI15: 6470744.3 | BJ15: 6664866.7
A16: 40607 | B16: 41244 | C16: 1109 | D16: A1T | E16: N/A | F16: 630 | G16: Pending renewal | H16: Whiteman, Elizabeth | I16: 03/08/2024 | K16: 05/23/2026 | L16: 05/21/2027 | M16: 0 | N16: RESIDENT | O16: 0 | P16: 0 | Q16: 0 | R16: 1674 | S16: 1674 | T16: 25 | U16: 8 | V16: 5 | W16: 5 | X16: 3 | Y16: 18 | Z16: 25 | AA16: 0 | AB16: 0 | AC16: 0 | AD16: 0 | AE16: 0 | AF16: 0 | AG16: 0 | AH16: 0 | AI16: 0 | AJ16: 1763 | BA16: Minus: Vacancy | BB16: -245710.08 | BC16: -254232.42 | BD16: -261051.43 | BE16: -267473.92 | BF16: -274366.7 | BG16: -282425.87 | BH16: -290898.64 | BI16: -299625.6 | BJ16: -308614.37
A17: 40959 | B17: 41212 | C17: 1110 | D17: A2T | E17: N/A | F17: 690 | G17: Occupied | H17: Dennis, Ezzerianna | I17: 03/06/2026 | K17: 03/06/2026 | L17: 03/05/2027 | M17: 1515 | N17: RESIDENT | O17: 0 | P17: 0 | Q17: -4.7 | R17: 1515 | S17: 1515 | T17: 25 | U17: 8 | V17: 5 | W17: 5 | X17: 3 | Y17: 18 | Z17: 25 | AA17: 0 | AB17: 0 | AC17: 0 | AD17: 0 | AE17: 0 | AF17: 0 | AG17: 0 | AH17: 0 | AI17: 0 | AJ17: 1604 | BA17: Minus: Credit Loss | BB17: -24571.008 | BC17: -25423.242 | BD17: -26105.143 | BE17: -26747.392 | BF17: -27436.67 | BG17: -28242.587 | BH17: -29089.864 | BI17: -29962.56 | BJ17: -30861.437
A18: 40918 | B18: 41134 | C18: 1111 | D18: A1T | E18: N/A | F18: 630 | G18: Occupied | H18: Trinh, Sarah | I18: 11/01/2025 | K18: 11/01/2025 | L18: 11/02/2026 | M18: 1485 | N18: RESIDENT | O18: 0 | P18: 0 | Q18: 0 | R18: 1485 | S18: 1485 | T18: 25 | U18: 8 | V18: 5 | W18: 5 | X18: 3 | Y18: 18 | Z18: 0 | AA18: 0 | AB18: 0 | AC18: 0 | AD18: 0 | AE18: 0 | AF18: 0 | AG18: 0 | AH18: 0 | AI18: 0 | AJ18: 1549 | BA18: Minus: Model Unit | BB18: 0 | BC18: 0 | BD18: 0 | BE18: 0 | BF18: 0 | BG18: 0 | BH18: 0 | BI18: 0 | BJ18: 0
A19: 40760 | B19: 41158 | C19: 1112 | D19: A3T | E19: N/A | F19: 750 | G19: Occupied | H19: Alanis, Victor | I19: 02/01/2025 | K19: 01/31/2026 | L19: 04/29/2027 | M19: 1610 | N19: RESIDENT | O19: 0 | P19: 0 | Q19: 0 | R19: 1665 | S19: 1665 | T19: 25 | U19: 8 | V19: 5 | W19: 5 | X19: 3 | Y19: 18 | Z19: 0 | AA19: 50 | AB19: 35 | AC19: 0 | AD19: 0 | AE19: 0 | AF19: 0 | AG19: 0 | AH19: 0 | AI19: 0 | AJ19: 1814 | BA19: Minus: Concessions Initial Lease Up | BB19: 0 | BC19: 0 | BD19: 0 | BE19: 0 | BF19: 0 | BG19: 0 | BH19: 0 | BI19: 0 | BJ19: 0
A20: 40897 | B20: 41097 | C20: 1113 | D20: A1T | E20: N/A | F20: 630 | G20: Occupied | H20: Voss, Neil | I20: 09/02/2025 | K20: 09/02/2025 | L20: 11/02/2026 | M20: 1485 | N20: RESIDENT | O20: 0 | P20: 0 | Q20: 0 | R20: 1515 | S20: 1515 | T20: 25 | U20: 8 | V20: 5 | W20: 5 | X20: 3 | Y20: 18 | Z20: 25 | AA20: 0 | AB20: 0 | AC20: 0 | AD20: 0 | AE20: 0 | AF20: 0 | AG20: 0 | AH20: 0 | AI20: 0 | AJ20: 1604 | AS20: Emp Credit | BA20: Minus: Concessions Ongoing | BB20: -207889.1 | BC20: -53510.637 | BD20: -54879.073 | BE20: -56220.361 | BF20: -57745.273 | BG20: -59477.631 | BH20: -61261.96 | BI20: -63099.819 | BJ20: -64992.813
A21: 40905 | B21: 41110 | C21: 1114 | D21: A5 | E21: N/A | F21: 780 | G21: Occupied | H21: Stuart, Breyana | I21: 10/06/2025 | K21: 10/06/2025 | L21: 11/05/2026 | M21: 1695 | N21: RESIDENT | O21: 0 | P21: 0 | Q21: 0 | R21: 1695 | S21: 1695 | T21: 25 | U21: 8 | V21: 5 | W21: 5 | X21: 3 | Y21: 18 | Z21: 0 | AA21: 0 | AB21: 0 | AC21: 0 | AD21: 0 | AE21: 0 | AF21: 0 | AG21: 0 | AH21: 0 | AI21: 0 | AJ21: 1759 | AS21: Concessions | BA21: Effective Gross Income | BB21: 4824878 | BC21: 5151994.2 | BD21: 5291520.4 | BE21: 5423940 | BF21: 5565435.6 | BG21: 5729151.1 | BH21: 5901025.6 | BI21: 6078056.4 | BJ21: 6260398.1
A22: 40919 | B22: 41135 | C22: 1115 | D22: E1T | E22: N/A | F22: 540 | G22: Occupied | H22: Toscano, Ariana | I22: 11/14/2025 | K22: 11/14/2025 | L22: 04/01/2026 | M22: 1365 | N22: RESIDENT | O22: 0 | P22: 0 | Q22: 0 | R22: 1365 | S22: 1365 | T22: 25 | U22: 8 | V22: 5 | W22: 5 | X22: 3 | Y22: 18 | Z22: 0 | AA22: 0 | AB22: 0 | AC22: 200 | AD22: 0 | AE22: 0 | AF22: 0 | AG22: 0 | AH22: 0 | AI22: 0 | AJ22: 1629 | AS22: Oct | AT22: 0
A23: 40743 | B23: 41129 | C23: 1116 | D23: B1T | E23: N/A | F23: 1080 | G23: Occupied | H23: mwansa, bwalya | I23: 11/29/2024 | K23: 11/29/2025 | L23: 11/27/2026 | M23: 1940 | N23: RESIDENT | O23: 0 | P23: 0 | Q23: 0 | R23: 2148 | S23: 2148 | T23: 25 | U23: 8 | V23: 5 | W23: 5 | X23: 3 | Y23: 18 | Z23: 0 | AA23: 0 | AB23: 0 | AC23: 0 | AD23: 0 | AE23: 0 | AF23: 0 | AG23: 0 | AH23: 0 | AI23: 0 | AJ23: 2212 | AS23: Nov | AT23: -14200 | BA23: OPERATING EXPENSES
A24: 40964 | B24: 41218 | C24: 1117 | D24: A1T | E24: N/A | F24: 630 | G24: Occupied | H24: Brustad, Grace | I24: 03/10/2026 | K24: 03/10/2026 | L24: 03/08/2027 | M24: 1485 | N24: RESIDENT | O24: 0 | P24: 0 | Q24: 0 | R24: 1485 | S24: 1485 | T24: 25 | U24: 8 | V24: 5 | W24: 5 | X24: 3 | Y24: 18 | Z24: 25 | AA24: 0 | AB24: 0 | AC24: 0 | AD24: 0 | AE24: 0 | AF24: 0 | AG24: 0 | AH24: 0 | AI24: 0 | AJ24: 1574 | AS24: Dec | AT24: -2880 | BA24: Payroll | BB24: 358873 | BC24: 369639.19 | BD24: 380728.37 | BE24: 392150.22 | BF24: 403914.72 | BG24: 416032.16 | BH24: 428513.13 | BI24: 441368.52 | BJ24: 454609.58
A25: 40793 | B25: 40934 | C25: 1118 | D25: E1T | E25: N/A | F25: 540 | G25: Occupied | H25: Newman, Ashley | I25: 02/27/2025 | K25: 02/27/2025 | L25: 04/27/2026 | M25: 1365 | N25: RESIDENT | O25: 0 | P25: 0 | Q25: 0 | R25: 1475 | S25: 1475 | T25: 25 | U25: 8 | V25: 5 | W25: 5 | X25: 3 | Y25: 18 | Z25: 25 | AA25: 0 | AB25: 0 | AC25: 0 | AD25: 0 | AE25: 0 | AF25: 0 | AG25: 0 | AH25: 0 | AI25: 0 | AJ25: 1564 | AS25: Quarterly | AT25: =SUM(AT22:AT24) -> -17080 | BA25: Employee Units | BB25: 0 | BC25: 0 | BD25: 0 | BE25: 0 | BF25: 0 | BG25: 0 | BH25: 0 | BI25: 0 | BJ25: 0
A26: 40793 | B26: 41199 | C26: 1118 | D26: E1T | E26: N/A | F26: 540 | G26: Pending renewal | H26: Newman, Ashley | I26: 02/27/2025 | K26: 04/28/2026 | L26: 06/28/2027 | M26: 0 | N26: RESIDENT | O26: 0 | P26: 0 | Q26: 0 | R26: 1475 | S26: 1475 | T26: 25 | U26: 8 | V26: 5 | W26: 5 | X26: 3 | Y26: 18 | Z26: 25 | AA26: 0 | AB26: 0 | AC26: 0 | AD26: 0 | AE26: 0 | AF26: 0 | AG26: 0 | AH26: 0 | AI26: 0 | AJ26: 1564 | AS26: Yearly | AT26: =+AT25*4 -> -68320 | BA26: Marketing | BB26: 42075 | BC26: 43337.25 | BD26: 44637.368 | BE26: 45976.489 | BF26: 47355.783 | BG26: 48776.457 | BH26: 50239.75 | BI26: 51746.943 | BJ26: 53299.351
A27: 40640 | B27: 40997 | C27: 1119 | D27: B2T | E27: N/A | F27: 1144 | G27: Occupied | H27: Castillo, Isabella | I27: 05/12/2025 | K27: 05/12/2025 | L27: 05/11/2026 | M27: 1960 | N27: RESIDENT | O27: 0 | P27: 0 | Q27: 0 | R27: 2065 | S27: 2065 | T27: 25 | U27: 8 | V27: 5 | W27: 5 | X27: 3 | Y27: 18 | Z27: 0 | AA27: 50 | AB27: 0 | AC27: 0 | AD27: 0 | AE27: 0 | AF27: 0 | AG27: 0 | AH27: 0 | AI27: 0 | AJ27: 2179 | BA27: General & Admin. | BB27: 105451.4 | BC27: 108614.94 | BD27: 111873.39 | BE27: 115229.59 | BF27: 118686.48 | BG27: 122247.07 | BH27: 125914.49 | BI27: 129691.92 | BJ27: 133582.68
A28: 40640 | B28: 41222 | C28: 1119 | D28: B2T | E28: N/A | F28: 1144 | G28: Pending renewal | H28: Castillo, Isabella | I28: 05/12/2025 | K28: 05/12/2026 | L28: 07/12/2027 | M28: 0 | N28: RESIDENT | O28: 0 | P28: 0 | Q28: 0 | R28: 2065 | S28: 2065 | T28: 25 | U28: 8 | V28: 5 | W28: 5 | X28: 3 | Y28: 18 | Z28: 25 | AA28: 0 | AB28: 0 | AC28: 0 | AD28: 0 | AE28: 0 | AF28: 0 | AG28: 0 | AH28: 0 | AI28: 0 | AJ28: 2154 | BA28: Miscellaneous | BB28: 0 | BC28: 0 | BD28: 0 | BE28: 0 | BF28: 0 | BG28: 0 | BH28: 0 | BI28: 0 | BJ28: 0
A29: 40633 | B29: 41169 | C29: 1120 | D29: B1T | E29: N/A | F29: 1080 | G29: Occupied | H29: Williams, Alexa | I29: 03/21/2025 | K29: 03/21/2026 | L29: 05/20/2027 | M29: 1940 | N29: RESIDENT | O29: 0 | P29: 0 | Q29: 0 | R29: 2085 | S29: 2085 | T29: 25 | U29: 8 | V29: 5 | W29: 5 | X29: 3 | Y29: 18 | Z29: 25 | AA29: 0 | AB29: 35 | AC29: 0 | AD29: 0 | AE29: 0 | AF29: 0 | AG29: 0 | AH29: 0 | AI29: 0 | AJ29: 2209 | BA29: Landscaping/Grounds | BB29: 37080 | BC29: 38192.4 | BD29: 39338.172 | BE29: 40518.317 | BF29: 41733.867 | BG29: 42985.883 | BH29: 44275.459 | BI29: 45603.723 | BJ29: 46971.835
A30: 40961 | B30: 41215 | C30: 1121 | D30: A3T | E30: N/A | F30: 750 | G30: Occupied | H30: Gastelum - EMP, Xavier | I30: 03/28/2026 | K30: 03/28/2026 | L30: 06/30/2027 | M30: 1610 | N30: RESIDENT | O30: 0 | P30: 0 | Q30: 0 | R30: 1610 | S30: 1610 | T30: 25 | U30: 8 | V30: 5 | W30: 5 | X30: 3 | Y30: 18 | Z30: 25 | AA30: 0 | AB30: 0 | AC30: 0 | AD30: 0 | AE30: 0 | AF30: 0 | AG30: 0 | AH30: 0 | AI30: -600 | AJ30: 1099 | BA30: Make-ready | BB30: 0 | BC30: 0 | BD30: 0 | BE30: 0 | BF30: 0 | BG30: 0 | BH30: 0 | BI30: 0 | BJ30: 0
A31: 40909 | B31: 41117 | C31: 1122 | D31: E1T | E31: N/A | F31: 540 | G31: Occupied | H31: Nurse, Kiaya | I31: 10/07/2025 | K31: 10/07/2025 | L31: 11/06/2026 | M31: 1365 | N31: RESIDENT | O31: 0 | P31: 0 | Q31: -2404.75 | R31: 1275 | S31: 1275 | T31: 25 | U31: 8 | V31: 5 | W31: 5 | X31: 3 | Y31: 18 | Z31: 0 | AA31: 50 | AB31: 0 | AC31: 0 | AD31: 0 | AE31: 0 | AF31: 0 | AG31: 0 | AH31: 0 | AI31: 0 | AJ31: 1389 | BA31: Repairs & Maint. | BB31: 96871.5 | BC31: 99777.645 | BD31: 102770.97 | BE31: 105854.1 | BF31: 109029.73 | BG31: 112300.62 | BH31: 115669.64 | BI31: 119139.73 | BJ31: 122713.92
A32: 0 | B32: 0 | C32: 1123 | D32: A6T | E32: N/A | F32: 840 | G32: Vacant | H32: VACANT | M32: 1815 | O32: 0 | P32: 0 | Q32: 0 | R32: 0 | S32: 0 | T32: 0 | U32: 0 | V32: 0 | W32: 0 | X32: 0 | Y32: 0 | Z32: 0 | AA32: 0 | AB32: 0 | AC32: 0 | AD32: 0 | AE32: 0 | AF32: 0 | AG32: 0 | AH32: 0 | AI32: 0 | AJ32: 0 | BA32: Janitorial | BB32: 0 | BC32: 0 | BD32: 0 | BE32: 0 | BF32: 0 | BG32: 0 | BH32: 0 | BI32: 0 | BJ32: 0
A33: 40479 | B33: 41075 | C33: 1124 | D33: A1T | E33: N/A | F33: 630 | G33: Occupied | H33: Hopkins, Alyssa | I33: 08/01/2025 | K33: 08/01/2025 | L33: 07/30/2026 | M33: 1485 | N33: RESIDENT | O33: 0 | P33: 0 | Q33: 0 | R33: 1535 | S33: 1535 | T33: 25 | U33: 8 | V33: 5 | W33: 5 | X33: 3 | Y33: 18 | Z33: 0 | AA33: 0 | AB33: 0 | AC33: 0 | AD33: 0 | AE33: 0 | AF33: 0 | AG33: 0 | AH33: 0 | AI33: 0 | AJ33: 1599 | BA33: Security/Life Safety | BB33: 0 | BC33: 0 | BD33: 0 | BE33: 0 | BF33: 0 | BG33: 0 | BH33: 0 | BI33: 0 | BJ33: 0
A34: 40520 | B34: 41108 | C34: 1125 | D34: A5T | E34: N/A | F34: 780 | G34: Occupied | H34: Acuna, Rafael | I34: 10/26/2023 | K34: 11/26/2025 | L34: 11/25/2026 | M34: 1695 | N34: RESIDENT | O34: 0 | P34: 0 | Q34: 0 | R34: 1921 | S34: 1921 | T34: 25 | U34: 8 | V34: 5 | W34: 5 | X34: 3 | Y34: 18 | Z34: 0 | AA34: 0 | AB34: 0 | AC34: 0 | AD34: 0 | AE34: 0 | AF34: 0 | AG34: 0 | AH34: 0 | AI34: 0 | AJ34: 1985 | BA34: Utilities | BB34: 214883.75 | BC34: 221330.26 | BD34: 227970.17 | BE34: 234809.28 | BF34: 241853.55 | BG34: 249109.16 | BH34: 256582.44 | BI34: 264279.91 | BJ34: 272208.31
A35: 40938 | B35: 41178 | C35: 1126 | D35: E1T | E35: N/A | F35: 540 | G35: Occupied | H35: Kadovik, Daria | I35: 02/06/2026 | K35: 02/06/2026 | L35: 02/05/2027 | M35: 1365 | N35: RESIDENT | O35: 0 | P35: 0 | Q35: -824.39 | R35: 1365 | S35: 1365 | T35: 25 | U35: 8 | V35: 5 | W35: 5 | X35: 3 | Y35: 18 | Z35: 25 | AA35: 0 | AB35: 35 | AC35: 0 | AD35: 0 | AE35: 0 | AF35: 0 | AG35: 0 | AH35: 0 | AI35: 0 | AJ35: 1489 | BA35: Insurance | BB35: 52760.72 | BC35: 54343.542 | BD35: 55973.848 | BE35: 57653.063 | BF35: 59382.655 | BG35: 61164.135 | BH35: 62999.059 | BI35: 64889.031 | BJ35: 66835.702
A36: 40885 | B36: 41078 | C36: 1127 | D36: A1T | E36: N/A | F36: 630 | G36: Occupied | H36: Nop, Donna | I36: 07/18/2025 | K36: 07/18/2025 | L36: 07/16/2026 | M36: 1485 | N36: RESIDENT | O36: 0 | P36: 0 | Q36: 0 | R36: 1535 | S36: 1535 | T36: 25 | U36: 8 | V36: 5 | W36: 5 | X36: 3 | Y36: 18 | Z36: 0 | AA36: 0 | AB36: 0 | AC36: 0 | AD36: 0 | AE36: 0 | AF36: 0 | AG36: 0 | AH36: 0 | AI36: 0 | AJ36: 1599 | BA36: Replacement Reserves | BB36: 0 | BC36: 0 | BD36: 0 | BE36: 0 | BF36: 0 | BG36: 0 | BH36: 0 | BI36: 0 | BJ36: 0
A37: 40762 | B37: 41076 | C37: 1128 | D37: B2T | E37: N/A | F37: 1144 | G37: Occupied | H37: Bernal, Cristina | I37: 08/30/2025 | K37: 08/30/2025 | L37: 08/28/2026 | M37: 1960 | N37: RESIDENT | O37: 0 | P37: 0 | Q37: -6.74 | R37: 2065 | S37: 2065 | T37: 25 | U37: 8 | V37: 5 | W37: 5 | X37: 3 | Y37: 18 | Z37: 0 | AA37: 0 | AB37: 0 | AC37: 0 | AD37: 0 | AE37: 0 | AF37: 0 | AG37: 0 | AH37: 0 | AI37: 0 | AJ37: 2129 | BA37: Misc #2 (GL Expense) | BB37: 0 | BC37: 0 | BD37: 0 | BE37: 0 | BF37: 0 | BG37: 0 | BH37: 0 | BI37: 0 | BJ37: 0
A38: 40924 | B38: 41149 | C38: 1129 | D38: B4T | E38: N/A | F38: 1240 | G38: Occupied | H38: Miller-Cruz - EMP, Anthony | I38: 02/07/2026 | K38: 02/07/2026 | L38: 06/30/2027 | M38: 2540 | N38: RESIDENT | O38: 0 | P38: 0 | Q38: -1904 | R38: 2540 | S38: 2540 | T38: 25 | U38: 8 | V38: 5 | W38: 5 | X38: 3 | Y38: 18 | Z38: 0 | AA38: 0 | AB38: 0 | AC38: 0 | AD38: -700 | AE38: 0 | AF38: 0 | AG38: 0 | AH38: 0 | AI38: 0 | AJ38: 1904 | BA38: RE Taxes | BB38: 555680.99 | BC38: 589300 | BD38: 618765 | BE38: 649703.25 | BF38: 682188.41 | BG38: 716297.83 | BH38: 752112.72 | BI38: 789718.36 | BJ38: 829204.28
A39: 40850 | B39: 41020 | C39: 1130 | D39: A3T | E39: N/A | F39: 750 | G39: Occupied | H39: Connell, Abbey | I39: 05/24/2025 | K39: 05/24/2025 | L39: 07/23/2026 | M39: 1610 | N39: RESIDENT | O39: 0 | P39: 0 | Q39: -770.5 | R39: 1665 | S39: 1665 | T39: 25 | U39: 8 | V39: 5 | W39: 5 | X39: 3 | Y39: 18 | Z39: 25 | AA39: 0 | AB39: 0 | AC39: 0 | AD39: 0 | AE39: 0 | AF39: 0 | AG39: 0 | AH39: 0 | AI39: 0 | AJ39: 1754 | BA39: Management Fee | BB39: 120621.95 | BC39: 128799.85 | BD39: 132288.01 | BE39: 135598.5 | BF39: 139135.89 | BG39: 143228.78 | BH39: 147525.64 | BI39: 151951.41 | BJ39: 156509.95
A40: 40849 | B40: 41019 | C40: 1131 | D40: A2T | E40: N/A | F40: 690 | G40: Occupied | H40: Wilson, Kaylie | I40: 06/28/2025 | K40: 06/28/2025 | L40: 06/29/2026 | M40: 1515 | N40: RESIDENT | O40: 0 | P40: 0 | Q40: -2092.5 | R40: 1565 | S40: 1565 | T40: 25 | U40: 8 | V40: 5 | W40: 5 | X40: 3 | Y40: 18 | Z40: 0 | AA40: 0 | AB40: 0 | AC40: 0 | AD40: 0 | AE40: 0 | AF40: 0 | AG40: 0 | AH40: 0 | AI40: 0 | AJ40: 1629 | BA40: Total Operating Expenses | BB40: 1584298.3 | BC40: 1653335.1 | BD40: 1714345.3 | BE40: 1777492.8 | BF40: 1843281.1 | BG40: 1912142.1 | BH40: 1983832.3 | BI40: 2058389.5 | BJ40: 2135935.6
...

Sheet AR
B2: OneSite Rents v3.0 | O2: Knightvest Management LLC - Lydian | BO2: Page 1 of 12
B3: 04/29/2026 10:27:48AM | O3: DELINQUENT AND PREPAID | BO3: 120.080.106
O4: Fiscal Period 032026 As of 04/29/2026
B6: Parameters: Report Type: Details
B8: Subproperties: ALL
B11: Subjournals: ALL
B13: Statuses to include: Current resident; Include delinquencies that equal NTV Credit? Yes; Exclude transactions payable in arrears: Yes***; Delinquency range 0.00 through 99999999.00; Aging Columns: Fiscal; Filter type: ALL; Summaries: ALL; Show Prepaid As Allocated: Yes; Include outstanding deposits: No; Hide all PII data: No;
B16: Detail - 56 Account(s)
F18: Name Phone Number Email
B19: Unit | J19: Status | N19: Move-In/ Out | S19: Code Description | Y19: Total Prepaid | AE19: Total Delinquent | AN19: Net Balance | AR19: Current | AW19: 30 Days | BA19: 60 Days | BD19: 90+ Days | BH19: Prorate Credits | BM19: Deposits Held | BS19: Outstanding Deposit | BX19: # Late/ # NSF
B24: 1102 | F24: Cornelius, Erica Elizabeth (480) 466-4039 erica.cornelius2@icloud.com | J24: Current resident | N24: 03/28/2023 | BN24: 0 | BS24: 0 | BX24: 15/0
S25: PMTOPCARD | X25: -25 | AD25: 0 | AN25: -25 | AR25: -25 | AW25: 0 | BA25: 0 | BD25: 0 | BI25: 0
B36: 1104 | F36: Ismond, Diane Roslyn (623) 986-4177 ypriest02@gmail.com | J36: Current resident | N36: 06/10/2025 | BN36: 0 | BS36: 0 | BX36: 0/0
S37: PMTOPACH | X37: -318.7 | AD37: 0 | AN37: -318.7 | AR37: -318.7 | AW37: 0 | BA37: 0 | BD37: 0 | BI37: 0
B47: 1105 | F47: Harvey, Chauncey T chaunceyharvey84@gmail.com | J47: Current resident | N47: 04/11/2024 | BN47: 0 | BS47: 0 | BX47: 10/3
S48: PMTOPCARD | X48: -2305.39 | AD48: 0 | AK48: † | AN48: -2305.39 | AR48: 0 | AW48: -2305.39 | BA48: 0 | BD48: 0 | BI48: 0
B57: 1109 | F57: Whiteman, Elizabeth Anne (602) 402-8522 4elizabeth.whiteman@gmail.com | J57: Current resident | N57: 03/08/2024 | BN57: 0 | BS57: 0 | BX57: 0/0
S58: PMTOPACH | X58: -1785.76 | AD58: 0 | AN58: -1785.76 | AR58: -1785.76 | AW58: 0 | BA58: 0 | BD58: 0 | BI58: 0
B69: 1110 | F69: Dennis, Ezzerianna Keosha (480) 796-4343 ezzerianna@gmail.com | J69: Current resident | N69: 03/06/2026 | BN69: 0 | BS69: 0 | BX69: 0/1
S70: PMTOPIRD | X70: -4.7 | AD70: 0 | AN70: -4.7 | AR70: -4.7 | AW70: 0 | BA70: 0 | BD70: 0 | BI70: 0
B81: 1121 | F81: Gastelum, Xavier (928) 278-3682 gastelumx3@gmail.com | J81: Current resident | N81: 03/28/2026 | BN81: 0 | BS81: 0 | BX81: 0/1
S82: RENTERSINS | X82: 0 | AD82: 2.32 | AR82: 2.32 | AW82: 0 | BA82: 0 | BD82: 0 | BI82: 0
S88: VALETTRASH | X88: 0 | AD88: 3.23 | AR88: 3.23 | AW88: 0 | BA88: 0 | BD88: 0 | BI88: 0
S93: TRASHREIMB | X93: 0 | AD93: 1.03 | AR93: 1.03 | AW93: 0 | BA93: 0 | BD93: 0 | BI93: 0
S97: GASREIMB | X97: 0 | AD97: 0.65 | AR97: 0.65 | AW97: 0 | BA97: 0 | BD97: 0 | BI97: 0
S100: UTILITY | X100: 0 | AD100: 0.65 | AR100: 0.65 | AW100: 0 | BA100: 0 | BD100: 0 | BI100: 0
S103: PESTREIMNB | X103: 0 | AD103: 0.39 | AR103: 0.39 | AW103: 0 | BA103: 0 | BD103: 0 | BI103: 0
S106: SMARTHOME | X106: 0 | AD106: 3.23 | AR106: 3.23 | AW106: 0 | BA106: 0 | BD106: 0 | BI106: 0
B109: Detail - 56 Account(s)
F111: Name Phone Number Email
B112: Unit | J112: Status | N112: Move-In/ Out | S112: Code Description | Y112: Total Prepaid | AE112: Total Delinquent | AN112: Net Balance | AR112: Current | AW112: 30 Days | BA112: 60 Days | BD112: 90+ Days | BH112: Prorate Credits | BM112: Deposits Held | BS112: Outstanding Deposit | BX112: # Late/ # NSF
S116: CORPEMPLCRED | X116: -11.5 | AD116: 0 | AR116: -11.5 | AW116: 0 | BA116: 0 | BD116: 0 | BI116: 0
S119: Subtotals: | X119: -11.5 | AD119: 11.5 | AN119: 0 | AR119: 0 | AW119: 0 | BA119: 0 | BD119: 0 | BH119: 0
B122: 1122 | F122: Nurse, Kiaya Reece (425)760-7447 kiaya.nurse@gmail.com | J122: Current resident | N122: 10/07/2025 | BN122: 0 | BS122: 0 | BX122: 0/0
S123: RNTGRAREF | X123: -50 | AD123: 0 | AR123: -50 | AW123: 0 | BA123: 0 | BD123: 0 | BI123: 0
S129: PMTOPACH | X129: -1250 | AD129: 0 | AR129: -1250 | AW129: 0 | BA129: 0 | BD129: 0 | BI129: 0
S134: PMTOPCARD | X134: -1104.75 | AD134: 0 | AR134: -600 | AW134: -504.75 | BA134: 0 | BD134: 0 | BI134: 0
S138: Subtotals: | X138: -2404.75 | AD138: 0 | AN138: -2404.75 | AR138: -1900 | AW138: -504.75 | BA138: 0 | BD138: 0 | BH138: 0
B141: 1126 | F141: Kadovik, Daria (602) 592-8126 d.kadovik@gmail.com | J141: Current resident | N141: 02/06/2026 | BN141: 0 | BS141: 0 | BX141: 0/0
S142: CONC/SPECL | X142: -824.39 | AD142: 0 | AN142: -824.39 | AR142: -824.39 | AW142: 0 | BA142: 0 | BD142: 0 | BI142: 0
...

Sheet Tax Statement
Y34: 473998
Y35: Tax Summary

Sheet Debt Service
B2: Interest Rate Cap | C2: 0.025 | D2: =IF(C2=C3,"At-the-Money",IF(C2<C3,"In-the-Money",IF(C2>C3,"Out-of-the-Money"))) -> In-the-Money
B3: SOFR | C3: 0.0368 | D3: 46112
B4: Spread | C4: 0.0245
B5: Effective Interest Rate | C5: =SUM(MIN(C3,C2),C4) -> 0.0495
B7: Current Principal Balance | C7: ='NEW OSAR'!E6 -> 52400000
B9: NOI | C9: ='NEW OSAR'!I57 -> 3338057.5
B10: Debt Service (w/o Cap) | C10: =C7*(C3+C4)*(365/360) -> 3256732.8
B11: Debt Service (w/Cap) | C11: =C7*C5*(365/360) -> 2629825
B13: DSCR (w/o Cap) | C13: =C9/C10 -> 1.0249713
B14: DSCR (w/Cap) | C14: =C9/C11 -> 1.2693078
B17: Mod Proposal
B18: Interest Rate Cap | C18: 0.0295
B19: SOFR | C19: 0.0430757
B20: Spread | C20: 0.0255
B21: Effective Interest Rate | C21: =SUM(MIN(C19,C18),C20) -> 0.055
B23: Current Principal Balance | C23: ='NEW OSAR'!E7 -> 48900000
B25: NOI | C25: ='NEW OSAR'!I57 -> 3338057.5
B26: Debt Service (w/o Cap) | C26: =C23*(C19+C20)*(365/360) -> 3399926.1
B27: Debt Service (w/Cap) | C27: =C23*C21*(365/360) -> 2726854.2
B29: DSCR (w/o Cap) | C29: =C25/C26 -> 0.98180296
B30: DSCR (w/Cap) | C30: =C25/C27 -> 1.2241423

Sheet Variance Analysis
A1: 1
C2: 3Q 2025 | G2: 45962 | K2: 4Q 2025 | O2: QoQ ∆ | S2: Cash Management
B3: Property | C3: Occupancy | D3: NOI | E3: DY | F3: DSCR | G3: Occupancy | H3: NOI | I3: DY | J3: DSCR | K3: Occupancy | L3: NOI | M3: DY | N3: DSCR | O3: Occupancy | P3: NOI | Q3: DY | R3: DSCR | S3: In CM? | T3: Threshold
B4: =+#REF! -> #REF! | C4: 0.92344498 | D4: 2855235.8 | E4: 0.054489232 | F4: 1.0857132 | G4: 0.92344498 | H4: 2894344.7 | I4: 0.055235585 | J4: 1.1005845 | K4: =#REF! -> #REF! | L4: =+#REF! -> #REF! | M4: =#REF! -> #REF! | N4: =#REF! -> #REF! | O4: =IF(K4="","-",K4-G4) -> #REF! | P4: =IF(L4="","-",L4-H4) -> #REF! | Q4: =IF(M4="","-",M4-I4) -> #REF! | R4: =IF(N4="","-",N4-J4) -> #REF! | S4: No | T4: 0.06
B6: Notes:
B7: NOI adjusted per the loan agreement.
B8: DSCR inclusive of benefit from in-the-money rate cap.
B9: Cash management testing begins in October 2023

Sheet Paydown Scenario
B2: DY
B3: Target DY | D3: 0.0675
B5: Current Principal | D5: =#REF! -> #REF!
B6: Paydown | D6: =+IF(D9/D5<D3,D5-(D9/D3),0) -> #REF!
B7: Total Principal | D7: =+D5-D6 -> #REF!
B9: Current Net Cash Flow | D9: =#REF!+ABS(F9) -> #REF!
B11: Needed Net Cash Flow | D11: 3535000
B12: DY | D12: =D11/D5 -> #REF!
B13: NCF Change | D13: =D11-D9 -> #REF!

Sheet Insurance
P20: 67264.33

Sheet Definitions
