Workbook
Name Benchmark: '1'!#REF!
Name Benchmark: [1]UPB!$C$8
Name Benchmark: [1]UPB!$C$8
Name Benchmark: 'Old OSAR'!#REF!
Name Capped_Benchmark: '1'!#REF!
Name Capped_Benchmark: '[2]Debt Service'!$C$10
Name Capped_Benchmark: [1]UPB!$C$10
Name Capped_Benchmark: [1]UPB!$C$10
Name Capped_Benchmark: 'Old OSAR'!#REF!
Name CMNOTES: #REF!
Name CMNOTES: #REF!
Name CMNOTES: #REF!
Name CMNOTES: #REF!
Name CMNOTES.: #REF!
Name CMNOTES.: #REF!
Name CMNOTES.: #REF!
Name CMNOTES..: #REF!
Name CMNOTES..: #REF!
Name CMNOTES..: #REF!
Name RESULTS: #REF!
Name RESULTS: #REF!
Name RESULTS: #REF!
Name RESULTS: #REF!

Sheet MF OSAR
B1: CREFC Investor Reporting Package
C2: MULTIFAMILY OPERATING STATEMENT ANALYSIS REPORT (includes Mobile Home Parks, Single Family Rentals, and Co-ops)
C3: ="as of" &TEXT(F6," mm/dd/yyyy") -> as of 03/31/2026
C4: PROPERTY OVERVIEW | H4: Allocated Loan Amount/Percentage
C5: Property ID | E5: 1001-001 | F5: Paid Thru Date | G5: Debt Outside Trust (1) | H5: $ | I5: %
C6: Note A-Scheduled Loan Balance | E6: =+'DSCR Calc'!H5 -> 47626516 | F6: 46112 | G6: X or Blank | H6: 0 | I6: 1
C7: Note B-Scheduled Loan Balance
C8: Note C-Scheduled Loan Balance
C9: Property Name | E9: Memorial Hills
C10: Property Type | E10: Multifamily
C11: Property Address, City, State | E11: 4200 Scotland Street, Houston, TX 77007
C12: Current Net Rentable SF/Units/Beds/Rooms | E12: 308 | F12: units | G12: Use second box to specify sqft.,units…
C13: Year Built/Year Renovated | E13: 2009 | F13: 2026
C14: Cap Ex Reserve (annually)/per Unit.etc. (2) | E14: 200 | F14: Per unit | G14: specify annual/per unit…
C15: Statement Ending Date | E15: Underwriting | F15: 45930 | G15: 46022 | H15: =+I15 -> 46112 | I15: 46112
C16: Occupancy Rate (physical) | E16: 0.94155844 | F16: 0.8961 | G16: 0.8896 | H16: =+I16 -> 0.8604 | I16: ='Rent Roll'!I389/100 -> 0.8604 | N16: Actual | O16: =1-I16 -> 0.1396
C17: Occupancy Date | E17: 45793 | F17: 45930 | G17: 46022 | H17: =+H15 -> 46112 | I17: =+I15 -> 46112 | N17: Factor | O17: 0.05
E18: (1) "X" if debt is outside of the trust, otherwise leave blank
E19: (2) Total $ amount of Capital Reserves required annually by loan documents
C20: INCOME:
C21: Number of Mos. Covered | J21: (prcdng yr to base) | K21: (prcdng yr to 2nd prcdng)
C22: Period Ended | E22: At Contribution | F22: DY Test | G22: DY Test | H22: T10 | I22: DY Test | J22: =TEXT(H15," mm/dd/yyyy")& "-U/W" -> 03/31/2026-U/W | K22: =TEXT(G15," mm/dd/yyyy -") & TEXT(H15,"mm/dd/yyyy") -> 12/31/2025 -03/31/2026
C23: Statement Ending Date | E23: Information | F23: 45930 | G23: 46022 | H23: 46112 | I23: =+I15 -> 46112 | J23: Variance | K23: Variance | L23: Notes | N23: Var $ | O23: Var %
C24: Gross Potential Rent (3) | E24: 6960534.1 | F24: 6181628.7 | G24: 6033557.5 | H24: =+SUMIF('Operating Statement'!U:U,'MF OSAR'!C24,'Operating Statement'!V:V) -> 7109950.2 | I24: =(('Rent Roll'!Z364+'Rent Roll'!Z362+'Rent Roll'!Z358)*12)+'Operating Statement'!V57 -> 5790122.7 | J24: =IF(E24=0, " ",(H24-E24)/E24) -> 0.021466188 | K24: =IF(G24=0, " ",(H24-G24)/G24) -> 0.17840101 | L24: ="Annualized RR as of "&TEXT(I15,"MM/DD/YYYY") & " less T6 concessions" -> Annualized RR as of 03/31/2026 less T6 concessions | N24: =+IFERROR(I24-G24,"") -> -243434.76 | O24: =+IFERROR(N24/G24,"") -> -0.040346804
C25: Less: Vacancy Loss | E25: -406784.46 | F25: 0 | H25: =+SUMIF('Operating Statement'!U:U,'MF OSAR'!C25,'Operating Statement'!V:V) -> -756218.51 | I25: =+IF(O16>O17,"",(O17-O16)*-I24) | J25: =IF(E25=0, " ",(H25-E25)/E25) -> 0.85901524 | K25: =IF(G25=0, " ",(H25-G25)/G25) -> #VALUE! | L25: ="Greater of actual vacancy ("&TEXT(1-I16,"#.0%")&") or "&TEXT(O17,"#.0%") -> Greater of actual vacancy (14.0%) or 5.0% | N25: =+IFERROR(I25-G25,"") | O25: =+IFERROR(N25/G25,"")
C26: OR | H26: =+SUMIF('Operating Statement'!U:U,'MF OSAR'!C26,'Operating Statement'!V:V) -> 0 | N26: =+IFERROR(I26-G26,"") -> 0 | O26: =+IFERROR(N26/G26,"")
C27: Base Rent (3) | E27: 0 | F27: 0 | G27: 0 | H27: =+SUMIF('Operating Statement'!U:U,'MF OSAR'!C27,'Operating Statement'!V:V) -> 0 | I27: =+H27 -> 0 | J27: =IF(E27=0, " ",(H27-E27)/E27) | K27: =IF(G27=0, " ",(H27-G27)/G27) | L27: =$H$22& " ended" &TEXT($I$15," mm/dd/yyyy") -> T10 ended 03/31/2026 | N27: =+IFERROR(I27-G27,"") -> 0 | O27: =+IFERROR(N27/G27,"")
C28: Laundry/Vending Income | E28: 0 | F28: 0 | G28: 0 | H28: =+SUMIF('Operating Statement'!U:U,'MF OSAR'!C28,'Operating Statement'!V:V) -> 0 | I28: =+H28 -> 0 | J28: =IF(E28=0, " ",(H28-E28)/E28) | K28: =IF(G28=0, " ",(H28-G28)/G28) | L28: =$I$22& " ended" &TEXT($I$15," mm/dd/yyyy") -> DY Test ended 03/31/2026 | N28: =+IFERROR(I28-G28,"") -> 0 | O28: =+IFERROR(N28/G28,"")
C29: Parking Income | E29: =+'Old OSAR'!E29 -> 17787.24 | F29: 15657 | G29: 16552.286 | H29: =+SUMIF('Operating Statement'!U:U,'MF OSAR'!C29,'Operating Statement'!V:V) -> 16272.576 | I29: =+H29 -> 16272.576 | J29: =IF(E29=0, " ",(H29-E29)/E29) -> -0.085154527 | K29: =IF(G29=0, " ",(H29-G29)/G29) -> -0.016898555 | L29: =$I$22& " ended" &TEXT($I$15," mm/dd/yyyy") -> DY Test ended 03/31/2026 | N29: =+IFERROR(I29-G29,"") -> -279.70971 | O29: =+IFERROR(N29/G29,"") -> -0.016898555
C30: Other Income | E30: ='Old OSAR'!E30+'Old OSAR'!E27 -> 528398.78 | F30: 637495.8 | G30: 592415.5 | H30: =+SUMIF('Operating Statement'!U:U,'MF OSAR'!C30,'Operating Statement'!V:V) -> 580172.36 | I30: =+H30 -> 580172.36 | J30: =IF(E30=0, " ",(H30-E30)/E30) -> 0.097982028 | K30: =IF(G30=0, " ",(H30-G30)/G30) -> -0.020666473 | L30: =$I$22& " ended" &TEXT($I$15," mm/dd/yyyy") -> DY Test ended 03/31/2026 | N30: =+IFERROR(I30-G30,"") -> -12243.139 | O30: =+IFERROR(N30/G30,"") -> -0.020666473
O31: =+IFERROR(N31/G31,"")
C32: *Effective Gross Income | E32: 7099935.6 | F32: 6834781.5 | G32: 6642525.2 | H32: =+SUM(H24:H30) -> 6950176.6 | I32: =+SUM(I24:I30) -> 6386567.6 | J32: =IF(E32=0, " ",(H32-E32)/E32) -> -0.021093008 | K32: =IF(G32=0, " ",(H32-G32)/G32) -> 0.046315424 | N32: =+IFERROR(I32-G32,"") -> -255957.61 | O32: =+IFERROR(N32/G32,"") -> -0.038533178
E33: (3) Use either Gross Potential (with Vacancy Loss) or Base Rents; use negative $amt for Vacancy Loss
C35: OPERATING EXPENSES: | J35: =IF(E35=0, " ",(H35-E35)/E35)
C36: Real Estate Taxes | E36: 1485043.6 | F36: 1583361.8 | G36: 1506316.6 | H36: =+SUMIF('Operating Statement'!U:U,'MF OSAR'!C36,'Operating Statement'!V:V) -> 1521691.7 | I36: =+MAX(H36,'RE Tax'!C2) -> 1521691.7 | J36: =IF(E36=0, " ",(H36-E36)/E36) -> 0.024678117 | K36: =IF(G36=0, " ",(H36-G36)/G36) -> 0.010207024 | L36: ="Greater of actual tax bill from " & TEXT('RE Tax'!$C$3,"mm/d/yyyy") & "-" & TEXT('RE Tax'!$C$4,"mm/d/yyyy") & " (" & TEXT('RE Tax'!$C$2/1000000,"$0.0""MM""") & ") and T10 ended " & TEXT($I$15,"mm/d/yyyy") -> Greater of actual tax bill from 11/15/2025-11/15/2026 ($1.4MM) and T10 ended 03/31/2026 | N36: =+IFERROR(I36-G36,"") -> 15375.01 | O36: =+IFERROR(N36/G36,"") -> 0.010207024
C37: Property Insurance | E37: 215600 | F37: 81669.58 | G37: 81669.58 | H37: =+SUMIF('Operating Statement'!U:U,'MF OSAR'!C37,'Operating Statement'!V:V) -> 68540.496 | I37: =+Insurance!C5 -> 81669.58 | J37: =IF(E37=0, " ",(H37-E37)/E37) -> -0.68209417 | K37: =IF(G37=0, " ",(H37-G37)/G37) -> -0.16075856 | L37: ="Actual insurance premium from " & TEXT(Insurance!$F$2,"mm/d/yyyy") & "-" & TEXT(Insurance!$F$3,"mm/d/yyyy") & " (" & TEXT(Insurance!$C$5/1000,"$00.0""K"")") -> Actual insurance premium from 06/26/2025-06/26/2026 ($81.7K) | N37: =+IFERROR(I37-G37,"") -> 0 | O37: =+IFERROR(N37/G37,"") -> 0
C38: Utilities | E38: 378063.92 | F38: 435251.49 | G38: 382429.13 | H38: =+SUMIF('Operating Statement'!U:U,'MF OSAR'!C38,'Operating Statement'!V:V) -> 423119.88 | I38: =+SUMIF('Operating Statement'!$U:$U,'MF OSAR'!C38,'Operating Statement'!$V:$V) -> 423119.88 | J38: =IF(E38=0, " ",(H38-E38)/E38) -> 0.11917551 | K38: =IF(G38=0, " ",(H38-G38)/G38) -> 0.10640076 | L38: =$H$22& " ended" &TEXT($I$15," mm/dd/yyyy") -> T10 ended 03/31/2026 | N38: =+IFERROR(I38-G38,"") -> 40690.749 | O38: =+IFERROR(N38/G38,"") -> 0.10640076
C39: Repairs and Maintenance | E39: 358377.1 | F39: 276857.22 | G39: 343370.95 | H39: =+SUMIF('Operating Statement'!U:U,'MF OSAR'!C39,'Operating Statement'!V:V) -> 333494.4 | I39: =+SUMIF('Operating Statement'!$U:$U,'MF OSAR'!C39,'Operating Statement'!$V:$V) -> 333494.4 | J39: =IF(E39=0, " ",(H39-E39)/E39) -> -0.069431613 | K39: =IF(G39=0, " ",(H39-G39)/G39) -> -0.028763495 | L39: =$H$22& " ended" &TEXT($I$15," mm/dd/yyyy") -> T10 ended 03/31/2026 | N39: =+IFERROR(I39-G39,"") -> -9876.5486 | O39: =+IFERROR(N39/G39,"") -> -0.028763495
C40: Management Fees | E40: 177498.39 | F40: 170869.54 | G40: 166063.13 | H40: =+SUMIF('Operating Statement'!U:U,'MF OSAR'!C40,'Operating Statement'!V:V) -> 125036.59 | I40: =+MAX(H40,0.025*I32) -> 159664.19 | J40: =IF(E40=0, " ",(H40-E40)/E40) -> -0.29556211 | K40: =IF(G40=0, " ",(H40-G40)/G40) -> -0.24705387 | L40: 0.025 | N40: =+IFERROR(I40-G40,"") -> -6398.9402 | O40: =+IFERROR(N40/G40,"") -> -0.038533178
C41: Payroll & Benefits | E41: 688888.39 | F41: 431244.93 | G41: 475945.49 | H41: =+SUMIF('Operating Statement'!U:U,'MF OSAR'!C41,'Operating Statement'!V:V) -> 510450.74 | I41: =+SUMIF('Operating Statement'!$U:$U,'MF OSAR'!C41,'Operating Statement'!$V:$V) -> 510450.74 | J41: =IF(E41=0, " ",(H41-E41)/E41) -> -0.25902258 | K41: =IF(G41=0, " ",(H41-G41)/G41) -> 0.072498328 | L41: =$H$22& " ended" &TEXT($I$15," mm/dd/yyyy") -> T10 ended 03/31/2026 | N41: =+IFERROR(I41-G41,"") -> 34505.253 | O41: =+IFERROR(N41/G41,"") -> 0.072498328
...

Sheet Old OSAR
D1: CREFC Investor Reporting Package
A2: 1 | D2: MULTIFAMILY OPERATING STATEMENT ANALYSIS REPORT (includes Mobile Home Parks, Single Family Rentals, and Co-ops)
D3: ="as of "&TEXT($J$14,"m/dd/yyyy") -> as of 12/31/2025
D4: PROPERTY OVERVIEW | H4: Allocated Loan Amount/Percentage
D5: Property ID | E5: 1001-001 | F5: Paid Thru Date | G5: Debt Outside Trust (1) | H5: $ | I5: %
D6: Note A-Scheduled Loan Balance | E6: ='DSCR Calc'!H5 -> 47626516 | F6: =J14 -> 46022 | H6: 0 | I6: 1
D7: Note B-Scheduled Loan Balance | E7: 0 | H7: 0
D8: Property Name | E8: Memorial Hills
D9: Property Type | E9: MF
D10: Property Address, City, State | E10: 4200 Scotland Street, Houston, TX 77007
D11: Current Net Rentable SF/Units/Beds/Rooms | E11: 308 | F11: Units
D12: Year Built/Year Renovated | E12: 2009
D13: Cap Ex Reserve (annually)/per Unit.etc. (2) | E13: 200 | F13: per unit
D14: Statement Ending Date | E14: ='UW Pro Forma CF'!C3 -> At Close (In Place) | F14: ='UW Pro Forma CF'!E12 -> 46173 | G14: ='UW Pro Forma CF'!F12 -> 46538 | H14: 45838 | I14: 45930 | J14: 46022 | K14: =J14 -> 46022
D15: Occupancy Rate (physical) | E15: ='UW Pro Forma CF'!C8 -> 0.94155844 | F15: ='UW Pro Forma CF'!E8 -> 0.90191795 | G15: ='UW Pro Forma CF'!F8 -> 0.88636364 | H15: 0.9188 | I15: 0.8961 | J15: ='Rent Roll'!#REF!/100 -> #REF! | K15: =J15 -> #REF! | M15: Vacancy Factor | N15: Actual
D16: Occupancy Date | E16: 45793 | F16: ='UW Pro Forma CF'!E12 -> 46173 | G16: ='UW Pro Forma CF'!F12 -> 46538 | H16: 45838 | I16: 45930 | J16: =J14 -> 46022 | K16: =K14 -> 46022 | M16: 0.05 | N16: =1-J15 -> #REF!
E17: Information
E18: (2) Total $ amount of Capital Reserves required annually by loan documents
D19: INCOME:
D20: Number of Mos. Covered
D21: Period Ended | E21: At Contribution | F21: UW Year 1 | G21: UW Year 2 | H21: DY 2Q 2025 | I21: DY 3Q 2025 | J21: ='Operating Statement'!V11 -> T10 | K21: DY 4Q 2025 | L21: Notes | N21: In place to UW Year 1
D22: Statement Ending Date | E22: Information | F22: ='UW Pro Forma CF'!E12 -> 46173 | G22: ='UW Pro Forma CF'!F12 -> 46538 | H22: 45838 | I22: 45930 | J22: =$J$14 -> 46022 | K22: =$J$14 -> 46022 | N22: Variance ($) | O22: Variance (%)
D23: Gross Potential Rent (3) | E23: ='UW Pro Forma CF'!C13 -> 6960534.1 | F23: ='UW Pro Forma CF'!E13 -> 7125090.4 | G23: ='UW Pro Forma CF'!F13 -> 7547179.1 | H23: 6437938.1 | I23: 6181628.7 | J23: =SUMIFS('Operating Statement'!Q:Q,'Operating Statement'!S:S,'Old OSAR'!D23) -> 0 | K23: =('Rent Roll'!Z363*12)+'Operating Statement'!V57 -> -327351.3 | L23: ="Annualized RR as of "&TEXT(J14,"MM/DD/YYYY") & " less T6 concessions" -> Annualized RR as of 12/31/2025 less T6 concessions | N23: =IFERROR(K23-I23,"N/A") -> -6508980 | O23: =IFERROR(N23/I23,"N/A") -> -1.0529555
D24: Less: Vacancy Loss | E24: ='UW Pro Forma CF'!C14 -> -406784.46 | F24: ='UW Pro Forma CF'!E14 -> -698843.45 | G24: ='UW Pro Forma CF'!F14 -> -857633.98 | J24: =SUMIFS('Operating Statement'!Q:Q,'Operating Statement'!S:S,'Old OSAR'!D24) -> 0 | K24: =IF(N16<M16,(-M16+N16)*K23,"") -> #REF! | L24: ="Greater of actual vacancy ("&TEXT(N16,"#.0%")&") or "&TEXT(M16,"#.0%") -> #REF! | N24: =IFERROR(K24-I24,"N/A") -> N/A | O24: =IFERROR(N24/I24,"N/A") -> N/A
D25: OR | N25: =IFERROR(K25-I25,"N/A") -> 0 | O25: =IFERROR(N25/I25,"N/A") -> N/A
D26: Base Rent (3) | E26: ='UW Pro Forma CF'!C16 -> 0 | N26: =IFERROR(K26-I26,"N/A") -> 0 | O26: =IFERROR(N26/I26,"N/A") -> N/A
D27: Delinquent Rent | E27: ='UW Pro Forma CF'!C17 -> -25478.68 | F27: ='UW Pro Forma CF'!E17 -> -16911.176 | G27: ='UW Pro Forma CF'!F17 -> -17604.066 | H27: -3334.08 | I27: -10224.39 | J27: =SUMIFS('Operating Statement'!Q:Q,'Operating Statement'!S:S,'Old OSAR'!D27) -> 0 | K27: =J27 -> 0 | L27: =TEXT($J$21,0) &" ended "&TEXT($J$14,"MM/DD/YYYY") -> T10 ended 12/31/2025 | N27: =IFERROR(K27-I27,"N/A") -> 10224.39 | O27: =IFERROR(N27/I27,"N/A") -> -1
D28: Expense Reimbursement | H28: 0 | I28: 370468.05 | J28: =SUMIFS('Operating Statement'!Q:Q,'Operating Statement'!S:S,'Old OSAR'!D28) -> 0 | K28: =J28 -> 0 | L28: =TEXT($J$21,0) &" ended "&TEXT($J$14,"MM/DD/YYYY") -> T10 ended 12/31/2025 | N28: =IFERROR(K28-I28,"N/A") -> -370468.05 | O28: =IFERROR(N28/I28,"N/A") -> -1
D29: Parking Income | E29: ='UW Pro Forma CF'!C18 -> 17787.24 | F29: ='UW Pro Forma CF'!E18 -> 22176 | G29: ='UW Pro Forma CF'!F18 -> 22841.28 | H29: 15060 | I29: 15657 | J29: =SUMIFS('Operating Statement'!Q:Q,'Operating Statement'!S:S,'Old OSAR'!D29) -> 0 | K29: =J29 -> 0 | L29: =TEXT($J$21,0) &" ended "&TEXT($J$14,"MM/DD/YYYY") -> T10 ended 12/31/2025 | N29: =IFERROR(K29-I29,"N/A") -> -15657 | O29: =IFERROR(N29/I29,"N/A") -> -1
D30: Other Income | E30: ='UW Pro Forma CF'!C19 -> 553877.46 | F30: ='UW Pro Forma CF'!E19 -> 363880.87 | G30: ='UW Pro Forma CF'!F19 -> 454679.07 | H30: 782824.2 | I30: 277252.14 | J30: =SUMIFS('Operating Statement'!Q:Q,'Operating Statement'!S:S,'Old OSAR'!D30) -> 0 | K30: =J30 -> 0 | L30: =TEXT($J$21,0) &" ended "&TEXT($J$14,"MM/DD/YYYY") -> T10 ended 12/31/2025 | N30: =IFERROR(K30-I30,"N/A") -> -277252.14 | O30: =IFERROR(N30/I30,"N/A") -> -1
N31: =IFERROR(K31-I31,"N/A") -> 0 | O31: =IFERROR(N31/I31,"N/A") -> N/A
D32: *Effective Gross Income | E32: ='UW Pro Forma CF'!C21 -> 7099935.6 | F32: ='UW Pro Forma CF'!E21 -> 6795392.6 | G32: ='UW Pro Forma CF'!F21 -> 7149461.4 | H32: 7232488.2 | I32: 6834781.5 | J32: =SUM(J23:J30) -> 0 | K32: =SUM(K23:K30) -> #REF! | N32: =IFERROR(K32-I32,"N/A") -> N/A | O32: =IFERROR(N32/I32,"N/A") -> N/A
E33: (3) Use either Gross Potential (with Vacancy Loss) or Base Rents; use negative $amt for Vacancy Loss
D35: OPERATING EXPENSES:
D36: Real Estate Taxes | E36: ='UW Pro Forma CF'!C25 -> 1485043.6 | F36: ='UW Pro Forma CF'!E25 -> 1484035.5 | G36: ='UW Pro Forma CF'!F25 -> 1529382.6 | H36: 1318188.1 | I36: 1583361.8 | J36: =SUMIFS('Operating Statement'!Q:Q,'Operating Statement'!S:S,'Old OSAR'!D36) -> 0 | K36: =+MAX(J36,'RE Tax'!C2) -> 1425631.4 | L36: Greater of T12 taxes & 2025 actual taxes | N36: =IFERROR(K36-I36,"N/A") -> -157730.35 | O36: =IFERROR(N36/I36,"N/A") -> -0.099617379
D37: Property Insurance | E37: ='UW Pro Forma CF'!C26 -> 215600 | F37: ='UW Pro Forma CF'!E26 -> 215600 | G37: ='UW Pro Forma CF'!F26 -> 226380 | H37: 76674.58 | I37: 81669.58 | J37: =SUMIFS('Operating Statement'!Q:Q,'Operating Statement'!S:S,'Old OSAR'!D37) -> 0 | K37: =Insurance!C5 -> 81669.58 | L37: 2025 insurance premium | M37: =K37/E37-1 -> -0.62119861 | N37: =IFERROR(K37-I37,"N/A") -> 0 | O37: =IFERROR(N37/I37,"N/A") -> 0
D38: Utilities | E38: ='UW Pro Forma CF'!C27 -> 378063.92 | F38: ='UW Pro Forma CF'!E27 -> 369600 | G38: ='UW Pro Forma CF'!F27 -> 388080 | H38: 388047.24 | I38: 435251.49 | J38: =SUMIFS('Operating Statement'!Q:Q,'Operating Statement'!S:S,'Old OSAR'!D38) -> 0 | K38: =J38 -> 0 | L38: =TEXT($J$21,0) &" ended "&TEXT($J$14,"MM/DD/YYYY") -> T10 ended 12/31/2025 | N38: =IFERROR(K38-I38,"N/A") -> -435251.49 | O38: =IFERROR(N38/I38,"N/A") -> -1
D39: Repairs and Maintenance | E39: ='UW Pro Forma CF'!C28 -> 358377.1 | F39: ='UW Pro Forma CF'!E28 -> 377300 | G39: ='UW Pro Forma CF'!F28 -> 396165 | H39: 102901.92 | I39: 276857.22 | J39: =SUMIFS('Operating Statement'!Q:Q,'Operating Statement'!S:S,'Old OSAR'!D39) -> 0 | K39: =J39 -> 0 | L39: =TEXT($J$21,0) &" ended "&TEXT($J$14,"MM/DD/YYYY") -> T10 ended 12/31/2025 | N39: =IFERROR(K39-I39,"N/A") -> -276857.22 | O39: =IFERROR(N39/I39,"N/A") -> -1
D40: Management Fees | E40: ='UW Pro Forma CF'!C29 -> 177498.39 | F40: ='UW Pro Forma CF'!E29 -> 169884.82 | G40: ='UW Pro Forma CF'!F29 -> 178736.53 | H40: 188251.8 | I40: 170869.54 | J40: =SUMIFS('Operating Statement'!Q:Q,'Operating Statement'!S:S,'Old OSAR'!D40) -> 0 | K40: =+MAX(J40,L40*K32) -> #REF! | L40: 0.025 | N40: =IFERROR(K40-I40,"N/A") -> N/A | O40: =IFERROR(N40/I40,"N/A") -> N/A
D41: Payroll & Benefits | E41: ='UW Pro Forma CF'!C30 -> 688888.39 | F41: ='UW Pro Forma CF'!E30 -> 646800 | G41: ='UW Pro Forma CF'!F30 -> 679140 | H41: 172441.56 | I41: 431244.93 | J41: =SUMIFS('Operating Statement'!Q:Q,'Operating Statement'!S:S,'Old OSAR'!D41) -> 0 | K41: =J41 -> 0 | L41: =TEXT($J$21,0) &" ended "&TEXT($J$14,"MM/DD/YYYY") -> T10 ended 12/31/2025 | N41: =IFERROR(K41-I41,"N/A") -> -431244.93 | O41: =IFERROR(N41/I41,"N/A") -> -1
...

Sheet DSCR Calc
A1: 0 | G1: Previous | H1: Current
G2: DY 4Q 2025 | H2: DY 1Q 2026
G3: 46022 | H3: ='MF OSAR'!F6 -> 46112
B5: UPB | G5: 47626516 | H5: =+G5 -> 47626516
B6: Occupancy | G6: 0.8896 | H6: ='MF OSAR'!I16 -> 0.8604
B8: Rate Cap | G8: 0.055 | H8: 0.055
B9: SOFR | G9: 0.0378659 | H9: 0.0368
B10: Spread | G10: 0.0225 | H10: 0.0225
B11: Effective Interest Rate | G11: 0.0603659 | H11: =H9+H10 -> 0.0593
B12: Effective Capped Interest Rate | G12: 0.0603659 | H12: =MIN(H8,H9)+H10 -> 0.0593
B14: Net Cash Flow | G14: 3337238.7 | H14: ='MF OSAR'!I57 -> 2973493.2
B16: Debt Service (Excluding Rate Cap) | G16: 2914948.3 | H16: =(H5*H11)*(365/360) -> 2863478.1
B17: Debt Service (Including Rate Cap) | G17: 2914948.3 | H17: =(H5*H12)*(365/360) -> 2863478.1
B19: DSCR (Excluding Rate Cap) | G19: 1.1448706 | H19: =H14/H16 -> 1.0384201
B20: DSCR (Including Rate Cap) | G20: 1.1448706 | H20: =H14/H17 -> 1.0384201
B22: DY | G22: 0.070071023 | H22: =H14/H5 -> 0.062433565
B25: Notes:

Sheet QoQ Variance
A1: 1
D2: 4Q 2025 | H2: =RIGHT('DSCR Calc'!H2,7) -> 1Q 2026 | L2: QoQ ∆ | P2: Cash Management
C3: Property | D3: Occupancy | E3: NOI | F3: DY | G3: DSCR | H3: Occupancy | I3: NOI | J3: DY | K3: DSCR | L3: Occupancy | M3: NOI | N3: DY | O3: DSCR | P3: In CM? | Q3: Threshold
C4: Memorial Hills [1] | D4: 0.8896 | E4: 3337238.7 | F4: 0.070071023 | G4: 1.1448706 | H4: =+'MF OSAR'!I16 -> 0.8604 | I4: =+'MF OSAR'!I57 -> 2973493.2 | J4: =+'MF OSAR'!I73 -> 0.062433565 | K4: =+'MF OSAR'!I69 -> 1.0384201 | L4: =IF(H4="","-",H4-D4) -> -0.0292 | M4: =IF(I4="","-",I4-E4) -> -363745.49 | N4: =IF(J4="","-",J4-F4) -> -0.0076374575 | O4: =IF(K4="","-",K4-G4) -> -0.10645054 | P4: No | Q4: ='Old OSAR'!L69 -> 0.065
C6: Notes:
C7: [1] 3Q 2025 and 4Q 2025 metrics are based on annnualized T4 as of 09/30/2025 and annualized T7 as of 12/31/2025, respectively.
C8: NOI adjusted per the Loan Agreement.
C9: DSCR includes the benefit of the rate cap.
C10: DY declined 88bps QoQ, driven by a $297.8K (5%) drop in GPR. In February, a flood incident occurred at the Property, which resulted in various units being shifted offline. Consequently, occupancy dropped ~3% QoQ as remidiation work continues to the damaged units.

Sheet Operating Statement
S10: OSAR Code | V10: ='Old OSAR'!J14 -> 46022 | W10: Prior
C11: 04/30/2025 | D11: 05/31/2025 | E11: 06/30/2025 | F11: 07/31/2025 | G11: 08/31/2025 | H11: 09/30/2025 | I11: 10/31/2025 | J11: 11/30/2025 | K11: 12/31/2025 | L11: 01/31/2026 | M11: 02/28/2026 | N11: 03/31/2026 | Q11: T10 Annualized | U11: Line Item | V11: T10 | W11: T7
U12: Gross Potential Rent (3) | V12: =SUMIF($S:$S,U12,$Q:$Q) -> 7109950.2 | W12: 7325240
U13: Less: Vacancy Loss | V13: =SUMIF($S:$S,U13,$Q:$Q) -> -756218.51 | W13: -732311.73
U14: Base Rent (3) | V14: =SUMIF($S:$S,U14,$Q:$Q) -> 0 | W14: 0
Q15: =IF(O15="","",N15*12) | U15: Laundry/Vending Income | V15: =SUMIF($S:$S,U15,$Q:$Q) -> 0 | W15: 0
U16: Parking Income | V16: =SUMIF($S:$S,U16,$Q:$Q) -> 16272.576 | W16: 16552.286
U17: Other Income | V17: =SUMIF($S:$S,U17,$Q:$Q) -> 580172.36 | W17: =359760.69+245805.27 -> 605565.96
B19: INCOME
U20: Effective Gross Income | V20: =SUM(V12:V18) -> 6950176.6 | W20: 7215046.5 | Y20: =V20/W20-1 -> -0.036710771
B21: 4000-000 - Market Rent | C21: 0 | D21: 0 | E21: 899741.5 | F21: 604344 | G21: 600176 | H21: 599866 | I21: 592100 | J21: 594725 | K21: 595038 | L21: 594638 | M21: 596758 | N21: 599233 | Q21: =IFERROR(SUM(E21:N21)*(12/10),"") -> 7531943.4 | S21: =_xlfn.XLOOKUP($B21,Coding!$D:$D,Coding!$F:$F,"x") -> Gross Potential Rent (3)
B22: 4010-000 - Gain/Loss to Lease | C22: 0 | D22: 0 | E22: -39367.52 | F22: -16403.46 | G22: -12324.43 | H22: -11233.73 | I22: -274.56 | J22: -6168.23 | K22: -5337.08 | L22: -6218 | M22: -5778.44 | N22: -8758.25 | Q22: =IFERROR(SUM(E22:N22)*(12/10),"") -> -134236.44 | S22: =_xlfn.XLOOKUP($B22,Coding!$D:$D,Coding!$F:$F,"x") -> Gross Potential Rent (3) | U22: OPERATING EXPENSES
U23: Real Estate Taxes | V23: =SUMIF($S:$S,U23,$Q:$Q) -> 1521691.7 | W23: 1506316.6
B24: Gross Possible | C24: 0 | D24: 0 | E24: 860373.98 | F24: 587940.54 | G24: 587851.57 | H24: 588632.27 | I24: 591825.44 | J24: 588556.77 | K24: 589700.92 | L24: 588420 | M24: 590979.56 | N24: 590474.75 | Q24: =IFERROR(SUM(E24:N24)*(12/10),"") -> 7397707 | U24: Property Insurance | V24: =SUMIF($S:$S,U24,$Q:$Q) -> 68540.496 | W24: 103490.9
U25: Utilities | V25: =SUMIF($S:$S,U25,$Q:$Q) -> 423119.88 | W25: 382429.13
B26: LESS DEDUCTIONS | U26: Repairs and Maintenance | V26: =SUMIF($S:$S,U26,$Q:$Q) -> 333494.4 | W26: 343370.95
B27: 4100-000 - Vacancy Loss | C27: 0 | D27: 0 | E27: -52293.8 | F27: -51385.87 | G27: -52569.63 | H27: -61876.78 | I27: -62929.87 | J27: -65039.73 | K27: -81086.16 | L27: -69354.19 | M27: -52620.42 | N27: -49406.16 | Q27: =IFERROR(SUM(E27:N27)*(12/10),"") -> -718275.13 | S27: =_xlfn.XLOOKUP($B27,Coding!$D:$D,Coding!$F:$F,"x") -> Less: Vacancy Loss | U27: Management Fees | V27: =SUMIF($S:$S,U27,$Q:$Q) -> 125036.59 | W27: 129714.72
B28: 4101-000 - Vacancy-Down Units | C28: 0 | D28: 0 | E28: 0 | F28: 0 | G28: 0 | H28: 0 | I28: 0 | J28: 0 | K28: 0 | L28: 0 | M28: 0 | N28: -31619.48 | Q28: =IFERROR(SUM(E28:N28)*(12/10),"") -> -37943.376 | S28: =_xlfn.XLOOKUP($B28,Coding!$D:$D,Coding!$F:$F,"x") -> Less: Vacancy Loss | U28: Payroll & Benefits | V28: =SUMIF($S:$S,U28,$Q:$Q) -> 510450.74 | W28: 475945.49
B29: 4110-000 - Concessions Market | C29: 0 | D29: 0 | E29: -4460.5 | F29: -13342.5 | G29: -12728.82 | H29: -17006.02 | I29: -21037.15 | J29: 79907.99 | K29: -14200 | L29: 0 | M29: 0 | N29: -8386.75 | Q29: =IFERROR(SUM(E29:N29)*(12/10),"") -> -13504.5 | S29: =_xlfn.XLOOKUP($B29,Coding!$D:$D,Coding!$F:$F,"x") -> Gross Potential Rent (3) | U29: Advertising & Marketing | V29: =SUMIF($S:$S,U29,$Q:$Q) -> 233007.19 | W29: 216404.33
B30: 4110-100 - Concessions-One Time | C30: 0 | D30: 0 | E30: 0 | F30: 0 | G30: -100 | H30: 0 | I30: -1000 | J30: -91240.99 | K30: -5579 | L30: -17874.11 | M30: -29857.75 | N30: -2586 | Q30: =IFERROR(SUM(E30:N30)*(12/10),"") -> -177885.42 | S30: =_xlfn.XLOOKUP($B30,Coding!$D:$D,Coding!$F:$F,"x") -> Gross Potential Rent (3) | U30: Professional Fees | V30: =SUMIF($S:$S,U30,$Q:$Q) -> 5848.896 | W30: 8355.5657
B31: 4110-300 - Concessions -Other | C31: 0 | D31: 0 | E31: 0 | F31: -1000 | G31: -275 | H31: -75.78 | I31: 0 | J31: 0 | K31: 0 | L31: -750 | M31: -225 | N31: -50876.89 | Q31: =IFERROR(SUM(E31:N31)*(12/10),"") -> -63843.204 | S31: =_xlfn.XLOOKUP($B31,Coding!$D:$D,Coding!$F:$F,"x") -> Gross Potential Rent (3) | U31: General and Administrative | V31: =SUMIF($S:$S,U31,$Q:$Q) -> 82527.912 | W31: 63131.743
B32: 4120-000 - Model/Guest Suite | C32: 0 | D32: 0 | E32: -1340 | F32: -3043 | G32: -4041 | H32: -2689.63 | I32: -1645 | J32: -1725 | K32: -3193.65 | L32: -3622 | M32: -1897 | N32: -1897 | Q32: =IFERROR(SUM(E32:N32)*(12/10),"") -> -30111.936 | S32: =_xlfn.XLOOKUP($B32,Coding!$D:$D,Coding!$F:$F,"x") -> Gross Potential Rent (3) | U32: Other Expenses | V32: =SUMIF($S:$S,U32,$Q:$Q) -> 0 | W32: 0
B33: 4130-000 - Employee Units | C33: 0 | D33: 0 | E33: -121.76 | F33: -472 | G33: -472 | H33: -472 | I33: -472 | J33: 0 | K33: 0 | L33: 0 | M33: 0 | N33: 0 | Q33: =IFERROR(SUM(E33:N33)*(12/10),"") -> -2411.712 | S33: =_xlfn.XLOOKUP($B33,Coding!$D:$D,Coding!$F:$F,"x") -> Gross Potential Rent (3) | U33: Ground Rent | V33: =SUMIF($S:$S,U33,$Q:$Q) -> 0 | W33: 0
W34: 0
B35: Total Deductions | C35: 0 | D35: 0 | E35: -58216.06 | F35: -69243.37 | G35: -70186.45 | H35: -82120.21 | I35: -87084.02 | J35: -78097.73 | K35: -104058.81 | L35: -91600.3 | M35: -84600.17 | N35: -144772.28 | Q35: =IFERROR(SUM(E35:N35)*(12/10),"") -> -1043975.3 | U35: Total Operating Expenses | V35: =SUM(V23:V34) -> 3303717.8 | W35: 3229159.5 | Y35: =V35/W35-1 -> 0.023089071
B37: EFFECTIVE ECONOMIC OCCUPANCY | C37: 0 | D37: 0 | E37: 802157.92 | F37: 518697.17 | G37: 517665.12 | H37: 506512.06 | I37: 504741.42 | J37: 510459.04 | K37: 485642.11 | L37: 496819.7 | M37: 506379.39 | N37: 445702.47 | Q37: =IFERROR(SUM(E37:N37)*(12/10),"") -> 6353731.7 | U37: NOI | V37: =V20-V35 -> 3646458.9 | W37: 3985887.1 | Y37: =V37/W37-1 -> -0.08515751
B39: 4140-000 - Rent Write Off | C39: 0 | D39: 0 | E39: -277.84 | F39: 47.19 | G39: -1110.37 | H39: -2067.11 | I39: -210.13 | J39: -4356.76 | K39: 303.92 | L39: -7347.68 | M39: 89.72 | N39: -595.36 | Q39: =IFERROR(SUM(E39:N39)*(12/10),"") -> -18629.304 | S39: =_xlfn.XLOOKUP($B39,Coding!$D:$D,Coding!$F:$F,"x") -> Other Income | U39: Non-Operating Expenses | V39: =SUMIF($S:$S,U39,$O:$O)*12 -> 0 | W39: 0
U40: Interest Expense | V40: =SUMIF($S:$S,U40,$O:$O)*12 -> 0 | W40: 0
B41: . | C41: 0 | D41: 0 | E41: -277.84 | F41: 47.19 | G41: -1110.37 | H41: -2067.11 | I41: -210.13 | J41: -4356.76 | K41: 303.92 | L41: -7347.68 | M41: 89.72 | N41: -595.36 | Q41: =IFERROR(SUM(E41:N41)*(12/10),"") -> -18629.304 | U41: Debt Service | V41: =SUMIF($S:$S,U41,$O:$O)*12 -> 0 | W41: 0
B43: Total Rental Income | C43: 0 | D43: 0 | E43: 801880.08 | F43: 518744.36 | G43: 516554.75 | H43: 504444.95 | I43: 504531.29 | J43: 506102.28 | K43: 485946.03 | L43: 489472.02 | M43: 506469.11 | N43: 445107.11 | Q43: =IFERROR(SUM(E43:N43)*(12/10),"") -> 6335102.4 | U43: Non-Recurring Expenses
U44: HVAC R&M
B45: OTHER INCOME | U45: Plumbing R&M
B46: 4200-000 - Application Fees | C46: 0 | D46: 0 | E46: 600 | F46: 450 | G46: 525 | H46: 450 | I46: 450 | J46: 600 | K46: 1275 | L46: 1050 | M46: 1725 | N46: 75 | Q46: =IFERROR(SUM(E46:N46)*(12/10),"") -> 8640 | S46: =_xlfn.XLOOKUP($B46,Coding!$D:$D,Coding!$F:$F,"x") -> Other Income | U46: FLS R&M
B47: 4201-000 - Administrative Fees | C47: 0 | D47: 0 | E47: 4339.93 | F47: 400 | G47: 1213.95 | H47: 1400 | I47: -200 | J47: 675 | K47: 400 | L47: 0 | M47: 1050 | N47: 0 | Q47: =IFERROR(SUM(E47:N47)*(12/10),"") -> 11134.656 | S47: =_xlfn.XLOOKUP($B47,Coding!$D:$D,Coding!$F:$F,"x") -> Other Income | U47: Bldg Interior - Painting
B48: 4205-000 - Month to Month Fees | C48: 0 | D48: 0 | E48: 1703.34 | F48: 926.17 | G48: 925.82 | H48: 2302.86 | I48: 1823.39 | J48: 1369.51 | K48: 1173.83 | L48: 1908.07 | M48: 603.23 | N48: 2267.73 | Q48: =IFERROR(SUM(E48:N48)*(12/10),"") -> 18004.74 | S48: =_xlfn.XLOOKUP($B48,Coding!$D:$D,Coding!$F:$F,"x") -> Other Income | U48: Tree Trimming
B49: 4210-000 - Late Fees | C49: 0 | D49: 0 | E49: 3121.89 | F49: 2173.34 | G49: 1134.35 | H49: 969.56 | I49: 2007.31 | J49: 736.25 | K49: 1385.22 | L49: 307.34 | M49: 1204.75 | N49: 1144.2 | Q49: =IFERROR(SUM(E49:N49)*(12/10),"") -> 17021.052 | S49: =_xlfn.XLOOKUP($B49,Coding!$D:$D,Coding!$F:$F,"x") -> Other Income | U49: Bldg Exterior R&M
B50: 4211-000 - NSF Fees | C50: 0 | D50: 0 | E50: 200 | F50: -100 | G50: 400 | H50: 400 | I50: 500 | J50: 0 | K50: 100 | L50: 77.38 | M50: 200 | N50: 100 | Q50: =IFERROR(SUM(E50:N50)*(12/10),"") -> 2252.856 | S50: =_xlfn.XLOOKUP($B50,Coding!$D:$D,Coding!$F:$F,"x") -> Other Income | U50: T12 Total
B51: 4238-000 - Amenity Fee | C51: 0 | D51: 0 | E51: 0 | F51: 0 | G51: 5390 | H51: 0 | I51: 9824.1 | J51: -24995.33 | K51: 0 | L51: 0 | M51: 4281.93 | N51: 0 | Q51: =IFERROR(SUM(E51:N51)*(12/10),"") -> -6599.16 | S51: =_xlfn.XLOOKUP($B51,Coding!$D:$D,Coding!$F:$F,"x") -> Other Income
B52: 4244-000 - Cleaning/Damages | C52: 0 | D52: 0 | E52: 125 | F52: 0 | G52: 0 | H52: 135.89 | I52: 1190 | J52: 0 | K52: 215.31 | L52: 300 | M52: 108.08 | N52: 0 | Q52: =IFERROR(SUM(E52:N52)*(12/10),"") -> 2489.136 | S52: =_xlfn.XLOOKUP($B52,Coding!$D:$D,Coding!$F:$F,"x") -> Other Income
B53: 4252-000 - Legal Fees | C53: 0 | D53: 0 | E53: 0 | F53: 368 | G53: 184 | H53: 224 | I53: -1127.9 | J53: 224 | K53: -845.48 | L53: -363 | M53: 278 | N53: 0 | Q53: =IFERROR(SUM(E53:N53)*(12/10),"") -> -1270.056 | S53: =_xlfn.XLOOKUP($B53,Coding!$D:$D,Coding!$F:$F,"x") -> Other Income | U53: NOI Check | V53: =V37+Q38 -> 3646458.9
...

Sheet Rent Roll
A1: ASSET LIVING SOUTHEAST, LLC dba JMG REALTY LLC - Memorial Hills
A2: RENT ROLL DETAIL
A3: 05/15/2026 04:22 PM
A4: As of Date: 03/31/2025
A5: Parameters: Properties: - all subproperties-; Show All Unit Designations or Filter by: ALL; Subjournals: ALL; Sort by: Unit; Report Type: Details + Summary; Exclude Formers?: Yes; Show Unit Rent as: Market Rent
A6: Resh ID | B6: Lease ID | C6: Unit | D6: Floorplan | E6: Unit Designation | F6: SQFT | G6: Unit/Lease Status | H6: Name | I6: Move-In | J6: Move-Out | K6: Lease Start | L6: Lease End | M6: Market + Addl. | N6: Required Deposit | O6: Dep On Hand | P6: Balance | Q6: Lease Rent | R6: RENT | S6: TRV | T6: GAS | U6: PACKAGE | V6: AMEN | W6: PET RENT | X6: CARPORT | Y6: TECH FEE | Z6: UTL | AA6: MTOM | AB6: CONo | AC6: CON | AD6: PST | AE6: MOD | AF6: Total Billing
A7: 69 | B7: 424 | C7: 104 | D7: A9b | E7: Conventional | F7: 892 | G7: Occupied | H7: Castro, Sergio | I7: 07/04/2021 | K7: 08/04/2025 | L7: 09/07/2026 | M7: 2025.6 | N7: 0 | O7: 0 | P7: 89.6 | Q7: 1696 | R7: 1696 | S7: 25 | T7: 12.6 | U7: 17 | V7: 20 | W7: 25 | X7: 35 | Y7: 0 | Z7: 0 | AA7: 0 | AB7: 0 | AC7: 0 | AD7: 0 | AE7: 0 | AF7: 1830.6
A8: 171 | B8: 616 | C8: 105 | D8: A10c | E8: Conventional | F8: 1036 | G8: Occupied | H8: Nelson, Ryan | I8: 02/01/2026 | K8: 02/01/2026 | L8: 01/31/2027 | M8: 2370.6 | N8: 0 | O8: 0 | P8: 0 | Q8: 2236 | R8: 2236 | S8: 30 | T8: 12.6 | U8: 22 | V8: 20 | W8: 25 | X8: 35 | Y8: 0 | Z8: 0 | AA8: 0 | AB8: 0 | AC8: 0 | AD8: 0 | AE8: 0 | AF8: 2380.6
A9: 431 | B9: 633 | C9: 106 | D9: B1 | E9: Conventional | F9: 1156 | G9: Occupied | H9: Pumala, Chelsea | I9: 03/21/2026 | K9: 03/21/2026 | L9: 03/20/2027 | M9: 2533.6 | N9: 250 | O9: 250 | P9: 0 | Q9: 2124 | R9: 2124 | S9: 30 | T9: 12.6 | U9: 22 | V9: 20 | W9: 0 | X9: 0 | Y9: 50 | Z9: 0 | AA9: 0 | AB9: 0 | AC9: 0 | AD9: 0 | AE9: 0 | AF9: 2258.6
A10: 160 | B10: 447 | C10: 107 | D10: A13 | E10: Conventional | F10: 1000 | G10: Occupied | H10: Breese, Matt | I10: 08/17/2023 | K10: 07/17/2025 | L10: 07/16/2026 | M10: 2070.6 | N10: 0 | O10: 0 | P10: 57.35 | Q10: 1737 | R10: 1737 | S10: 25 | T10: 12.6 | U10: 17 | V10: 20 | W10: 0 | X10: 0 | Y10: 0 | Z10: 0 | AA10: 0 | AB10: 0 | AC10: 0 | AD10: 0 | AE10: 0 | AF10: 1811.6
A11: 329 | B11: 356 | C11: 108 | D11: B1b | E11: Conventional | F11: 1211 | G11: Occupied | H11: Perez Alvarez, Leonardo | I11: 07/01/2025 | K11: 07/01/2025 | L11: 06/30/2026 | M11: 2363.6 | N11: 0 | O11: 0 | P11: 85.29 | Q11: 2304 | R11: 2304 | S11: 25 | T11: 12.6 | U11: 0 | V11: 0 | W11: 0 | X11: 50 | Y11: 0 | Z11: 0 | AA11: 0 | AB11: 0 | AC11: 0 | AD11: 0 | AE11: 0 | AF11: 2391.6
A12: 394 | B12: 564 | C12: 109 | D12: A5a | E12: Conventional | F12: 730 | G12: Occupied | H12: Maldonado, Arely | I12: 01/23/2026 | K12: 01/23/2026 | L12: 01/22/2027 | M12: 1571.6 | N12: 500 | O12: 500 | P12: 0 | Q12: 1437 | R12: 1437 | S12: 30 | T12: 12.6 | U12: 22 | V12: 0 | W12: 0 | X12: 0 | Y12: 0 | Z12: 0 | AA12: 0 | AB12: 0 | AC12: 0 | AD12: 0 | AE12: 0 | AF12: 1501.6
A13: 0 | B13: 0 | C13: 110 | D13: B1 | E13: Conventional | F13: 1156 | G13: Vacant-Leased | H13: VACANT | M13: 2533.6 | N13: 0 | O13: 0 | P13: 0 | Q13: 0 | R13: 0 | S13: 0 | T13: 0 | U13: 0 | V13: 0 | W13: 0 | X13: 0 | Y13: 0 | Z13: 0 | AA13: 0 | AB13: 0 | AC13: 0 | AD13: 0 | AE13: 0 | AF13: 0
A14: 441 | B14: 691 | C14: 110 | D14: B1 | E14: Conventional | F14: 1156 | G14: Applicant | H14: Olson, Corey | I14: 04/18/2026 | K14: 04/18/2026 | L14: 04/17/2027 | M14: 0 | N14: 250 | O14: 0 | P14: -250 | Q14: 2399 | R14: 2399 | S14: 30 | T14: 12.6 | U14: 22 | V14: 20 | W14: 0 | X14: 0 | Y14: 50 | Z14: 0 | AA14: 0 | AB14: 0 | AC14: 0 | AD14: 0 | AE14: 0 | AF14: 2533.6
A15: 30 | B15: 682 | C15: 111 | D15: B1c | E15: Conventional | F15: 1102 | G15: Occupied | H15: Suarato, Alison | I15: 03/11/2026 | K15: 03/11/2026 | L15: 04/12/2026 | M15: 2488.6 | N15: 250 | O15: 250 | P15: -935.88 | Q15: 2354 | R15: 2354 | S15: 30 | T15: 12.6 | U15: 22 | V15: 20 | W15: 30 | X15: 0 | Y15: 0 | Z15: 0 | AA15: 0 | AB15: 0 | AC15: 0 | AD15: 0 | AE15: 0 | AF15: 2468.6
A16: 401 | B16: 580 | C16: 112 | D16: A11 | E16: Conventional | F16: 908 | G16: Occupied | H16: Fields, Roshanti | I16: 01/02/2026 | K16: 01/02/2026 | L16: 01/02/2027 | M16: 1522.6 | N16: 250 | O16: 250 | P16: 0 | Q16: 1388 | R16: 1388 | S16: 30 | T16: 12.6 | U16: 22 | V16: 0 | W16: 0 | X16: 0 | Y16: 0 | Z16: 0 | AA16: 0 | AB16: 0 | AC16: 0 | AD16: 0 | AE16: 0 | AF16: 1452.6
A17: 111 | B17: 117 | C17: 113 | D17: A6a | E17: Conventional | F17: 791 | G17: Occupied | H17: Brittain III, David | I17: 11/16/2022 | K17: 04/16/2025 | L17: 04/15/2026 | M17: 1791.6 | N17: 0 | O17: 0 | P17: 73.89 | Q17: 1761 | R17: 1761 | S17: 25 | T17: 11.5 | U17: 20 | V17: 20 | W17: 0 | X17: 35 | Y17: 0 | Z17: 0 | AA17: 0 | AB17: 0 | AC17: 0 | AD17: 0 | AE17: 0 | AF17: 1872.5
A18: 248 | B18: 670 | C18: 114 | D18: A9d | E18: Conventional | F18: 958 | G18: Occupied | H18: Scheurich, Alissa | I18: 02/26/2026 | K18: 02/26/2026 | L18: 08/03/2026 | M18: 2280.6 | N18: 0 | O18: 0 | P18: -1708.62 | Q18: 2146 | R18: 2146 | S18: 30 | T18: 12.6 | U18: 22 | V18: 20 | W18: 50 | X18: 0 | Y18: 50 | Z18: 0 | AA18: 0 | AB18: -2059.61 | AC18: 0 | AD18: 0 | AE18: 0 | AF18: 270.99
A19: 37 | B19: 38 | C19: 115 | D19: A3 | E19: Conventional | F19: 609 | G19: Occupied | H19: Bowden, Alethe | I19: 10/18/2019 | K19: 03/27/2025 | L19: 06/26/2026 | M19: 1631.6 | N19: 0 | O19: 0 | P19: 64.09 | Q19: 1493 | R19: 1493 | S19: 25 | T19: 12.6 | U19: 21 | V19: 20 | W19: 0 | X19: 0 | Y19: 0 | Z19: 0 | AA19: 0 | AB19: 0 | AC19: 0 | AD19: 0 | AE19: 0 | AF19: 1571.6
A20: 35 | B20: 416 | C20: 116 | D20: A9 | E20: Conventional | F20: 813 | G20: Occupied-NTV | H20: Stone, Brittany | I20: 05/04/2019 | J20: 04/03/2026 | K20: 07/26/2025 | L20: 02/25/2026 | M20: 2195.6 | N20: 0 | O20: 0 | P20: 83.17 | Q20: 2026 | R20: 2026 | S20: 30 | T20: 12.6 | U20: 22 | V20: 20 | W20: 0 | X20: 0 | Y20: 0 | Z20: 0 | AA20: 350 | AB20: 0 | AC20: 0 | AD20: 0 | AE20: 0 | AF20: 2460.6
A21: 0 | B21: 0 | C21: 121 | D21: A6b | E21: Conventional | F21: 728 | G21: Admin/Down | H21: VACANT | M21: 1891.6 | N21: 0 | O21: 0 | P21: 0 | Q21: 0 | R21: 0 | S21: 0 | T21: 0 | U21: 0 | V21: 0 | W21: 0 | X21: 0 | Y21: 0 | Z21: 0 | AA21: 0 | AB21: 0 | AC21: 0 | AD21: 0 | AE21: 0 | AF21: 0
A22: 0 | B22: 0 | C22: 122 | D22: A8 | E22: Conventional | F22: 787 | G22: Admin/Down | H22: VACANT | M22: 1814.6 | N22: 0 | O22: 0 | P22: 0 | Q22: 0 | R22: 0 | S22: 0 | T22: 0 | U22: 0 | V22: 0 | W22: 0 | X22: 0 | Y22: 0 | Z22: 0 | AA22: 0 | AB22: 0 | AC22: 0 | AD22: 0 | AE22: 0 | AF22: 0
A23: 0 | B23: 0 | C23: 123 | D23: A10b | E23: Conventional | F23: 1037 | G23: Admin/Down | H23: VACANT | M23: 1859.6 | N23: 0 | O23: 0 | P23: 0 | Q23: 0 | R23: 0 | S23: 0 | T23: 0 | U23: 0 | V23: 0 | W23: 0 | X23: 0 | Y23: 0 | Z23: 0 | AA23: 0 | AB23: 0 | AC23: 0 | AD23: 0 | AE23: 0 | AF23: 0
A24: 0 | B24: 0 | C24: 124 | D24: A12 | E24: Conventional | F24: 937 | G24: Admin/Down | H24: VACANT | M24: 1985.6 | N24: 0 | O24: 0 | P24: 0 | Q24: 0 | R24: 0 | S24: 0 | T24: 0 | U24: 0 | V24: 0 | W24: 0 | X24: 0 | Y24: 0 | Z24: 0 | AA24: 0 | AB24: 0 | AC24: 0 | AD24: 0 | AE24: 0 | AF24: 0
A25: 0 | B25: 0 | C25: 125 | D25: B3 | E25: Conventional | F25: 1219 | G25: Admin/Down | H25: VACANT | M25: 2418.6 | N25: 0 | O25: 0 | P25: 0 | Q25: 0 | R25: 0 | S25: 0 | T25: 0 | U25: 0 | V25: 0 | W25: 0 | X25: 0 | Y25: 0 | Z25: 0 | AA25: 0 | AB25: 0 | AC25: 0 | AD25: 0 | AE25: 0 | AF25: 0
A26: 0 | B26: 0 | C26: 126 | D26: B6 | E26: Conventional | F26: 1429 | G26: Admin/Down | H26: VACANT | M26: 2308.6 | N26: 0 | O26: 0 | P26: 0 | Q26: 0 | R26: 0 | S26: 0 | T26: 0 | U26: 0 | V26: 0 | W26: 0 | X26: 0 | Y26: 0 | Z26: 0 | AA26: 0 | AB26: 0 | AC26: 0 | AD26: 0 | AE26: 0 | AF26: 0
A27: 124 | B27: 131 | C27: 127 | D27: A4 | E27: Conventional | F27: 698 | G27: Occupied | H27: Quinn, Megan | I27: 04/01/2023 | K27: 04/01/2025 | L27: 03/31/2026 | M27: 1806.6 | N27: 0 | O27: 0 | P27: -413.67 | Q27: 1730 | R27: 1730 | S27: 25 | T27: 12.6 | U27: 21 | V27: 20 | W27: 30 | X27: 0 | Y27: 0 | Z27: 0 | AA27: 0 | AB27: 0 | AC27: 0 | AD27: 0 | AE27: 0 | AF27: 1838.6
A28: 0 | B28: 0 | C28: 128 | D28: A2 | E28: Conventional | F28: 645 | G28: Admin/Down | H28: VACANT | M28: 1636.6 | N28: 0 | O28: 0 | P28: 0 | Q28: 0 | R28: 0 | S28: 0 | T28: 0 | U28: 0 | V28: 0 | W28: 0 | X28: 0 | Y28: 0 | Z28: 0 | AA28: 0 | AB28: 0 | AC28: 0 | AD28: 0 | AE28: 0 | AF28: 0
A29: 402 | B29: 582 | C29: 129 | D29: A4 | E29: Conventional | F29: 698 | G29: Occupied | H29: Model, Model | I29: 12/08/2025 | K29: 12/08/2025 | L29: 12/07/2026 | M29: 2031.6 | N29: 0 | O29: 0 | P29: -1871.16 | Q29: 0 | R29: 0 | S29: 0 | T29: 0 | U29: 0 | V29: 0 | W29: 0 | X29: 0 | Y29: 0 | Z29: 0 | AA29: 0 | AB29: 0 | AC29: 0 | AD29: 0 | AE29: -1897 | AF29: -1897
A30: 0 | B30: 0 | C30: 130 | D30: A7 | E30: Conventional | F30: 731 | G30: Admin/Down | H30: VACANT | M30: 1756.6 | N30: 0 | O30: 0 | P30: 0 | Q30: 0 | R30: 0 | S30: 0 | T30: 0 | U30: 0 | V30: 0 | W30: 0 | X30: 0 | Y30: 0 | Z30: 0 | AA30: 0 | AB30: 0 | AC30: 0 | AD30: 0 | AE30: 0 | AF30: 0
A31: 326 | B31: 353 | C31: 131 | D31: B5 | E31: Conventional | F31: 1399 | G31: Occupied | H31: Perez, Jennifer | I31: 06/04/2025 | K31: 06/04/2025 | L31: 06/08/2026 | M31: 2713.6 | N31: 0 | O31: 0 | P31: 93.47 | Q31: 2579 | R31: 2579 | S31: 25 | T31: 12.6 | U31: 0 | V31: 0 | W31: 25 | X31: 0 | Y31: 0 | Z31: 0 | AA31: 0 | AB31: 0 | AC31: 0 | AD31: 0 | AE31: 0 | AF31: 2641.6
A32: 208 | B32: 226 | C32: 132 | D32: A1 | E32: Conventional | F32: 570 | G32: Occupied | H32: Richey, Hudson | I32: 03/05/2024 | K32: 05/04/2025 | L32: 08/03/2026 | M32: 1576.6 | N32: 0 | O32: 0 | P32: 79.92 | Q32: 1457 | R32: 1457 | S32: 25 | T32: 11.5 | U32: 17 | V32: 20 | W32: 0 | X32: 0 | Y32: 0 | Z32: 0 | AA32: 0 | AB32: 0 | AC32: 0 | AD32: 0 | AE32: 0 | AF32: 1530.5
A33: 231 | B33: 257 | C33: 133 | D33: A7 | E33: Conventional | F33: 731 | G33: Occupied | H33: Bazzle, Jennifer | I33: 06/24/2024 | K33: 06/24/2025 | L33: 06/23/2026 | M33: 1771.6 | N33: 0 | O33: 0 | P33: -1756.2 | Q33: 1686 | R33: 1686 | S33: 25 | T33: 12.6 | U33: 21 | V33: 20 | W33: 0 | X33: 0 | Y33: 0 | Z33: 0 | AA33: 0 | AB33: 0 | AC33: 0 | AD33: 0 | AE33: 0 | AF33: 1764.6
A34: 286 | B34: 613 | C34: 134 | D34: A5 | E34: Conventional | F34: 698 | G34: Occupied | H34: Sandonato, Austin | I34: 11/26/2024 | K34: 01/01/2026 | L34: 06/30/2026 | M34: 1806.6 | N34: 0 | O34: 0 | P34: 28.32 | Q34: 1822 | R34: 1822 | S34: 30 | T34: 12.6 | U34: 22 | V34: 20 | W34: 30 | X34: 0 | Y34: 0 | Z34: 0 | AA34: 0 | AB34: 0 | AC34: 0 | AD34: 0 | AE34: 0 | AF34: 1936.6
A35: 396 | B35: 566 | C35: 135 | D35: A5 | E35: Conventional | F35: 698 | G35: Occupied | H35: Spuches, Maria | I35: 12/20/2025 | K35: 12/20/2025 | L35: 12/19/2026 | M35: 1656.6 | N35: 250 | O35: 250 | P35: 46.94 | Q35: 1522 | R35: 1522 | S35: 30 | T35: 12.6 | U35: 22 | V35: 0 | W35: 0 | X35: 0 | Y35: 0 | Z35: 0 | AA35: 0 | AB35: 0 | AC35: 0 | AD35: 0 | AE35: 0 | AF35: 1586.6
A36: 27 | B36: 530 | C36: 136 | D36: A13 | E36: Conventional | F36: 1000 | G36: Occupied | H36: Heard, Nehemiah | I36: 02/26/2018 | K36: 10/27/2025 | L36: 04/27/2026 | M36: 2070.6 | N36: 350 | O36: 350 | P36: 42.34 | Q36: 2024 | R36: 2024 | S36: 30 | T36: 12.6 | U36: 22 | V36: 20 | W36: 25 | X36: 35 | Y36: 0 | Z36: 0 | AA36: 0 | AB36: 0 | AC36: 0 | AD36: 0 | AE36: 0 | AF36: 2168.6
A37: 250 | B37: 546 | C37: 137 | D37: A5 | E37: Conventional | F37: 698 | G37: Occupied | H37: Cornavaca, Julio | I37: 08/15/2024 | K37: 11/15/2025 | L37: 02/15/2027 | M37: 1806.6 | N37: 0 | O37: 0 | P37: 96.57 | Q37: 1722 | R37: 1722 | S37: 30 | T37: 12.6 | U37: 22 | V37: 20 | W37: 30 | X37: 35 | Y37: 0 | Z37: 0 | AA37: 0 | AB37: 0 | AC37: 0 | AD37: 0 | AE37: 0 | AF37: 1871.6
A38: 225 | B38: 247 | C38: 138 | D38: A10 | E38: Conventional | F38: 934 | G38: Occupied | H38: Batemon, Jeremy | I38: 06/06/2024 | K38: 06/05/2025 | L38: 06/04/2026 | M38: 2065.6 | N38: 1756 | O38: 1756 | P38: 101.54 | Q38: 1896 | R38: 1896 | S38: 25 | T38: 12.6 | U38: 21 | V38: 20 | W38: 0 | X38: 35 | Y38: 0 | Z38: 0 | AA38: 0 | AB38: 0 | AC38: 0 | AD38: 0 | AE38: 0 | AF38: 2009.6
A39: 84 | B39: 88 | C39: 139 | D39: A12 | E39: Conventional | F39: 937 | G39: Occupied | H39: Travis, Amelia | I39: 02/15/2022 | K39: 02/01/2025 | L39: 03/31/2026 | M39: 1985.6 | N39: 0 | O39: 0 | P39: 63.07 | Q39: 1793 | R39: 1793 | S39: 25 | T39: 12.6 | U39: 20 | V39: 20 | W39: 0 | X39: 35 | Y39: 0 | Z39: 0 | AA39: 0 | AB39: 0 | AC39: 0 | AD39: 0 | AE39: 0 | AF39: 1905.6
A40: 380 | B40: 534 | C40: 140 | D40: B4 | E40: Conventional | F40: 1235 | G40: Occupied | H40: Contreras, Luz | I40: 11/07/2025 | K40: 11/07/2025 | L40: 01/06/2027 | M40: 2493.6 | N40: 250 | O40: 250 | P40: 0 | Q40: 2359 | R40: 2359 | S40: 30 | T40: 12.6 | U40: 22 | V40: 0 | W40: 0 | X40: 0 | Y40: 0 | Z40: 0 | AA40: 0 | AB40: 0 | AC40: 0 | AD40: 0 | AE40: 0 | AF40: 2423.6
...

Sheet Paydown Analysis
B2: Paydown Analysis
B3: Arboretum at South Mountain | D3: ='DSCR Calc'!H3 -> 46112
B4: Current DY | D4: ='DSCR Calc'!H22 -> 0.062433565
B5: Target DY | D5: 0.0625
B7: Current Principal | D7: ='DSCR Calc'!H5 -> 47626516
B8: Paydown | D8: -22020120
B9: Adjusted Principal | D9: =D7+D8 -> 25606396
B11: Current Net Cash Flow | D11: ='DSCR Calc'!H14 -> 2973493.2
B13: Resulting DY | D13: =D11/D9 -> 0.11612306

Sheet Aged Receivables
A1: ASSET LIVING SOUTHEAST, LLC dba JMG REALTY LLC - Memorial Hills - Central DELINQUENT AND PREPAID FISCAL PERIOD 032026 AS OF 05/17/2026 05/19/2026 09:16 AM Parameters: Report Type: Details Subproperties: ALL Subjournals: ALL Statuses to include: Applicant,Approved applicant,Former applicant,Pending resident,Current resident,Former resident; Include delinquencies that equal NTV Credit? Yes; Exclude transactions payable in arrears: Yes; Delinquency range 0.00 through 99999999.00; Aging Columns: Fiscal; Filter type: ALL; Show Prepaid As Allocated: No; Include outstanding deposits: No; Hide all PII data: No; Delinquent Comments: Current only
A2: Resh ID | B2: Lease ID | C2: Bldg/Unit | D2: Name | E2: Phone Number | F2: Email | G2: Status | H2: Move-In/Out | I2: Code Description | J2: Total Prepaid | K2: Total Delinquent | L2: D | M2: O | N2: Net Balance | O2: Current | P2: 30 Days | Q2: 60 Days | R2: 90+ Days | S2: Prorate Credit | T2: Deposits Held | U2: Outstanding Deposit | V2: #Late | W2: #NSF | X2: Comment Date | Y2: Leasing Agent
A3: 69 | B3: 424 | C3: 104 | D3: Castro, Sergio | E3: N/A | F3: Castrosergio3000@gmail.com | G3: Current resident | H3: 07/04/2021 | I3: GAS | J3: 0 | K3: 8.64 | N3: 8.64 | O3: 8.64 | P3: 0 | Q3: 0 | R3: 0 | S3: 0 | T3: 0 | U3: 0 | V3: 1 | W3: 0
A4: 69 | B4: 424 | C4: 104 | D4: Castro, Sergio | E4: N/A | F4: Castrosergio3000@gmail.com | G4: Current resident | H4: 07/04/2021 | I4: PST | J4: 0 | K4: 6.5 | N4: 6.5 | O4: 6.5 | P4: 0 | Q4: 0 | R4: 0 | S4: 0 | T4: 0 | U4: 0 | V4: 1 | W4: 0
A5: 69 | B5: 424 | C5: 104 | D5: Castro, Sergio | E5: N/A | F5: Castrosergio3000@gmail.com | G5: Current resident | H5: 07/04/2021 | I5: TRV | J5: 0 | K5: 9.83 | N5: 9.83 | O5: 9.83 | P5: 0 | Q5: 0 | R5: 0 | S5: 0 | T5: 0 | U5: 0 | V5: 1 | W5: 0
A6: 69 | B6: 424 | C6: 104 | D6: Castro, Sergio | E6: N/A | F6: Castrosergio3000@gmail.com | G6: Current resident | H6: 07/04/2021 | I6: WSR | J6: 0 | K6: 64.63 | N6: 64.63 | O6: 64.63 | P6: 0 | Q6: 0 | R6: 0 | S6: 0 | T6: 0 | U6: 0 | V6: 1 | W6: 0
A7: 160 | B7: 447 | C7: 107 | D7: Breese, Matt Thomas | E7: N/A | F7: mtbreese1@gmail.com | G7: Current resident | H7: 08/17/2023 | I7: GAS | J7: 0 | K7: 5.25 | N7: 5.25 | O7: 5.25 | P7: 0 | Q7: 0 | R7: 0 | S7: 0 | T7: 0 | U7: 0 | V7: 0 | W7: 0
A8: 160 | B8: 447 | C8: 107 | D8: Breese, Matt Thomas | E8: N/A | F8: mtbreese1@gmail.com | G8: Current resident | H8: 08/17/2023 | I8: PST | J8: 0 | K8: 6.5 | N8: 6.5 | O8: 6.5 | P8: 0 | Q8: 0 | R8: 0 | S8: 0 | T8: 0 | U8: 0 | V8: 0 | W8: 0
A9: 160 | B9: 447 | C9: 107 | D9: Breese, Matt Thomas | E9: N/A | F9: mtbreese1@gmail.com | G9: Current resident | H9: 08/17/2023 | I9: TRV | J9: 0 | K9: 9.83 | N9: 9.83 | O9: 9.83 | P9: 0 | Q9: 0 | R9: 0 | S9: 0 | T9: 0 | U9: 0 | V9: 0 | W9: 0
A10: 160 | B10: 447 | C10: 107 | D10: Breese, Matt Thomas | E10: N/A | F10: mtbreese1@gmail.com | G10: Current resident | H10: 08/17/2023 | I10: WSR | J10: 0 | K10: 35.77 | N10: 35.77 | O10: 35.77 | P10: 0 | Q10: 0 | R10: 0 | S10: 0 | T10: 0 | U10: 0 | V10: 0 | W10: 0
A11: 329 | B11: 356 | C11: 108 | D11: Perez Alvarez, Leonardo Alberto | E11: (786) 757-1399 | F11: perezleo74@gmail.com | G11: Current resident | H11: 07/01/2025 | I11: GAS | J11: 0 | K11: 11.42 | N11: 11.42 | O11: 11.42 | P11: 0 | Q11: 0 | R11: 0 | S11: 0 | T11: 0 | U11: 0 | V11: 2 | W11: 0
A12: 329 | B12: 356 | C12: 108 | D12: Perez Alvarez, Leonardo Alberto | E12: (786) 757-1399 | F12: perezleo74@gmail.com | G12: Current resident | H12: 07/01/2025 | I12: PST | J12: 0 | K12: 5 | N12: 5 | O12: 5 | P12: 0 | Q12: 0 | R12: 0 | S12: 0 | T12: 0 | U12: 0 | V12: 2 | W12: 0
A13: 329 | B13: 356 | C13: 108 | D13: Perez Alvarez, Leonardo Alberto | E13: (786) 757-1399 | F13: perezleo74@gmail.com | G13: Current resident | H13: 07/01/2025 | I13: TRV | J13: 0 | K13: 4.45 | N13: 4.45 | O13: 4.45 | P13: 0 | Q13: 0 | R13: 0 | S13: 0 | T13: 0 | U13: 0 | V13: 2 | W13: 0
A14: 329 | B14: 356 | C14: 108 | D14: Perez Alvarez, Leonardo Alberto | E14: (786) 757-1399 | F14: perezleo74@gmail.com | G14: Current resident | H14: 07/01/2025 | I14: WSR | J14: 0 | K14: 64.42 | N14: 64.42 | O14: 64.42 | P14: 0 | Q14: 0 | R14: 0 | S14: 0 | T14: 0 | U14: 0 | V14: 2 | W14: 0
A15: 30 | B15: 682 | C15: 111 | D15: Alison Suarato | F15: asuarato@gmail.com | G15: Former resident | H15: 04/12/2026 | I15: PMTFLEX | J15: -949.83 | K15: 0 | N15: -949.83 | O15: -949.83 | P15: 0 | Q15: 0 | R15: 0 | S15: 0 | T15: 0 | U15: 0 | V15: 0 | W15: 0
A16: 111 | B16: 117 | C16: 113 | D16: Brittain III, David | E16: N/A | F16: trey@tbrittain.com | G16: Current resident | H16: 11/16/2022 | I16: PST | J16: 0 | K16: 6.5 | N16: 6.5 | O16: 6.5 | P16: 0 | Q16: 0 | R16: 0 | S16: 0 | T16: 0 | U16: 0 | V16: 1 | W16: 0
A17: 111 | B17: 117 | C17: 113 | D17: Brittain III, David | E17: N/A | F17: trey@tbrittain.com | G17: Current resident | H17: 11/16/2022 | I17: TRV | J17: 0 | K17: 9.83 | N17: 9.83 | O17: 9.83 | P17: 0 | Q17: 0 | R17: 0 | S17: 0 | T17: 0 | U17: 0 | V17: 1 | W17: 0
A18: 111 | B18: 117 | C18: 113 | D18: Brittain III, David | E18: N/A | F18: trey@tbrittain.com | G18: Current resident | H18: 11/16/2022 | I18: WSR | J18: 0 | K18: 57.56 | N18: 57.56 | O18: 57.56 | P18: 0 | Q18: 0 | R18: 0 | S18: 0 | T18: 0 | U18: 0 | V18: 1 | W18: 0
A19: 248 | B19: 670 | C19: 114 | D19: Scheurich, Alissa | E19: N/A | F19: alissarscheurich@gmail.com | G19: Current resident | H19: 02/26/2026 | I19: PMTBILTACH | J19: -1588.62 | K19: 0 | N19: -1588.62 | O19: -1588.62 | P19: 0 | Q19: 0 | R19: 0 | S19: 0 | T19: 0 | U19: 0 | V19: 0 | W19: 0
A20: 37 | B20: 38 | C20: 115 | D20: Bowden, Alethe | E20: N/A | F20: alethebowden46@gmail.com | G20: Current resident | H20: 10/18/2019 | I20: GAS | J20: 0 | K20: 8.37 | N20: 8.37 | O20: 8.37 | P20: 0 | Q20: 0 | R20: 0 | S20: 0 | T20: 0 | U20: 0 | V20: 0 | W20: 0
A21: 37 | B21: 38 | C21: 115 | D21: Bowden, Alethe | E21: N/A | F21: alethebowden46@gmail.com | G21: Current resident | H21: 10/18/2019 | I21: PST | J21: 0 | K21: 6.5 | N21: 6.5 | O21: 6.5 | P21: 0 | Q21: 0 | R21: 0 | S21: 0 | T21: 0 | U21: 0 | V21: 0 | W21: 0
A22: 37 | B22: 38 | C22: 115 | D22: Bowden, Alethe | E22: N/A | F22: alethebowden46@gmail.com | G22: Current resident | H22: 10/18/2019 | I22: TRV | J22: 0 | K22: 9.83 | N22: 9.83 | O22: 9.83 | P22: 0 | Q22: 0 | R22: 0 | S22: 0 | T22: 0 | U22: 0 | V22: 0 | W22: 0
A23: 37 | B23: 38 | C23: 115 | D23: Bowden, Alethe | E23: N/A | F23: alethebowden46@gmail.com | G23: Current resident | H23: 10/18/2019 | I23: WSR | J23: 0 | K23: 39.39 | N23: 39.39 | O23: 39.39 | P23: 0 | Q23: 0 | R23: 0 | S23: 0 | T23: 0 | U23: 0 | V23: 0 | W23: 0
A24: 35 | B24: 416 | C24: 116 | D24: Brittany Stone | F24: brittanyd.stone@gmail.com | G24: Former resident | H24: 04/03/2026 | I24: GAS | J24: 0 | K24: 40.05 | N24: 40.05 | O24: 40.05 | P24: 0 | Q24: 0 | R24: 0 | S24: 0 | T24: 0 | U24: 0 | V24: 1 | W24: 1
A25: 35 | B25: 416 | C25: 116 | D25: Brittany Stone | F25: brittanyd.stone@gmail.com | G25: Former resident | H25: 04/03/2026 | I25: PST | J25: 0 | K25: 6.5 | N25: 6.5 | O25: 6.5 | P25: 0 | Q25: 0 | R25: 0 | S25: 0 | T25: 0 | U25: 0 | V25: 1 | W25: 1
A26: 35 | B26: 416 | C26: 116 | D26: Brittany Stone | F26: brittanyd.stone@gmail.com | G26: Former resident | H26: 04/03/2026 | I26: TRV | J26: 0 | K26: 9.83 | N26: 9.83 | O26: 9.83 | P26: 0 | Q26: 0 | R26: 0 | S26: 0 | T26: 0 | U26: 0 | V26: 1 | W26: 1
A27: 35 | B27: 416 | C27: 116 | D27: Brittany Stone | F27: brittanyd.stone@gmail.com | G27: Former resident | H27: 04/03/2026 | I27: WSR | J27: 0 | K27: 26.79 | N27: 26.79 | O27: 26.79 | P27: 0 | Q27: 0 | R27: 0 | S27: 0 | T27: 0 | U27: 0 | V27: 1 | W27: 1
A28: 124 | B28: 131 | C28: 127 | D28: Quinn, Megan Christine | E28: N/A | F28: meganchristinequinn@gmail.com | G28: Current resident | H28: 04/01/2023 | I28: GAS | J28: 0 | K28: 3.14 | N28: 3.14 | O28: 3.14 | P28: 0 | Q28: 0 | R28: 0 | S28: 0 | T28: 0 | U28: 0 | V28: 0 | W28: 0
A29: 124 | B29: 131 | C29: 127 | D29: Quinn, Megan Christine | E29: N/A | F29: meganchristinequinn@gmail.com | G29: Current resident | H29: 04/01/2023 | I29: PST | J29: 0 | K29: 6.5 | N29: 6.5 | O29: 6.5 | P29: 0 | Q29: 0 | R29: 0 | S29: 0 | T29: 0 | U29: 0 | V29: 0 | W29: 0
A30: 124 | B30: 131 | C30: 127 | D30: Quinn, Megan Christine | E30: N/A | F30: meganchristinequinn@gmail.com | G30: Current resident | H30: 04/01/2023 | I30: TRV | J30: 0 | K30: 9.83 | N30: 9.83 | O30: 9.83 | P30: 0 | Q30: 0 | R30: 0 | S30: 0 | T30: 0 | U30: 0 | V30: 0 | W30: 0
A31: 124 | B31: 131 | C31: 127 | D31: Quinn, Megan Christine | E31: N/A | F31: meganchristinequinn@gmail.com | G31: Current resident | H31: 04/01/2023 | I31: WSR | J31: 0 | K31: 26.21 | N31: 26.21 | O31: 26.21 | P31: 0 | Q31: 0 | R31: 0 | S31: 0 | T31: 0 | U31: 0 | V31: 0 | W31: 0
A32: 303 | B32: 330 | C32: 128 | D32: Maria Jose Santacruz Puig; April Cruz | F32: mj.sp@outlook.com | G32: Former resident | H32: 03/18/2026 | I32: PMTOPACH | J32: -561.54 | K32: 0 | N32: -561.54 | O32: -561.54 | P32: 0 | Q32: 0 | R32: 0 | S32: 0 | T32: 0 | U32: 0 | V32: 0 | W32: 0
A33: 402 | B33: 582 | C33: 129 | D33: Model, Model | E33: (832) 589-9608 | F33: Megan.Behrens@assetliving.com | G33: Current resident | H33: 12/08/2025 | I33: MOD | J33: -1871.16 | K33: 0 | N33: -1871.16 | O33: -1871.16 | P33: 0 | Q33: 0 | R33: 0 | S33: 0 | T33: 0 | U33: 0 | V33: 0 | W33: 0
A34: 326 | B34: 353 | C34: 131 | D34: Perez, Jennifer Lynn | E34: (281)881-9946 | F34: jenperez527@gmail.com | G34: Current resident | H34: 06/04/2025 | I34: GAS | J34: 0 | K34: 25.64 | N34: 25.64 | O34: 25.64 | P34: 0 | Q34: 0 | R34: 0 | S34: 0 | T34: 0 | U34: 0 | V34: 0 | W34: 0
A35: 326 | B35: 353 | C35: 131 | D35: Perez, Jennifer Lynn | E35: (281)881-9946 | F35: jenperez527@gmail.com | G35: Current resident | H35: 06/04/2025 | I35: PST | J35: 0 | K35: 6.5 | N35: 6.5 | O35: 6.5 | P35: 0 | Q35: 0 | R35: 0 | S35: 0 | T35: 0 | U35: 0 | V35: 0 | W35: 0
A36: 326 | B36: 353 | C36: 131 | D36: Perez, Jennifer Lynn | E36: (281)881-9946 | F36: jenperez527@gmail.com | G36: Current resident | H36: 06/04/2025 | I36: TRV | J36: 0 | K36: 9.83 | N36: 9.83 | O36: 9.83 | P36: 0 | Q36: 0 | R36: 0 | S36: 0 | T36: 0 | U36: 0 | V36: 0 | W36: 0
A37: 326 | B37: 353 | C37: 131 | D37: Perez, Jennifer Lynn | E37: (281)881-9946 | F37: jenperez527@gmail.com | G37: Current resident | H37: 06/04/2025 | I37: WSR | J37: 0 | K37: 51.5 | N37: 51.5 | O37: 51.5 | P37: 0 | Q37: 0 | R37: 0 | S37: 0 | T37: 0 | U37: 0 | V37: 0 | W37: 0
A38: 208 | B38: 226 | C38: 132 | D38: Richey, Hudson Lanier | E38: N/A | F38: hlrichey19@gmail.com | G38: Current resident | H38: 03/05/2024 | I38: GAS | J38: 0 | K38: 4.79 | N38: 4.79 | O38: 4.79 | P38: 0 | Q38: 0 | R38: 0 | S38: 0 | T38: 0 | U38: 0 | V38: 0 | W38: 0
A39: 208 | B39: 226 | C39: 132 | D39: Richey, Hudson Lanier | E39: N/A | F39: hlrichey19@gmail.com | G39: Current resident | H39: 03/05/2024 | I39: PST | J39: 0 | K39: 6.5 | N39: 6.5 | O39: 6.5 | P39: 0 | Q39: 0 | R39: 0 | S39: 0 | T39: 0 | U39: 0 | V39: 0 | W39: 0
A40: 208 | B40: 226 | C40: 132 | D40: Richey, Hudson Lanier | E40: N/A | F40: hlrichey19@gmail.com | G40: Current resident | H40: 03/05/2024 | I40: TRV | J40: 0 | K40: 9.83 | N40: 9.83 | O40: 9.83 | P40: 0 | Q40: 0 | R40: 0 | S40: 0 | T40: 0 | U40: 0 | V40: 0 | W40: 0
...

Sheet Market Rate
B2: Broker | C2: Submarket | D2: 3Q 2023 | E2: 4Q 2023 | F2: 1Q 2024 | G2: 2Q 2024 | H2: 3Q 2024 | I2: QoQ Change | L2: MULTIFAMILY 3Q 2024 | M2: INVENTORY (UNITS) | N2: YTD DELIVERIES (UNITS) | O2: YTD % INVENTORY GROWTH | P2: UNDER CONSTR (UNITS) | Q2: YTD NET ABSORPTION (UNITS) | R2: VACANCY RATE | S2: YOY VACANCY RATE CHANGE (BPS) | T2: AVG EFFECTIVE RENT / UNIT | U2: YOY % EFFECTIVE RENT GROWTH
B3: Cushman & Wakefield | C3: Ahwatukee | D3: 1668 | E3: 1629 | I3: =E3/D3-1 -> -0.023381295 | L3: Ahwatukee | M3: 12362 | N3: 166 | O3: 1.4% | P3: 1142 | Q3: 425 | R3: 5.7% | S3: 40 | T3: 1642 | U3: -1.6%
B4: Costar | C4: Chandler | D4: 1689 | E4: 1689 | I4: =E4/D4-1 -> 0 | L4: Central Phoenix | M4: 33310 | N4: 959 | O4: 3.0% | P4: 5478 | Q4: 1305 | R4: 7.0% | S4: 50 | T4: 1598 | U4: -2.3%
L5: Chandler/Queen Creek | M5: 40264 | N5: 1389 | O5: 3.6% | P5: 5630 | Q5: 1779 | R5: 5.3% | S5: -30 | T5: 1771 | U5: -2.0%
B6: Average | D6: =AVERAGE(D3:D4) -> 1678.5 | E6: =AVERAGE(E3:E4) -> 1659 | F6: =AVERAGE(F3:F4) -> #DIV/0! | I6: =E6/D6-1 -> -0.011617516 | L6: East Phoenix | M6: 19203 | N6: 593 | O6: 3.2% | P6: 320 | Q6: 532 | R6: 7.1% | S6: 10 | T6: 1532 | U6: -1.2%
L7: Glendale/West Valley | M7: 27494 | N7: 2532 | O7: 10.1% | P7: 7444 | Q7: 1441 | R7: 7.8% | S7: 60 | T7: 1493 | U7: -0.9%
L8: Mesa/Gilbert | M8: 41651 | N8: 1426 | O8: 3.5% | P8: 3351 | Q8: 1774 | R8: 6.4% | S8: 0 | T8: 1492 | U8: -0.8%
L9: Northeast Valley | M9: 32612 | N9: 1960 | O9: 6.4% | P9: 4947 | Q9: 34 | R9: 5.9% | S9: -10 | T9: 1779 | U9: -0.4%
D10: Last Year | E10: 45261 | F10: 44986 | G10: 45473 | H10: 45565 | I10: QoQ Change | L10: Northwest Valley | M10: 39932 | N10: 2011 | O10: 5.3% | P10: 3991 | Q10: 308 | R10: 7.2% | S10: 70 | T10: 1510 | U10: -3.1%
B11: Submarket Rate ($/unit) | D11: 1668 | E11: 1629 | F11: 1614 | G11: 1643 | H11: =T3 -> 1642 | I11: =IFERROR(H11/G11-1,0%) -> -0.00060864273 | L11: Scottsdale | M11: 27759 | N11: 1930 | O11: 7.5% | P11: 574 | Q11: 1317 | R11: 5.3% | S11: -60 | T11: 1963 | U11: -1.6%
B12: Total Submarket Inventory (Units) | E12: 12181 | F12: 12196 | G12: 12196 | H12: =M3 -> 12362 | I12: =IFERROR(H12/G12-1,0%) -> 0.01361102 | L12: Tempe | M12: 36694 | N12: 1363 | O12: 3.9% | P12: 3780 | Q12: 838 | R12: 6.2% | S12: 20 | T12: 1887 | U12: -1.2%
B13: Submarket Vacancy (Units) | E13: =E12*E14 -> 791.765 | F13: =F12*F14 -> 829.328 | G13: =G12*G14 -> 731.76 | H13: =H12*H14 -> 704.634 | I13: =IFERROR(H13/G13-1,0%) -> -0.037069531 | L13: West Phoenix | M13: 41296 | N13: 1998 | O13: 5.1% | P13: 4026 | Q13: 2097 | R13: 8.3% | S13: 40 | T13: 1379 | U13: -0.9%
B14: Submarket Vacancy Rate | E14: 0.065 | F14: 0.068 | G14: 0.06 | H14: =R3 -> 5.7% | I14: =IFERROR(H14/G14-1,0%) -> -0.05 | L14: MARKET | M14: 352577 | N14: 16327 | O14: 4.9% | P14: 40683 | Q14: 11850 | R14: 6.6% | S14: 10 | T14: 1635 | U14: -1.6%
B15: Net Absorption QoQ (Units) | E15: -31 | F15: 63 | G15: 19 | H15: =H16-G16 -> 84 | I15: =IFERROR(H15/G15-1,0%) -> 3.4210526
B16: Net Absorption YTD (Units) | E16: -131 | F16: 63 | G16: 341 | H16: =Q3 -> 425 | I16: =IFERROR(H16/G16-1,0%) -> 0.24633431
B17: Under Construction (Units) | E17: 834 | F17: 834 | G17: 1136 | H17: =P3 -> 1142 | I17: =IFERROR(H17/G17-1,0%) -> 0.0052816901
B18: Planned (Units) | E18: 1111 | F18: 1558 | G18: 1478 | I18: =IFERROR(H18/G18-1,0%) -> -1
B19: Submarket Inventory Expansion | E19: =((E17+E12)/E12)-1 -> 0.068467285 | F19: =((F17+F12)/F12)-1 -> 0.068383076 | G19: =((G17+G12)/G12)-1 -> 0.093145294 | H19: =((H17+H12)/H12)-1 -> 0.092379874
B20: Notes:
B21: Below national average unemployement, and job and wage growth, in the Phoenix market, has resulted in the toal number of housholds to increase 2.2% YoY.
B23: Overall vacancy remained flat QoQ as absorption matches new deliveries. Asking rent fell slightly for the ninth quarter in a row.
B24: Construction pipeline slowed to its slowest pace since 2020; however, new inventory is still 230% above the 10-year annual average of 11.4K units.

Sheet Coding
D3: T12 | E3: Line Item | H3: Line Items
H4: Gross Potential Rent (3) | K4: Gross Potential Rent (3)
D5: INCOME | H5: Less: Vacancy Loss | K5: Less: Vacancy Loss
H6: Base Rent (3) | K6: OR
D7: 4000-000 - Market Rent | E7: Gross Potential Rent (3) | F7: Gross Potential Rent (3) | H7: Expense Reimbursement | K7: Base Rent (3)
D8: 4010-000 - Gain/Loss to Lease | E8: Gross Potential Rent (3) | F8: Gross Potential Rent (3) | H8: Percentage Rent | K8: Laundry/Vending Income
H9: Parking Income | K9: Parking Income
D10: Gross Possible | H10: Other Income | K10: Other Income
H11: Real Estate Taxes
D12: LESS DEDUCTIONS | H12: Property Insurance | K12: *Effective Gross Income
D13: 4100-000 - Vacancy Loss | E13: Less: Vacancy Loss | F13: Less: Vacancy Loss | H13: Utilities | K13: Debt Service - A Note
D14: 4101-000 - Vacancy-Down Units | E14: Less: Vacancy Loss | F14: Less: Vacancy Loss | H14: Repairs and Maintenance | K14: Capital Expenditures
D15: 4110-000 - Concessions Market | E15: Gross Potential Rent (3) | F15: Gross Potential Rent (3) | H15: Janitorial | K15: OPERATING EXPENSES:
D16: 4110-100 - Concessions-One Time | E16: Gross Potential Rent (3) | F16: Gross Potential Rent (3) | H16: Management Fees | K16: Real Estate Taxes
D17: 4110-300 - Concessions -Other | E17: Gross Potential Rent (3) | F17: Gross Potential Rent (3) | H17: Payroll & Benefits | K17: Property Insurance
D18: 4120-000 - Model/Guest Suite | E18: Gross Potential Rent (3) | F18: Gross Potential Rent (3) | H18: Advertising & Marketing | K18: Utilities
D19: 4130-000 - Employee Units | E19: Gross Potential Rent (3) | F19: Gross Potential Rent (3) | H19: Professional Fees | K19: Repairs and Maintenance
H20: General and Administrative | K20: Management Fees
D21: Total Deductions | H21: Other Expenses | K21: Payroll & Benefits
H22: Ground Rent | K22: Advertising & Marketing
