Workbook
Name \a: #N/A
Name \d: #N/A
Name _Order1: 255
Name _Order2: 0
Name ActEconInputs: #REF!
Name ActEconInputs: #REF!
Name Amortized: [1]!PMT
Name AmortToggle: #REF!
Name AmortToggle: #REF!
Name AptCleanContractPerTurn: #REF!
Name AptCleanContractPerTurn: #REF!
Name AptCleanInHousePerTurn: #REF!
Name AptCleanInHousePerTurn: #REF!
Name asdfasdf: #REF!
Name AvgEconRent: #REF!
Name AvgInPlaceRent: #REF!
Name AvgSF: #REF!
Name AvgStreetRent: #REF!
Name BackendMgtFee: #REF!
Name BaseRehabInputs: #REF!
Name Benchmark: #REF!
Name BKL_35: #REF!
Name Budget: #REF!
Name BUDTITLE: [2]DETAIL!#REF!
Name BURLINMM: #REF!
Name BURLINMM: #REF!
Name CapExContingPct: #REF!
Name CapExContingPct: #REF!
Name Capped: ' OSAR'!#REF!
Name CENDAV: [3]CAUSCAN!#REF!
Name CENDAV: [3]CAUSCAN!#REF!
Name CENDAV: [3]CAUSCAN!#REF!
Name City: [4]Input!$B$4
Name CITYSQMM: #REF!
Name CITYSQMM: #REF!
Name CITYSQMM: #REF!
Name ClientName: #REF!
Name ClientName: #REF!
Name ClosingAssump: #REF!
Name ClosingAssump: #REF!
Name ClosingComm: #REF!
Name ClosingCommRate: #REF!
Name CMNOTES: #REF!
Name COE: #REF!
Name colleen: [2]RENT!#REF!
Name CoveredbyInsurance: #REF!
Name CoveredbyInsurance: #REF!
Name CoveredbyInsurance: #REF!
Name cpirent: [2]RENT!#REF!
Name cpirent: [2]RENT!#REF!
Name cpirent: [2]RENT!#REF!
Name cpirent2: [2]RENT!#REF!
Name cpirent2: [2]RENT!#REF!
Name CreditCkFeePerTurn: #REF!
Name CreditCkFeePerTurn: #REF!
Name CreditCkFeePerTurn: #REF!
Name CreditCkFeePerTurnYr2: #REF!
Name CreditCkFeePerTurnYr2: #REF!
Name CreditCkFeePerTurnYr3: #REF!
Name CreditCkFeePerTurnYr3: #REF!

Sheet MF OSAR
B1: CREFC Investor Reporting Package
C2: MULTIFAMILY OPERATING STATEMENT ANALYSIS REPORT (includes Mobile Home Parks, Single Family Rentals, and Co-ops)
C3: ="as of" &TEXT(F6," MM/DD/YY") -> as of 03/31/26
C4: PROPERTY OVERVIEW | H4: Allocated Loan Amount/Percentage
C5: Property ID | E5: 1001-001 | F5: Paid Thru Date | G5: Debt Outside Trust (1) | H5: $ | I5: %
C6: Note A-Scheduled Loan Balance | E6: 280000000 | F6: 46112 | H6: 0 | I6: 1
C7: Note B-Scheduled Loan Balance
C8: Note C-Scheduled Loan Balance
C9: Property Name | E9: Quincy & Hollingsworth
C10: Property Type | E10: Mixed-Use (Multi-family) | M10: Commcercial Vacancy
C11: Property Address, City, State | E11: 70 W. 37th St. | M11: =1-(SUM('Rent Roll (COMM)'!F9:F16)/'Rent Roll (COMM)'!F18) -> 0.10014965
C12: Current Net Rentable SF/Units/Beds/Rooms | E12: 455 | G12: Use second box to specify sqft.,units…
C13: Year Built/Year Renovated | E13: 1986 | F13: 2021 | M13: Vacancy Factor
C14: Cap Ex Reserve (annually)/per Unit.etc. (2) | E14: 250 | F14: per unit | G14: specify annual/per unit… | M14: Commercial | N14: 0.1
C15: Statement Ending Date | E15: Underwriting | G15: 46022 | H15: =+$F$6 -> 46112 | I15: =+$F$6 -> 46112 | M15: Residential | N15: 0.03
C16: Occupancy Rate (physical) | E16: 0.93 | G16: 0.90549451 | H16: ='Rent Roll (MF)'!K536 -> 0.96043956 | I16: =+H16 -> 0.96043956
C17: Occupancy Date | E17: 45930 | G17: 46022 | H17: =+H15 -> 46112 | I17: =+I15 -> 46112
E18: (1) "X" if debt is outside of the trust, otherwise leave blank
E19: (2) Total $ amount of Capital Reserves required annually by loan documents
C20: INCOME:
C21: Number of Mos. Covered | J21: (prcdng yr to base) | K21: (prcdng yr to 2nd prcdng)
C22: Period Ended | E22: At Contribution | F22: 3rd Preceding | G22: DY Test | H22: TTM | I22: DY Test | J22: =TEXT(H15," mm/dd/yyyy")& "-U/W" -> 03/31/2026-U/W | K22: =TEXT(G15," mm/dd/yyyy - ") & TEXT(H15,"mm/dd/yyyy") -> 12/31/2025 - 03/31/2026 | M22: QoQ Variance | N22: QoQ Variance
C23: Statement Ending Date | E23: Information | G23: 46022 | H23: =+H15 -> 46112 | I23: =+I15 -> 46112 | J23: Variance | K23: Variance | L23: Notes | M23: $ | N23: %
C24: Gross Potential Rent (3) | E24: 28640482 | G24: 24755526 | H24: =+_xlfn.XLOOKUP(C24,'T12'!U:U,'T12'!V:V,"") -> 25677021 | I24: ='Rent Roll (MF)'!C531 -> 27270606 | J24: =IF(E24=0, " ",(H24-E24)/E24) -> -0.10347103 | K24: =IF(G24=0, " ",(H24-G24)/G24) -> 0.037223823 | L24: ="Annualized RR as of" &TEXT($I$15," mm/dd/yyy") & " less delinquent tenants & KV's" -> Annualized RR as of 03/31/2026 less delinquent tenants & KV's | M24: =+IFERROR(I24-G24,"") -> 2515080 | N24: =+IFERROR(M24/G24,"") -> 0.10159671
C25: Less: Vacancy Loss | E25: -1674366.6 | H25: =+_xlfn.XLOOKUP(C25,'T12'!U:U,'T12'!V:V,"") -> 0 | I25: =IF((1-N16)>'MF OSAR'!N15,"",-('MF OSAR'!N15-'MF OSAR'!M11)*O23) | J25: =IF(E25=0, " ",(H25-E25)/E25) -> -1 | K25: =IF(G25=0, " ",(H25-G25)/G25) -> #VALUE! | L25: Greater of actual & 3% vacancy factor | M25: =+IFERROR(I25-G25,"") | N25: =+IFERROR(M25/G25,"")
C26: OR | H26: =+_xlfn.XLOOKUP(C26,'T12'!U:U,'T12'!V:V,"") | M26: =+IFERROR(I26-G26,"") -> 0 | N26: =+IFERROR(M26/G26,"")
C27: Base Rent (3) | E27: 2816135.1 | G27: 2747575.1 | H27: =+_xlfn.XLOOKUP(C27,'T12'!U:U,'T12'!V:V,"") -> 2671554.2 | I27: ='Rent Roll (COMM)'!K18 -> 2774713.4 | J27: =IF(E27=0, " ",(H27-E27)/E27) -> -0.051340183 | K27: =IF(G27=0, " ",(H27-G27)/G27) -> -0.02766835 | L27: ="Annualized Commercial RR adjusted for greater of actual "&TEXT(1-'Rent Roll (COMM)'!O22,"0.00%")&" or 10.00% vacancy factor" -> Annualized Commercial RR adjusted for greater of actual 10.01% or 10.00% vacancy factor | M27: =+IFERROR(I27-G27,"") -> 27138.36 | N27: =+IFERROR(M27/G27,"") -> 0.0098772042
C28: Laundry/Vending Income | H28: =+_xlfn.XLOOKUP(C28,'T12'!U:U,'T12'!V:V,"") -> 0 | J28: =IF(E28=0, " ",(H28-E28)/E28) | K28: =IF(G28=0, " ",(H28-G28)/G28) | L28: =IF(G28=0, " ",(J28-G28)/G28) | M28: =+IFERROR(I28-G28,"") -> 0 | N28: =+IFERROR(M28/G28,"")
C29: Parking Income | G29: 600000 | H29: =+_xlfn.XLOOKUP(C29,'T12'!U:U,'T12'!V:V,"") -> 853260.5 | I29: ='Rent Roll (COMM)'!K24 -> 600000 | J29: =IF(E29=0, " ",(H29-E29)/E29) | K29: =IF(G29=0, " ",(H29-G29)/G29) -> 0.42210083 | L29: Annualized RR less delinquent tenants & KV's | M29: =+IFERROR(I29-G29,"") -> 0 | N29: =+IFERROR(M29/G29,"") -> 0
C30: Other Income | E30: -630195.19 | G30: -322324.28 | H30: =+_xlfn.XLOOKUP(C30,'T12'!U:U,'T12'!V:V,"") -> -748852.72 | I30: ='T12'!V35 -> -230307.58 | J30: =IF(E30=0, " ",(H30-E30)/E30) -> 0.18828695 | K30: =IF(G30=0, " ",(H30-G30)/G30) -> 1.3232898 | L30: ="T6 Other Income Less T6 Concessions " &TEXT($I$15,"mm/dd/yyyy") -> T6 Other Income Less T6 Concessions 03/31/2026 | M30: =+IFERROR(I30-G30,"") -> 92016.7 | N30: =+IFERROR(M30/G30,"") -> -0.28547865
C32: *Effective Gross Income | E32: =SUM(E23:E30) -> 29152055 | G32: 27780777 | H32: =+SUM(H24:H30) -> 28452983 | I32: =+SUM(I24:I30) -> 30415012 | J32: =IF(E32=0, " ",(H32-E32)/E32) -> -0.023980181 | K32: =IF(G32=0, " ",(H32-G32)/G32) -> 0.024196822 | M32: =+IFERROR(I32-G32,"") -> 2634235.1 | N32: =+IFERROR(M32/G32,"") -> 0.094822225
E33: (3) Use either Gross Potential (with Vacancy Loss) or Base Rents; use negative $amt for Vacancy Loss
C35: OPERATING EXPENSES: | J35: =IF(E35=0, " ",(H35-E35)/E35) | L35: =IF(G35=0, " ",(J35-G35)/G35)
C36: Real Estate Taxes | E36: 7092817.1 | G36: 6749271.6 | H36: =+_xlfn.XLOOKUP(C36,'T12'!U:U,'T12'!V:V,"") -> 6802665.6 | I36: =+MAX(H36,'RE Tax'!K1) -> 6802665.6 | J36: =IF(E36=0, " ",(H36-E36)/E36) -> -0.040907792 | K36: =IF(G36=0, " ",(H36-G36)/G36) -> 0.0079110833 | L36: ="Greater of actual tax bill from " & TEXT('RE Tax'!$J$3,"mm/d/yyyy") & "-" & TEXT('RE Tax'!$J$4,"mm/d/yyyy") & " (" & TEXT('RE Tax'!$K$1/1000000,"$0.0""MM""") & ") and TTM ended " & TEXT($I$15,"mm/d/yyyy") -> Greater of actual tax bill from 07/1/2025-06/30/2026 ($3.4MM) and TTM ended 03/31/2026 | M36: =+IFERROR(I36-G36,"") -> 53394.05 | N36: =+IFERROR(M36/G36,"") -> 0.0079110833
C37: Property Insurance | E37: 662281.56 | G37: 649173.44 | H37: =+_xlfn.XLOOKUP(C37,'T12'!U:U,'T12'!V:V,"") -> 651481 | I37: =+MAX(H37,Insurance!I1) -> 651481 | J37: =IF(E37=0, " ",(H37-E37)/E37) -> -0.016308114 | K37: =IF(G37=0, " ",(H37-G37)/G37) -> 0.0035546125 | L37: ="Greater of actual insurance premium from " & TEXT(Insurance!$I$4,"mm/d/yyyy") & "-" & TEXT(Insurance!$I$5,"mm/d/yyyy") & " (" & TEXT(Insurance!$I$1/1000,"$00.0""K""") & ") and TTM ended " & TEXT($I$15,"mm/d/yyyy") -> Greater of actual insurance premium from 09/30/2025-09/30/2026 ($605.1K) and TTM ended 03/31/2026 | M37: =+IFERROR(I37-G37,"") -> 2307.56 | N37: =+IFERROR(M37/G37,"") -> 0.0035546125
C38: Utilities | E38: 1133802.4 | G38: 1016154.2 | H38: =+_xlfn.XLOOKUP(C38,'T12'!U:U,'T12'!V:V,"") -> 1344132.8 | I38: =+H38 -> 1344132.8 | J38: =IF(E38=0, " ",(H38-E38)/E38) -> 0.18550889 | K38: =IF(G38=0, " ",(H38-G38)/G38) -> 0.32276452 | L38: =$H$22& " ended as of" &TEXT($I$15," mm/dd/yyyy") -> TTM ended as of 03/31/2026 | M38: =+IFERROR(I38-G38,"") -> 327978.54 | N38: =+IFERROR(M38/G38,"") -> 0.32276452
C39: Repairs and Maintenance | E39: 658885.75 | G39: 695520.41 | H39: =+_xlfn.XLOOKUP(C39,'T12'!U:U,'T12'!V:V,"") -> 781368.51 | I39: =+H39 -> 781368.51 | J39: =IF(E39=0, " ",(H39-E39)/E39) -> 0.18589378 | K39: =IF(G39=0, " ",(H39-G39)/G39) -> 0.12343002 | L39: =$H$22& " ended as of" &TEXT($I$15," mm/dd/yyyy") -> TTM ended as of 03/31/2026 | M39: =+IFERROR(I39-G39,"") -> 85848.1 | N39: =+IFERROR(M39/G39,"") -> 0.12343002
C40: Management Fees | E40: 728801.37 | G40: 694519.42 | H40: =+_xlfn.XLOOKUP(C40,'T12'!U:U,'T12'!V:V,"") -> 385416.19 | I40: =+MAX(H40,0.025*I32) -> 760375.3 | J40: =IF(E40=0, " ",(H40-E40)/E40) -> -0.47116429 | K40: =IF(G40=0, " ",(H40-G40)/G40) -> -0.4450606 | L40: Greater of actual or 2.50% of EGI | M40: =+IFERROR(I40-G40,"") -> 65855.877 | N40: =+IFERROR(M40/G40,"") -> 0.094822225
C41: Payroll & Benefits | E41: 628788.67 | G41: 294391.6 | H41: =+_xlfn.XLOOKUP(C41,'T12'!U:U,'T12'!V:V,"") -> 321346.34 | I41: =+H41 -> 321346.34 | J41: =IF(E41=0, " ",(H41-E41)/E41) -> -0.48894382 | K41: =IF(G41=0, " ",(H41-G41)/G41) -> 0.091560833 | L41: =$H$22& " ended as of" &TEXT($I$15," mm/dd/yyyy") -> TTM ended as of 03/31/2026 | M41: =+IFERROR(I41-G41,"") -> 26954.74 | N41: =+IFERROR(M41/G41,"") -> 0.091560833
C42: Advertising & Marketing | E42: 105422.37 | G42: 115325.44 | H42: =+_xlfn.XLOOKUP(C42,'T12'!U:U,'T12'!V:V,"") -> 112073.59 | I42: =+H42 -> 112073.59 | J42: =IF(E42=0, " ",(H42-E42)/E42) -> 0.063091182 | K42: =IF(G42=0, " ",(H42-G42)/G42) -> -0.028197161 | L42: =$H$22& " ended as of" &TEXT($I$15," mm/dd/yyyy") -> TTM ended as of 03/31/2026 | M42: =+IFERROR(I42-G42,"") -> -3251.85 | N42: =+IFERROR(M42/G42,"") -> -0.028197161
...

Sheet Debt Service
K2: PREVIOUS | L2: CURRENT
K4: 46022 | L4: 46112
A5: UPB | K5: 280000000 | L5: =+'MF OSAR'!E6 -> 280000000 | M5: ="UPB as of" &TEXT('MF OSAR'!$F$6," mm/dd/yyy") -> UPB as of 03/31/2026
A7: SOFR | K7: 0.0368751 | L7: 0.0368 | M7: ="SOFR as of" &TEXT('MF OSAR'!$F$6," mm/dd/yyy") -> SOFR as of 03/31/2026
A8: Spread | K8: 0.021 | L8: 0.021
A9: Uncapped Interest Rate | K9: 0.0578751 | L9: =SUM(L7:L8) -> 0.0578 | M9: SOFR + Spread
A10: Rate Cap Strike Price | K10: 0.05 | L10: 0.05
A11: Effective Interest Rate | K11: 0.0578751 | L11: =MIN(L10,L7)+L8 -> 0.0578 | M11: MIN. of Rate Cap and SOFR + Spread
A13: Uncapped Debt Service | K13: 16430098 | L13: =L5*L9*(365/360) -> 16408778 | M13: Based on Act/360
A14: Capped Debt Service | K14: 16430098 | L14: =L5*L11*(365/360) -> 16408778 | M14: Based on Act/360
A16: DSCR (w/o Rate Cap) | K16: 0.89216642 | L16: =$L$19/L13 -> 1.0209093
A17: DSCR (with Rate Cap) | K17: 0.89216642 | L17: =$L$19/L14 -> 1.0209093
A19: NCF | K19: 14658382 | L19: =+'MF OSAR'!I57 -> 16751874
A20: Debt Yield (NCF/UPB) | K20: 0.052351363 | L20: =+L19/L5 -> 0.059828121

Sheet  OSAR
C1: CREFC Investor Reporting Package
B2: Print Switch | C2: 1 | D2: MULTIFAMILY OPERATING STATEMENT ANALYSIS REPORT (includes Mobile Home Parks, Single Family Rentals, and Co-ops)
D3: ="as of " &TEXT($G$6,"mm/dd/yyyy") -> as of 12/31/2025
D4: PROPERTY OVERVIEW | I4: Allocated Loan Amount/Percentage
D5: Property ID | F5: ="250231" -> 250231 | G5: Paid Thru Date | H5: Debt Outside Trust (1) | I5: $ | K5: %
D6: Note A-Scheduled Loan Balance | F6: 280000000 | G6: 46022 | I6: 0 | K6: =F6/SUM($F$6:$F$8) -> 1
D7: Note B-Scheduled Loan Balance
D8: Note C-Scheduled Loan Balance
D9: Property Name | F9: Quincy & Hollingsworth
D10: Property Type | F10: Mixed-Use (Multi-family)
D11: Property Address, City, State | F11: 70 W. 37th St.
D12: Current Net Rentable SF/Units/Beds/Rooms | F12: 455 | G12: Units | H12: Use second box to specify sqft.,units…
D13: Year Built/Year Renovated | F13: 1986 | G13: 2021
D14: Cap Ex Reserve (annually)/per Unit.etc. (2) | F14: 250 | G14: (Annual/ Per Unit) | H14: specify annual/per unit…
D15: Statement Ending Date | F15: Underwriting | N15: =G6 -> 46022
D16: Occupancy Rate (physical) | F16: 0.93 | N16: ='Rent Roll (MF)'!K536 -> 0.96043956
D17: Occupancy Date | F17: 45930 | N17: =G6 -> 46022
F18: (1) "X" if debt is outside of the trust, otherwise leave blank
F19: (2) Total $ amount of Capital Reserves required annually by loan documents
D20: INCOME:
D21: Number of Mos. Covered
D22: Period Ended | F22: At Contribution | N22: T12 | O22: DY Test | P22: Notes | R22: QoQ Variance | S22: QoQ Variance
D23: Statement Ending Date | F23: Information | N23: =N15 -> 46022 | O23: =N15 -> 46022 | R23: % | S23: $
D24: Gross Potential Rent (3) | F24: =UW!F9 -> 28640482 | N24: =SUMIF('T12'!$Q:$Q,$D24,'T12'!$O:$O) -> 25677021 | O24: ='Rent Roll (MF)'!C531 -> 27270606 | P24: ="Annualized RR as of" &TEXT(G6," mm/dd/yyy") & " less delinquent tenants & KV's" -> Annualized RR as of 12/31/2025 less delinquent tenants & KV's | R24: =IFERROR(S24/M24,"") | S24: =IFERROR(O24-M24,"") -> 27270606
D25: Less: Vacancy Loss | F25: =UW!F13 -> -1674366.6 | N25: =SUMIF('T12'!$Q:$Q,$D25,'T12'!$O:$O) -> 0 | O25: =IF((1-N16)>'MF OSAR'!N15,"",-('MF OSAR'!N15-'MF OSAR'!M11)*O23) | P25: Greater of actual & 3% vacancy factor | R25: =IFERROR(S25/M25,"") | S25: =IFERROR(O25-M25,"")
D26: OR | N26: =SUMIF('T12'!$Q:$Q,$D26,'T12'!$O:$O) -> 0 | R26: =IFERROR(S26/M26,"") | S26: =IFERROR(O26-M26,"") -> 0
D27: Commercial Income | F27: =UW!F10 -> 2816135.1 | N27: =SUMIF('T12'!$Q:$Q,$D27,'T12'!$O:$O) -> 0 | O27: ='Rent Roll (COMM)'!K18 -> 2774713.4 | P27: ="Annualized RR as of" &TEXT(G6," mm/dd/yyy") & " less delinquent tenants & KV's" -> Annualized RR as of 12/31/2025 less delinquent tenants & KV's | R27: =IFERROR(S27/M27,"") | S27: =IFERROR(O27-M27,"") -> 2774713.4
D28: Less: Vacancy Loss © | N28: =SUMIF('T12'!$Q:$Q,$D28,'T12'!$O:$O) -> 0 | O28: =IF('MF OSAR'!M11>'MF OSAR'!N14,"",-('MF OSAR'!N14-'MF OSAR'!M11)*O27) | P28: Greater of actual & 10% vacancy factor | S28: =IFERROR(O28-M28,"")
D29: Laundry/Vending Income | N29: =SUMIF('T12'!$Q:$Q,$D29,'T12'!$O:$O) -> 0 | O29: =N29 -> 0 | P29: =IF(G29=0, " ",(H29-G29)/G29) | R29: =IFERROR(S29/M29,"") | S29: =IFERROR(O29-M29,"") -> 0
D30: Parking Income | N30: =SUMIF('T12'!$Q:$Q,$D30,'T12'!$O:$O) -> 853260.5 | O30: ='Rent Roll (COMM)'!K24 -> 600000 | P30: Annualized RR less delinquent tenants & KV's | R30: =IFERROR(S30/M30,"") | S30: =IFERROR(O30-M30,"") -> 600000
D31: Other Income | F31: =UW!F11+SUM(UW!F14:F17) -> -630195.19 | N31: =SUMIF('T12'!$Q:$Q,$D31,'T12'!$O:$O) -> -748852.72 | O31: ='T12'!V35 -> -230307.58 | P31: ="T6 Other Income Less T6 Concessions " &TEXT($G$6,"mm/dd/yyyy") -> T6 Other Income Less T6 Concessions 12/31/2025 | R31: =IFERROR(S31/M31,"") | S31: =IFERROR(O31-M31,"") -> -230307.58
R32: =IFERROR(S32/M32,"") | S32: =IFERROR(O32-M32,"") -> 0
D33: *Effective Gross Income | F33: =SUM(F24:F31) -> 29152055 | G33: =SUM(G24:G31) -> 0 | H33: =SUM(H24:H31) -> 0 | I33: =SUM(I24:I31) -> 0 | J33: =SUM(J24:J31) -> 0 | K33: =SUM(K24:K31) -> 0 | L33: =SUM(L24:L31) -> 0 | M33: =SUM(M24:M31) -> 0 | ... O33: =SUM(O24:O31) -> 30415012 | R33: =IFERROR(S33/M33,"") | S33: =IFERROR(O33-M33,"") -> 30415012
F34: (3) Use either Gross Potential (with Vacancy Loss) or Base Rents; use negative $amt for Vacancy Loss
D36: OPERATING EXPENSES:
D37: Real Estate Taxes | F37: =UW!F36 -> 7092817.1 | N37: =SUMIF('T12'!$Q:$Q,$D37,'T12'!$O:$O) -> 6802665.6 | O37: =MAX(N37,'RE Tax'!K1) -> 6802665.6 | P37: ="Greater of Actual"& " or T12 ended " &TEXT($G$6,"mm/dd/yyyy") -> Greater of Actual or T12 ended 12/31/2025 | R37: =IFERROR(S37/M37,"") | S37: =IFERROR(O37-M37,"") -> 6802665.6
D38: Property Insurance | F38: =UW!F32 -> 662281.56 | N38: =SUMIF('T12'!$Q:$Q,$D38,'T12'!$O:$O) -> 651481 | O38: =MAX(N38,Insurance!I1) -> 651481 | P38: ="Greater of Actual"& " or T12 ended " &TEXT($G$6,"mm/dd/yyyy") -> Greater of Actual or T12 ended 12/31/2025 | R38: =IFERROR(S38/M38,"") | S38: =IFERROR(O38-M38,"") -> 651481
D39: Utilities | F39: =UW!F31 -> 1133802.4 | N39: =SUMIF('T12'!$Q:$Q,$D39,'T12'!$O:$O) -> 1344132.8 | O39: =N39 -> 1344132.8 | P39: ="T12"& " ended " &TEXT($G$6,"mm/dd/yyyy") -> T12 ended 12/31/2025 | R39: =IFERROR(S39/M39,"") | S39: =IFERROR(O39-M39,"") -> 1344132.8
D40: Repairs and Maintenance | F40: =UW!F28 -> 658885.75 | N40: =SUMIF('T12'!$Q:$Q,$D40,'T12'!$O:$O) -> 781368.51 | O40: =N40 -> 781368.51 | P40: ="T12"& " ended " &TEXT($G$6,"mm/dd/yyyy") -> T12 ended 12/31/2025 | R40: =IFERROR(S40/M40,"") | S40: =IFERROR(O40-M40,"") -> 781368.51
D41: Management Fees | F41: =UW!F37 -> 728801.37 | N41: =SUMIF('T12'!$Q:$Q,$D41,'T12'!$O:$O) -> 385416.19 | O41: =+MAX(N41,0.025*O33) -> 760375.3 | P41: 0.025 | R41: =IFERROR(S41/M41,"") | S41: =IFERROR(O41-M41,"") -> 760375.3
...

Sheet QoQ ∆
C2: 4Q25 | G2: 1Q26 | K2: QoQ ∆ | O2: Cash Management
B3: Property | C3: Occupancy | D3: NOI | E3: DY | F3: DSCR | G3: Occupancy | H3: NOI | I3: DY | J3: DSCR | K3: Occupancy | L3: NOI | M3: DY | N3: DSCR | O3: In CM? | P3: Threshold
B4: Quincy & Hollingsworth | C4: 0.90549451 | D4: 14772132 | E4: 0.052351363 | F4: 0.89216642 | G4: =+'MF OSAR'!I16 -> 0.96043956 | H4: =+'MF OSAR'!I51 -> 16865624 | I4: =+'MF OSAR'!I73 -> 0.059828121 | J4: =+'MF OSAR'!I69 -> 1.0209093 | K4: =G4-C4 -> 0.054945055 | L4: =H4-D4 -> 2093492.3 | M4: =I4-E4 -> 0.0074767582 | N4: =J4-F4 -> 0.12874288 | O4: No | P4: 0.065
B6: Notes:
B7: NOI adjusted per the loan agreement.
B8: DSCR inclusive of benefit from in-the-money rate cap.
B9: DY increased 70bps, driven by a 6% increase in occupancy

Sheet RR - Market & Affordable 4Q24
A1: Rent Roll with Lease Charges
A2: For Selected Properties
A3: As Of = 12/31/2024
A4: Month Year = 12/2024
A5: Unit | B5: Unit Type | C5: Unit | D5: Resident | E5: Name | F5: Market | G5: Charge | H5: Amount | I5: Resident | J5: Other | K5: Move In | L5: Lease | M5: Move Out | N5: Balance
C6: Sq Ft | F6: Rent | G6: Code | I6: Deposit | J6: Deposit | L6: Expiration
A7: Current/Notice/Vacant Residents
A8: 303 | B8: NY10CO3 | C8: 879 | D8: t0004256 | E8: Leila McDowell | F8: 3700 | G8: rent | H8: 3725 | I8: 3725 | J8: 0 | K8: 44188 | L8: 46013 | N8: 2400
G9: amenity | H9: 75
G10: gymspa | H10: -75
G11: Total | H11: 3725
A13: 304 | B13: NY10C47 | C13: 833 | D13: t0004257 | E13: Dwight Rhoden | F13: 3825 | G13: rent | H13: 3875 | I13: 3875 | J13: 0 | K13: 45145 | L13: 45874 | N13: 0
G14: amenity | H14: 75
G15: gas | H15: 20
G16: water | H16: 15
G17: Total | H17: 3985
A19: 309 | B19: NY10CO2 | C19: 862 | D19: t0004258 | E19: Lauren Sordo | F19: 3995 | G19: rent | H19: 3995 | I19: 3995 | J19: 0 | K19: 45579 | L19: 46125 | N19: 0
G20: amenity | H20: 100
G21: gas | H21: 20
G22: water | H22: 15
G23: Total | H23: 4130
A25: 310 | B25: NY10CO4 | C25: 879 | D25: t0004259 | E25: Rainee Walker | F25: 3907.75 | G25: rent | H25: 3953.75 | I25: 3953.75 | J25: 0 | K25: 44232 | L25: 45781 | N25: 596.42
G26: Total | H26: 3953.75
A28: 311 | B28: NY10C46 | C28: 828 | D28: t0004260 | E28: Alexander Demopoulos | F28: 3795 | G28: rent | H28: 3650 | I28: 3650 | J28: 0 | K28: 45342 | L28: 45747 | N28: -3650
G29: gas | H29: 20
G30: water | H30: 15
G31: Total | H31: 3685
A33: 403 | B33: NY10CO1 | C33: 837 | D33: t0004261 | E33: BRITTANY BROWN | F33: 4000 | G33: rent | H33: 4000 | I33: 4000 | J33: 0 | K33: 45372 | L33: 45767 | N33: -1600
G34: amenity | H34: 75
G35: gas | H35: 15
G36: water | H36: 10
G37: Total | H37: 4100
A39: 404 | B39: NY10C47 | C39: 818 | D39: t0004262 | E39: Tricia Newell | F39: 3600 | G39: rent | H39: 3750 | I39: 3750 | J39: 0 | K39: 45261 | L39: 46053 | N39: 0
G40: amenity | H40: 75
G41: Total | H41: 3825
A43: 405 | B43: NY10B17 | C43: 604 | D43: VACANT | E43: VACANT | F43: 3299 | H43: 0 | I43: 0 | J43: 0 | N43: 0
G44: Total | H44: 0
A46: 410 | B46: NY10C46 | C46: 817 | D46: t0004263 | E46: Laurence Smith | F46: 3656.5 | G46: rent | H46: 3850 | I46: 3850 | J46: 0 | K46: 45061 | L46: 45822 | N46: 0
G47: amenity | H47: 100
G48: Total | H48: 3950
...

Sheet T12
A1: VBG 990 AOA LLC (Consolidated) (990conso)
A2: Statement (12 months)
A3: Period = Apr 2025-Mar 2026
A4: Book = Accrual | V4: 46112 | W4: 46022
C5: Apr 2025 | D5: May 2025 | E5: Jun 2025 | F5: Jul 2025 | G5: Aug 2025 | H5: Sep 2025 | I5: Oct 2025 | J5: Nov 2025 | K5: Dec 2025 | L5: Jan 2026 | M5: Feb 2026 | N5: Mar 2026 | O5: Total | Q5: Cost Category | S5: T6 | V5: Current T12 | W5: Previous T12
A6: 4000-0000 | B6: Revenues | U6: Gross Potential Rent (3) | V6: =+SUMIF(Q:Q,U6,O:O) -> 25677021 | W6: 24624190 | Y6: =+IF(ISNUMBER(W6),V6-W6,"") -> 1052831 | Z6: =+IF(ISNUMBER(Y6),Y6/W6,"") -> 0.042755963
A7: 4100-0000 | B7: RENTAL INCOME | U7: Less: Vacancy Loss | V7: =+SUMIF(Q:Q,U7,O:O) -> 0 | W7: 0 | Y7: =+IF(ISNUMBER(W7),V7-W7,"") -> 0 | Z7: =+IF(ISNUMBER(Y7),Y7/W7,"") -> #DIV/0!
A8: 4100-0010 | B8: Rent Income | C8: 25102.22 | D8: 25102.22 | E8: 25102.22 | F8: 0 | G8: 0 | H8: 0 | I8: 0 | J8: 0 | K8: 0 | L8: 0 | M8: 0 | N8: 0 | O8: 75306.66 | Q8: =IFERROR(INDEX(Coding!$D:$D,MATCH('T12'!$B8,Coding!$B:$B,0)),"") -> Gross Potential Rent (3) | S8: =IF(ISNUMBER(O8),SUM(I8:N8)*2,"") -> 0 | U8: Base Rent (3) | V8: =+SUMIF(Q:Q,U8,O:O) -> 2671554.2 | W8: 2720517.9 | Y8: =+IF(ISNUMBER(W8),V8-W8,"") -> -48963.7 | Z8: =+IF(ISNUMBER(Y8),Y8/W8,"") -> -0.017997933
A9: 4100-0011 | B9: Apartment Rent | C9: 1943935.2 | D9: 2079051.9 | E9: 2119875.6 | F9: 2150640 | G9: 2145712.1 | H9: 2163454.8 | I9: 2160223.7 | J9: 2144525.2 | K9: 2147740.2 | L9: 2128015.3 | M9: 2204388 | N9: 2214152.5 | O9: 25601715 | Q9: =IFERROR(INDEX(Coding!$D:$D,MATCH('T12'!$B9,Coding!$B:$B,0)),"") -> Gross Potential Rent (3) | S9: =IF(ISNUMBER(O9),SUM(I9:N9)*2,"") -> 25998090 | U9: Laundry/Vending Income | V9: =+SUMIF(Q:Q,U9,O:O) -> 0 | W9: 0 | Y9: =+IF(ISNUMBER(W9),V9-W9,"") -> 0 | Z9: =+IF(ISNUMBER(Y9),Y9/W9,"") -> #DIV/0!
A10: 4100-0014 | B10: Parking Income | C10: 50000 | D10: 50000 | E10: 50000 | F10: 50000 | G10: 50000 | H10: 50000 | I10: 50000 | J10: 50000 | K10: 50000 | L10: 50000 | M10: 50000 | N10: 50000 | O10: 600000 | Q10: =IFERROR(INDEX(Coding!$D:$D,MATCH('T12'!$B10,Coding!$B:$B,0)),"") -> Parking Income | S10: =IF(ISNUMBER(O10),SUM(I10:N10)*2,"") -> 600000 | U10: Parking Income | V10: =+SUMIF(Q:Q,U10,O:O) -> 853260.5 | W10: 863523 | Y10: =+IF(ISNUMBER(W10),V10-W10,"") -> -10262.5 | Z10: =+IF(ISNUMBER(Y10),Y10/W10,"") -> -0.011884455
A11: 4100-0016 | B11: Retail Rent | C11: 199667.01 | D11: 200701.39 | E11: 202566.99 | F11: 227669.21 | G11: 227763.45 | H11: 228776.26 | I11: 229785.44 | J11: 230473.05 | K11: 230473.05 | L11: 231226.12 | M11: 231226.12 | N11: 231226.12 | O11: 2671554.2 | Q11: =IFERROR(INDEX(Coding!$D:$D,MATCH('T12'!$B11,Coding!$B:$B,0)),"") -> Base Rent (3) | S11: =IF(ISNUMBER(O11),SUM(I11:N11)*2,"") -> 2768819.8 | U11: Other Income | V11: =+SUMIF(Q:Q,U11,O:O) -> -748852.72 | W11: -1105705.6 | Y11: =+IF(ISNUMBER(W11),V11-W11,"") -> 356852.93 | Z11: =+IF(ISNUMBER(Y11),Y11/W11,"") -> -0.32273773
A12: 4100-0050 | B12: Concessions | C12: -186855 | D12: -216204.5 | E12: -232135 | F12: -197780 | G12: -145260 | H12: -152872.5 | I12: -147080 | J12: -104641.33 | K12: -67435 | L12: -73037.5 | M12: -186702.5 | N12: -185560 | O12: -1895563.3 | Q12: =IFERROR(INDEX(Coding!$D:$D,MATCH('T12'!$B12,Coding!$B:$B,0)),"") -> Other Income | S12: =IF(ISNUMBER(O12),SUM(I12:N12)*2,"") -> -1528912.7 | U12: *Effective Gross Income | V12: =+SUM(V6:V11) -> 28452983 | W12: 27102526 | Y12: =+IF(ISNUMBER(W12),V12-W12,"") -> 1350457.7 | Z12: =+IF(ISNUMBER(Y12),Y12/W12,"") -> 0.049827744
A13: 4100-0052 | B13: Employer Provided Housing | C13: -9000 | D13: -9000 | E13: -9000 | F13: -9000 | G13: -9000 | H13: -9000 | I13: -9000 | J13: -9000 | K13: -9000 | L13: -9000 | M13: -9000 | N13: -9000 | O13: -108000 | Q13: =IFERROR(INDEX(Coding!$D:$D,MATCH('T12'!$B13,Coding!$B:$B,0)),"") -> Other Income | S13: =IF(ISNUMBER(O13),SUM(I13:N13)*2,"") -> -108000 | Y13: =+IF(ISNUMBER(W13),V13-W13,"") | Z13: =+IF(ISNUMBER(Y13),Y13/W13,"")
A14: 4100-0057 | B14: Cleaning Fees | C14: 0 | D14: 0 | E14: 0 | F14: 0 | G14: 200 | H14: 150 | I14: 250 | J14: 0 | K14: 0 | L14: 300 | M14: 400 | N14: 0 | O14: 1300 | Q14: =IFERROR(INDEX(Coding!$D:$D,MATCH('T12'!$B14,Coding!$B:$B,0)),"") -> Other Income | S14: =IF(ISNUMBER(O14),SUM(I14:N14)*2,"") -> 1900 | Y14: =+IF(ISNUMBER(W14),V14-W14,"") | Z14: =+IF(ISNUMBER(Y14),Y14/W14,"")
A15: 4100-0060 | B15: Percentage Rent | C15: 0 | D15: 0 | E15: 561 | F15: 0 | G15: 610.5 | H15: 0 | I15: 0 | J15: 594 | K15: 0 | L15: 0 | M15: 0 | N15: 0 | O15: 1765.5 | Q15: =IFERROR(INDEX(Coding!$D:$D,MATCH('T12'!$B15,Coding!$B:$B,0)),"") -> Other Income | S15: =IF(ISNUMBER(O15),SUM(I15:N15)*2,"") -> 1188 | U15: OPERATING EXPENSES: | Y15: =+IF(ISNUMBER(W15),V15-W15,"") | Z15: =+IF(ISNUMBER(Y15),Y15/W15,"")
A16: 4100-0061 | B16: Percentage Rent - Parking | C16: 0 | D16: 0 | E16: 64324 | F16: 0 | G16: 0 | H16: 70541 | I16: 0 | J16: 0 | K16: 87458 | L16: -87458 | M16: 87458 | N16: 30937.5 | O16: 253260.5 | Q16: =IFERROR(INDEX(Coding!$D:$D,MATCH('T12'!$B16,Coding!$B:$B,0)),"") -> Parking Income | S16: =IF(ISNUMBER(O16),SUM(I16:N16)*2,"") -> 236791 | U16: Real Estate Taxes | V16: =+SUMIF(Q:Q,U16,O:O) -> 6802665.6 | W16: 6749271.6 | Y16: =+IF(ISNUMBER(W16),V16-W16,"") -> 53394.05 | Z16: =+IF(ISNUMBER(Y16),Y16/W16,"") -> 0.0079110833
A17: 4100-0063 | B17: Pet Rent/Fees | C17: 50 | D17: 50 | E17: 50 | F17: 50 | G17: 50 | H17: 50 | I17: 50 | J17: 50 | K17: 50 | L17: 50 | M17: 50 | N17: 50 | O17: 600 | Q17: =IFERROR(INDEX(Coding!$D:$D,MATCH('T12'!$B17,Coding!$B:$B,0)),"") -> Other Income | S17: =IF(ISNUMBER(O17),SUM(I17:N17)*2,"") -> 600 | U17: Property Insurance | V17: =+SUMIF(Q:Q,U17,O:O) -> 651481 | W17: 649173.44 | Y17: =+IF(ISNUMBER(W17),V17-W17,"") -> 2307.56 | Z17: =+IF(ISNUMBER(Y17),Y17/W17,"") -> 0.0035546125
A18: 4100-0064 | B18: Resident Referral | C18: 0 | D18: 0 | E18: 0 | F18: 0 | G18: 0 | H18: 0 | I18: -1500 | J18: 0 | K18: 0 | L18: 0 | M18: -2500 | N18: -500 | O18: -4500 | Q18: =IFERROR(INDEX(Coding!$D:$D,MATCH('T12'!$B18,Coding!$B:$B,0)),"") -> Other Income | S18: =IF(ISNUMBER(O18),SUM(I18:N18)*2,"") -> -9000 | U18: Utilities | V18: =+SUMIF(Q:Q,U18,O:O) -> 1344132.8 | W18: 1016154.2 | Y18: =+IF(ISNUMBER(W18),V18-W18,"") -> 327978.54 | Z18: =+IF(ISNUMBER(Y18),Y18/W18,"") -> 0.32276452
A19: 4100-0450 | B19: Bad Debt Expense - Non operating | C19: 0 | D19: 0 | E19: -134000.03 | F19: 340 | G19: 0 | H19: 159 | I19: 0 | J19: 0 | K19: -60274.18 | L19: 0 | M19: 0 | N19: 26170.49 | O19: -167604.72 | Q19: =IFERROR(INDEX(Coding!$D:$D,MATCH('T12'!$B19,Coding!$B:$B,0)),"") -> Other Income | S19: =IF(ISNUMBER(O19),SUM(I19:N19)*2,"") -> -68207.38 | U19: Repairs and Maintenance | V19: =+SUMIF(Q:Q,U19,O:O) -> 781368.51 | W19: 695520.41 | Y19: =+IF(ISNUMBER(W19),V19-W19,"") -> 85848.1 | Z19: =+IF(ISNUMBER(Y19),Y19/W19,"") -> 0.12343002
A20: 4199-9999 | B20: Total Rent Income | C20: 2022899.5 | D20: 2129701 | E20: 2087344.8 | F20: 2221919.2 | G20: 2270076.1 | H20: 2351258.6 | I20: 2282729.1 | J20: 2312000.9 | K20: 2379012.1 | L20: 2240095.9 | M20: 2375319.7 | N20: 2357476.6 | O20: 27029833 | Q20: =IFERROR(INDEX(Coding!$C:$C,MATCH('T12'!$B20,Coding!$B:$B,0)),"") -> 0 | S20: =IF(ISNUMBER(O20),SUM(I20:N20)*2,"") -> 27893269 | U20: Management Fees | V20: =+SUMIF(Q:Q,U20,O:O) -> 385416.19 | W20: 369733.47 | Y20: =+IF(ISNUMBER(W20),V20-W20,"") -> 15682.72 | Z20: =+IF(ISNUMBER(Y20),Y20/W20,"") -> 0.042416284
A21: 4200-0000 | B21: Reimbursements & Escalations | Q21: =IFERROR(INDEX(Coding!$C:$C,MATCH('T12'!$B21,Coding!$B:$B,0)),"") -> 0 | S21: =IF(ISNUMBER(O21),SUM(I21:N21)*2,"") | U21: Payroll & Benefits | V21: =+SUMIF(Q:Q,U21,O:O) -> 321346.34 | W21: 294391.6 | Y21: =+IF(ISNUMBER(W21),V21-W21,"") -> 26954.74 | Z21: =+IF(ISNUMBER(Y21),Y21/W21,"") -> 0.091560833
A22: 4200-0010 | B22: Operating Expense Escalations | C22: -54202 | D22: 0 | E22: 44689.35 | F22: -44689.35 | G22: 0 | H22: 48021.82 | I22: -48021.82 | J22: 0 | K22: 18586.29 | L22: -18586.29 | M22: 0 | N22: 29432.76 | O22: -24769.24 | Q22: =IFERROR(INDEX(Coding!$D:$D,MATCH('T12'!$B22,Coding!$B:$B,0)),"") -> Other Income | S22: =IF(ISNUMBER(O22),SUM(I22:N22)*2,"") -> -37178.12 | U22: Advertising & Marketing | V22: =+SUMIF(Q:Q,U22,O:O) -> 112073.59 | W22: 115325.44 | Y22: =+IF(ISNUMBER(W22),V22-W22,"") -> -3251.85 | Z22: =+IF(ISNUMBER(Y22),Y22/W22,"") -> -0.028197161
A23: 4200-0025 | B23: Water & Sewer Income | C23: 2020 | D23: 2170.86 | E23: 4397.06 | F23: 0 | G23: 8564.24 | H23: 5039.32 | I23: 0 | J23: 4475.28 | K23: 4656.66 | L23: 4978.64 | M23: 5201.51 | N23: 4741.31 | O23: 46244.88 | Q23: =IFERROR(INDEX(Coding!$D:$D,MATCH('T12'!$B23,Coding!$B:$B,0)),"") -> Other Income | S23: =IF(ISNUMBER(O23),SUM(I23:N23)*2,"") -> 48106.8 | U23: Professional Fees | V23: =+SUMIF(Q:Q,U23,O:O) -> 171187.81 | W23: 195156.35 | Y23: =+IF(ISNUMBER(W23),V23-W23,"") -> -23968.54 | Z23: =+IF(ISNUMBER(Y23),Y23/W23,"") -> -0.12281712
A24: 4200-0027 | B24: Sprinkler Supervisory Service | C24: 325 | D24: 325 | E24: 325 | F24: 325 | G24: 325 | H24: 325 | I24: 325 | J24: 325 | K24: 325 | L24: 325 | M24: 325 | N24: 325 | O24: 3900 | Q24: =IFERROR(INDEX(Coding!$D:$D,MATCH('T12'!$B24,Coding!$B:$B,0)),"") -> Other Income | S24: =IF(ISNUMBER(O24),SUM(I24:N24)*2,"") -> 3900 | U24: General and Administrative | V24: =+SUMIF(Q:Q,U24,O:O) -> 2604757 | W24: 2599132.7 | Y24: =+IF(ISNUMBER(W24),V24-W24,"") -> 5624.3 | Z24: =+IF(ISNUMBER(Y24),Y24/W24,"") -> 0.0021639141
A25: 4200-0031 | B25: Electric - Sub metering | C25: 20376.44 | D25: 31723.82 | E25: 66669.22 | F25: 102016.17 | G25: 89368.35 | H25: 33248.96 | I25: 112964.63 | J25: 19188.96 | K25: 52168.8 | L25: 42118.14 | M25: 49008.81 | N25: 37892.87 | O25: 656745.17 | Q25: =IFERROR(INDEX(Coding!$D:$D,MATCH('T12'!$B25,Coding!$B:$B,0)),"") -> Other Income | S25: =IF(ISNUMBER(O25),SUM(I25:N25)*2,"") -> 626684.42 | U25: Other Expenses | V25: =+SUMIF(Q:Q,U25,O:O) -> 0 | W25: 0 | Y25: =+IF(ISNUMBER(W25),V25-W25,"") -> 0 | Z25: =+IF(ISNUMBER(Y25),Y25/W25,"") -> #DIV/0!
A26: 4200-0040 | B26: Hvac Income Escalation | C26: 2793.75 | D26: 2793.75 | E26: 2793.75 | F26: 2793.75 | G26: 2793.75 | H26: 2793.75 | I26: 2793.75 | J26: 2793.75 | K26: 2793.75 | L26: 10293.75 | M26: 2793.75 | N26: 2793.75 | O26: 41025 | Q26: =IFERROR(INDEX(Coding!$D:$D,MATCH('T12'!$B26,Coding!$B:$B,0)),"") -> Other Income | S26: =IF(ISNUMBER(O26),SUM(I26:N26)*2,"") -> 48525 | U26: Ground Rent | V26: =+SUMIF(Q:Q,U26,O:O) -> 0 | W26: 0 | Y26: =+IF(ISNUMBER(W26),V26-W26,"") -> 0 | Z26: =+IF(ISNUMBER(Y26),Y26/W26,"") -> #DIV/0!
A27: 4200-0050 | B27: Real Estate Tax Escalations | C27: 3412.8 | D27: 3412.8 | E27: 3412.8 | F27: 5056.02 | G27: 5056.02 | H27: 5056.02 | I27: 5056.02 | J27: 5056.02 | K27: 5056.02 | L27: 4675.79 | M27: 4675.79 | N27: 4675.79 | O27: 54601.89 | Q27: =IFERROR(INDEX(Coding!$D:$D,MATCH('T12'!$B27,Coding!$B:$B,0)),"") -> Other Income | S27: =IF(ISNUMBER(O27),SUM(I27:N27)*2,"") -> 58390.86 | U27: *Total Operating Expenses | V27: =+SUM(V16:V26) -> 13174429 | W27: 12683859 | Y27: =+IF(ISNUMBER(W27),V27-W27,"") -> 490569.62 | Z27: =+IF(ISNUMBER(Y27),Y27/W27,"") -> 0.038676684
A28: 4200-0060 | B28: Back charges - Net | C28: 0 | D28: 0 | E28: 0 | F28: 0 | G28: 0 | H28: 0 | I28: 5784.02 | J28: 80 | K28: 0 | L28: 0 | M28: 910 | N28: 0 | O28: 6774.02 | Q28: =IFERROR(INDEX(Coding!$D:$D,MATCH('T12'!$B28,Coding!$B:$B,0)),"") -> Other Income | S28: =IF(ISNUMBER(O28),SUM(I28:N28)*2,"") -> 13548.04 | Y28: =+IF(ISNUMBER(W28),V28-W28,"") | Z28: =+IF(ISNUMBER(Y28),Y28/W28,"")
A29: 4200-0090 | B29: Income - Sundry Billings | C29: 0 | D29: -120 | E29: -120 | F29: 0 | G29: 0 | H29: 0 | I29: 0 | J29: 0 | K29: 0 | L29: 0 | M29: 0 | N29: 0 | O29: -240 | Q29: =IFERROR(INDEX(Coding!$D:$D,MATCH('T12'!$B29,Coding!$B:$B,0)),"") -> Other Income | S29: =IF(ISNUMBER(O29),SUM(I29:N29)*2,"") -> 0 | U29: *Net Operating Income | V29: =+V12-V27 -> 15278554 | W29: 14418666 | Y29: =+IF(ISNUMBER(W29),V29-W29,"") -> 859888.09 | Z29: =+IF(ISNUMBER(Y29),Y29/W29,"") -> 0.059637145
A30: 4299-9999 | B30: Total Reimbursements & Escal. | C30: -25274.01 | D30: 40306.23 | E30: 122167.18 | F30: 65501.59 | G30: 106107.36 | H30: 94484.87 | I30: 78901.6 | J30: 31919.01 | K30: 83586.52 | L30: 43805.03 | M30: 62914.86 | N30: 79861.48 | O30: 784281.72 | Q30: =IFERROR(INDEX(Coding!$C:$C,MATCH('T12'!$B30,Coding!$B:$B,0)),"") -> 0 | S30: =IF(ISNUMBER(O30),SUM(I30:N30)*2,"") -> 761977
A31: 4300-0000 | B31: Other | Q31: =IFERROR(INDEX(Coding!$C:$C,MATCH('T12'!$B31,Coding!$B:$B,0)),"") -> 0 | S31: =IF(ISNUMBER(O31),SUM(I31:N31)*2,"")
A32: 4300-0150 | B32: Application Fee Income | C32: 800 | D32: 400 | E32: 1240 | F32: 1200 | G32: 1040 | H32: 760 | I32: 920 | J32: 420 | K32: 340 | L32: 1680 | M32: 920 | N32: 380 | O32: 10100 | Q32: =IFERROR(INDEX(Coding!$D:$D,MATCH('T12'!$B32,Coding!$B:$B,0)),"") -> Other Income | S32: =IF(ISNUMBER(O32),SUM(I32:N32)*2,"") -> 9320 | V32: T6 Figures
A33: 4300-0300 | B33: Miscellaneous Income | C33: 42889.57 | D33: 45286.29 | E33: 40372.54 | F33: 38722.55 | G33: 49829.81 | H33: 43994.3 | I33: 43532.79 | J33: 56230.76 | K33: 51369.8 | L33: 51517.83 | M33: 71793.8 | N33: 54020.68 | O33: 589560.72 | Q33: =IFERROR(INDEX(Coding!$D:$D,MATCH('T12'!$B33,Coding!$B:$B,0)),"") -> Other Income | S33: =IF(ISNUMBER(O33),SUM(I33:N33)*2,"") -> 656931.32 | U33: Other Income | V33: =SUMIF(Q:Q,U33,S:S)-S12 -> 1298605.1
A34: 4300-0350 | B34: Late Charges | C34: 350 | D34: 440 | E34: 450 | F34: 550 | G34: 1725.28 | H34: 2994.04 | I34: -177.91 | J34: 450 | K34: 350 | L34: 700 | M34: 4430.7 | N34: 8190.28 | O34: 20452.39 | Q34: =IFERROR(INDEX(Coding!$D:$D,MATCH('T12'!$B34,Coding!$B:$B,0)),"") -> Other Income | S34: =IF(ISNUMBER(O34),SUM(I34:N34)*2,"") -> 27886.14 | U34: Concessions | V34: =S12 -> -1528912.7
A35: 4300-0400 | B35: Bounced/Stopped Check Income | C35: 50 | D35: 400 | E35: 475 | F35: 200 | G35: 200 | H35: 275 | I35: 425 | J35: 400 | K35: 325 | L35: 230 | M35: 975 | N35: 1100 | O35: 5055 | Q35: =IFERROR(INDEX(Coding!$D:$D,MATCH('T12'!$B35,Coding!$B:$B,0)),"") -> Other Income | S35: =IF(ISNUMBER(O35),SUM(I35:N35)*2,"") -> 6910 | U35: T6 Other Income less Concessions | V35: =V33+V34 -> -230307.58
A36: 4300-0450 | B36: Lease Termination Income | C36: 0 | D36: 0 | E36: 0 | F36: 5150 | G36: 0 | H36: 0 | I36: 0 | J36: 0 | K36: 6550 | L36: 0 | M36: 2000 | N36: 0 | O36: 13700 | Q36: =IFERROR(INDEX(Coding!$D:$D,MATCH('T12'!$B36,Coding!$B:$B,0)),"") -> Other Income | S36: =IF(ISNUMBER(O36),SUM(I36:N36)*2,"") -> 17100
A37: 4399-9999 | B37: Total Other Income | C37: 44089.57 | D37: 46526.29 | E37: 42537.54 | F37: 45822.55 | G37: 52795.09 | H37: 48023.34 | I37: 44699.88 | J37: 57500.76 | K37: 58934.8 | L37: 54127.83 | M37: 80119.5 | N37: 63690.96 | O37: 638868.11 | Q37: =IFERROR(INDEX(Coding!$C:$C,MATCH('T12'!$B37,Coding!$B:$B,0)),"") -> 0 | S37: =IF(ISNUMBER(O37),SUM(I37:N37)*2,"") -> 718147.46
A38: 4599-9999 | B38: TOTAL OPERATING INCOME | C38: 2041715 | D38: 2216533.5 | E38: 2252049.5 | F38: 2333243.4 | G38: 2428978.5 | H38: 2493766.8 | I38: 2406330.6 | J38: 2401420.7 | K38: 2521533.4 | L38: 2338028.8 | M38: 2518354 | N38: 2501029 | O38: 28452983 | Q38: =IFERROR(INDEX(Coding!$C:$C,MATCH('T12'!$B38,Coding!$B:$B,0)),"") -> 0 | S38: =IF(ISNUMBER(O38),SUM(I38:N38)*2,"") -> 29373393
A39: 4999-9999 | B39: Total Revenues | C39: 2041715 | D39: 2216533.5 | E39: 2252049.5 | F39: 2333243.4 | G39: 2428978.5 | H39: 2493766.8 | I39: 2406330.6 | J39: 2401420.7 | K39: 2521533.4 | L39: 2338028.8 | M39: 2518354 | N39: 2501029 | O39: 28452983 | Q39: =IFERROR(INDEX(Coding!$C:$C,MATCH('T12'!$B39,Coding!$B:$B,0)),"") -> 0 | S39: =IF(ISNUMBER(O39),SUM(I39:N39)*2,"") -> 29373393
A40: 5000-0000 | B40: OPERATING EXPENSES | Q40: =IFERROR(INDEX(Coding!$C:$C,MATCH('T12'!$B40,Coding!$B:$B,0)),"") -> 0 | S40: =IF(ISNUMBER(O40),SUM(I40:N40)*2,"")
...

Sheet Occupancy Rollup
B3: Residential | D3: Total Units | E3: Occupied Units | F3: Occupancy % | I3: Rollup | J3: % of Property | K3: Occupancy
B4: Quincy | I4: Residential | J4: =J10/J12 -> 0.8677586 | K4: =F6 -> 0
B5: Hollingsworth | I5: Commercial | J5: =J11/J12 -> 0.1322414 | K5: =F12 -> 0
B6: Total | D6: =SUM(D4:D5) -> 0 | E6: =SUM(E4:E5) -> 0 | I6: Wtd. AVG | J6: =SUM(J4:J5) -> 1 | K6: =SUMPRODUCT(J4:J5,K4:K5) -> 0
B9: Commercial | D9: Total SF | E9: Occupied SF | F9: Occupancy % | I9: Property Type | J9: Total SF
B10: Retail | I10: MF | J10: 276979
B11: Parking | I11: Commercial | J11: 42210
B12: Total | D12: =SUM(D10:D11) -> 0 | E12: =SUM(E10:E11) -> 0 | I12: Total | J12: =SUM(J10:J11) -> 319189

Sheet Rent Roll (MF)
B2: Rent Roll
B3: For Selected Properties
B4: As Of = 03/31/2026
B5: Month Year = 03/2026
B6: Unit | C6: Unit Type | D6: Unit | E6: Resident | F6: Name | G6: Market | H6: Actual | I6: Resident | J6: Other | K6: Move In | L6: Lease | M6: Move Out | N6: Balance
D7: Sq Ft | G7: Rent | H7: Rent | I7: Deposit | J7: Deposit | L7: Expiration
B8: Current/Notice/Vacant Residents | P8: 4Q25 Rent
B9: 501 | C9: hw0101 | D9: 461 | E9: t0002659 | F9: Yash Sinha | G9: 4000 | H9: 4050 | I9: 2025 | J9: 0 | K9: 46080 | L9: 46444 | N9: -3626.78 | P9: =+_xlfn.XLOOKUP(F9,'[15]Rent Roll (MF)'!$F:$F,'[15]Rent Roll (MF)'!$H:$H,"x") -> x
B10: 502 | C10: hw1102 | D10: 677 | E10: t0002376 | F10: Shannon Suhendra | G10: 5000 | H10: 5150 | I10: 5150 | J10: 0 | K10: 45888 | L10: 46252 | N10: 50 | P10: =+_xlfn.XLOOKUP(F10,'[15]Rent Roll (MF)'!$F:$F,'[15]Rent Roll (MF)'!$H:$H,"x") -> 5150
B11: 503 | C11: hw1103 | D11: 729 | E11: t0002341 | F11: Giebien Na | G11: 5200 | H11: 5250 | I11: 5250 | J11: 0 | K11: 45897 | L11: 46261 | N11: 0 | P11: =+_xlfn.XLOOKUP(F11,'[15]Rent Roll (MF)'!$F:$F,'[15]Rent Roll (MF)'!$H:$H,"x") -> 5250
B12: 504 | C12: hw0104 | D12: 538 | E12: t0001981 | F12: William Sauser | G12: 3700 | H12: 4275 | I12: 4175 | J12: 0 | K12: 45747 | L12: 46476 | N12: 0 | P12: =+_xlfn.XLOOKUP(F12,'[15]Rent Roll (MF)'!$F:$F,'[15]Rent Roll (MF)'!$H:$H,"x") -> 4175
B13: 505 | C13: hw2105 | D13: 735 | E13: t0002578 | F13: Danyal Khomusi | G13: 6000 | H13: 6000 | I13: 3000 | J13: 0 | K13: 46037 | L13: 46401 | N13: 0 | P13: =+_xlfn.XLOOKUP(F13,'[15]Rent Roll (MF)'!$F:$F,'[15]Rent Roll (MF)'!$H:$H,"x") -> x
B14: 506 | C14: hw1106 | D14: 583 | E14: t0001679 | F14: Miriam George | G14: 5000 | H14: 5100 | I14: 5000 | J14: 0 | K14: 45562 | L14: 46295 | N14: 0 | P14: =+_xlfn.XLOOKUP(F14,'[15]Rent Roll (MF)'!$F:$F,'[15]Rent Roll (MF)'!$H:$H,"x") -> 5100
B15: 507 | C15: hw0107 | D15: 420 | E15: t0002319 | F15: Ishika Kaushal | G15: 3950 | H15: 4100 | I15: 4100 | J15: 0 | K15: 45867 | L15: 46234 | N15: -4225 | P15: =+_xlfn.XLOOKUP(F15,'[15]Rent Roll (MF)'!$F:$F,'[15]Rent Roll (MF)'!$H:$H,"x") -> 4100
B16: 508 | C16: hw1108 | D16: 694 | E16: t0002654 | F16: Ted Chung | G16: 5250 | H16: 5300 | I16: 2650 | J16: 0 | K16: 46087 | L16: 46512 | N16: -750 | P16: =+_xlfn.XLOOKUP(F16,'[15]Rent Roll (MF)'!$F:$F,'[15]Rent Roll (MF)'!$H:$H,"x") -> x
B17: 509 | C17: hw1109 | D17: 698 | E17: VACANT | F17: VACANT | G17: 5400 | H17: 0 | I17: 0 | J17: 0 | N17: 0 | P17: =+_xlfn.XLOOKUP(F17,'[15]Rent Roll (MF)'!$F:$F,'[15]Rent Roll (MF)'!$H:$H,"x") -> 0
B18: 510 | C18: hw1110 | D18: 698 | E18: t0000625 | F18: Marc Stanke | G18: 4000 | H18: 5000 | I18: 4000 | J18: 0 | K18: 45261 | L18: 46326 | N18: 0 | P18: =+_xlfn.XLOOKUP(F18,'[15]Rent Roll (MF)'!$F:$F,'[15]Rent Roll (MF)'!$H:$H,"x") -> 5000
B19: 511 | C19: hw1111 | D19: 698 | E19: t0002411 | F19: Cooper Sherman | G19: 5170 | H19: 5170 | I19: 2585 | J19: 0 | K19: 45915 | L19: 46248 | N19: 0 | P19: =+_xlfn.XLOOKUP(F19,'[15]Rent Roll (MF)'!$F:$F,'[15]Rent Roll (MF)'!$H:$H,"x") -> 5170
B20: 512 | C20: hw0112 | D20: 456 | E20: t0002470 | F20: Kyle Taneja | G20: 3800 | H20: 3650 | I20: 1825 | J20: 0 | K20: 45960 | L20: 46324 | N20: -3775 | P20: =+_xlfn.XLOOKUP(F20,'[15]Rent Roll (MF)'!$F:$F,'[15]Rent Roll (MF)'!$H:$H,"x") -> 3650
B21: 514 | C21: hw1114 | D21: 736 | E21: t0000431 | F21: Chirag Patel | G21: 4000 | H21: 5000 | I21: 0 | J21: 0 | K21: 46055 | L21: 46539 | N21: -2625 | P21: =+_xlfn.XLOOKUP(F21,'[15]Rent Roll (MF)'!$F:$F,'[15]Rent Roll (MF)'!$H:$H,"x") -> 4500
B22: 515 | C22: hw1115 | D22: 523 | E22: t0001636 | F22: Felipe Valderrama | G22: 4750 | H22: 4820 | I22: 4750 | J22: 0 | K22: 45562 | L22: 46295 | N22: 280 | P22: =+_xlfn.XLOOKUP(F22,'[15]Rent Roll (MF)'!$F:$F,'[15]Rent Roll (MF)'!$H:$H,"x") -> 4820
B23: 516 | C23: hw1116 | D23: 662 | E23: t0001609 | F23: Soumya Mishra | G23: 5250 | H23: 5350 | I23: 5250 | J23: 0 | K23: 45541 | L23: 46295 | N23: 0 | P23: =+_xlfn.XLOOKUP(F23,'[15]Rent Roll (MF)'!$F:$F,'[15]Rent Roll (MF)'!$H:$H,"x") -> 5350
B24: 517 | C24: hw2217 | D24: 902 | E24: t0002726 | F24: Byung Park | G24: 8480 | H24: 8480 | I24: 3568.71 | J24: 0 | K24: 46097 | L24: 46461 | N24: -3838.71 | P24: =+_xlfn.XLOOKUP(F24,'[15]Rent Roll (MF)'!$F:$F,'[15]Rent Roll (MF)'!$H:$H,"x") -> x
B25: 518 | C25: hw1118 | D25: 520 | E25: t0000374 | F25: YowJen Chen | G25: 4715 | H25: 4500 | I25: 4409 | J25: 0 | K25: 45139 | L25: 46326 | N25: 0 | P25: =+_xlfn.XLOOKUP(F25,'[15]Rent Roll (MF)'!$F:$F,'[15]Rent Roll (MF)'!$H:$H,"x") -> 4500
B26: 519 | C26: hw0119 | D26: 481 | E26: t0002363 | F26: David Panangian | G26: 4250 | H26: 4000 | I26: 4000 | J26: 0 | K26: 45896 | L26: 46260 | N26: -4125 | P26: =+_xlfn.XLOOKUP(F26,'[15]Rent Roll (MF)'!$F:$F,'[15]Rent Roll (MF)'!$H:$H,"x") -> 4000
B27: 520 | C27: hw0120 | D27: 550 | E27: VACANT | F27: VACANT | G27: 3600 | H27: 0 | I27: 0 | J27: 0 | N27: 0 | P27: =+_xlfn.XLOOKUP(F27,'[15]Rent Roll (MF)'!$F:$F,'[15]Rent Roll (MF)'!$H:$H,"x") -> 0
B28: 601 | C28: hw0101 | D28: 461 | E28: t0002245 | F28: Jordan Lee | G28: 3890 | H28: 4450 | I28: 2225 | J28: 0 | K28: 45849 | L28: 46234 | N28: 0 | P28: =+_xlfn.XLOOKUP(F28,'[15]Rent Roll (MF)'!$F:$F,'[15]Rent Roll (MF)'!$H:$H,"x") -> 4450
B29: 602 | C29: hw1102 | D29: 677 | E29: t0001859 | F29: Alexander Serafine | G29: 5100 | H29: 5150 | I29: 5100 | J29: 0 | K29: 45660 | L29: 46418 | N29: 0 | P29: =+_xlfn.XLOOKUP(F29,'[15]Rent Roll (MF)'!$F:$F,'[15]Rent Roll (MF)'!$H:$H,"x") -> 5100
B30: 603 | C30: hw1103 | D30: 729 | E30: t0000015 | F30: Rina Desai | G30: 5535 | H30: 5400 | I30: 5210 | J30: 0 | K30: 44344 | L30: 46173 | M30: 46144 | N30: -5400 | P30: =+_xlfn.XLOOKUP(F30,'[15]Rent Roll (MF)'!$F:$F,'[15]Rent Roll (MF)'!$H:$H,"x") -> 5400
B31: 604 | C31: hw0104 | D31: 538 | E31: t0001864 | F31: Xueying Li | G31: 4100 | H31: 4150 | I31: 4100 | J31: 0 | K31: 45666 | L31: 46418 | N31: 0 | P31: =+_xlfn.XLOOKUP(F31,'[15]Rent Roll (MF)'!$F:$F,'[15]Rent Roll (MF)'!$H:$H,"x") -> 4100
B32: 605 | C32: hw2105 | D32: 735 | E32: t0002511 | F32: Heung Lam Chang | G32: 6900 | H32: 6000 | I32: 3000 | J32: 0 | K32: 45975 | L32: 46339 | M32: 46148 | N32: -6125 | P32: =+_xlfn.XLOOKUP(F32,'[15]Rent Roll (MF)'!$F:$F,'[15]Rent Roll (MF)'!$H:$H,"x") -> 6000
B33: 606 | C33: hw1106 | D33: 583 | E33: VACANT | F33: VACANT | G33: 5370 | H33: 0 | I33: 0 | J33: 0 | N33: 0 | P33: =+_xlfn.XLOOKUP(F33,'[15]Rent Roll (MF)'!$F:$F,'[15]Rent Roll (MF)'!$H:$H,"x") -> 0
B34: 607 | C34: hw0107 | D34: 420 | E34: t0002340 | F34: Mona Patel | G34: 3740 | H34: 4000 | I34: 4000 | J34: 0 | K34: 45876 | L34: 46240 | N34: -4125 | P34: =+_xlfn.XLOOKUP(F34,'[15]Rent Roll (MF)'!$F:$F,'[15]Rent Roll (MF)'!$H:$H,"x") -> 4000
B35: 608 | C35: hw1108 | D35: 694 | E35: t0000004 | F35: Erik Peterson | G35: 5295 | H35: 5150 | I35: 4870 | J35: 0 | K35: 44065 | L35: 46630 | N35: 0 | P35: =+_xlfn.XLOOKUP(F35,'[15]Rent Roll (MF)'!$F:$F,'[15]Rent Roll (MF)'!$H:$H,"x") -> 5150
B36: 609 | C36: hw1109 | D36: 698 | E36: t0001929 | F36: David Booth | G36: 5300 | H36: 5250 | I36: 5250 | J36: 0 | K36: 45712 | L36: 46446 | N36: 0 | P36: =+_xlfn.XLOOKUP(F36,'[15]Rent Roll (MF)'!$F:$F,'[15]Rent Roll (MF)'!$H:$H,"x") -> 5250
B37: 610 | C37: hw1110 | D37: 698 | E37: t0002684 | F37: Lawrence Goldberg | G37: 5300 | H37: 5420 | I37: 2710 | J37: 0 | K37: 46072 | L37: 46436 | N37: -3314.65 | P37: =+_xlfn.XLOOKUP(F37,'[15]Rent Roll (MF)'!$F:$F,'[15]Rent Roll (MF)'!$H:$H,"x") -> x
B38: 611 | C38: hw1111 | D38: 698 | E38: t0002306 | F38: Rhaíza Garanovschi Peres Ceolim | G38: 5000 | H38: 5400 | I38: 5400 | J38: 0 | K38: 45870 | L38: 46234 | N38: -5525 | P38: =+_xlfn.XLOOKUP(F38,'[15]Rent Roll (MF)'!$F:$F,'[15]Rent Roll (MF)'!$H:$H,"x") -> 5400
B39: 612 | C39: hw0112 | D39: 456 | E39: t0001960 | F39: Hanah Jun | G39: 4100 | H39: 4000 | I39: 4000 | J39: 0 | K39: 45747 | L39: 46111 | M39: 46122 | N39: 0 | P39: =+_xlfn.XLOOKUP(F39,'[15]Rent Roll (MF)'!$F:$F,'[15]Rent Roll (MF)'!$H:$H,"x") -> 4000
B40: 614 | C40: hw1114 | D40: 736 | E40: t0002307 | F40: Brenna Chitkara | G40: 5400 | H40: 5550 | I40: 5550 | J40: 0 | K40: 45880 | L40: 46245 | N40: 0 | P40: =+_xlfn.XLOOKUP(F40,'[15]Rent Roll (MF)'!$F:$F,'[15]Rent Roll (MF)'!$H:$H,"x") -> 5550
B41: 615 | C41: hw1115 | D41: 523 | E41: t0002715 | F41: Eesh Dadheech | G41: 4750 | H41: 4900 | I41: 2450 | J41: 0 | K41: 46079 | L41: 46502 | N41: -6686.61 | P41: =+_xlfn.XLOOKUP(F41,'[15]Rent Roll (MF)'!$F:$F,'[15]Rent Roll (MF)'!$H:$H,"x") -> x
...

Sheet Rent Roll (COMM)
B2: Rent Roll
B3: Property: 990conso From Date: 03/31/2026 By Property
B4: Property | C4: Unit(s) | D4: Lease | E4: Lease Type | F4: Area | G4: Lease From | H4: Lease To | I4: Term | J4: Monthly | K4: Annual
J5: Rent | K5: Rent | M5: 46112
M6: WALT
B7: 990comvb - VBG 990 AOA LLC,New York
B8: Current Leases
B9: 990comvb | C9: 980A | D9: 980 FOOD CORP. | E9: Retail | F9: 823 | G9: 44964 | H9: 48944 | I9: 131 | J9: 25855.29 | K9: =+J9*12 -> 310263.48 | M9: =(H9-$M$5)/365 -> 7.7589041
B10: 990comvb | C10: 980B | D10: Sanmiwago 980 Inc. | E10: Retail | F10: 799 | G10: 45166 | H10: 50801 | I10: 186 | J10: 25076.58 | K10: =+J10*12 -> 300918.96 | M10: =(H10-$M$5)/365 -> 12.846575
B11: 990comvb | C11: 980C | D11: Daebak Shinhwa Inc | E11: Retail | F11: 931 | G11: 44679 | H11: 48610 | I11: 130 | J11: 35513.63 | K11: =+J11*12 -> 426163.56 | M11: =(H11-$M$5)/365 -> 6.8438356
B12: 990comvb | C12: 986 | D12: OAKBERRY MIDTOWN EAST LLC | E12: Retail | F12: 466 | G12: 45078 | H12: 48852 | I12: 124 | J12: 14852.6 | K12: =+J12*12 -> 178231.2 | M12: =(H12-$M$5)/365 -> 7.5068493
B13: 990comvb | C13: 988 | D13: Teso Mini | E13: Retail | F13: 1606 | G13: 45204 | H13: 48975 | I13: 124 | J13: 32357.45 | K13: =+J13*12 -> 388289.4 | M13: =(H13-$M$5)/365 -> 7.8438356
B14: 990comvb | C14: 992 | D14: I Milky Management INC | E14: Retail | F14: 558 | G14: 43770 | H14: 47879 | I14: 135 | J14: 19433.2 | K14: =+J14*12 -> 233198.4 | M14: =(H14-$M$5)/365 -> 4.8410959
B15: 990comvb | C15: 994 | D15: Krispy Kreme Doughnut Corporation # 205 | E15: Retail | F15: 557 | G15: 43585 | H15: 49368 | I15: 191 | J15: 19398.37 | K15: =+J15*12 -> 232780.44 | M15: =(H15-$M$5)/365 -> 8.9205479
B16: 990comvb | C16: 996 | D16: Panks Private Corporation | E16: Retail | F16: 2077 | G16: 43617 | H16: 47452 | I16: 126 | J16: 58739 | K16: =+J16*12 -> 704868 | M16: =(H16-$M$5)/365 -> 3.6712329
B17: 990comvb | C17: 1I-MEZZ | D17: VACANT | F17: 870 | I17: 0 | J17: 0 | K17: =+J17*12 -> 0
B18: Total Current | F18: =+SUM(F9:F17) -> 8687 | J18: =+SUM(J9:J17) -> 231226.12 | K18: =+SUM(K9:K17) -> 2774713.4 | M18: =SUMPRODUCT(M9:M16,F9:F16)/SUM(F9:F16) -> 6.960755
B21: 990prkvb - VBG 990 AOA LLC,New York
B22: Current Leases | N22: Comm Occupancy | O22: =SUM(F9:F16)/F18 -> 0.89985035
B23: 990prkvb | C23: 1H | D23: 990 6th Avenue Garage LLC | E23: Parking | F23: 33523 | G23: 44129 | H23: 46477 | I23: 78 | J23: 50000 | K23: 600000
B24: Total Current | F24: 33523 | J24: 50000 | K24: 600000

Sheet Insurance
H1: 25/26 Premium | I1: 605061
H4: From | I4: 45930
H5: To | I5: =+I4+365 -> 46295

Sheet RE Tax
J1: ="Taxes paid through" & TEXT(' OSAR'!$G$6," mm/dd/yyy") -> Taxes paid through 12/31/2025 | K1: 3441526.6
AD2: Taxes due: | AE2: 0
J3: 45839 | K3: From
J4: =+J3+364 -> 46203 | K4: To

Sheet UW
B1: IP & MTM CASH FLOW
B2: Quincy & Hollingsworth
B3: Investment Year | C3: T-12 | D3: T-12 | E3: T-12 | F3: In-Place | G3: Comments | H3: MTM | I3: Comments | K3: 1 | L3: 1 | M3: 1 | N3: 2 | O3: 3 | P3: 4 | Q3: 5 | R3: 6 | S3: 7 | T3: 8 | U3: 9 | V3: 10 | W3: 11 | X3: 12 | Y3: 13 | Z3: 14 | AA3: 15 | AB3: 16 | AC3: 17 | AD3: 18 | AE3: 19 | AF3: 20 | AG3: 21 | AJ3: T-12 | AK3: T-12 Manual | AL3: T-6 Annualized | AM3: T-3 Annualized
B4: Year Ending | K4: $/SF | L4: $/Unit | M4: 46295 | N4: 46660 | O4: 47026 | P4: 47391 | Q4: 47756 | R4: 48121 | S4: 48487 | T4: 48852 | U4: 49217 | V4: 49582 | W4: 49948 | X4: 50313 | Y4: 50678 | Z4: 51043 | AA4: 51409 | AB4: 51774 | AC4: 52139 | AD4: 52504 | AE4: 52870 | AF4: 53235 | AG4: N/A
M5: 107.09866 | N5: 112.11664 | O5: 115.48014 | P5: 118.94454 | Q5: 122.51288 | R5: 126.18826 | S5: 129.97391
B6: INCOME | C6: $/SF | D6: $/Unit | E6: $ Gross | F6: $ Gross | H6: $ Gross | K6: $/SF | L6: $/Unit | AP6: UW Year 1 | AQ6: Current | AS6: VAR % | AT6: VAR $
B7: Potential Rental Revenue | C7: 79.142305 | D7: 48179.226 | E7: 21921548 | F7: 28640482 | G7: 103.39935 | H7: 30534159 | I7: 110.236 | K7: 107.13964 | L7: 65223.083 | M7: 29676503 | N7: 31066959 | O7: 31998968 | P7: 32958937 | Q7: 33947705 | R7: 34966136 | S7: 36015120 | T7: 37095574 | U7: 38208441 | V7: 39354695 | W7: 40535335 | X7: 41751395 | Y7: 0 | Z7: 0 | AA7: 0 | AB7: 0 | AC7: 0 | AD7: 0 | AE7: 0 | AF7: 0 | AG7: 0 | AJ7: 21921548 | AK7: 0 | AL7: 23103085 | AM7: 24571451
B8: Loss To Lease | C8: 0 | D8: 0 | E8: 0 | F8: 0 | G8: - | H8: 0 | I8: - | K8: -2.2911194 | L8: -1394.758 | M8: -634614.88 | N8: -553282.57 | O8: -429447.79 | P8: -442331.22 | Q8: -455601.16 | R8: -469269.19 | S8: -483347.27 | T8: -497847.69 | U8: -512783.12 | V8: -528166.61 | W8: -544011.61 | X8: -560331.96 | Y8: 0 | Z8: 0 | AA8: 0 | AB8: 0 | AC8: 0 | AD8: 0 | AE8: 0 | AF8: 0 | AG8: 0 | AJ8: 0 | AK8: 0 | AL8: 0 | AM8: 0 | AO8: INCOME:
A9: Gross Potential Rent (3) | B9: Scheduled Base Rental Revenue | C9: 79.142305 | D9: 48179.226 | E9: 21921548 | F9: 28640482 | H9: 30534159 | K9: 104.84852 | L9: 63828.325 | M9: 29041888 | N9: 30513677 | O9: 31569520 | P9: 32516606 | Q9: 33492104 | R9: 34496867 | S9: 35531773 | T9: 36597726 | U9: 37695658 | V9: 38826528 | W9: 39991324 | X9: 41191064 | Y9: 0 | Z9: 0 | AA9: 0 | AB9: 0 | AC9: 0 | AD9: 0 | AE9: 0 | AF9: 0 | AG9: 0 | AJ9: 21921548 | AK9: 0 | AL9: 23103085 | AM9: 24571451 | AO9: Number of Mos. Covered
A10: Commercial Income | B10: Commerical Income | D10: 6597.3025 | E10: 3001772.6 | F10: 2816135.1 | G10: Year 1 | H10: 2816135.1 | I10: Year 1 | K10: 10.166956 | L10: 6189.3079 | M10: 2816135.1 | N10: 3061480.5 | O10: 3196818.9 | P10: 3349627.2 | Q10: 3551449.5 | R10: 3525657.3 | S10: 3635641.8 | T10: 3744711.1 | U10: 3857052.4 | V10: 3972764 | W10: 4091946.9 | X10: 4214705.3 | AO10: Period Ended
A11: Other Income | B11: Other Income | C11: 5.6840306 | D11: 3460.2504 | E11: 1574413.9 | F11: 2125510.6 | G11: Year 1 | H11: 2125510.6 | I11: Year 1 | K11: 7.6736281 | L11: 4671.4518 | M11: 2125510.6 | N11: 2189275.9 | O11: 2254954.2 | P11: 2322602.8 | Q11: 2392280.9 | R11: 2464049.3 | S11: 2537970.8 | T11: 2614109.9 | U11: 2692533.2 | V11: 2773309.2 | W11: 6948455.4 | X11: 7156909 | Y11: 0 | Z11: 0 | AA11: 0 | AB11: 0 | AC11: 0 | AD11: 0 | AE11: 0 | AF11: 0 | AG11: 0 | AJ11: 4576186.6 | AK11: 0 | AL11: 4615272.4 | AM11: 4352092.8 | AO11: Statement Ending Date
B12: Potential Gross Income | C12: 95.66349 | D12: 58236.779 | E12: 26497735 | F12: 33582127 | H12: 35475805 | K12: 122.68911 | L12: 74689.085 | M12: 33983534 | N12: 35764433 | O12: 37021293 | P12: 38188836 | Q12: 39435834 | R12: 40486574 | S12: 41705386 | T12: 42956547 | U12: 44245244 | V12: 45572601 | W12: 51031726 | X12: 52562678 | Y12: 0 | Z12: 0 | AA12: 0 | AB12: 0 | AC12: 0 | AD12: 0 | AE12: 0 | AF12: 0 | AG12: 0 | AJ12: 26497735 | AK12: 0 | AL12: 27718357 | AM12: 28923544 | AO12: Gross Potential Rent (3) | AP12: =SUMIF(A:A,$AO12,$M:$M) -> 29041888 | AQ12: =SUMIF(' OSAR'!D:D,UW!$AO12,' OSAR'!O:O) -> 27270606 | AS12: =IFERROR(IF(ISNUMBER(AT12),AT12/AP12,""),"") -> -0.060990588 | AT12: =IF(ISNUMBER(AQ12),AQ12-AP12,"") -> -1771281.8
A13: Less: Vacancy Loss | B13: Minus: Vacancy | C13: 0 | D13: 0 | E13: 0 | F13: -1674366.6 | G13: 0.058461538 | H13: -916024.77 | I13: 0.03 | K13: -3.1454557 | L13: -1914.8497 | M13: -871256.63 | N13: -915410.3 | O13: -947085.61 | P13: -975498.18 | Q13: -1004763.1 | R13: -1034906 | S13: -1065953.2 | T13: -1097931.8 | U13: -1130869.7 | V13: -1164795.8 | W13: -1199739.7 | X13: -1235731.9 | Y13: 0 | Z13: 0 | AA13: 0 | AB13: 0 | AC13: 0 | AD13: 0 | AE13: 0 | AF13: 0 | AG13: 0 | AJ13: 0 | AK13: 0 | AL13: 0 | AM13: 0 | AO13: Less: Vacancy Loss | AP13: =SUMIF(A:A,$AO13,$M:$M) -> -871256.63 | AQ13: =SUMIF(' OSAR'!D:D,UW!$AO13,' OSAR'!O:O) -> 0 | AS13: =IF(ISNUMBER(AT13),AT13/AP13,"") -> -1 | AT13: =IF(ISNUMBER(AQ13),AQ13-AP13,"") -> 871256.63
A14: Other Income | B14: Minus: Credit Loss | C14: -0.54869204 | D14: -334.02563 | E14: -151981.66 | F14: -151981.66 | G14: 0.005306533 | H14: -76335.398 | I14: 0.0025 | K14: -0.26212131 | L14: -159.57081 | M14: -72604.72 | N14: -76284.192 | O14: -78923.801 | P14: -81291.515 | Q14: -83730.26 | R14: -86242.168 | S14: -88829.433 | T14: -91494.316 | U14: -94239.146 | V14: -97066.32 | W14: -99978.309 | X14: -102977.66 | Y14: 0 | Z14: 0 | AA14: 0 | AB14: 0 | AC14: 0 | AD14: 0 | AE14: 0 | AF14: 0 | AG14: 0 | AJ14: -151981.66 | AK14: 0 | AL14: -192131.98 | AM14: -536000.12 | AO14: OR | AP14: =SUMIF(A:A,$AO14,$M:$M) -> 0 | AS14: =IF(ISNUMBER(AT14),AT14/AP14,"") | AT14: =IF(ISNUMBER(AQ14),AQ14-AP14,"")
A15: Other Income | B15: Minus: Model Unit | C15: -0.38990718 | D15: -237.36264 | E15: -108000 | F15: -62946.113 | G15: 1 | H15: -67108.042 | I15: 1 | K15: -0.23043632 | L15: -140.28203 | M15: -63828.325 | N15: -67063.026 | O15: -69383.561 | P15: -71465.068 | Q15: -73609.02 | R15: -75817.291 | S15: -78091.809 | T15: -80434.564 | U15: -82847.6 | V15: -85333.028 | W15: -87893.019 | X15: -90529.81 | Y15: 0 | Z15: 0 | AA15: 0 | AB15: 0 | AC15: 0 | AD15: 0 | AE15: 0 | AF15: 0 | AG15: 0 | AJ15: -108000 | AK15: 0 | AL15: -108000 | AM15: -108000 | AO15: Commercial Income | AP15: =SUMIF(A:A,$AO15,$M:$M) -> 2816135.1 | AQ15: =SUMIF(' OSAR'!D:D,UW!$AO15,' OSAR'!O:O) -> 2774713.4 | AS15: =IFERROR(IF(ISNUMBER(AT15),AT15/AP15,""),"") -> -0.014708691 | AT15: =IF(ISNUMBER(AQ15),AQ15-AP15,"") -> -41421.66
A16: Other Income | B16: Minus: Concessions Initial Lease Up | C16: -9.4885566 | D16: -5776.3205 | E16: -2628225.8 | F16: 0 | G16: - | H16: 0 | I16: - | K16: 0 | L16: 0 | M16: 0 | N16: 0 | O16: 0 | P16: 0 | Q16: 0 | R16: 0 | S16: 0 | T16: 0 | U16: 0 | V16: 0 | W16: 0 | X16: 0 | Y16: 0 | Z16: 0 | AA16: 0 | AB16: 0 | AC16: 0 | AD16: 0 | AE16: 0 | AF16: 0 | AG16: 0 | AJ16: -2628225.8 | AK16: 0 | AL16: -2703024.5 | AM16: -2540778 | AO16: Less: Vacancy Loss © | AP16: =SUMIF(A:A,$AO16,$M:$M) -> 0 | AQ16: =SUMIF(' OSAR'!D:D,UW!$AO16,' OSAR'!O:O) -> 0 | AS16: =IFERROR(IF(ISNUMBER(AT16),AT16/AP16,""),"") | AT16: =IF(ISNUMBER(AQ16),AQ16-AP16,"") -> 0
A17: Other Income | B17: Minus: Concessions Ongoing | C17: 0 | D17: 0 | E17: 0 | F17: -2540778 | G17: 1.0645539 | H17: 0 | I17: 0 | K17: -13.017589 | L17: -7924.6789 | M17: -3605728.9 | N17: -1941626.9 | O17: 0 | P17: 0 | Q17: 0 | R17: 0 | S17: 0 | T17: 0 | U17: 0 | V17: 0 | W17: 0 | X17: 0 | Y17: 0 | Z17: 0 | AA17: 0 | AB17: 0 | AC17: 0 | AD17: 0 | AE17: 0 | AF17: 0 | AG17: 0 | AJ17: 0 | AK17: 0 | AL17: 0 | AM17: 0 | AO17: Laundry/Vending Income | AP17: =SUMIF(A:A,$AO17,$M:$M) -> 0 | AQ17: =SUMIF(' OSAR'!D:D,UW!$AO17,' OSAR'!O:O) -> 0 | AS17: =IFERROR(IF(ISNUMBER(AT17),AT17/AP17,""),"") | AT17: =IF(ISNUMBER(AQ17),AQ17-AP17,"") -> 0
B18: Effective Gross Income | C18: 85.236335 | D18: 51889.07 | E18: 23609527 | F18: 29152055 | H18: 34416336 | K18: 106.03351 | L18: 64549.703 | M18: 29370115 | N18: 32764049 | O18: 35925900 | P18: 37060581 | Q18: 38273732 | R18: 39289608 | S18: 40472511 | T18: 41686687 | U18: 42937287 | V18: 44225406 | W18: 49644115 | X18: 51133438 | Y18: 0 | Z18: 0 | AA18: 0 | AB18: 0 | AC18: 0 | AD18: 0 | AE18: 0 | AF18: 0 | AG18: 0 | AJ18: 23609527 | AK18: 0 | AL18: 24715201 | AM18: 25738766 | AO18: Parking Income | AP18: =SUMIF(A:A,$AO18,$M:$M) -> 0 | AQ18: =SUMIF(' OSAR'!D:D,UW!$AO18,' OSAR'!O:O) -> 600000 | AS18: =IFERROR(IF(ISNUMBER(AT18),AT18/AP18,""),"") | AT18: =IF(ISNUMBER(AQ18),AQ18-AP18,"") -> 600000
M19: 0.007480093 | N19: 0.11555739 | O19: 0.096503693 | P19: 0.031583919 | Q19: 0.032734266 | R19: 0.026542389 | AO19: Other Income | AP19: =SUMIF(A:A,$AO19,$M:$M) -> -1616651.4 | AQ19: =SUMIF(' OSAR'!D:D,UW!$AO19,' OSAR'!O:O) -> -230307.58 | AS19: =IFERROR(IF(ISNUMBER(AT19),AT19/AP19,""),"") -> -0.85754035 | AT19: =IF(ISNUMBER(AQ19),AQ19-AP19,"") -> 1386343.8
B20: OPERATING EXPENSES | C20: $/SF | D20: $/Unit | E20: $ Gross | F20: $ Gross | H20: $ Gross | K20: $/SF | L20: $/Unit | AS20: =IF(ISNUMBER(AT20),AT20/AP20,"") | AT20: =IF(ISNUMBER(AQ20),AQ20-AP20,"")
A21: Payroll & Benefits | B21: Payroll | C21: 1.8652456 | D21: 1135.5 | E21: 516652.5 | F21: 628788.67 | G21: Year 1 | H21: 628788.67 | I21: Year 1 | K21: 2.2700854 | L21: 1381.9531 | M21: 628788.67 | N21: 647652.33 | O21: 667081.9 | P21: 687094.36 | Q21: 707707.19 | R21: 728938.41 | S21: 750806.56 | T21: 773330.76 | U21: 796530.68 | V21: 820426.6 | W21: 845039.4 | X21: 870390.58 | Y21: 0 | Z21: 0 | AA21: 0 | AB21: 0 | AC21: 0 | AD21: 0 | AE21: 0 | AF21: 0 | AG21: 0 | AJ21: 516652.5 | AK21: 0 | AL21: 300552.52 | AM21: 298921.16 | AO21: *Effective Gross Income | AP21: =SUM(AP12:AP19) -> 29370115 | AQ21: =SUM(AQ12:AQ19) -> 30415012 | AS21: =IFERROR(IF(ISNUMBER(AT21),AT21/AP21,""),"") -> 0.035576876 | AT21: =IF(ISNUMBER(AQ21),AQ21-AP21,"") -> 1044896.9
B22: Employee Units | C22: 0 | D22: 0 | E22: 0 | F22: 0 | G22: Year 1 | H22: 0 | I22: Year 1 | K22: 0 | L22: 0 | M22: 0 | N22: 0 | O22: 0 | P22: 0 | Q22: 0 | R22: 0 | S22: 0 | T22: 0 | U22: 0 | V22: 0 | W22: 0 | X22: 0 | Y22: 0 | Z22: 0 | AA22: 0 | AB22: 0 | AC22: 0 | AD22: 0 | AE22: 0 | AF22: 0 | AG22: 0 | AJ22: 0 | AK22: 0 | AL22: 0 | AM22: 0 | AS22: =IF(ISNUMBER(AT22),AT22/AP22,"") | AT22: =IF(ISNUMBER(AQ22),AQ22-AP22,"")
A23: Advertising & Marketing | B23: Marketing | C23: 0.8439851 | D23: 513.79031 | E23: 233774.59 | F23: 105422.37 | G23: Year 1 | H23: 105422.37 | I23: Year 1 | K23: 0.38060128 | L23: 231.69751 | M23: 105422.37 | N23: 108585.04 | O23: 111842.59 | P23: 115197.87 | Q23: 118653.8 | R23: 122213.42 | S23: 125879.82 | T23: 129656.22 | U23: 133545.9 | V23: 137552.28 | W23: 141678.85 | X23: 145929.21 | Y23: 0 | Z23: 0 | AA23: 0 | AB23: 0 | AC23: 0 | AD23: 0 | AE23: 0 | AF23: 0 | AG23: 0 | AJ23: 233774.59 | AK23: 0 | AL23: 122914.18 | AM23: 94312.56 | AS23: =IF(ISNUMBER(AT23),AT23/AP23,"") | AT23: =IF(ISNUMBER(AQ23),AQ23-AP23,"")
A24: General and Administrative | B24: General & Admin. | C24: 1.2472661 | D24: 759.29446 | E24: 345478.98 | F24: 230687.46 | G24: Year 1 | H24: 230687.46 | I24: Year 1 | K24: 0.83283977 | L24: 507.0054 | M24: 230687.46 | N24: 237608.08 | O24: 244736.32 | P24: 252078.41 | Q24: 259640.76 | R24: 267429.99 | S24: 275452.89 | T24: 283716.47 | U24: 292227.97 | V24: 300994.81 | W24: 310024.65 | X24: 319325.39 | Y24: 0 | Z24: 0 | AA24: 0 | AB24: 0 | AC24: 0 | AD24: 0 | AE24: 0 | AF24: 0 | AG24: 0 | AJ24: 345478.98 | AK24: 0 | AL24: 418691.58 | AM24: 406850.28 | AO24: OPERATING EXPENSES: | AS24: =IFERROR(IF(ISNUMBER(AT24),AT24/AP24,""),"") | AT24: =IF(ISNUMBER(AQ24),AQ24-AP24,"")
